package fr.toss.common.world.bioms.deco;

import java.util.Random;

import net.minecraft.block.Block;
import net.minecraft.enchantment.Enchantment;
import net.minecraft.enchantment.EnchantmentData;
import net.minecraft.init.Blocks;
import net.minecraft.init.Items;
import net.minecraft.item.ItemStack;
import net.minecraft.tileentity.TileEntityChest;
import net.minecraft.world.World;
import net.minecraft.world.chunk.IChunkProvider;
import cpw.mods.fml.common.IWorldGenerator;
import fr.toss.common.Main;
import fr.toss.common.entity.EntityVillagerDim;
import fr.toss.common.register.BlockRegister;
import fr.toss.common.register.ItemRegister;

public class WorldGenFloatingHouse implements IWorldGenerator {
	
	public World world;
	public Random rand;

	@Override
	public void generate(Random r, int chunkX, int chunkZ, World w, IChunkProvider chunkGenerator, IChunkProvider chunkProvider) 
	{
		if (r.nextInt(260) == 0 && w.provider.dimensionId == Main.DIM_ID)
		{
			int x = chunkX * 16 + r.nextInt(16);
			int z = chunkZ * 16 + r.nextInt(16);
			int y = 90 + r.nextInt(20);	
		    int X = x;
		    int Z = z;
		    
			this.world = w;
			this.rand = r;
			
			world.setBlock(x+9, y+0, z+4, BlockRegister.LEAVES);
			world.setBlockMetadataWithNotify(x+9, y+0, z+4, 1, 2);
			world.setBlock(x+10, y+0, z+4, BlockRegister.LEAVES);
			world.setBlockMetadataWithNotify(x+10, y+0, z+4, 1, 2);
			world.setBlock(x+8, y+0, z+5, BlockRegister.LEAVES);
			world.setBlockMetadataWithNotify(x+8, y+0, z+5, 1, 2);
			world.setBlock(x+19, y+0, z+5, BlockRegister.LEAVES);
			world.setBlockMetadataWithNotify(x+19, y+0, z+5, 1, 2);
			world.setBlock(x+20, y+0, z+5, BlockRegister.LEAVES);
			world.setBlockMetadataWithNotify(x+20, y+0, z+5, 1, 2);
			world.setBlock(x+22, y+0, z+6, BlockRegister.LEAVES);
			world.setBlockMetadataWithNotify(x+22, y+0, z+6, 1, 2);
			world.setBlock(x+23, y+0, z+7, BlockRegister.LEAVES);
			world.setBlockMetadataWithNotify(x+23, y+0, z+7, 1, 2);
			world.setBlock(x+3, y+0, z+9, BlockRegister.LEAVES);
			world.setBlockMetadataWithNotify(x+3, y+0, z+9, 1, 2);
			world.setBlock(x+3, y+0, z+10, BlockRegister.LEAVES);
			world.setBlockMetadataWithNotify(x+3, y+0, z+10, 1, 2);
			world.setBlock(x+3, y+0, z+11, BlockRegister.LEAVES);
			world.setBlockMetadataWithNotify(x+3, y+0, z+11, 1, 2);
			world.setBlock(x+26, y+0, z+13, BlockRegister.LEAVES);
			world.setBlockMetadataWithNotify(x+26, y+0, z+13, 1, 2);
			world.setBlock(x+3, y+0, z+14, BlockRegister.LEAVES);
			world.setBlockMetadataWithNotify(x+3, y+0, z+14, 1, 2);
			world.setBlock(x+4, y+0, z+14, BlockRegister.LEAVES);
			world.setBlockMetadataWithNotify(x+4, y+0, z+14, 1, 2);
			world.setBlock(x+5, y+0, z+14, BlockRegister.LEAVES);
			world.setBlockMetadataWithNotify(x+5, y+0, z+14, 1, 2);
			world.setBlock(x+26, y+0, z+14, BlockRegister.LEAVES);
			world.setBlockMetadataWithNotify(x+26, y+0, z+14, 1, 2);
			world.setBlock(x+4, y+0, z+15, BlockRegister.LEAVES);
			world.setBlockMetadataWithNotify(x+4, y+0, z+15, 1, 2);
			world.setBlock(x+5, y+0, z+15,Blocks.packed_ice);
			world.setBlock(x+26, y+0, z+15, BlockRegister.LEAVES);
			world.setBlockMetadataWithNotify(x+26, y+0, z+15, 1, 2);
			world.setBlock(x+2, y+0, z+19, BlockRegister.LEAVES);
			world.setBlockMetadataWithNotify(x+2, y+0, z+19, 1, 2);
			world.setBlock(x+2, y+0, z+20, BlockRegister.LEAVES);
			world.setBlockMetadataWithNotify(x+2, y+0, z+20, 1, 2);
			world.setBlock(x+1, y+0, z+21, BlockRegister.LEAVES);
			world.setBlockMetadataWithNotify(x+1, y+0, z+21, 1, 2);
			world.setBlock(x+22, y+0, z+23, BlockRegister.LEAVES);
			world.setBlockMetadataWithNotify(x+22, y+0, z+23, 1, 2);
			world.setBlock(x+22, y+0, z+24, BlockRegister.LEAVES);
			world.setBlockMetadataWithNotify(x+22, y+0, z+24, 1, 2);
			world.setBlock(x+21, y+0, z+25, BlockRegister.LEAVES);
			world.setBlockMetadataWithNotify(x+21, y+0, z+25, 1, 2);
			world.setBlock(x+6, y+0, z+28, BlockRegister.LEAVES);
			world.setBlockMetadataWithNotify(x+6, y+0, z+28, 1, 2);
			world.setBlock(x+8, y+0, z+28, BlockRegister.LEAVES);
			world.setBlockMetadataWithNotify(x+8, y+0, z+28, 1, 2);
			world.setBlock(x+9, y+0, z+28, BlockRegister.LEAVES);
			world.setBlockMetadataWithNotify(x+9, y+0, z+28, 1, 2);
			world.setBlock(x+10, y+0, z+28, BlockRegister.LEAVES);
			world.setBlockMetadataWithNotify(x+10, y+0, z+28, 1, 2);
			world.setBlock(x+7, y+0, z+29, BlockRegister.LEAVES);
			world.setBlockMetadataWithNotify(x+7, y+0, z+29, 1, 2);
			world.setBlock(x+14, y+0, z+30, BlockRegister.LEAVES);
			world.setBlockMetadataWithNotify(x+14, y+0, z+30, 1, 2);
			world.setBlock(x+15, y+0, z+30, BlockRegister.LEAVES);
			world.setBlockMetadataWithNotify(x+15, y+0, z+30, 1, 2);
			world.setBlock(x+16, y+0, z+30, BlockRegister.LEAVES);
			world.setBlockMetadataWithNotify(x+16, y+0, z+30, 1, 2);
			world.setBlock(x+27, y+0, z+31, Blocks.snow);
			world.setBlock(x+9, y+1, z+4, BlockRegister.LEAVES);
			world.setBlockMetadataWithNotify(x+9, y+1, z+4, 1, 2);
			world.setBlock(x+10, y+1, z+4, BlockRegister.LEAVES);
			world.setBlockMetadataWithNotify(x+10, y+1, z+4, 1, 2);
			world.setBlock(x+8, y+1, z+5, BlockRegister.LEAVES);
			world.setBlockMetadataWithNotify(x+8, y+1, z+5, 1, 2);
			world.setBlock(x+19, y+1, z+5, BlockRegister.LEAVES);
			world.setBlockMetadataWithNotify(x+19, y+1, z+5, 1, 2);
			world.setBlock(x+20, y+1, z+5, BlockRegister.LEAVES);
			world.setBlockMetadataWithNotify(x+20, y+1, z+5, 1, 2);
			world.setBlock(x+13, y+1, z+6, Blocks.snow);
			world.setBlock(x+22, y+1, z+6, BlockRegister.LEAVES);
			world.setBlockMetadataWithNotify(x+22, y+1, z+6, 1, 2);
			world.setBlock(x+23, y+1, z+7, BlockRegister.LEAVES);
			world.setBlockMetadataWithNotify(x+23, y+1, z+7, 1, 2);
			world.setBlock(x+9, y+1, z+8, Blocks.snow);
			world.setBlock(x+3, y+1, z+9, BlockRegister.LEAVES);
			world.setBlockMetadataWithNotify(x+3, y+1, z+9, 1, 2);
			world.setBlock(x+3, y+1, z+10, BlockRegister.LEAVES);
			world.setBlockMetadataWithNotify(x+3, y+1, z+10, 1, 2);
			world.setBlock(x+3, y+1, z+11, BlockRegister.LEAVES);
			world.setBlockMetadataWithNotify(x+3, y+1, z+11, 1, 2);
			world.setBlock(x+6, y+1, z+13, Blocks.snow);
			world.setBlock(x+26, y+1, z+13, BlockRegister.LEAVES);
			world.setBlockMetadataWithNotify(x+26, y+1, z+13, 1, 2);
			world.setBlock(x+3, y+1, z+14, BlockRegister.LEAVES);
			world.setBlockMetadataWithNotify(x+3, y+1, z+14, 1, 2);
			world.setBlock(x+4, y+1, z+14, BlockRegister.LEAVES);
			world.setBlockMetadataWithNotify(x+4, y+1, z+14, 1, 2);
			world.setBlock(x+5, y+1, z+14, BlockRegister.LEAVES);
			world.setBlockMetadataWithNotify(x+5, y+1, z+14, 1, 2);
			world.setBlock(x+26, y+1, z+14, BlockRegister.LEAVES);
			world.setBlockMetadataWithNotify(x+26, y+1, z+14, 1, 2);
			world.setBlock(x+4, y+1, z+15, BlockRegister.LEAVES);
			world.setBlockMetadataWithNotify(x+4, y+1, z+15, 1, 2);
			world.setBlock(x+5, y+1, z+15,Blocks.packed_ice);
			world.setBlock(x+26, y+1, z+15, BlockRegister.LEAVES);
			world.setBlockMetadataWithNotify(x+26, y+1, z+15, 1, 2);
			world.setBlock(x+2, y+1, z+19, BlockRegister.LEAVES);
			world.setBlockMetadataWithNotify(x+2, y+1, z+19, 1, 2);
			world.setBlock(x+2, y+1, z+20, BlockRegister.LEAVES);
			world.setBlockMetadataWithNotify(x+2, y+1, z+20, 1, 2);
			world.setBlock(x+1, y+1, z+21, BlockRegister.LEAVES);
			world.setBlockMetadataWithNotify(x+1, y+1, z+21, 1, 2);
			world.setBlock(x+22, y+1, z+23, BlockRegister.LEAVES);
			world.setBlockMetadataWithNotify(x+22, y+1, z+23, 1, 2);
			world.setBlock(x+22, y+1, z+24, BlockRegister.LEAVES);
			world.setBlockMetadataWithNotify(x+22, y+1, z+24, 1, 2);
			world.setBlock(x+21, y+1, z+25, BlockRegister.LEAVES);
			world.setBlockMetadataWithNotify(x+21, y+1, z+25, 1, 2);
			world.setBlock(x+6, y+1, z+28, BlockRegister.LEAVES);
			world.setBlockMetadataWithNotify(x+6, y+1, z+28, 1, 2);
			world.setBlock(x+8, y+1, z+28, BlockRegister.LEAVES);
			world.setBlockMetadataWithNotify(x+8, y+1, z+28, 1, 2);
			world.setBlock(x+9, y+1, z+28, BlockRegister.LEAVES);
			world.setBlockMetadataWithNotify(x+9, y+1, z+28, 1, 2);
			world.setBlock(x+10, y+1, z+28, BlockRegister.LEAVES);
			world.setBlockMetadataWithNotify(x+10, y+1, z+28, 1, 2);
			world.setBlock(x+7, y+1, z+29, BlockRegister.LEAVES);
			world.setBlockMetadataWithNotify(x+7, y+1, z+29, 1, 2);
			world.setBlock(x+8, y+1, z+29, BlockRegister.LEAVES);
			world.setBlockMetadataWithNotify(x+8, y+1, z+29, 1, 2);
			world.setBlock(x+14, y+1, z+30, BlockRegister.LEAVES);
			world.setBlockMetadataWithNotify(x+14, y+1, z+30, 1, 2);
			world.setBlock(x+15, y+1, z+30, BlockRegister.LEAVES);
			world.setBlockMetadataWithNotify(x+15, y+1, z+30, 1, 2);
			world.setBlock(x+16, y+1, z+30, BlockRegister.LEAVES);
			world.setBlockMetadataWithNotify(x+16, y+1, z+30, 1, 2);
			world.setBlock(x+9, y+2, z+4, BlockRegister.LEAVES);
			world.setBlockMetadataWithNotify(x+9, y+2, z+4, 1, 2);
			world.setBlock(x+10, y+2, z+4, BlockRegister.LEAVES);
			world.setBlockMetadataWithNotify(x+10, y+2, z+4, 1, 2);
			world.setBlock(x+8, y+2, z+5, BlockRegister.LEAVES);
			world.setBlockMetadataWithNotify(x+8, y+2, z+5, 1, 2);
			world.setBlock(x+19, y+2, z+5, BlockRegister.LEAVES);
			world.setBlockMetadataWithNotify(x+19, y+2, z+5, 1, 2);
			world.setBlock(x+20, y+2, z+5, BlockRegister.LEAVES);
			world.setBlockMetadataWithNotify(x+20, y+2, z+5, 1, 2);
			world.setBlock(x+13, y+2, z+6, Blocks.snow);
			world.setBlock(x+22, y+2, z+6, BlockRegister.LEAVES);
			world.setBlockMetadataWithNotify(x+22, y+2, z+6, 1, 2);
			world.setBlock(x+12, y+2, z+7,Blocks.packed_ice);
			world.setBlock(x+23, y+2, z+7, BlockRegister.LEAVES);
			world.setBlockMetadataWithNotify(x+23, y+2, z+7, 1, 2);
			world.setBlock(x+9, y+2, z+8, Blocks.snow);
			world.setBlock(x+20, y+2, z+8,Blocks.packed_ice);
			world.setBlock(x+3, y+2, z+9, BlockRegister.LEAVES);
			world.setBlockMetadataWithNotify(x+3, y+2, z+9, 1, 2);
			world.setBlock(x+3, y+2, z+10, BlockRegister.LEAVES);
			world.setBlockMetadataWithNotify(x+3, y+2, z+10, 1, 2);
			world.setBlock(x+7, y+2, z+10, Blocks.snow);
			world.setBlock(x+22, y+2, z+10, Blocks.snow);
			world.setBlock(x+3, y+2, z+11, BlockRegister.LEAVES);
			world.setBlockMetadataWithNotify(x+3, y+2, z+11, 1, 2);
			world.setBlock(x+7, y+2, z+12, Blocks.snow);
			world.setBlock(x+6, y+2, z+13, Blocks.snow);
			world.setBlock(x+26, y+2, z+13, BlockRegister.LEAVES);
			world.setBlockMetadataWithNotify(x+26, y+2, z+13, 1, 2);
			world.setBlock(x+3, y+2, z+14, BlockRegister.LEAVES);
			world.setBlockMetadataWithNotify(x+3, y+2, z+14, 1, 2);
			world.setBlock(x+4, y+2, z+14, BlockRegister.LEAVES);
			world.setBlockMetadataWithNotify(x+4, y+2, z+14, 1, 2);
			world.setBlock(x+5, y+2, z+14, BlockRegister.LEAVES);
			world.setBlockMetadataWithNotify(x+5, y+2, z+14, 1, 2);
			world.setBlock(x+26, y+2, z+14, BlockRegister.LEAVES);
			world.setBlockMetadataWithNotify(x+26, y+2, z+14, 1, 2);
			world.setBlock(x+4, y+2, z+15, BlockRegister.LEAVES);
			world.setBlockMetadataWithNotify(x+4, y+2, z+15, 1, 2);
			world.setBlock(x+5, y+2, z+15,Blocks.packed_ice);
			world.setBlock(x+26, y+2, z+15, BlockRegister.LEAVES);
			world.setBlockMetadataWithNotify(x+26, y+2, z+15, 1, 2);
			world.setBlock(x+2, y+2, z+19, BlockRegister.LEAVES);
			world.setBlockMetadataWithNotify(x+2, y+2, z+19, 1, 2);
			world.setBlock(x+6, y+2, z+19, Blocks.snow);
			world.setBlock(x+2, y+2, z+20, BlockRegister.LEAVES);
			world.setBlockMetadataWithNotify(x+2, y+2, z+20, 1, 2);
			world.setBlock(x+1, y+2, z+21, BlockRegister.LEAVES);
			world.setBlockMetadataWithNotify(x+1, y+2, z+21, 1, 2);
			world.setBlock(x+5, y+2, z+22, Blocks.snow);
			world.setBlock(x+22, y+2, z+23, BlockRegister.LEAVES);
			world.setBlockMetadataWithNotify(x+22, y+2, z+23, 1, 2);
			world.setBlock(x+18, y+2, z+24, Blocks.snow);
			world.setBlock(x+22, y+2, z+24, BlockRegister.LEAVES);
			world.setBlockMetadataWithNotify(x+22, y+2, z+24, 1, 2);
			world.setBlock(x+8, y+2, z+25, Blocks.snow);
			world.setBlock(x+21, y+2, z+25, BlockRegister.LEAVES);
			world.setBlockMetadataWithNotify(x+21, y+2, z+25, 1, 2);
			world.setBlock(x+10, y+2, z+27,Blocks.packed_ice);
			world.setBlock(x+6, y+2, z+28, BlockRegister.LEAVES);
			world.setBlockMetadataWithNotify(x+6, y+2, z+28, 1, 2);
			world.setBlock(x+8, y+2, z+28, BlockRegister.LEAVES);
			world.setBlockMetadataWithNotify(x+8, y+2, z+28, 1, 2);
			world.setBlock(x+9, y+2, z+28, BlockRegister.LEAVES);
			world.setBlockMetadataWithNotify(x+9, y+2, z+28, 1, 2);
			world.setBlock(x+10, y+2, z+28, BlockRegister.LEAVES);
			world.setBlockMetadataWithNotify(x+10, y+2, z+28, 1, 2);
			world.setBlock(x+7, y+2, z+29, BlockRegister.LEAVES);
			world.setBlockMetadataWithNotify(x+7, y+2, z+29, 1, 2);
			world.setBlock(x+8, y+2, z+29, BlockRegister.LEAVES);
			world.setBlockMetadataWithNotify(x+8, y+2, z+29, 1, 2);
			world.setBlock(x+14, y+2, z+30, BlockRegister.LEAVES);
			world.setBlockMetadataWithNotify(x+14, y+2, z+30, 1, 2);
			world.setBlock(x+15, y+2, z+30, BlockRegister.LEAVES);
			world.setBlockMetadataWithNotify(x+15, y+2, z+30, 1, 2);
			world.setBlock(x+16, y+2, z+30, BlockRegister.LEAVES);
			world.setBlockMetadataWithNotify(x+16, y+2, z+30, 1, 2);
			world.setBlock(x+9, y+3, z+4, BlockRegister.LEAVES);
			world.setBlockMetadataWithNotify(x+9, y+3, z+4, 1, 2);
			world.setBlock(x+10, y+3, z+4, BlockRegister.LEAVES);
			world.setBlockMetadataWithNotify(x+10, y+3, z+4, 1, 2);
			world.setBlock(x+8, y+3, z+5, BlockRegister.LEAVES);
			world.setBlockMetadataWithNotify(x+8, y+3, z+5, 1, 2);
			world.setBlock(x+19, y+3, z+5, BlockRegister.LEAVES);
			world.setBlockMetadataWithNotify(x+19, y+3, z+5, 1, 2);
			world.setBlock(x+20, y+3, z+5, BlockRegister.LEAVES);
			world.setBlockMetadataWithNotify(x+20, y+3, z+5, 1, 2);
			world.setBlock(x+13, y+3, z+6, Blocks.snow);
			world.setBlock(x+17, y+3, z+6,Blocks.packed_ice);
			world.setBlock(x+22, y+3, z+6, BlockRegister.LEAVES);
			world.setBlockMetadataWithNotify(x+22, y+3, z+6, 1, 2);
			world.setBlock(x+12, y+3, z+7,Blocks.packed_ice);
			world.setBlock(x+19, y+3, z+7, Blocks.snow);
			world.setBlock(x+23, y+3, z+7, BlockRegister.LEAVES);
			world.setBlockMetadataWithNotify(x+23, y+3, z+7, 1, 2);
			world.setBlock(x+9, y+3, z+8, Blocks.snow);
			world.setBlock(x+20, y+3, z+8,Blocks.packed_ice);
			world.setBlock(x+3, y+3, z+9, BlockRegister.LEAVES);
			world.setBlockMetadataWithNotify(x+3, y+3, z+9, 1, 2);
			world.setBlock(x+8, y+3, z+9, Blocks.snow);
			world.setBlock(x+3, y+3, z+10, BlockRegister.LEAVES);
			world.setBlockMetadataWithNotify(x+3, y+3, z+10, 1, 2);
			world.setBlock(x+7, y+3, z+10, Blocks.snow);
			world.setBlock(x+22, y+3, z+10, Blocks.snow);
			world.setBlock(x+3, y+3, z+11, BlockRegister.LEAVES);
			world.setBlockMetadataWithNotify(x+3, y+3, z+11, 1, 2);
			world.setBlock(x+7, y+3, z+12, Blocks.snow);
			world.setBlock(x+23, y+3, z+12, Blocks.snow);
			world.setBlock(x+6, y+3, z+13, Blocks.snow);
			world.setBlock(x+7, y+3, z+13, Blocks.snow);
			world.setBlock(x+26, y+3, z+13, BlockRegister.LEAVES);
			world.setBlockMetadataWithNotify(x+26, y+3, z+13, 1, 2);
			world.setBlock(x+3, y+3, z+14, BlockRegister.LEAVES);
			world.setBlockMetadataWithNotify(x+3, y+3, z+14, 1, 2);
			world.setBlock(x+4, y+3, z+14, BlockRegister.LEAVES);
			world.setBlockMetadataWithNotify(x+4, y+3, z+14, 1, 2);
			world.setBlock(x+5, y+3, z+14, BlockRegister.LEAVES);
			world.setBlockMetadataWithNotify(x+5, y+3, z+14, 1, 2);
			world.setBlock(x+6, y+3, z+14, Blocks.snow);
			world.setBlock(x+26, y+3, z+14, BlockRegister.LEAVES);
			world.setBlockMetadataWithNotify(x+26, y+3, z+14, 1, 2);
			world.setBlock(x+4, y+3, z+15, BlockRegister.LEAVES);
			world.setBlockMetadataWithNotify(x+4, y+3, z+15, 1, 2);
			world.setBlock(x+5, y+3, z+15,Blocks.packed_ice);
			world.setBlock(x+24, y+3, z+15,Blocks.packed_ice);
			world.setBlock(x+26, y+3, z+15, BlockRegister.LEAVES);
			world.setBlockMetadataWithNotify(x+26, y+3, z+15, 1, 2);
			world.setBlock(x+6, y+3, z+17, Blocks.snow);
			world.setBlock(x+2, y+3, z+19, BlockRegister.LEAVES);
			world.setBlockMetadataWithNotify(x+2, y+3, z+19, 1, 2);
			world.setBlock(x+6, y+3, z+19, Blocks.snow);
			world.setBlock(x+2, y+3, z+20, BlockRegister.LEAVES);
			world.setBlockMetadataWithNotify(x+2, y+3, z+20, 1, 2);
			world.setBlock(x+5, y+3, z+20, Blocks.snow);
			world.setBlock(x+1, y+3, z+21, BlockRegister.LEAVES);
			world.setBlockMetadataWithNotify(x+1, y+3, z+21, 1, 2);
			world.setBlock(x+21, y+3, z+21,Blocks.packed_ice);
			world.setBlock(x+5, y+3, z+22, Blocks.snow);
			world.setBlock(x+22, y+3, z+23, BlockRegister.LEAVES);
			world.setBlockMetadataWithNotify(x+22, y+3, z+23, 1, 2);
			world.setBlock(x+5, y+3, z+24,Blocks.packed_ice);
			world.setBlock(x+18, y+3, z+24, Blocks.snow);
			world.setBlock(x+22, y+3, z+24, BlockRegister.LEAVES);
			world.setBlockMetadataWithNotify(x+22, y+3, z+24, 1, 2);
			world.setBlock(x+8, y+3, z+25, Blocks.snow);
			world.setBlock(x+21, y+3, z+25, BlockRegister.LEAVES);
			world.setBlockMetadataWithNotify(x+21, y+3, z+25, 1, 2);
			world.setBlock(x+10, y+3, z+27,Blocks.packed_ice);
			world.setBlock(x+11, y+3, z+27,Blocks.packed_ice);
			world.setBlock(x+15, y+3, z+27,Blocks.packed_ice);
			world.setBlock(x+6, y+3, z+28, BlockRegister.LEAVES);
			world.setBlockMetadataWithNotify(x+6, y+3, z+28, 1, 2);
			world.setBlock(x+8, y+3, z+28, BlockRegister.LEAVES);
			world.setBlockMetadataWithNotify(x+8, y+3, z+28, 1, 2);
			world.setBlock(x+9, y+3, z+28, BlockRegister.LEAVES);
			world.setBlockMetadataWithNotify(x+9, y+3, z+28, 1, 2);
			world.setBlock(x+10, y+3, z+28, BlockRegister.LEAVES);
			world.setBlockMetadataWithNotify(x+10, y+3, z+28, 1, 2);
			world.setBlock(x+7, y+3, z+29, BlockRegister.LEAVES);
			world.setBlockMetadataWithNotify(x+7, y+3, z+29, 1, 2);
			world.setBlock(x+8, y+3, z+29, BlockRegister.LEAVES);
			world.setBlockMetadataWithNotify(x+8, y+3, z+29, 1, 2);
			world.setBlock(x+14, y+3, z+30, BlockRegister.LEAVES);
			world.setBlockMetadataWithNotify(x+14, y+3, z+30, 1, 2);
			world.setBlock(x+15, y+3, z+30, BlockRegister.LEAVES);
			world.setBlockMetadataWithNotify(x+15, y+3, z+30, 1, 2);
			world.setBlock(x+16, y+3, z+30, BlockRegister.LEAVES);
			world.setBlockMetadataWithNotify(x+16, y+3, z+30, 1, 2);
			world.setBlock(x+9, y+4, z+4, BlockRegister.LEAVES);
			world.setBlockMetadataWithNotify(x+9, y+4, z+4, 1, 1);
			world.setBlock(x+10, y+4, z+4, BlockRegister.LEAVES);
			world.setBlockMetadataWithNotify(x+10, y+4, z+4, 1, 1);
			world.setBlock(x+8, y+4, z+5, BlockRegister.LEAVES);
			world.setBlockMetadataWithNotify(x+8, y+4, z+5, 1, 2);
			world.setBlock(x+19, y+4, z+5, BlockRegister.LEAVES);
			world.setBlockMetadataWithNotify(x+19, y+4, z+5, 1, 2);
			world.setBlock(x+20, y+4, z+5, BlockRegister.LEAVES);
			world.setBlockMetadataWithNotify(x+20, y+4, z+5, 1, 2);
			world.setBlock(x+13, y+4, z+6, Blocks.snow);
			world.setBlock(x+14, y+4, z+6,Blocks.packed_ice);
			world.setBlock(x+15, y+4, z+6,Blocks.packed_ice);
			world.setBlock(x+17, y+4, z+6,Blocks.packed_ice);
			world.setBlock(x+22, y+4, z+6, BlockRegister.LEAVES);
			world.setBlockMetadataWithNotify(x+22, y+4, z+6, 1, 1);
			world.setBlock(x+11, y+4, z+7,Blocks.packed_ice);
			world.setBlock(x+12, y+4, z+7,Blocks.packed_ice);
			world.setBlock(x+13, y+4, z+7, Blocks.snow);
			world.setBlock(x+14, y+4, z+7, Blocks.snow);
			world.setBlock(x+19, y+4, z+7, Blocks.snow);
			world.setBlock(x+23, y+4, z+7, BlockRegister.LEAVES);
			world.setBlockMetadataWithNotify(x+23, y+4, z+7, 1, 2);
			world.setBlock(x+9, y+4, z+8, Blocks.snow);
			world.setBlock(x+18, y+4, z+8, Blocks.snow);
			world.setBlock(x+19, y+4, z+8, Blocks.snow);
			world.setBlock(x+20, y+4, z+8,Blocks.packed_ice);
			world.setBlock(x+3, y+4, z+9, BlockRegister.LEAVES);
			world.setBlockMetadataWithNotify(x+3, y+4, z+9, 1, 2);
			world.setBlock(x+7, y+4, z+9, Blocks.snow);
			world.setBlock(x+8, y+4, z+9, Blocks.snow);
			world.setBlock(x+17, y+4, z+9, Blocks.snow);
			world.setBlock(x+18, y+4, z+9, Blocks.snow);
			world.setBlock(x+19, y+4, z+9, Blocks.glowstone);
			world.setBlock(x+20, y+4, z+9, Blocks.snow);
			world.setBlock(x+21, y+4, z+9, Blocks.snow);
			world.setBlock(x+3, y+4, z+10, BlockRegister.LEAVES);
			world.setBlockMetadataWithNotify(x+3, y+4, z+10, 1, 2);
			world.setBlock(x+7, y+4, z+10, Blocks.snow);
			world.setBlock(x+16, y+4, z+10, Blocks.snow);
			world.setBlock(x+17, y+4, z+10, Blocks.snow);
			world.setBlock(x+18, y+4, z+10, Blocks.snow);
			world.setBlock(x+19, y+4, z+10, Blocks.snow);
			world.setBlock(x+22, y+4, z+10, Blocks.snow);
			world.setBlock(x+3, y+4, z+11, BlockRegister.LEAVES);
			world.setBlockMetadataWithNotify(x+3, y+4, z+11, 1, 2);
			world.setBlock(x+13, y+4, z+11, Blocks.snow);
			world.setBlock(x+14, y+4, z+11, Blocks.snow);
			world.setBlock(x+15, y+4, z+11, Blocks.snow);
			world.setBlock(x+16, y+4, z+11, Blocks.snow);
			world.setBlock(x+17, y+4, z+11, Blocks.snow);
			world.setBlock(x+18, y+4, z+11, Blocks.snow);
			world.setBlock(x+19, y+4, z+11, Blocks.snow);
			world.setBlock(x+7, y+4, z+12, Blocks.snow);
			world.setBlock(x+8, y+4, z+12, Blocks.snow);
			world.setBlock(x+12, y+4, z+12, Blocks.snow);
			world.setBlock(x+13, y+4, z+12, Blocks.snow);
			world.setBlock(x+14, y+4, z+12, Blocks.snow);
			world.setBlock(x+15, y+4, z+12, Blocks.snow);
			world.setBlock(x+16, y+4, z+12, Blocks.snow);
			world.setBlock(x+17, y+4, z+12, Blocks.snow);
			world.setBlock(x+23, y+4, z+12, Blocks.snow);
			world.setBlock(x+6, y+4, z+13, Blocks.snow);
			world.setBlock(x+7, y+4, z+13, Blocks.snow);
			world.setBlock(x+8, y+4, z+13, Blocks.snow);
			world.setBlock(x+9, y+4, z+13, Blocks.snow);
			world.setBlock(x+10, y+4, z+13, Blocks.snow);
			world.setBlock(x+11, y+4, z+13, Blocks.snow);
			world.setBlock(x+13, y+4, z+13, Blocks.snow);
			world.setBlock(x+14, y+4, z+13, Blocks.snow);
			world.setBlock(x+15, y+4, z+13, Blocks.snow);
			world.setBlock(x+16, y+4, z+13, Blocks.snow);
			world.setBlock(x+26, y+4, z+13, BlockRegister.LEAVES);
			world.setBlockMetadataWithNotify(x+26, y+4, z+13, 1, 2);
			world.setBlock(x+3, y+4, z+14, BlockRegister.LEAVES);
			world.setBlockMetadataWithNotify(x+3, y+4, z+14, 1, 2);
			world.setBlock(x+4, y+4, z+14, BlockRegister.LEAVES);
			world.setBlockMetadataWithNotify(x+4, y+4, z+14, 1, 2);
			world.setBlock(x+5, y+4, z+14, BlockRegister.LEAVES);
			world.setBlockMetadataWithNotify(x+5, y+4, z+14, 1, 2);
			world.setBlock(x+6, y+4, z+14, Blocks.snow);
			world.setBlock(x+7, y+4, z+14, Block.getBlockById(89));
			world.setBlock(x+8, y+4, z+14, Blocks.snow);
			world.setBlock(x+9, y+4, z+14, Blocks.snow);
			world.setBlock(x+10, y+4, z+14, Blocks.snow);
			world.setBlock(x+14, y+4, z+14, Blocks.snow);
			world.setBlock(x+26, y+4, z+14, BlockRegister.LEAVES);
			world.setBlockMetadataWithNotify(x+26, y+4, z+14, 1, 2);
			world.setBlock(x+4, y+4, z+15, BlockRegister.LEAVES);
			world.setBlockMetadataWithNotify(x+4, y+4, z+15, 1, 2);
			world.setBlock(x+5, y+4, z+15,Blocks.packed_ice);
			world.setBlock(x+6, y+4, z+15, Blocks.snow);
			world.setBlock(x+7, y+4, z+15, Blocks.snow);
			world.setBlock(x+8, y+4, z+15, Blocks.snow);
			world.setBlock(x+9, y+4, z+15, Blocks.snow);
			world.setBlock(x+10, y+4, z+15, Blocks.snow);
			world.setBlock(x+24, y+4, z+15,Blocks.packed_ice);
			world.setBlock(x+26, y+4, z+15, BlockRegister.LEAVES);
			world.setBlockMetadataWithNotify(x+26, y+4, z+15, 1, 2);
			world.setBlock(x+6, y+4, z+16, Blocks.snow);
			world.setBlock(x+7, y+4, z+16, Blocks.snow);
			world.setBlock(x+8, y+4, z+16, Blocks.snow);
			world.setBlock(x+12, y+4, z+16, Blocks.snow);
			world.setBlock(x+13, y+4, z+16, Blocks.snow);
			world.setBlock(x+14, y+4, z+16, Blocks.snow);
			world.setBlock(x+6, y+4, z+17, Blocks.snow);
			world.setBlock(x+7, y+4, z+17, Blocks.snow);
			world.setBlock(x+11, y+4, z+17, Blocks.snow);
			world.setBlock(x+12, y+4, z+17, Blocks.snow);
			world.setBlock(x+13, y+4, z+17, Blocks.snow);
			world.setBlock(x+14, y+4, z+17, Blocks.snow);
			world.setBlock(x+15, y+4, z+17, Blocks.snow);
			world.setBlock(x+6, y+4, z+18, Blocks.snow);
			world.setBlock(x+11, y+4, z+18, Blocks.snow);
			world.setBlock(x+12, y+4, z+18, Blocks.snow);
			world.setBlock(x+13, y+4, z+18, Blocks.snow);
			world.setBlock(x+14, y+4, z+18, Blocks.snow);
			world.setBlock(x+15, y+4, z+18, Blocks.snow);
			world.setBlock(x+2, y+4, z+19, BlockRegister.LEAVES);
			world.setBlockMetadataWithNotify(x+2, y+4, z+19, 1, 2);
			world.setBlock(x+6, y+4, z+19, Blocks.snow);
			world.setBlock(x+11, y+4, z+19, Blocks.snow);
			world.setBlock(x+12, y+4, z+19, Blocks.snow);
			world.setBlock(x+13, y+4, z+19, Blocks.snow);
			world.setBlock(x+14, y+4, z+19, Blocks.snow);
			world.setBlock(x+15, y+4, z+19, Blocks.snow);
			world.setBlock(x+16, y+4, z+19, Blocks.snow);
			world.setBlock(x+23, y+4, z+19, Blocks.snow);
			world.setBlock(x+2, y+4, z+20, BlockRegister.LEAVES);
			world.setBlockMetadataWithNotify(x+2, y+4, z+20, 1, 2);
			world.setBlock(x+5, y+4, z+20, Blocks.snow);
			world.setBlock(x+12, y+4, z+20, Blocks.snow);
			world.setBlock(x+13, y+4, z+20, Blocks.snow);
			world.setBlock(x+14, y+4, z+20, Blocks.snow);
			world.setBlock(x+15, y+4, z+20, Blocks.snow);
			world.setBlock(x+16, y+4, z+20, Blocks.snow);
			world.setBlock(x+1, y+4, z+21, BlockRegister.LEAVES);
			world.setBlockMetadataWithNotify(x+1, y+4, z+21, 1, 2);
			world.setBlock(x+5, y+4, z+21, Blocks.snow);
			world.setBlock(x+6, y+4, z+21, Blocks.snow);
			world.setBlock(x+13, y+4, z+21, Blocks.snow);
			world.setBlock(x+14, y+4, z+21, Blocks.snow);
			world.setBlock(x+15, y+4, z+21, Blocks.snow);
			world.setBlock(x+16, y+4, z+21, Blocks.snow);
			world.setBlock(x+17, y+4, z+21, Blocks.snow);
			world.setBlock(x+18, y+4, z+21, Blocks.snow);
			world.setBlock(x+21, y+4, z+21,Blocks.packed_ice);
			world.setBlock(x+5, y+4, z+22, Blocks.snow);
			world.setBlock(x+15, y+4, z+22, Blocks.snow);
			world.setBlock(x+16, y+4, z+22, Blocks.snow);
			world.setBlock(x+17, y+4, z+22, Blocks.snow);
			world.setBlock(x+18, y+4, z+22, Blocks.snow);
			world.setBlock(x+15, y+4, z+23, Blocks.snow);
			world.setBlock(x+16, y+4, z+23, Blocks.snow);
			world.setBlock(x+17, y+4, z+23, Blocks.snow);
			world.setBlock(x+18, y+4, z+23, Blocks.snow);
			world.setBlock(x+20, y+4, z+23, Blocks.snow);
			world.setBlock(x+22, y+4, z+23, BlockRegister.LEAVES);
			world.setBlockMetadataWithNotify(x+22, y+4, z+23, 1, 2);
			world.setBlock(x+5, y+4, z+24,Blocks.packed_ice);
			world.setBlock(x+6, y+4, z+24, Blocks.snow);
			world.setBlock(x+18, y+4, z+24, Blocks.snow);
			world.setBlock(x+22, y+4, z+24, BlockRegister.LEAVES);
			world.setBlockMetadataWithNotify(x+22, y+4, z+24, 1, 2);
			world.setBlock(x+8, y+4, z+25, Blocks.snow);
			world.setBlock(x+18, y+4, z+25, Blocks.snow);
			world.setBlock(x+21, y+4, z+25, BlockRegister.LEAVES);
			world.setBlockMetadataWithNotify(x+21, y+4, z+25, 1, 2);
			world.setBlock(x+3, y+4, z+26, BlockRegister.LEAVES);
			world.setBlockMetadataWithNotify(x+3, y+4, z+26, 1, 2);
			world.setBlock(x+8, y+4, z+26, Blocks.snow);
			world.setBlock(x+10, y+4, z+26, Blocks.snow);
			world.setBlock(x+11, y+4, z+27,Blocks.packed_ice);
			world.setBlock(x+12, y+4, z+27,Blocks.packed_ice);
			world.setBlock(x+15, y+4, z+27,Blocks.packed_ice);
			world.setBlock(x+16, y+4, z+27,Blocks.packed_ice);
			world.setBlock(x+6, y+4, z+28, BlockRegister.LEAVES);
			world.setBlockMetadataWithNotify(x+6, y+4, z+28, 1, 2);
			world.setBlock(x+8, y+4, z+28, BlockRegister.LEAVES);
			world.setBlockMetadataWithNotify(x+8, y+4, z+28, 1, 2);
			world.setBlock(x+9, y+4, z+28, BlockRegister.LEAVES);
			world.setBlockMetadataWithNotify(x+9, y+4, z+28, 1, 2);
			world.setBlock(x+10, y+4, z+28, BlockRegister.LEAVES);
			world.setBlockMetadataWithNotify(x+10, y+4, z+28, 1, 2);
			world.setBlock(x+7, y+4, z+29, BlockRegister.LEAVES);
			world.setBlockMetadataWithNotify(x+7, y+4, z+29, 1, 2);
			world.setBlock(x+8, y+4, z+29, BlockRegister.LEAVES);
			world.setBlockMetadataWithNotify(x+8, y+4, z+29, 1, 2);
			world.setBlock(x+14, y+4, z+30, BlockRegister.LEAVES);
			world.setBlockMetadataWithNotify(x+14, y+4, z+30, 1, 2);
			world.setBlock(x+15, y+4, z+30, BlockRegister.LEAVES);
			world.setBlockMetadataWithNotify(x+15, y+4, z+30, 1, 2);
			world.setBlock(x+16, y+4, z+30, BlockRegister.LEAVES);
			world.setBlockMetadataWithNotify(x+16, y+4, z+30, 1, 2);
			world.setBlock(x+9, y+5, z+4, BlockRegister.LEAVES);
			world.setBlockMetadataWithNotify(x+9, y+5, z+4, 1, 2);
			world.setBlock(x+10, y+5, z+4, BlockRegister.LEAVES);
			world.setBlockMetadataWithNotify(x+10, y+5, z+4, 1, 2);
			world.setBlock(x+8, y+5, z+5, BlockRegister.LEAVES);
			world.setBlockMetadataWithNotify(x+8, y+5, z+5, 1, 2);
			world.setBlock(x+13, y+5, z+5, Blocks.snow);
			world.setBlock(x+14, y+5, z+5, Blocks.snow);
			world.setBlock(x+19, y+5, z+5, BlockRegister.LEAVES);
			world.setBlockMetadataWithNotify(x+19, y+5, z+5, 1, 1);
			world.setBlock(x+20, y+5, z+5, BlockRegister.LEAVES);
			world.setBlockMetadataWithNotify(x+20, y+5, z+5, 1, 1);
			world.setBlock(x+12, y+5, z+6, Blocks.snow);
			world.setBlock(x+13, y+5, z+6,Blocks.packed_ice);
			world.setBlock(x+14, y+5, z+6,Blocks.packed_ice);
			world.setBlock(x+15, y+5, z+6,Blocks.packed_ice);
			world.setBlock(x+16, y+5, z+6,Blocks.packed_ice);
			world.setBlock(x+17, y+5, z+6,Blocks.packed_ice);
			world.setBlock(x+18, y+5, z+6, Blocks.snow);
			world.setBlock(x+22, y+5, z+6, BlockRegister.LEAVES);
			world.setBlockMetadataWithNotify(x+22, y+5, z+6, 1, 1);
			world.setBlock(x+11, y+5, z+7,Blocks.packed_ice);
			world.setBlock(x+12, y+5, z+7, Blocks.snow);
			world.setBlock(x+13, y+5, z+7, Blocks.snow);
			world.setBlock(x+14, y+5, z+7, Blocks.snow);
			world.setBlock(x+15, y+5, z+7, Blocks.snow);
			world.setBlock(x+16, y+5, z+7, Blocks.snow);
			world.setBlock(x+17, y+5, z+7, Blocks.snow);
			world.setBlock(x+18, y+5, z+7, Blocks.snow);
			world.setBlock(x+19, y+5, z+7, Blocks.snow);
			world.setBlock(x+23, y+5, z+7, BlockRegister.LEAVES);
			world.setBlockMetadataWithNotify(x+23, y+5, z+7, 2, 2);
			world.setBlock(x+9, y+5, z+8, Blocks.snow);
			world.setBlock(x+10, y+5, z+8, Blocks.snow);
			world.setBlock(x+11, y+5, z+8, Blocks.snow);
			world.setBlock(x+12, y+5, z+8, Blocks.snow);
			world.setBlock(x+13, y+5, z+8, Blocks.snow);
			world.setBlock(x+14, y+5, z+8, Blocks.snow);
			world.setBlock(x+15, y+5, z+8, Blocks.snow);
			world.setBlock(x+16, y+5, z+8, Blocks.snow);
			world.setBlock(x+17, y+5, z+8, Blocks.snow);
			world.setBlock(x+18, y+5, z+8, Blocks.snow);
			world.setBlock(x+19, y+5, z+8, Blocks.snow);
			world.setBlock(x+20, y+5, z+8,Blocks.packed_ice);
			world.setBlock(x+3, y+5, z+9, BlockRegister.LEAVES);
			world.setBlockMetadataWithNotify(x+3, y+5, z+9, 1, 2);
			world.setBlock(x+7, y+5, z+9,Blocks.packed_ice);
			world.setBlock(x+8, y+5, z+9, Blocks.snow);
			world.setBlock(x+9, y+5, z+10, Blocks.glowstone);
			world.setBlock(x+10, y+5, z+9, Blocks.snow);
			world.setBlock(x+11, y+5, z+9, Blocks.snow);
			world.setBlock(x+12, y+5, z+9, Blocks.snow);
			world.setBlock(x+13, y+5, z+9, Blocks.snow);
			world.setBlock(x+14, y+5, z+9, Blocks.snow);
			world.setBlock(x+15, y+5, z+9, Blocks.snow);
			world.setBlock(x+16, y+5, z+9, Blocks.snow);
			world.setBlock(x+17, y+5, z+9, Blocks.snow);
			world.setBlock(x+18, y+5, z+9, Blocks.snow);
			world.setBlock(x+19, y+5, z+9, Blocks.snow);
			world.setBlock(x+20, y+5, z+9, Blocks.snow);
			world.setBlock(x+21, y+5, z+9, Blocks.snow);
			world.setBlock(x+22, y+5, z+9, Blocks.snow);
			world.setBlock(x+3, y+5, z+10, BlockRegister.LEAVES);
			world.setBlockMetadataWithNotify(x+3, y+5, z+10, 1, 2);
			world.setBlock(x+6, y+5, z+10, Blocks.snow);
			world.setBlock(x+7, y+5, z+10, Blocks.snow);
			world.setBlock(x+8, y+5, z+10, Blocks.snow);
			world.setBlock(x+9, y+5, z+10, Blocks.snow);
			world.setBlock(x+10, y+5, z+10, Blocks.snow);
			world.setBlock(x+11, y+5, z+10, Blocks.snow);
			world.setBlock(x+12, y+5, z+10, Blocks.snow);
			world.setBlock(x+13, y+5, z+10, Blocks.snow);
			world.setBlock(x+14, y+5, z+10, Blocks.snow);
			world.setBlock(x+15, y+5, z+10, Blocks.snow);
			world.setBlock(x+16, y+5, z+10, Blocks.snow);
			world.setBlock(x+17, y+5, z+10, Blocks.snow);
			world.setBlock(x+18, y+5, z+10, Blocks.snow);
			world.setBlock(x+19, y+5, z+10, Blocks.snow);
			world.setBlock(x+20, y+5, z+10, Blocks.snow);
			world.setBlock(x+21, y+5, z+9, Blocks.glowstone);
			world.setBlock(x+22, y+5, z+10, Blocks.snow);
			world.setBlock(x+3, y+5, z+11, BlockRegister.LEAVES);
			world.setBlockMetadataWithNotify(x+3, y+5, z+11, 8, 8);
			world.setBlock(x+7, y+5, z+11, Blocks.snow);
			world.setBlock(x+8, y+5, z+11, Blocks.snow);
			world.setBlock(x+9, y+5, z+11, Blocks.snow);
			world.setBlock(x+10, y+5, z+11, Blocks.snow);
			world.setBlock(x+11, y+5, z+11, Blocks.snow);
			world.setBlock(x+12, y+5, z+11, Blocks.snow);
			world.setBlock(x+13, y+5, z+11, Blocks.snow);
			world.setBlock(x+14, y+5, z+11, Blocks.snow);
			world.setBlock(x+15, y+5, z+11, Blocks.snow);
			world.setBlock(x+16, y+5, z+11, Blocks.snow);
			world.setBlock(x+17, y+5, z+11, Blocks.snow);
			world.setBlock(x+18, y+5, z+11, Blocks.snow);
			world.setBlock(x+19, y+5, z+11, Blocks.snow);
			world.setBlock(x+20, y+5, z+11, Blocks.snow);
			world.setBlock(x+21, y+5, z+11, Blocks.snow);
			world.setBlock(x+22, y+5, z+11, Blocks.snow);
			world.setBlock(x+23, y+5, z+11, Blocks.snow);
			world.setBlock(x+7, y+5, z+12, Blocks.snow);
			world.setBlock(x+8, y+5, z+12, Blocks.snow);
			world.setBlock(x+9, y+5, z+12, Blocks.snow);
			world.setBlock(x+10, y+5, z+12, Blocks.snow);
			world.setBlock(x+11, y+5, z+12, Blocks.snow);
			world.setBlock(x+12, y+5, z+12, Blocks.snow);
			world.setBlock(x+13, y+5, z+12, Blocks.snow);
			world.setBlock(x+14, y+5, z+12, Blocks.snow);
			world.setBlock(x+15, y+5, z+12, Blocks.snow);
			world.setBlock(x+16, y+5, z+12, Blocks.snow);
			world.setBlock(x+17, y+5, z+12, Blocks.snow);
			world.setBlock(x+18, y+5, z+12, Blocks.snow);
			world.setBlock(x+19, y+5, z+12, Blocks.snow);
			world.setBlock(x+20, y+5, z+12, Blocks.snow);
			world.setBlock(x+21, y+5, z+12, Blocks.snow);
			world.setBlock(x+22, y+5, z+12, Blocks.snow);
			world.setBlock(x+23, y+5, z+12, Blocks.snow);
			world.setBlock(x+6, y+5, z+13, Blocks.snow);
			world.setBlock(x+7, y+5, z+13, Blocks.snow);
			world.setBlock(x+8, y+5, z+13, Blocks.snow);
			world.setBlock(x+9, y+5, z+13, Blocks.snow);
			world.setBlock(x+10, y+5, z+13, Blocks.snow);
			world.setBlock(x+11, y+5, z+13, Blocks.snow);
			world.setBlock(x+12, y+5, z+13, Blocks.snow);
			world.setBlock(x+13, y+5, z+13, Blocks.snow);
			world.setBlock(x+14, y+5, z+13, Blocks.snow);
			world.setBlock(x+15, y+5, z+13, Blocks.snow);
			world.setBlock(x+16, y+5, z+13, Blocks.snow);
			world.setBlock(x+17, y+5, z+13, Blocks.snow);
			world.setBlock(x+18, y+5, z+13, Blocks.snow);
			world.setBlock(x+19, y+5, z+13, Blocks.snow);
			world.setBlock(x+20, y+5, z+13, Blocks.snow);
			world.setBlock(x+21, y+5, z+13, Blocks.snow);
			world.setBlock(x+22, y+5, z+13, Blocks.snow);
			world.setBlock(x+24, y+5, z+13, Blocks.snow);
			world.setBlock(x+26, y+5, z+13, BlockRegister.LEAVES);
			world.setBlockMetadataWithNotify(x+26, y+5, z+13, 1, 2);
			world.setBlock(x+3, y+5, z+14, BlockRegister.LEAVES);
			world.setBlockMetadataWithNotify(x+3, y+5, z+14, 1, 2);
			world.setBlock(x+4, y+5, z+14, BlockRegister.LEAVES);
			world.setBlockMetadataWithNotify(x+4, y+5, z+14, 1, 2);
			world.setBlock(x+5, y+5, z+14,Blocks.packed_ice);
			world.setBlock(x+6, y+5, z+14, Blocks.snow);
			world.setBlock(x+7, y+5, z+14, Blocks.snow);
			world.setBlock(x+8, y+5, z+14, Blocks.snow);
			world.setBlock(x+9, y+5, z+14, Blocks.snow);
			world.setBlock(x+10, y+5, z+14, Blocks.snow);
			world.setBlock(x+11, y+5, z+14, Blocks.snow);
			world.setBlock(x+12, y+5, z+14, Blocks.snow);
			world.setBlock(x+13, y+5, z+14, Blocks.snow);
			world.setBlock(x+14, y+5, z+14, Block.getBlockById(33));
			world.setBlockMetadataWithNotify(x+14, y+5, z+14, 11, 11);
			world.setBlock(x+15, y+5, z+14, Blocks.snow);
			world.setBlock(x+16, y+5, z+14, Blocks.snow);
			world.setBlock(x+17, y+5, z+14, Blocks.snow);
			world.setBlock(x+18, y+5, z+14, Blocks.snow);
			world.setBlock(x+19, y+5, z+14, Blocks.snow);
			world.setBlock(x+20, y+5, z+14, Blocks.snow);
			world.setBlock(x+21, y+5, z+14, Blocks.snow);
			world.setBlock(x+22, y+5, z+14, Blocks.snow);
			world.setBlock(x+26, y+5, z+14, BlockRegister.LEAVES);
			world.setBlockMetadataWithNotify(x+26, y+5, z+14, 1, 2);
			world.setBlock(x+4, y+5, z+15, BlockRegister.LEAVES);
			world.setBlockMetadataWithNotify(x+4, y+5, z+15, 1, 2);
			world.setBlock(x+5, y+5, z+15,Blocks.packed_ice);
			world.setBlock(x+6, y+5, z+15, Blocks.snow);
			world.setBlock(x+7, y+5, z+15, Blocks.snow);
			world.setBlock(x+8, y+5, z+15, Blocks.snow);
			world.setBlock(x+9, y+5, z+15, Blocks.snow);
			world.setBlock(x+10, y+5, z+15, Blocks.snow);
			world.setBlock(x+11, y+5, z+15, Blocks.snow);
			world.setBlock(x+12, y+5, z+15, Blocks.snow);
			world.setBlock(x+13, y+5, z+15, Blocks.snow);
			world.setBlock(x+14, y+5, z+15, Block.getBlockById(34));
			world.setBlockMetadataWithNotify(x+14, y+5, z+15, 3, 3);
			world.setBlock(x+15, y+5, z+15, Blocks.snow);
			world.setBlock(x+16, y+5, z+15, Blocks.snow);
			world.setBlock(x+17, y+5, z+15, Blocks.snow);
			world.setBlock(x+18, y+5, z+15, Blocks.snow);
			world.setBlock(x+19, y+5, z+15, Blocks.snow);
			world.setBlock(x+20, y+5, z+15, Blocks.snow);
			world.setBlock(x+21, y+5, z+15, Blocks.snow);
			world.setBlock(x+22, y+5, z+15, Blocks.snow);
			world.setBlock(x+23, y+5, z+15, Blocks.snow);
			world.setBlock(x+24, y+5, z+15,Blocks.packed_ice);
			world.setBlock(x+26, y+5, z+15, BlockRegister.LEAVES);
			world.setBlockMetadataWithNotify(x+26, y+5, z+15, 1, 2);
			world.setBlock(x+6, y+5, z+16, Blocks.snow);
			world.setBlock(x+7, y+5, z+16, Blocks.snow);
			world.setBlock(x+8, y+5, z+16, Blocks.snow);
			world.setBlock(x+9, y+5, z+16, Blocks.snow);
			world.setBlock(x+10, y+5, z+16, Blocks.snow);
			world.setBlock(x+11, y+5, z+16, Blocks.snow);
			world.setBlock(x+12, y+5, z+16, Blocks.snow);
			world.setBlock(x+13, y+5, z+16, Blocks.snow);
			world.setBlock(x+14, y+5, z+16, Blocks.snow);
			world.setBlock(x+15, y+5, z+16, Blocks.snow);
			world.setBlock(x+16, y+5, z+16, Blocks.snow);
			world.setBlock(x+17, y+5, z+16, Blocks.snow);
			world.setBlock(x+18, y+5, z+16, Blocks.snow);
			world.setBlock(x+19, y+5, z+16, Blocks.snow);
			world.setBlock(x+20, y+5, z+16, Blocks.snow);
			world.setBlock(x+21, y+5, z+16, Blocks.snow);
			world.setBlock(x+22, y+5, z+16, Block.getBlockById(89));
			world.setBlock(x+23, y+5, z+16, Blocks.snow);
			world.setBlock(x+6, y+5, z+17, Blocks.snow);
			world.setBlock(x+7, y+5, z+17, Blocks.snow);
			world.setBlock(x+8, y+5, z+17, Blocks.snow);
			world.setBlock(x+9, y+5, z+17, Blocks.snow);
			world.setBlock(x+10, y+5, z+17, Blocks.snow);
			world.setBlock(x+11, y+5, z+17, Blocks.snow);
			world.setBlock(x+12, y+5, z+17, Blocks.snow);
			world.setBlock(x+13, y+5, z+17, Blocks.snow);
			world.setBlock(x+15, y+5, z+17, Blocks.snow);
			world.setBlock(x+16, y+5, z+17, Blocks.snow);
			world.setBlock(x+17, y+5, z+17, Blocks.snow);
			world.setBlock(x+18, y+5, z+17, Blocks.snow);
			world.setBlock(x+19, y+5, z+17, Blocks.snow);
			world.setBlock(x+20, y+5, z+17, Blocks.snow);
			world.setBlock(x+21, y+5, z+17, Blocks.snow);
			world.setBlock(x+22, y+5, z+17, Blocks.snow);
			world.setBlock(x+23, y+5, z+17, Blocks.snow);
			world.setBlock(x+24, y+5, z+17, Blocks.snow);
			world.setBlock(x+6, y+5, z+18, Blocks.snow);
			world.setBlock(x+7, y+5, z+18, Blocks.snow);
			world.setBlock(x+8, y+5, z+18, Blocks.snow);
			world.setBlock(x+9, y+5, z+18, Blocks.snow);
			world.setBlock(x+10, y+5, z+18, Blocks.snow);
			world.setBlock(x+11, y+5, z+18, Blocks.snow);
			world.setBlock(x+12, y+5, z+18, Blocks.snow);
			world.setBlock(x+13, y+5, z+18, Blocks.snow);
			world.setBlock(x+14, y+5, z+18, Blocks.snow);
			world.setBlock(x+15, y+5, z+18, Blocks.snow);
			world.setBlock(x+16, y+5, z+18, Blocks.snow);
			world.setBlock(x+17, y+5, z+18, Blocks.snow);
			world.setBlock(x+18, y+5, z+18, Blocks.snow);
			world.setBlock(x+19, y+5, z+18, Blocks.snow);
			world.setBlock(x+20, y+5, z+18, Blocks.snow);
			world.setBlock(x+21, y+5, z+18, Blocks.snow);
			world.setBlock(x+22, y+5, z+18, Blocks.snow);
			world.setBlock(x+2, y+5, z+19, BlockRegister.LEAVES);
			world.setBlockMetadataWithNotify(x+2, y+5, z+19, 1, 2);
			world.setBlock(x+5, y+5, z+19, Blocks.snow);
			world.setBlock(x+6, y+5, z+19, Blocks.snow);
			world.setBlock(x+7, y+5, z+19, Blocks.snow);
			world.setBlock(x+8, y+5, z+19, Blocks.snow);
			world.setBlock(x+9, y+5, z+19, Blocks.snow);
			world.setBlock(x+10, y+5, z+19, Blocks.snow);
			world.setBlock(x+11, y+5, z+19, Blocks.snow);
			world.setBlock(x+12, y+5, z+19, Blocks.snow);
			world.setBlock(x+13, y+5, z+19, Blocks.snow);
			world.setBlock(x+14, y+5, z+19, Blocks.snow);
			world.setBlock(x+15, y+5, z+19, Blocks.snow);
			world.setBlock(x+16, y+5, z+19, Blocks.snow);
			world.setBlock(x+17, y+5, z+19, Blocks.snow);
			world.setBlock(x+18, y+5, z+19, Blocks.snow);
			world.setBlock(x+19, y+5, z+19, Blocks.snow);
			world.setBlock(x+20, y+5, z+19, Blocks.snow);
			world.setBlock(x+21, y+5, z+19, Blocks.snow);
			world.setBlock(x+22, y+5, z+19, Blocks.snow);
			world.setBlock(x+23, y+5, z+19, Blocks.snow);
			world.setBlock(x+2, y+5, z+20, BlockRegister.LEAVES);
			world.setBlockMetadataWithNotify(x+2, y+5, z+20, 1, 2);
			world.setBlock(x+4, y+5, z+20, Blocks.snow);
			world.setBlock(x+5, y+5, z+20, Blocks.snow);
			world.setBlock(x+6, y+5, z+20, Blocks.snow);
			world.setBlock(x+7, y+5, z+20, Blocks.snow);
			world.setBlock(x+8, y+5, z+20, Blocks.snow);
			world.setBlock(x+9, y+5, z+20, Blocks.snow);
			world.setBlock(x+10, y+5, z+20, Blocks.snow);
			world.setBlock(x+11, y+5, z+20, Blocks.snow);
			world.setBlock(x+12, y+5, z+20, Blocks.snow);
			world.setBlock(x+13, y+5, z+20, Blocks.snow);
			world.setBlock(x+14, y+5, z+20, Blocks.snow);
			world.setBlock(x+15, y+5, z+20, Blocks.snow);
			world.setBlock(x+16, y+5, z+20, Blocks.snow);
			world.setBlock(x+17, y+5, z+20, Blocks.snow);
			world.setBlock(x+18, y+5, z+20, Blocks.snow);
			world.setBlock(x+19, y+5, z+20, Blocks.snow);
			world.setBlock(x+20, y+5, z+20, Blocks.snow);
			world.setBlock(x+22, y+5, z+20, Blocks.snow);
			world.setBlock(x+1, y+5, z+21, BlockRegister.LEAVES);
			world.setBlockMetadataWithNotify(x+1, y+5, z+21, 1, 2);
			world.setBlock(x+4, y+5, z+21, Blocks.snow);
			world.setBlock(x+5, y+5, z+21, Blocks.snow);
			world.setBlock(x+6, y+5, z+21, Blocks.snow);
			world.setBlock(x+7, y+5, z+21, Blocks.snow);
			world.setBlock(x+8, y+5, z+21, Blocks.snow);
			world.setBlock(x+9, y+5, z+21, Blocks.snow);
			world.setBlock(x+10, y+5, z+21, Blocks.snow);
			world.setBlock(x+11, y+5, z+21, Blocks.snow);
			world.setBlock(x+12, y+5, z+21, Blocks.snow);
			world.setBlock(x+13, y+5, z+21, Blocks.snow);
			world.setBlock(x+14, y+5, z+21, Blocks.snow);
			world.setBlock(x+15, y+5, z+21, Blocks.snow);
			world.setBlock(x+16, y+5, z+21, Blocks.snow);
			world.setBlock(x+17, y+5, z+21, Blocks.snow);
			world.setBlock(x+18, y+5, z+21, Blocks.snow);
			world.setBlock(x+19, y+5, z+21, Blocks.snow);
			world.setBlock(x+21, y+5, z+21,Blocks.packed_ice);
			world.setBlock(x+4, y+5, z+22, Blocks.snow);
			world.setBlock(x+5, y+5, z+22, Blocks.snow);
			world.setBlock(x+6, y+5, z+22, Blocks.snow);
			world.setBlock(x+7, y+5, z+22, Blocks.snow);
			world.setBlock(x+8, y+5, z+22, Blocks.snow);
			world.setBlock(x+9, y+5, z+22, Blocks.snow);
			world.setBlock(x+10, y+5, z+22, Blocks.snow);
			world.setBlock(x+11, y+5, z+22, Blocks.snow);
			world.setBlock(x+12, y+5, z+22, Blocks.snow);
			world.setBlock(x+13, y+5, z+22, Blocks.snow);
			world.setBlock(x+14, y+5, z+22, Blocks.snow);
			world.setBlock(x+15, y+5, z+22, Blocks.snow);
			world.setBlock(x+16, y+5, z+22, Blocks.snow);
			world.setBlock(x+17, y+5, z+22, Blocks.snow);
			world.setBlock(x+18, y+5, z+22, Blocks.snow);
			world.setBlock(x+19, y+5, z+22, Block.getBlockById(89));
			world.setBlock(x+20, y+5, z+22, Blocks.snow);
			world.setBlock(x+5, y+5, z+23, Blocks.snow);
			world.setBlock(x+6, y+5, z+23, Blocks.snow);
			world.setBlock(x+7, y+5, z+23, Block.getBlockById(89));
			world.setBlock(x+8, y+5, z+23, Blocks.snow);
			world.setBlock(x+9, y+5, z+23, Blocks.snow);
			world.setBlock(x+10, y+5, z+23, Blocks.snow);
			world.setBlock(x+12, y+5, z+23, Blocks.snow);
			world.setBlock(x+13, y+5, z+23, Blocks.snow);
			world.setBlock(x+14, y+5, z+23, Blocks.snow);
			world.setBlock(x+15, y+5, z+23, Blocks.snow);
			world.setBlock(x+16, y+5, z+23, Blocks.snow);
			world.setBlock(x+18, y+5, z+23, Blocks.snow);
			world.setBlock(x+19, y+5, z+23, Blocks.snow);
			world.setBlock(x+20, y+5, z+23, Blocks.snow);
			world.setBlock(x+22, y+5, z+23, BlockRegister.LEAVES);
			world.setBlockMetadataWithNotify(x+22, y+5, z+23, 1, 2);
			world.setBlock(x+5, y+5, z+24,Blocks.packed_ice);
			world.setBlock(x+6, y+5, z+24, Blocks.snow);
			world.setBlock(x+7, y+5, z+24, Blocks.snow);
			world.setBlock(x+8, y+5, z+24, Blocks.snow);
			world.setBlock(x+9, y+5, z+24, Blocks.snow);
			world.setBlock(x+18, y+5, z+24, Blocks.snow);
			world.setBlock(x+19, y+5, z+24, Blocks.snow);
			world.setBlock(x+22, y+5, z+24, BlockRegister.LEAVES);
			world.setBlockMetadataWithNotify(x+22, y+5, z+24, 1, 2);
			world.setBlock(x+6, y+5, z+25, Blocks.snow);
			world.setBlock(x+7, y+5, z+25, Blocks.snow);
			world.setBlock(x+8, y+5, z+25, Blocks.snow);
			world.setBlock(x+18, y+5, z+25, Blocks.snow);
			world.setBlock(x+21, y+5, z+25, BlockRegister.LEAVES);
			world.setBlockMetadataWithNotify(x+21, y+5, z+25, 1, 2);
			world.setBlock(x+3, y+5, z+26, BlockRegister.LEAVES);
			world.setBlockMetadataWithNotify(x+3, y+5, z+26, 1, 2);
			world.setBlock(x+8, y+5, z+26, Blocks.snow);
			world.setBlock(x+9, y+5, z+26, Blocks.snow);
			world.setBlock(x+10, y+5, z+26, Blocks.snow);
			world.setBlock(x+17, y+5, z+26, Blocks.snow);
			world.setBlock(x+8, y+5, z+27, BlockRegister.LEAVES);
			world.setBlock(x+11, y+5, z+27,Blocks.packed_ice);
			world.setBlock(x+12, y+5, z+27,Blocks.packed_ice);
			world.setBlock(x+14, y+5, z+27, Blocks.snow);
			world.setBlock(x+15, y+5, z+27,Blocks.packed_ice);
			world.setBlock(x+16, y+5, z+27,Blocks.packed_ice);
			world.setBlock(x+6, y+5, z+28, BlockRegister.LEAVES);
			world.setBlockMetadataWithNotify(x+6, y+5, z+28, 1, 2);
			world.setBlock(x+8, y+5, z+28, BlockRegister.LEAVES);
			world.setBlockMetadataWithNotify(x+8, y+5, z+28, 1, 2);
			world.setBlock(x+9, y+5, z+28, BlockRegister.LEAVES);
			world.setBlockMetadataWithNotify(x+9, y+5, z+28, 1, 2);
			world.setBlock(x+10, y+5, z+28, BlockRegister.LEAVES);
			world.setBlockMetadataWithNotify(x+10, y+5, z+28, 1, 2);
			world.setBlock(x+7, y+5, z+29, BlockRegister.LEAVES);
			world.setBlockMetadataWithNotify(x+7, y+5, z+29, 1, 2);
			world.setBlock(x+8, y+5, z+29, BlockRegister.LEAVES);
			world.setBlockMetadataWithNotify(x+8, y+5, z+29, 1, 2);
			world.setBlock(x+14, y+5, z+30, BlockRegister.LEAVES);
			world.setBlockMetadataWithNotify(x+14, y+5, z+30, 1, 2);
			world.setBlock(x+15, y+5, z+30, BlockRegister.LEAVES);
			world.setBlockMetadataWithNotify(x+15, y+5, z+30, 1, 2);
			world.setBlock(x+16, y+5, z+30, BlockRegister.LEAVES);
			world.setBlockMetadataWithNotify(x+16, y+5, z+30, 1, 2);
			world.setBlock(x+14, y+6, z+2, BlockRegister.LEAVES);
			world.setBlockMetadataWithNotify(x+14, y+6, z+2, 1, 2);
			world.setBlock(x+9, y+6, z+4, BlockRegister.LEAVES);
			world.setBlockMetadataWithNotify(x+9, y+6, z+4, 1, 2);
			world.setBlock(x+10, y+6, z+4, BlockRegister.LEAVES);
			world.setBlockMetadataWithNotify(x+10, y+6, z+4, 1, 2);
			world.setBlock(x+8, y+6, z+5, BlockRegister.LEAVES);
			world.setBlockMetadataWithNotify(x+8, y+6, z+5, 1, 2);
			world.setBlock(x+13, y+6, z+5, Blocks.snow);
			world.setBlock(x+14, y+6, z+5, Blocks.snow);
			world.setBlock(x+15, y+6, z+5, Blocks.snow);
			world.setBlock(x+19, y+6, z+5, BlockRegister.LEAVES);
			world.setBlockMetadataWithNotify(x+19, y+6, z+5, 1, 2);
			world.setBlock(x+20, y+6, z+5, BlockRegister.LEAVES);
			world.setBlockMetadataWithNotify(x+20, y+6, z+5, 1, 2);
			world.setBlock(x+12, y+6, z+6, Blocks.snow);
			world.setBlock(x+13, y+6, z+6,Blocks.packed_ice);
			world.setBlock(x+14, y+6, z+6,Blocks.packed_ice);
			world.setBlock(x+15, y+6, z+6,Blocks.packed_ice);
			world.setBlock(x+16, y+6, z+6,Blocks.packed_ice);
			world.setBlock(x+17, y+6, z+6,Blocks.packed_ice);
			world.setBlock(x+18, y+6, z+6, Blocks.snow);
			world.setBlock(x+22, y+6, z+6, BlockRegister.LEAVES);
			world.setBlockMetadataWithNotify(x+22, y+6, z+6, 1, 2);
			world.setBlock(x+10, y+6, z+7,Blocks.packed_ice);
			world.setBlock(x+11, y+6, z+7,Blocks.packed_ice);
			world.setBlock(x+12, y+6, z+7, Block.getBlockById(17));
			world.setBlockMetadataWithNotify(x+12, y+6, z+7, 7, 7);
			world.setBlock(x+13, y+6, z+7, Block.getBlockById(17));
			world.setBlockMetadataWithNotify(x+13, y+6, z+7, 7, 7);
			world.setBlock(x+14, y+6, z+7, Block.getBlockById(17));
			world.setBlockMetadataWithNotify(x+14, y+6, z+7, 7, 7);
			world.setBlock(x+15, y+6, z+7, Block.getBlockById(17));
			world.setBlockMetadataWithNotify(x+15, y+6, z+7, 7, 7);
			world.setBlock(x+16, y+6, z+7, Block.getBlockById(17));
			world.setBlockMetadataWithNotify(x+16, y+6, z+7, 7, 7);
			world.setBlock(x+17, y+6, z+7, Blocks.snow);
			world.setBlock(x+18, y+6, z+7, Blocks.snow);
			world.setBlock(x+19, y+6, z+7, Blocks.snow);
			world.setBlock(x+20, y+6, z+7,Blocks.packed_ice);
			world.setBlock(x+23, y+6, z+7, BlockRegister.LEAVES);
			world.setBlockMetadataWithNotify(x+23, y+6, z+7, 2, 2);
			world.setBlock(x+9, y+6, z+8, Blocks.snow);
			world.setBlock(x+10, y+6, z+8, Block.getBlockById(17));
			world.setBlockMetadataWithNotify(x+10, y+6, z+8, 7, 7);
			world.setBlock(x+11, y+6, z+8, Block.getBlockById(17));
			world.setBlockMetadataWithNotify(x+11, y+6, z+8, 7, 7);
			world.setBlock(x+12, y+6, z+8, Block.getBlockById(4));
			world.setBlock(x+13, y+6, z+8, Block.getBlockById(4));
			world.setBlock(x+14, y+6, z+8, Block.getBlockById(4));
			world.setBlock(x+15, y+6, z+8, Block.getBlockById(4));
			world.setBlock(x+16, y+6, z+8, Block.getBlockById(4));
			world.setBlock(x+17, y+6, z+8, Block.getBlockById(17));
			world.setBlockMetadataWithNotify(x+17, y+6, z+8, 7, 7);
			world.setBlock(x+18, y+6, z+8, Block.getBlockById(17));
			world.setBlockMetadataWithNotify(x+18, y+6, z+8, 7, 7);
			world.setBlock(x+19, y+6, z+8, Blocks.snow);
			world.setBlock(x+20, y+6, z+8,Blocks.packed_ice);
			world.setBlock(x+22, y+6, z+8,Blocks.packed_ice);
			world.setBlock(x+3, y+6, z+9, BlockRegister.LEAVES);
			world.setBlockMetadataWithNotify(x+3, y+6, z+9, 8, 8);
			world.setBlock(x+7, y+6, z+9,Blocks.packed_ice);
			world.setBlock(x+8, y+6, z+9, Blocks.snow);
			world.setBlock(x+9, y+6, z+9, Block.getBlockById(17));
			world.setBlockMetadataWithNotify(x+9, y+6, z+9, 7, 7);
			world.setBlock(x+10, y+6, z+9, Block.getBlockById(4));
			world.setBlock(x+11, y+6, z+9, Block.getBlockById(4));
			world.setBlock(x+12, y+6, z+9, Block.getBlockById(4));
			world.setBlock(x+13, y+6, z+9, Block.getBlockById(4));
			world.setBlock(x+14, y+6, z+9, Block.getBlockById(4));
			world.setBlock(x+15, y+6, z+9, Block.getBlockById(4));
			world.setBlock(x+16, y+6, z+9, Block.getBlockById(4));
			world.setBlock(x+17, y+6, z+9, Block.getBlockById(4));
			world.setBlock(x+18, y+6, z+9, Block.getBlockById(4));
			world.setBlock(x+19, y+6, z+9, Block.getBlockById(17));
			world.setBlockMetadataWithNotify(x+19, y+6, z+9, 7, 7);
			world.setBlock(x+20, y+6, z+9, Blocks.snow);
			world.setBlock(x+21, y+6, z+9, Blocks.snow);
			world.setBlock(x+22, y+6, z+9, Blocks.snow);
			world.setBlock(x+3, y+6, z+10, BlockRegister.LEAVES);
			world.setBlockMetadataWithNotify(x+3, y+6, z+10, 1, 2);
			world.setBlock(x+6, y+6, z+10, Blocks.snow);
			world.setBlock(x+7, y+6, z+10, Blocks.snow);
			world.setBlock(x+8, y+6, z+10, Block.getBlockById(17));
			world.setBlockMetadataWithNotify(x+8, y+6, z+10, 11, 11);
			world.setBlock(x+9, y+6, z+10, Block.getBlockById(4));
			world.setBlock(x+10, y+6, z+10, Block.getBlockById(4));
			world.setBlock(x+11, y+6, z+10, Block.getBlockById(4));
			world.setBlock(x+12, y+6, z+10, Block.getBlockById(4));
			world.setBlock(x+13, y+6, z+10, Block.getBlockById(4));
			world.setBlock(x+14, y+6, z+10, Block.getBlockById(4));
			world.setBlock(x+15, y+6, z+10, Block.getBlockById(4));
			world.setBlock(x+16, y+6, z+10, Block.getBlockById(4));
			world.setBlock(x+17, y+6, z+10, Block.getBlockById(4));
			world.setBlock(x+18, y+6, z+10, Block.getBlockById(4));
			world.setBlock(x+19, y+6, z+10, Block.getBlockById(4));
			world.setBlock(x+20, y+6, z+10, Block.getBlockById(17));
			world.setBlockMetadataWithNotify(x+20, y+6, z+10, 11, 11);
			world.setBlock(x+21, y+6, z+10, Blocks.snow);
			world.setBlock(x+22, y+6, z+10, Blocks.snow);
			world.setBlock(x+23, y+6, z+10, Blocks.snow);
			world.setBlock(x+3, y+6, z+11, BlockRegister.LEAVES);
			world.setBlockMetadataWithNotify(x+3, y+6, z+11, 1, 2);
			world.setBlock(x+6, y+6, z+11, Blocks.snow);
			world.setBlock(x+7, y+6, z+11, Block.getBlockById(17));
			world.setBlockMetadataWithNotify(x+7, y+6, z+11, 11, 11);
			world.setBlock(x+8, y+6, z+11, Block.getBlockById(4));
			world.setBlock(x+9, y+6, z+11, Block.getBlockById(4));
			world.setBlock(x+10, y+6, z+11, Block.getBlockById(4));
			world.setBlock(x+11, y+6, z+11, Block.getBlockById(4));
			world.setBlock(x+12, y+6, z+11, Block.getBlockById(4));
			world.setBlock(x+13, y+6, z+11, Block.getBlockById(4));
			world.setBlock(x+14, y+6, z+11, Block.getBlockById(4));
			world.setBlock(x+15, y+6, z+11, Block.getBlockById(4));
			world.setBlock(x+16, y+6, z+11, Block.getBlockById(4));
			world.setBlock(x+17, y+6, z+11, Block.getBlockById(4));
			world.setBlock(x+18, y+6, z+11, Block.getBlockById(4));
			world.setBlock(x+19, y+6, z+11, Block.getBlockById(4));
			world.setBlock(x+20, y+6, z+11, Block.getBlockById(4));
			world.setBlock(x+21, y+6, z+11, Block.getBlockById(17));
			world.setBlockMetadataWithNotify(x+21, y+6, z+11, 11, 11);
			world.setBlock(x+22, y+6, z+11, Blocks.snow);
			world.setBlock(x+23, y+6, z+11, Blocks.snow);
			world.setBlock(x+6, y+6, z+12, Blocks.snow);
			world.setBlock(x+7, y+6, z+12, Block.getBlockById(17));
			world.setBlockMetadataWithNotify(x+7, y+6, z+12, 11, 11);
			world.setBlock(x+8, y+6, z+12, Block.getBlockById(4));
			world.setBlock(x+9, y+6, z+12, Block.getBlockById(4));
			world.setBlock(x+10, y+6, z+12, Block.getBlockById(4));
			world.setBlock(x+11, y+6, z+12, Block.getBlockById(4));
			world.setBlock(x+12, y+6, z+12, Block.getBlockById(4));
			world.setBlock(x+13, y+6, z+12, Block.getBlockById(4));
			world.setBlock(x+14, y+6, z+12, Block.getBlockById(4));
			world.setBlock(x+15, y+6, z+12, Block.getBlockById(4));
			world.setBlock(x+16, y+6, z+12, Block.getBlockById(4));
			world.setBlock(x+17, y+6, z+12, Block.getBlockById(4));
			world.setBlock(x+18, y+6, z+12, Block.getBlockById(4));
			world.setBlock(x+19, y+6, z+12, Block.getBlockById(4));
			world.setBlock(x+20, y+6, z+12, Block.getBlockById(4));
			world.setBlock(x+21, y+6, z+12, Block.getBlockById(17));
			world.setBlockMetadataWithNotify(x+21, y+6, z+12, 11, 11);
			world.setBlock(x+22, y+6, z+12, Blocks.snow);
			world.setBlock(x+23, y+6, z+12, Blocks.snow);
			world.setBlock(x+24, y+6, z+12, Blocks.snow);
			world.setBlock(x+5, y+6, z+13,Blocks.packed_ice);
			world.setBlock(x+6, y+6, z+13, Block.getBlockById(17));
			world.setBlockMetadataWithNotify(x+6, y+6, z+13, 11, 11);
			world.setBlock(x+7, y+6, z+13, Block.getBlockById(4));
			world.setBlock(x+8, y+6, z+13, Block.getBlockById(4));
			world.setBlock(x+9, y+6, z+13, Block.getBlockById(4));
			world.setBlock(x+10, y+6, z+13, Block.getBlockById(4));
			world.setBlock(x+11, y+6, z+13, Block.getBlockById(4));
			world.setBlock(x+12, y+6, z+13, Block.getBlockById(4));
			world.setBlock(x+13, y+6, z+13, Block.getBlockById(4));
			world.setBlock(x+14, y+6, z+13, Block.getBlockById(4));
			world.setBlock(x+15, y+6, z+13, Block.getBlockById(4));
			world.setBlock(x+16, y+6, z+13, Block.getBlockById(4));
			world.setBlock(x+17, y+6, z+13, Block.getBlockById(4));
			world.setBlock(x+18, y+6, z+13, Block.getBlockById(4));
			world.setBlock(x+19, y+6, z+13, Block.getBlockById(4));
			world.setBlock(x+20, y+6, z+13, Block.getBlockById(4));
			world.setBlock(x+21, y+6, z+13, Block.getBlockById(4));
			world.setBlock(x+22, y+6, z+13, Block.getBlockById(17));
			world.setBlockMetadataWithNotify(x+22, y+6, z+13, 11, 11);
			world.setBlock(x+23, y+6, z+13, Blocks.snow);
			world.setBlock(x+24, y+6, z+13, Blocks.snow);
			world.setBlock(x+26, y+6, z+13, BlockRegister.LEAVES);
			world.setBlockMetadataWithNotify(x+26, y+6, z+13, 2, 2);
			world.setBlock(x+3, y+6, z+14, BlockRegister.LEAVES);
			world.setBlockMetadataWithNotify(x+3, y+6, z+14, 8, 8);
			world.setBlock(x+4, y+6, z+14, Blocks.snow);
			world.setBlock(x+5, y+6, z+14,Blocks.packed_ice);
			world.setBlock(x+6, y+6, z+14, Block.getBlockById(17));
			world.setBlockMetadataWithNotify(x+6, y+6, z+14, 11, 11);
			world.setBlock(x+7, y+6, z+14, Block.getBlockById(4));
			world.setBlock(x+8, y+6, z+14, Block.getBlockById(4));
			world.setBlock(x+9, y+6, z+14, Block.getBlockById(4));
			world.setBlock(x+10, y+6, z+14, Block.getBlockById(4));
			world.setBlock(x+11, y+6, z+14, Block.getBlockById(4));
			world.setBlock(x+12, y+6, z+14, Block.getBlockById(4));
			world.setBlock(x+13, y+6, z+14, Block.getBlockById(4));
			world.setBlock(x+14, y+6, z+14, Block.getBlockById(4));
			world.setBlock(x+15, y+6, z+14, Block.getBlockById(4));
			world.setBlock(x+16, y+6, z+14, Block.getBlockById(4));
			world.setBlock(x+17, y+6, z+14, Block.getBlockById(4));
			world.setBlock(x+18, y+6, z+14, Block.getBlockById(4));
			world.setBlock(x+19, y+6, z+14, Block.getBlockById(4));
			world.setBlock(x+20, y+6, z+14, Block.getBlockById(4));
			world.setBlock(x+21, y+6, z+14, Block.getBlockById(4));
			world.setBlock(x+22, y+6, z+14, Block.getBlockById(17));
			world.setBlockMetadataWithNotify(x+22, y+6, z+14, 11, 11);
			world.setBlock(x+23, y+6, z+14, Blocks.snow);
			world.setBlock(x+26, y+6, z+14, BlockRegister.LEAVES);
			world.setBlockMetadataWithNotify(x+26, y+6, z+14, 2, 2);
			world.setBlock(x+4, y+6, z+15, BlockRegister.LEAVES);
			world.setBlockMetadataWithNotify(x+4, y+6, z+15, 12, 12);
			world.setBlock(x+5, y+6, z+15,Blocks.packed_ice);
			world.setBlock(x+6, y+6, z+15, Block.getBlockById(17));
			world.setBlockMetadataWithNotify(x+6, y+6, z+15, 11, 11);
			world.setBlock(x+7, y+6, z+15, Block.getBlockById(4));
			world.setBlock(x+8, y+6, z+15, Block.getBlockById(4));
			world.setBlock(x+9, y+6, z+15, Block.getBlockById(4));
			world.setBlock(x+10, y+6, z+15, Block.getBlockById(4));
			world.setBlock(x+11, y+6, z+15, Block.getBlockById(4));
			world.setBlock(x+12, y+6, z+15, Block.getBlockById(4));
			world.setBlock(x+13, y+6, z+15, Block.getBlockById(4));
			world.setBlock(x+14, y+6, z+15, Block.getBlockById(9));
			world.setBlockMetadataWithNotify(x+14, y+6, z+15, 8, 8);
			world.setBlock(x+15, y+6, z+15, Block.getBlockById(4));
			world.setBlock(x+16, y+6, z+15, Block.getBlockById(4));
			world.setBlock(x+17, y+6, z+15, Block.getBlockById(4));
			world.setBlock(x+18, y+6, z+15, Block.getBlockById(4));
			world.setBlock(x+19, y+6, z+15, Block.getBlockById(4));
			world.setBlock(x+20, y+6, z+15, Block.getBlockById(4));
			world.setBlock(x+21, y+6, z+15, Block.getBlockById(4));
			world.setBlock(x+22, y+6, z+15, Block.getBlockById(17));
			world.setBlockMetadataWithNotify(x+22, y+6, z+15, 11, 11);
			world.setBlock(x+23, y+6, z+15, Blocks.snow);
			world.setBlock(x+24, y+6, z+15,Blocks.packed_ice);
			world.setBlock(x+26, y+6, z+15, BlockRegister.LEAVES);
			world.setBlockMetadataWithNotify(x+26, y+6, z+15, 2, 2);
			world.setBlock(x+5, y+6, z+16,Blocks.packed_ice);
			world.setBlock(x+6, y+6, z+16, Block.getBlockById(17));
			world.setBlockMetadataWithNotify(x+6, y+6, z+16, 11, 11);
			world.setBlock(x+7, y+6, z+16, Block.getBlockById(4));
			world.setBlock(x+8, y+6, z+16, Block.getBlockById(4));
			world.setBlock(x+9, y+6, z+16, Block.getBlockById(4));
			world.setBlock(x+10, y+6, z+16, Block.getBlockById(4));
			world.setBlock(x+11, y+6, z+16, Block.getBlockById(4));
			world.setBlock(x+12, y+6, z+16, Block.getBlockById(4));
			world.setBlock(x+13, y+6, z+16, Block.getBlockById(4));
			world.setBlock(x+14, y+6, z+16, Block.getBlockById(4));
			world.setBlock(x+15, y+6, z+16, Block.getBlockById(4));
			world.setBlock(x+16, y+6, z+16, Block.getBlockById(4));
			world.setBlock(x+17, y+6, z+16, Block.getBlockById(4));
			world.setBlock(x+18, y+6, z+16, Block.getBlockById(4));
			world.setBlock(x+19, y+6, z+16, Block.getBlockById(4));
			world.setBlock(x+20, y+6, z+16, Block.getBlockById(4));
			world.setBlock(x+21, y+6, z+16, Block.getBlockById(4));
			world.setBlock(x+22, y+6, z+16, Block.getBlockById(17));
			world.setBlockMetadataWithNotify(x+22, y+6, z+16, 11, 11);
			world.setBlock(x+23, y+6, z+16, Blocks.snow);
			world.setBlock(x+24, y+6, z+16,Blocks.packed_ice);
			world.setBlock(x+5, y+6, z+17,Blocks.packed_ice);
			world.setBlock(x+6, y+6, z+17, Block.getBlockById(17));
			world.setBlockMetadataWithNotify(x+6, y+6, z+17, 11, 11);
			world.setBlock(x+7, y+6, z+17, Block.getBlockById(4));
			world.setBlock(x+8, y+6, z+17, Block.getBlockById(4));
			world.setBlock(x+9, y+6, z+17, Block.getBlockById(4));
			world.setBlock(x+10, y+6, z+17, Block.getBlockById(4));
			world.setBlock(x+11, y+6, z+17, Block.getBlockById(4));
			world.setBlock(x+12, y+6, z+17, Block.getBlockById(4));
			world.setBlock(x+13, y+6, z+17, Block.getBlockById(4));
			world.setBlock(x+14, y+6, z+17, Block.getBlockById(4));
			world.setBlock(x+15, y+6, z+17, Block.getBlockById(4));
			world.setBlock(x+16, y+6, z+17, Block.getBlockById(4));
			world.setBlock(x+17, y+6, z+17, Block.getBlockById(4));
			world.setBlock(x+18, y+6, z+17, Block.getBlockById(4));
			world.setBlock(x+19, y+6, z+17, Block.getBlockById(4));
			world.setBlock(x+20, y+6, z+17, Block.getBlockById(4));
			world.setBlock(x+21, y+6, z+17, Block.getBlockById(4));
			world.setBlock(x+22, y+6, z+17, Block.getBlockById(17));
			world.setBlockMetadataWithNotify(x+22, y+6, z+17, 11, 11);
			world.setBlock(x+23, y+6, z+17, Blocks.snow);
			world.setBlock(x+24, y+6, z+17, Blocks.snow);
			world.setBlock(x+6, y+6, z+18, Blocks.snow);
			world.setBlock(x+7, y+6, z+18, Block.getBlockById(17));
			world.setBlockMetadataWithNotify(x+7, y+6, z+18, 11, 11);
			world.setBlock(x+8, y+6, z+18, Block.getBlockById(4));
			world.setBlock(x+9, y+6, z+18, Block.getBlockById(4));
			world.setBlock(x+10, y+6, z+18, Block.getBlockById(4));
			world.setBlock(x+11, y+6, z+18, Block.getBlockById(4));
			world.setBlock(x+12, y+6, z+18, Block.getBlockById(4));
			world.setBlock(x+13, y+6, z+18, Block.getBlockById(4));
			world.setBlock(x+14, y+6, z+18, Block.getBlockById(4));
			world.setBlock(x+15, y+6, z+18, Block.getBlockById(4));
			world.setBlock(x+16, y+6, z+18, Block.getBlockById(4));
			world.setBlock(x+17, y+6, z+18, Block.getBlockById(4));
			world.setBlock(x+18, y+6, z+18, Block.getBlockById(4));
			world.setBlock(x+19, y+6, z+18, Block.getBlockById(4));
			world.setBlock(x+20, y+6, z+18, Block.getBlockById(4));
			world.setBlock(x+21, y+6, z+18, Block.getBlockById(17));
			world.setBlockMetadataWithNotify(x+21, y+6, z+18, 11, 11);
			world.setBlock(x+22, y+6, z+18, Blocks.snow);
			world.setBlock(x+23, y+6, z+18, Blocks.snow);
			world.setBlock(x+2, y+6, z+19, BlockRegister.LEAVES);
			world.setBlockMetadataWithNotify(x+2, y+6, z+19, 8, 8);
			world.setBlock(x+4, y+6, z+19, Blocks.snow);
			world.setBlock(x+5, y+6, z+19, Blocks.snow);
			world.setBlock(x+6, y+6, z+19, Block.getBlockById(17));
			world.setBlockMetadataWithNotify(x+6, y+6, z+19, 11, 11);
			world.setBlock(x+7, y+6, z+19, Block.getBlockById(4));
			world.setBlock(x+8, y+6, z+19, Block.getBlockById(4));
			world.setBlock(x+9, y+6, z+19, Block.getBlockById(4));
			world.setBlock(x+10, y+6, z+19, Block.getBlockById(4));
			world.setBlock(x+11, y+6, z+19, Block.getBlockById(4));
			world.setBlock(x+12, y+6, z+19, Block.getBlockById(4));
			world.setBlock(x+13, y+6, z+19, Block.getBlockById(4));
			world.setBlock(x+14, y+6, z+19, Block.getBlockById(4));
			world.setBlock(x+15, y+6, z+19, Block.getBlockById(4));
			world.setBlock(x+16, y+6, z+19, Block.getBlockById(4));
			world.setBlock(x+17, y+6, z+19, Block.getBlockById(4));
			world.setBlock(x+18, y+6, z+19, Block.getBlockById(4));
			world.setBlock(x+19, y+6, z+19, Block.getBlockById(4));
			world.setBlock(x+20, y+6, z+19, Block.getBlockById(4));
			world.setBlock(x+21, y+6, z+19, Block.getBlockById(17));
			world.setBlockMetadataWithNotify(x+21, y+6, z+19, 11, 11);
			world.setBlock(x+22, y+6, z+19, Blocks.snow);
			world.setBlock(x+23, y+6, z+19, Blocks.snow);
			world.setBlock(x+2, y+6, z+20, BlockRegister.LEAVES);
			world.setBlockMetadataWithNotify(x+2, y+6, z+20, 9, 9);
			world.setBlock(x+4, y+6, z+20, Blocks.snow);
			world.setBlock(x+5, y+6, z+20, Block.getBlockById(17));
			world.setBlockMetadataWithNotify(x+5, y+6, z+20, 11, 11);
			world.setBlock(x+6, y+6, z+20, Block.getBlockById(4));
			world.setBlock(x+7, y+6, z+20, Block.getBlockById(4));
			world.setBlock(x+8, y+6, z+20, Block.getBlockById(4));
			world.setBlock(x+9, y+6, z+20, Block.getBlockById(4));
			world.setBlock(x+10, y+6, z+20, Block.getBlockById(4));
			world.setBlock(x+11, y+6, z+20, Block.getBlockById(4));
			world.setBlock(x+12, y+6, z+20, Block.getBlockById(4));
			world.setBlock(x+13, y+6, z+20, Block.getBlockById(4));
			world.setBlock(x+14, y+6, z+20, Block.getBlockById(4));
			world.setBlock(x+15, y+6, z+20, Block.getBlockById(4));
			world.setBlock(x+16, y+6, z+20, Block.getBlockById(4));
			world.setBlock(x+17, y+6, z+20, Block.getBlockById(4));
			world.setBlock(x+18, y+6, z+20, Block.getBlockById(4));
			world.setBlock(x+19, y+6, z+20, Block.getBlockById(4));
			world.setBlock(x+20, y+6, z+20, Block.getBlockById(17));
			world.setBlockMetadataWithNotify(x+20, y+6, z+20, 11, 11);
			world.setBlock(x+21, y+6, z+20, Blocks.snow);
			world.setBlock(x+22, y+6, z+20, Blocks.snow);
			world.setBlock(x+24, y+6, z+20, BlockRegister.LEAVES);
			world.setBlockMetadataWithNotify(x+24, y+6, z+20, 7, 7);
			world.setBlock(x+1, y+6, z+21, BlockRegister.LEAVES);
			world.setBlockMetadataWithNotify(x+1, y+6, z+21, 8, 8);
			world.setBlock(x+4, y+6, z+21, Blocks.snow);
			world.setBlock(x+5, y+6, z+21, Block.getBlockById(17));
			world.setBlockMetadataWithNotify(x+5, y+6, z+21, 11, 11);
			world.setBlock(x+6, y+6, z+21, Block.getBlockById(4));
			world.setBlock(x+7, y+6, z+21, Block.getBlockById(4));
			world.setBlock(x+8, y+6, z+21, Block.getBlockById(4));
			world.setBlock(x+9, y+6, z+21, Block.getBlockById(4));
			world.setBlock(x+10, y+6, z+21, Block.getBlockById(4));
			world.setBlock(x+11, y+6, z+21, Block.getBlockById(4));
			world.setBlock(x+12, y+6, z+21, Block.getBlockById(4));
			world.setBlock(x+13, y+6, z+21, Block.getBlockById(4));
			world.setBlock(x+14, y+6, z+21, Block.getBlockById(4));
			world.setBlock(x+15, y+6, z+21, Block.getBlockById(4));
			world.setBlock(x+16, y+6, z+21, Block.getBlockById(4));
			world.setBlock(x+17, y+6, z+21, Block.getBlockById(4));
			world.setBlock(x+18, y+6, z+21, Block.getBlockById(4));
			world.setBlock(x+19, y+6, z+21, Block.getBlockById(17));
			world.setBlockMetadataWithNotify(x+19, y+6, z+21, 7, 7);
			world.setBlock(x+20, y+6, z+21, Blocks.snow);
			world.setBlock(x+21, y+6, z+21,Blocks.packed_ice);
			world.setBlock(x+4, y+6, z+22, Blocks.snow);
			world.setBlock(x+5, y+6, z+22, Block.getBlockById(17));
			world.setBlockMetadataWithNotify(x+5, y+6, z+22, 11, 11);
			world.setBlock(x+6, y+6, z+22, Block.getBlockById(4));
			world.setBlock(x+7, y+6, z+22, Block.getBlockById(4));
			world.setBlock(x+8, y+6, z+22, Block.getBlockById(4));
			world.setBlock(x+9, y+6, z+22, Block.getBlockById(4));
			world.setBlock(x+10, y+6, z+22, Block.getBlockById(4));
			world.setBlock(x+11, y+6, z+22, Block.getBlockById(17));
			world.setBlockMetadataWithNotify(x+11, y+6, z+22, 7, 7);
			world.setBlock(x+12, y+6, z+22, Block.getBlockById(4));
			world.setBlock(x+13, y+6, z+22, Block.getBlockById(4));
			world.setBlock(x+14, y+6, z+22, Block.getBlockById(4));
			world.setBlock(x+15, y+6, z+22, Block.getBlockById(4));
			world.setBlock(x+16, y+6, z+22, Block.getBlockById(4));
			world.setBlock(x+17, y+6, z+22, Block.getBlockById(17));
			world.setBlockMetadataWithNotify(x+17, y+6, z+22, 7, 7);
			world.setBlock(x+18, y+6, z+22, Block.getBlockById(17));
			world.setBlockMetadataWithNotify(x+18, y+6, z+22, 7, 7);
			world.setBlock(x+19, y+6, z+22, Blocks.snow);
			world.setBlock(x+20, y+6, z+22, Blocks.snow);
			world.setBlock(x+4, y+6, z+23,Blocks.packed_ice);
			world.setBlock(x+5, y+6, z+23, Blocks.snow);
			world.setBlock(x+6, y+6, z+23, Block.getBlockById(17));
			world.setBlockMetadataWithNotify(x+6, y+6, z+23, 7, 7);
			world.setBlock(x+7, y+6, z+23, Block.getBlockById(4));
			world.setBlock(x+8, y+6, z+23, Block.getBlockById(4));
			world.setBlock(x+9, y+6, z+23, Block.getBlockById(4));
			world.setBlock(x+10, y+6, z+23, Block.getBlockById(17));
			world.setBlockMetadataWithNotify(x+10, y+6, z+23, 7, 7);
			world.setBlock(x+11, y+6, z+23, Blocks.snow);
			world.setBlock(x+12, y+6, z+23, Block.getBlockById(17));
			world.setBlockMetadataWithNotify(x+12, y+6, z+23, 7, 7);
			world.setBlock(x+13, y+6, z+23, Block.getBlockById(17));
			world.setBlockMetadataWithNotify(x+13, y+6, z+23, 7, 7);
			world.setBlock(x+14, y+6, z+23, Block.getBlockById(17));
			world.setBlockMetadataWithNotify(x+14, y+6, z+23, 7, 7);
			world.setBlock(x+15, y+6, z+23, Block.getBlockById(17));
			world.setBlockMetadataWithNotify(x+15, y+6, z+23, 7, 7);
			world.setBlock(x+16, y+6, z+23, Block.getBlockById(17));
			world.setBlockMetadataWithNotify(x+16, y+6, z+23, 7, 7);
			world.setBlock(x+17, y+6, z+23, Blocks.snow);
			world.setBlock(x+18, y+6, z+23, Blocks.snow);
			world.setBlock(x+19, y+6, z+23, Blocks.snow);
			world.setBlock(x+20, y+6, z+23, Blocks.snow);
			world.setBlock(x+22, y+6, z+23, BlockRegister.LEAVES);
			world.setBlockMetadataWithNotify(x+22, y+6, z+23, 2, 2);
			world.setBlock(x+2, y+6, z+24, BlockRegister.LEAVES);
			world.setBlockMetadataWithNotify(x+2, y+6, z+24, 15, 15);
			world.setBlock(x+5, y+6, z+24,Blocks.packed_ice);
			world.setBlock(x+6, y+6, z+24, Blocks.snow);
			world.setBlock(x+7, y+6, z+24, Block.getBlockById(17));
			world.setBlockMetadataWithNotify(x+7, y+6, z+24, 7, 7);
			world.setBlock(x+8, y+6, z+24, Block.getBlockById(17));
			world.setBlockMetadataWithNotify(x+8, y+6, z+24, 7, 7);
			world.setBlock(x+9, y+6, z+24, Block.getBlockById(17));
			world.setBlockMetadataWithNotify(x+9, y+6, z+24, 7, 7);
			world.setBlock(x+10, y+6, z+24, Blocks.snow);
			world.setBlock(x+11, y+6, z+24, Blocks.snow);
			world.setBlock(x+12, y+6, z+24, Blocks.snow);
			world.setBlock(x+13, y+6, z+24, Blocks.snow);
			world.setBlock(x+14, y+6, z+24, Blocks.snow);
			world.setBlock(x+15, y+6, z+24, Blocks.snow);
			world.setBlock(x+16, y+6, z+24, Blocks.snow);
			world.setBlock(x+17, y+6, z+24, Blocks.snow);
			world.setBlock(x+20, y+6, z+24,Blocks.packed_ice);
			world.setBlock(x+22, y+6, z+24, BlockRegister.LEAVES);
			world.setBlockMetadataWithNotify(x+22, y+6, z+24, 2, 2);
			world.setBlock(x+6, y+6, z+25, Blocks.snow);
			world.setBlock(x+7, y+6, z+25, Blocks.snow);
			world.setBlock(x+8, y+6, z+25, Blocks.snow);
			world.setBlock(x+9, y+6, z+25, Blocks.snow);
			world.setBlock(x+10, y+6, z+25, Blocks.snow);
			world.setBlock(x+11, y+6, z+25, Blocks.snow);
			world.setBlock(x+12, y+6, z+25, Blocks.snow);
			world.setBlock(x+13, y+6, z+25, Blocks.snow);
			world.setBlock(x+14, y+6, z+25, Blocks.snow);
			world.setBlock(x+15, y+6, z+25, Blocks.snow);
			world.setBlock(x+16, y+6, z+25, Blocks.snow);
			world.setBlock(x+17, y+6, z+25, Blocks.snow);
			world.setBlock(x+18, y+6, z+25, Blocks.snow);
			world.setBlock(x+19, y+6, z+25, Blocks.snow);
			world.setBlock(x+21, y+6, z+25, BlockRegister.LEAVES);
			world.setBlockMetadataWithNotify(x+21, y+6, z+25, 4, 4);
			world.setBlock(x+3, y+6, z+26, BlockRegister.LEAVES);
			world.setBlockMetadataWithNotify(x+3, y+6, z+26, 7, 7);
			world.setBlock(x+8, y+6, z+26, Blocks.snow);
			world.setBlock(x+9, y+6, z+26, Blocks.snow);
			world.setBlock(x+10, y+6, z+26, Blocks.snow);
			world.setBlock(x+11, y+6, z+26, Blocks.snow);
			world.setBlock(x+12, y+6, z+26, Blocks.snow);
			world.setBlock(x+13, y+6, z+26, Blocks.snow);
			world.setBlock(x+14, y+6, z+26, Blocks.snow);
			world.setBlock(x+15, y+6, z+26, Block.getBlockById(89));
			world.setBlock(x+16, y+6, z+26, Blocks.snow);
			world.setBlock(x+17, y+6, z+26, Blocks.snow);
			world.setBlock(x+18, y+6, z+26, Blocks.snow);
			world.setBlock(x+8, y+6, z+27, Blocks.snow);
			world.setBlock(x+9, y+6, z+27, Blocks.snow);
			world.setBlock(x+10, y+6, z+27,Blocks.packed_ice);
			world.setBlock(x+11, y+6, z+27,Blocks.packed_ice);
			world.setBlock(x+12, y+6, z+27, Blocks.snow);
			world.setBlock(x+13, y+6, z+27, Blocks.snow);
			world.setBlock(x+14, y+6, z+27, Blocks.snow);
			world.setBlock(x+15, y+6, z+27, Blocks.snow);
			world.setBlock(x+16, y+6, z+27,Blocks.packed_ice);
			world.setBlock(x+17, y+6, z+27,Blocks.packed_ice);
			world.setBlock(x+6, y+6, z+28, BlockRegister.LEAVES);
			world.setBlockMetadataWithNotify(x+6, y+6, z+28, 8, 8);
			world.setBlock(x+8, y+6, z+28, BlockRegister.LEAVES);
			world.setBlockMetadataWithNotify(x+8, y+6, z+28, 6, 6);
			world.setBlock(x+9, y+6, z+28, BlockRegister.LEAVES);
			world.setBlockMetadataWithNotify(x+9, y+6, z+28, 4, 4);
			world.setBlock(x+10, y+6, z+28, BlockRegister.LEAVES);
			world.setBlockMetadataWithNotify(x+10, y+6, z+28, 4, 4);
			world.setBlock(x+12, y+6, z+28, Blocks.snow);
			world.setBlock(x+13, y+6, z+28, Blocks.snow);
			world.setBlock(x+14, y+6, z+28, Blocks.snow);
			world.setBlock(x+15, y+6, z+28,Blocks.packed_ice);
			world.setBlock(x+7, y+6, z+29, BlockRegister.LEAVES);
			world.setBlockMetadataWithNotify(x+7, y+6, z+29, 4, 4);
			world.setBlock(x+8, y+6, z+29, BlockRegister.LEAVES);
			world.setBlockMetadataWithNotify(x+8, y+6, z+29, 4, 4);
			world.setBlock(x+14, y+6, z+30, BlockRegister.LEAVES);
			world.setBlockMetadataWithNotify(x+14, y+6, z+30, 4, 4);
			world.setBlock(x+15, y+6, z+30, BlockRegister.LEAVES);
			world.setBlockMetadataWithNotify(x+15, y+6, z+30, 4, 4);
			world.setBlock(x+16, y+6, z+30, BlockRegister.LEAVES);
			world.setBlockMetadataWithNotify(x+16, y+6, z+30, 4, 4);
			world.setBlock(x+14, y+7, z+2, BlockRegister.LEAVES);
			world.setBlockMetadataWithNotify(x+14, y+7, z+2, 7, 7);
			world.setBlock(x+9, y+7, z+4, BlockRegister.LEAVES);
			world.setBlockMetadataWithNotify(x+9, y+7, z+4, 1, 1);
			world.setBlock(x+10, y+7, z+4, BlockRegister.LEAVES);
			world.setBlockMetadataWithNotify(x+10, y+7, z+4, 1, 1);
			world.setBlock(x+15, y+7, z+4, Blocks.snow);
			world.setBlock(x+8, y+7, z+5, BlockRegister.LEAVES);
			world.setBlockMetadataWithNotify(x+8, y+7, z+5, 9, 9);
			world.setBlock(x+11, y+7, z+5, Blocks.snow);
			world.setBlock(x+12, y+7, z+5, Blocks.snow);
			world.setBlock(x+13, y+7, z+5, Blocks.snow);
			world.setBlock(x+14, y+7, z+5, Blocks.snow);
			world.setBlock(x+15, y+7, z+5, Blocks.snow);
			world.setBlock(x+16, y+7, z+5,Blocks.packed_ice);
			world.setBlock(x+19, y+7, z+5, BlockRegister.LEAVES);
			world.setBlockMetadataWithNotify(x+19, y+7, z+5, 1, 1);
			world.setBlock(x+20, y+7, z+5, BlockRegister.LEAVES);
			world.setBlockMetadataWithNotify(x+20, y+7, z+5, 1, 1);
			world.setBlock(x+9, y+7, z+6, Blocks.snow);
			world.setBlock(x+10, y+7, z+6, Blocks.snow);
			world.setBlock(x+11, y+7, z+6, Blocks.snow);
			world.setBlock(x+12, y+7, z+6, Blocks.snow);
			world.setBlock(x+13, y+7, z+6, Blocks.snow);
			world.setBlock(x+14, y+7, z+6, Blocks.snow);
			world.setBlock(x+15, y+7, z+6, Blocks.snow);
			world.setBlock(x+16, y+7, z+6, Blocks.snow);
			world.setBlock(x+17, y+7, z+6,Blocks.packed_ice);
			world.setBlock(x+18, y+7, z+6, Blocks.snow);
			world.setBlock(x+22, y+7, z+6, BlockRegister.LEAVES);
			world.setBlockMetadataWithNotify(x+22, y+7, z+6, 1, 1);
			world.setBlock(x+5, y+7, z+7, BlockRegister.LEAVES);
			world.setBlockMetadataWithNotify(x+5, y+7, z+7, 7, 7);
			world.setBlock(x+8, y+7, z+7,Blocks.packed_ice);
			world.setBlock(x+9, y+7, z+7, Blocks.snow);
			world.setBlock(x+10, y+7, z+7, Blocks.snow);
			world.setBlock(x+11, y+7, z+7, Blocks.snow);
			world.setBlock(x+12, y+7, z+7, BlockRegister.PLANKS);
			world.setBlock(x+13, y+7, z+7, Block.getBlockById(85));
			world.setBlock(x+14, y+7, z+7, Block.getBlockById(17));
			world.setBlockMetadataWithNotify(x+14, y+7, z+7, 3, 3);
			world.setBlock(x+15, y+7, z+7, Block.getBlockById(85));
			world.setBlock(x+16, y+7, z+7, BlockRegister.PLANKS);
			world.setBlock(x+17, y+7, z+7, Blocks.snow);
			world.setBlock(x+18, y+7, z+7, Blocks.snow);
			world.setBlock(x+19, y+7, z+7, Blocks.snow);
			world.setBlock(x+20, y+7, z+7,Blocks.packed_ice);
			world.setBlock(x+23, y+7, z+7, BlockRegister.LEAVES);
			world.setBlockMetadataWithNotify(x+23, y+7, z+7, 2, 2);
			world.setBlock(x+6, y+7, z+8,Blocks.packed_ice);
			world.setBlock(x+7, y+7, z+8,Blocks.packed_ice);
			world.setBlock(x+8, y+7, z+8, Blocks.snow);
			world.setBlock(x+9, y+7, z+8, Blocks.snow);
			world.setBlock(x+10, y+7, z+8, BlockRegister.PLANKS);
			world.setBlock(x+11, y+7, z+8, Block.getBlockById(85));
			world.setBlock(x+12, y+7, z+8, BlockRegister.PLANKS);
			this.setChest(x+13, y+7, z+8);
			world.setBlockMetadataWithNotify(x+13, y+7, z+8, 3, 3);
			this.setChest(x+15, y+7, z+8);
			world.setBlockMetadataWithNotify(x+15, y+7, z+8, 3, 3);
			world.setBlock(x+16, y+7, z+8, BlockRegister.PLANKS);
			world.setBlock(x+17, y+7, z+8, Block.getBlockById(85));
			world.setBlock(x+18, y+7, z+8, BlockRegister.PLANKS);
			world.setBlock(x+19, y+7, z+8, Blocks.snow);
			world.setBlock(x+20, y+7, z+8, Blocks.snow);
			world.setBlock(x+21, y+7, z+8,Blocks.packed_ice);
			world.setBlock(x+22, y+7, z+8,Blocks.packed_ice);
			world.setBlock(x+3, y+7, z+9, BlockRegister.LEAVES);
			world.setBlockMetadataWithNotify(x+3, y+7, z+9, 8, 8);
			world.setBlock(x+5, y+7, z+9, Blocks.snow);
			world.setBlock(x+6, y+7, z+9, Blocks.snow);
			world.setBlock(x+7, y+7, z+9, Blocks.snow);
			world.setBlock(x+8, y+7, z+9, Blocks.snow);
			world.setBlock(x+9, y+7, z+9, Block.getBlockById(85));
			this.setChest(x+10, y+7, z+9);
			world.setBlockMetadataWithNotify(x+10, y+7, z+9, 3, 3);
			this.setChest(x+11, y+7, z+9);
			world.setBlockMetadataWithNotify(x+11, y+7, z+9, 3, 3);
			this.setChest(x+17, y+7, z+9);
			world.setBlockMetadataWithNotify(x+17, y+7, z+9, 3, 3);
			this.setChest(x+18, y+7, z+9);
			world.setBlockMetadataWithNotify(x+18, y+7, z+9, 3, 3);
			world.setBlock(x+19, y+7, z+9, Block.getBlockById(85));
			world.setBlock(x+20, y+7, z+9, Blocks.snow);
			world.setBlock(x+21, y+7, z+9, Blocks.snow);
			world.setBlock(x+22, y+7, z+9,Blocks.packed_ice);
			world.setBlock(x+3, y+7, z+10, BlockRegister.LEAVES);
			world.setBlockMetadataWithNotify(x+3, y+7, z+10, 8, 8);
			world.setBlock(x+5, y+7, z+10, Blocks.snow);
			world.setBlock(x+7, y+7, z+10, Blocks.snow);
			world.setBlock(x+8, y+7, z+10, Block.getBlockById(85));
			world.setBlock(x+9, y+7, z+10, Block.getBlockById(85));
			world.setBlock(x+19, y+7, z+10, Block.getBlockById(85));
			world.setBlock(x+20, y+7, z+10, Block.getBlockById(85));
			world.setBlock(x+21, y+7, z+10, Blocks.snow);
			world.setBlock(x+22, y+7, z+10, Blocks.snow);
			world.setBlock(x+23, y+7, z+10, Blocks.snow);
			world.setBlock(x+3, y+7, z+11, BlockRegister.LEAVES);
			world.setBlockMetadataWithNotify(x+3, y+7, z+11, 8, 8);
			world.setBlock(x+5, y+7, z+11, Blocks.snow);
			world.setBlock(x+6, y+7, z+11, Blocks.snow);
			world.setBlock(x+7, y+7, z+11, BlockRegister.PLANKS);
			this.setChest(x+8, y+7, z+11);
			world.setBlockMetadataWithNotify(x+8, y+7, z+11, 5, 5);
			this.setChest(x+20, y+7, z+11);
			world.setBlockMetadataWithNotify(x+20, y+7, z+11, 4, 4);
			world.setBlock(x+21, y+7, z+11, BlockRegister.PLANKS);
			world.setBlock(x+22, y+7, z+11, Blocks.snow);
			world.setBlock(x+23, y+7, z+11, Blocks.snow);
			world.setBlock(x+4, y+7, z+12, Blocks.snow);
			world.setBlock(x+5, y+7, z+12, Blocks.snow);
			world.setBlock(x+6, y+7, z+12, Blocks.snow);
			world.setBlock(x+7, y+7, z+12, Block.getBlockById(85));
			this.setChest(x+8, y+7, z+12);
			world.setBlockMetadataWithNotify(x+8, y+7, z+12, 5, 5);
			world.setBlock(x+13, y+7, z+12, Block.getBlockById(61));
			world.setBlockMetadataWithNotify(x+13, y+7, z+12, 2, 2);
			world.setBlock(x+14, y+7, z+12, Block.getBlockById(61));
			world.setBlockMetadataWithNotify(x+14, y+7, z+12, 2, 2);
			this.setChest(x+20, y+7, z+12);
			world.setBlockMetadataWithNotify(x+20, y+7, z+12, 4, 4);
			world.setBlock(x+21, y+7, z+12, Block.getBlockById(85));
			world.setBlock(x+22, y+7, z+12, Blocks.snow);
			world.setBlock(x+23, y+7, z+12, Blocks.snow);
			world.setBlock(x+24, y+7, z+12, Blocks.snow);
			world.setBlock(x+2, y+7, z+13,Blocks.packed_ice);
			world.setBlock(x+3, y+7, z+13, Blocks.snow);
			world.setBlock(x+4, y+7, z+13, Blocks.snow);
			world.setBlock(x+5, y+7, z+13, Blocks.snow);
			world.setBlock(x+6, y+7, z+13, BlockRegister.PLANKS);
			world.setBlock(x+7, y+7, z+13, BlockRegister.PLANKS);
			world.setBlock(x+11, y+7, z+13, Block.getBlockById(17));
			world.setBlockMetadataWithNotify(x+11, y+7, z+13, 3, 3);
			world.setBlock(x+12, y+7, z+13, Block.getBlockById(58));
			world.setBlock(x+13, y+7, z+13, BlockRegister.PLANKS);
			world.setBlock(x+14, y+7, z+13, BlockRegister.PLANKS);
			world.setBlock(x+15, y+7, z+13, Block.getBlockById(61));
			world.setBlockMetadataWithNotify(x+15, y+7, z+13, 2, 2);
			world.setBlock(x+16, y+7, z+13, Block.getBlockById(145));
			world.setBlockMetadataWithNotify(x+16, y+7, z+13, 3, 3);
			world.setBlock(x+21, y+7, z+13, BlockRegister.PLANKS);
			world.setBlock(x+22, y+7, z+13, BlockRegister.PLANKS);
			world.setBlock(x+23, y+7, z+13, Blocks.snow);
			world.setBlock(x+24, y+7, z+13, Blocks.snow);
			world.setBlock(x+26, y+7, z+13, BlockRegister.LEAVES);
			world.setBlockMetadataWithNotify(x+26, y+7, z+13, 2, 2);
			world.setBlock(x+3, y+7, z+14, Blocks.snow);
			world.setBlock(x+4, y+7, z+14, Blocks.snow);
			world.setBlock(x+5, y+7, z+14, Blocks.snow);
			world.setBlock(x+6, y+7, z+14, Block.getBlockById(85));
			this.setChest(x+7, y+7, z+14);
			world.setBlockMetadataWithNotify(x+7, y+7, z+14, 5, 5);
			world.setBlock(x+14, y+7, z+14, Block.getBlockById(69));
			world.setBlockMetadataWithNotify(x+14, y+7, z+14, 14, 14);
			world.setBlock(x+15, y+7, z+14, BlockRegister.PLANKS);
			world.setBlock(x+16, y+7, z+14, Block.getBlockById(61));
			world.setBlockMetadataWithNotify(x+16, y+7, z+14, 5, 5);
			this.setChest(x+21, y+7, z+14);
			world.setBlockMetadataWithNotify(x+21, y+7, z+14, 4, 4);
			world.setBlock(x+22, y+7, z+14, Block.getBlockById(85));
			world.setBlock(x+23, y+7, z+14, Blocks.snow);
			world.setBlock(x+24, y+7, z+14, Blocks.snow);
			world.setBlock(x+26, y+7, z+14, BlockRegister.LEAVES);
			world.setBlockMetadataWithNotify(x+26, y+7, z+14, 2, 2);
			world.setBlock(x+3, y+7, z+15,Blocks.packed_ice);
			world.setBlock(x+4, y+7, z+15, Blocks.snow);
			world.setBlock(x+5, y+7, z+15, Blocks.snow);
			world.setBlock(x+6, y+7, z+15, Block.getBlockById(17));
			world.setBlockMetadataWithNotify(x+6, y+7, z+15, 3, 3);
			this.setChest(x+7, y+7, z+15);
			world.setBlockMetadataWithNotify(x+7, y+7, z+15, 5, 5);
			world.setBlock(x+14, y+7, z+15, Block.getBlockById(9));
			world.setBlockMetadataWithNotify(x+14, y+7, z+15, 8, 8);
			world.setBlock(x+16, y+7, z+15, BlockRegister.PLANKS);
			world.setBlock(x+17, y+7, z+15, Block.getBlockById(61));
			world.setBlockMetadataWithNotify(x+17, y+7, z+15, 5, 5);
			world.setBlock(x+22, y+7, z+15, Block.getBlockById(17));
			world.setBlockMetadataWithNotify(x+22, y+7, z+15, 3, 3);
			world.setBlock(x+23, y+7, z+15, Blocks.snow);
			world.setBlock(x+24, y+7, z+15, Blocks.snow);
			world.setBlock(x+26, y+7, z+15, BlockRegister.LEAVES);
			world.setBlockMetadataWithNotify(x+26, y+7, z+15, 2, 2);
			world.setBlock(x+4, y+7, z+16, Blocks.snow);
			world.setBlock(x+5, y+7, z+16, Blocks.snow);
			world.setBlock(x+6, y+7, z+16, Block.getBlockById(85));
			world.setBlock(x+16, y+7, z+16, BlockRegister.PLANKS);
			world.setBlock(x+17, y+7, z+16, Block.getBlockById(61));
			world.setBlockMetadataWithNotify(x+17, y+7, z+16, 5, 5);
			this.setChest(x+21, y+7, z+16);
			world.setBlockMetadataWithNotify(x+21, y+7, z+16, 4, 4);
			world.setBlock(x+22, y+7, z+16, Block.getBlockById(85));
			world.setBlock(x+23, y+7, z+16, Blocks.snow);
			world.setBlock(x+24, y+7, z+16,Blocks.packed_ice);
			world.setBlock(x+4, y+7, z+17, Blocks.snow);
			world.setBlock(x+5, y+7, z+17, Blocks.snow);
			world.setBlock(x+6, y+7, z+17, BlockRegister.PLANKS);
			world.setBlock(x+7, y+7, z+17, BlockRegister.PLANKS);
			world.setBlock(x+8, y+7, z+17, Block.getBlockById(85));
			world.setBlock(x+9, y+7, z+17, Block.getBlockById(85));
			world.setBlock(x+10, y+7, z+17, Block.getBlockById(17));
			world.setBlockMetadataWithNotify(x+10, y+7, z+17, 3, 3);
			world.setBlock(x+16, y+7, z+17, Block.getBlockById(58));
			world.setBlock(x+21, y+7, z+17, BlockRegister.PLANKS);
			world.setBlock(x+22, y+7, z+17, BlockRegister.PLANKS);
			world.setBlock(x+23, y+7, z+17, Blocks.snow);
			world.setBlock(x+25, y+7, z+17, Blocks.snow);
			world.setBlock(x+5, y+7, z+18, Blocks.snow);
			world.setBlock(x+6, y+7, z+18, Blocks.snow);
			world.setBlock(x+7, y+7, z+18, Block.getBlockById(85));
			world.setBlock(x+8, y+7, z+18, Block.getBlockById(130));
			world.setBlockMetadataWithNotify(x+8, y+7, z+18, 3, 3);
			world.setBlock(x+9, y+7, z+18, Block.getBlockById(117));
			world.setBlock(x+16, y+7, z+18, Block.getBlockById(17));
			world.setBlockMetadataWithNotify(x+16, y+7, z+18, 3, 3);
			this.setChest(x+20, y+7, z+18);
			world.setBlockMetadataWithNotify(x+20, y+7, z+18, 4, 4);
			world.setBlock(x+21, y+7, z+18, Block.getBlockById(85));
			world.setBlock(x+22, y+7, z+18, Blocks.snow);
			world.setBlock(x+23, y+7, z+18, Blocks.snow);
			world.setBlock(x+24, y+7, z+18, Blocks.snow);
			world.setBlock(x+2, y+7, z+19, BlockRegister.LEAVES);
			world.setBlockMetadataWithNotify(x+2, y+7, z+19, 8, 8);
			world.setBlock(x+4, y+7, z+19, Blocks.snow);
			world.setBlock(x+5, y+7, z+19, Blocks.snow);
			world.setBlock(x+6, y+7, z+19, Block.getBlockById(85));
			world.setBlock(x+12, y+7, z+19, Block.getBlockById(17));
			world.setBlockMetadataWithNotify(x+12, y+7, z+19, 3, 3);
			this.setChest(x+20, y+7, z+19);
			world.setBlockMetadataWithNotify(x+20, y+7, z+19, 4, 4);
			world.setBlock(x+21, y+7, z+19, BlockRegister.PLANKS);
			world.setBlock(x+22, y+7, z+19, Blocks.snow);
			world.setBlock(x+23, y+7, z+19, Blocks.snow);
			world.setBlock(x+2, y+7, z+20, BlockRegister.LEAVES);
			world.setBlockMetadataWithNotify(x+2, y+7, z+20, 9, 9);
			world.setBlock(x+4, y+7, z+20, Blocks.snow);
			world.setBlock(x+5, y+7, z+20, Block.getBlockById(85));
			world.setBlock(x+11, y+7, z+20, Block.getBlockById(117));
			world.setBlock(x+12, y+7, z+20, Block.getBlockById(85));
			world.setBlock(x+19, y+7, z+20, Block.getBlockById(85));
			world.setBlock(x+20, y+7, z+20, Block.getBlockById(85));
			world.setBlock(x+21, y+7, z+20, Blocks.snow);
			world.setBlock(x+22, y+7, z+20, Blocks.snow);
			world.setBlock(x+24, y+7, z+20, BlockRegister.LEAVES);
			world.setBlockMetadataWithNotify(x+24, y+7, z+20, 7, 7);
			world.setBlock(x+1, y+7, z+21, BlockRegister.LEAVES);
			world.setBlockMetadataWithNotify(x+1, y+7, z+21, 8, 8);
			world.setBlock(x+3, y+7, z+21,Blocks.packed_ice);
			world.setBlock(x+4, y+7, z+21, Blocks.snow);
			world.setBlock(x+5, y+7, z+21, Block.getBlockById(17));
			world.setBlockMetadataWithNotify(x+5, y+7, z+21, 3, 3);
			world.setBlock(x+8, y+7, z+21, Block.getBlockById(116));
			world.setBlock(x+11, y+7, z+21, Block.getBlockById(118));
			world.setBlockMetadataWithNotify(x+11, y+7, z+21, 3, 3);
			world.setBlock(x+12, y+7, z+21, Block.getBlockById(85));
			this.setChest(x+17, y+7, z+21);
			world.setBlockMetadataWithNotify(x+17, y+7, z+21, 2, 2);
			this.setChest(x+18, y+7, z+21);
			world.setBlockMetadataWithNotify(x+18, y+7, z+21, 2, 2);
			world.setBlock(x+19, y+7, z+21, Block.getBlockById(85));
			world.setBlock(x+20, y+7, z+21, Blocks.snow);
			world.setBlock(x+21, y+7, z+21,Blocks.packed_ice);
			world.setBlock(x+3, y+7, z+22,Blocks.packed_ice);
			world.setBlock(x+4, y+7, z+22, Blocks.snow);
			world.setBlock(x+5, y+7, z+22, Block.getBlockById(85));
			world.setBlock(x+11, y+7, z+22, Block.getBlockById(85));
			world.setBlock(x+12, y+7, z+22, BlockRegister.PLANKS);
			this.setChest(x+14, y+7, z+22);
			world.setBlockMetadataWithNotify(x+14, y+7, z+22, 2, 2);
			this.setChest(x+15, y+7, z+22);
			world.setBlockMetadataWithNotify(x+15, y+7, z+22, 2, 2);
			world.setBlock(x+16, y+7, z+22, BlockRegister.PLANKS);
			world.setBlock(x+17, y+7, z+22, Block.getBlockById(85));
			world.setBlock(x+18, y+7, z+22, BlockRegister.PLANKS);
			world.setBlock(x+19, y+7, z+22, Blocks.snow);
			world.setBlock(x+21, y+7, z+22,Blocks.packed_ice);
			world.setBlock(x+4, y+7, z+23,Blocks.packed_ice);
			world.setBlock(x+5, y+7, z+23, Blocks.snow);
			world.setBlock(x+6, y+7, z+23, Block.getBlockById(85));
			world.setBlock(x+10, y+7, z+23, Block.getBlockById(85));
			world.setBlock(x+11, y+7, z+23, Blocks.snow);
			world.setBlock(x+12, y+7, z+23, BlockRegister.PLANKS);
			world.setBlock(x+13, y+7, z+23, Block.getBlockById(85));
			world.setBlock(x+14, y+7, z+23, Block.getBlockById(17));
			world.setBlockMetadataWithNotify(x+14, y+7, z+23, 3, 3);
			world.setBlock(x+15, y+7, z+23, Block.getBlockById(85));
			world.setBlock(x+16, y+7, z+23, BlockRegister.PLANKS);
			world.setBlock(x+17, y+7, z+23, Blocks.snow);
			world.setBlock(x+18, y+7, z+23, Blocks.snow);
			world.setBlock(x+20, y+7, z+23,Blocks.packed_ice);
			world.setBlock(x+22, y+7, z+23, BlockRegister.LEAVES);
			world.setBlockMetadataWithNotify(x+22, y+7, z+23, 2, 2);
			world.setBlock(x+2, y+7, z+24, BlockRegister.LEAVES);
			world.setBlockMetadataWithNotify(x+2, y+7, z+24, 15, 15);
			world.setBlock(x+3, y+7, z+24,Blocks.packed_ice);
			world.setBlock(x+4, y+7, z+24,Blocks.packed_ice);
			world.setBlock(x+5, y+7, z+24, Blocks.snow);
			world.setBlock(x+6, y+7, z+24, Blocks.snow);
			world.setBlock(x+7, y+7, z+24, Block.getBlockById(85));
			world.setBlock(x+8, y+7, z+24, Block.getBlockById(17));
			world.setBlockMetadataWithNotify(x+8, y+7, z+24, 3, 3);
			world.setBlock(x+9, y+7, z+24, Block.getBlockById(85));
			world.setBlock(x+10, y+7, z+24, Blocks.snow);
			world.setBlock(x+12, y+7, z+24, Blocks.snow);
			world.setBlock(x+13, y+7, z+24, Blocks.snow);
			world.setBlock(x+14, y+7, z+24, Blocks.snow);
			world.setBlock(x+15, y+7, z+24, Blocks.snow);
			world.setBlock(x+16, y+7, z+24, Blocks.snow);
			world.setBlock(x+20, y+7, z+24,Blocks.packed_ice);
			world.setBlock(x+22, y+7, z+24, BlockRegister.LEAVES);
			world.setBlockMetadataWithNotify(x+22, y+7, z+24, 2, 2);
			world.setBlock(x+4, y+7, z+25,Blocks.packed_ice);
			world.setBlock(x+5, y+7, z+25, Blocks.snow);
			world.setBlock(x+6, y+7, z+25, Blocks.snow);
			world.setBlock(x+7, y+7, z+25, Blocks.snow);
			world.setBlock(x+8, y+7, z+25, Blocks.snow);
			world.setBlock(x+9, y+7, z+25, Blocks.snow);
			world.setBlock(x+14, y+7, z+25, Block.getBlockById(55));
			world.setBlockMetadataWithNotify(x+14, y+7, z+25, 15, 15);
			world.setBlock(x+15, y+7, z+25, Block.getBlockById(76));
			world.setBlockMetadataWithNotify(x+15, y+7, z+25, 2, 2);
			world.setBlock(x+16, y+7, z+25, Blocks.snow);
			world.setBlock(x+17, y+7, z+25, Block.getBlockById(55));
			world.setBlock(x+18, y+7, z+25, Blocks.snow);
			world.setBlock(x+19, y+7, z+25, Blocks.snow);
			world.setBlock(x+21, y+7, z+25, BlockRegister.LEAVES);
			world.setBlockMetadataWithNotify(x+21, y+7, z+25, 4, 4);
			world.setBlock(x+3, y+7, z+26, BlockRegister.LEAVES);
			world.setBlockMetadataWithNotify(x+3, y+7, z+26, 15, 15);
			world.setBlock(x+5, y+7, z+26, Blocks.snow);
			world.setBlock(x+6, y+7, z+26, Blocks.snow);
			world.setBlock(x+7, y+7, z+26, Blocks.snow);
			world.setBlock(x+8, y+7, z+26, Blocks.snow);
			world.setBlock(x+14, y+7, z+26, Block.getBlockById(55));
			world.setBlockMetadataWithNotify(x+14, y+7, z+26, 14, 14);
			world.setBlock(x+17, y+7, z+26, Blocks.snow);
			world.setBlock(x+18, y+7, z+26, Blocks.snow);
			world.setBlock(x+7, y+7, z+27, Blocks.snow);
			world.setBlock(x+8, y+7, z+27, Blocks.snow);
			world.setBlock(x+9, y+7, z+27,Blocks.packed_ice);
			world.setBlock(x+10, y+7, z+27,Blocks.packed_ice);
			world.setBlock(x+11, y+7, z+27, Blocks.snow);
			world.setBlock(x+14, y+7, z+27, Blocks.snow);
			world.setBlock(x+17, y+7, z+27, Blocks.snow);
			world.setBlock(x+6, y+7, z+28, BlockRegister.LEAVES);
			world.setBlockMetadataWithNotify(x+6, y+7, z+28, 8, 8);
			world.setBlock(x+8, y+7, z+28, BlockRegister.LEAVES);
			world.setBlockMetadataWithNotify(x+8, y+7, z+28, 6, 6);
			world.setBlock(x+11, y+7, z+28,Blocks.packed_ice);
			world.setBlock(x+12, y+7, z+28, Blocks.snow);
			world.setBlock(x+13, y+7, z+28, Blocks.snow);
			world.setBlock(x+14, y+7, z+28, Blocks.snow);
			world.setBlock(x+15, y+7, z+28,Blocks.packed_ice);
			world.setBlock(x+16, y+7, z+28,Blocks.packed_ice);
			world.setBlock(x+7, y+7, z+29, BlockRegister.LEAVES);
			world.setBlockMetadataWithNotify(x+7, y+7, z+29, 4, 4);
			world.setBlock(x+8, y+7, z+29, BlockRegister.LEAVES);
			world.setBlockMetadataWithNotify(x+8, y+7, z+29, 4, 4);
			world.setBlock(x+14, y+7, z+30, BlockRegister.LEAVES);
			world.setBlockMetadataWithNotify(x+14, y+7, z+30, 4, 4);
			world.setBlock(x+15, y+7, z+30, BlockRegister.LEAVES);
			world.setBlockMetadataWithNotify(x+15, y+7, z+30, 4, 4);
			world.setBlock(x+16, y+7, z+30, BlockRegister.LEAVES);
			world.setBlockMetadataWithNotify(x+16, y+7, z+30, 4, 4);
			world.setBlock(x+14, y+8, z+2, BlockRegister.LEAVES);
			world.setBlockMetadataWithNotify(x+14, y+8, z+2, 7, 7);
			world.setBlock(x+15, y+8, z+3, BlockRegister.LEAVES);
			world.setBlockMetadataWithNotify(x+15, y+8, z+3, 7, 7);
			world.setBlock(x+9, y+8, z+4, BlockRegister.LEAVES);
			world.setBlockMetadataWithNotify(x+9, y+8, z+4, 1, 1);
			world.setBlock(x+10, y+8, z+4, BlockRegister.LEAVES);
			world.setBlockMetadataWithNotify(x+10, y+8, z+4, 1, 1);
			world.setBlock(x+11, y+8, z+4, Blocks.snow);
			world.setBlock(x+12, y+8, z+4, Blocks.snow);
			world.setBlock(x+13, y+8, z+4, Blocks.snow);
			world.setBlock(x+14, y+8, z+4, Blocks.snow);
			world.setBlock(x+15, y+8, z+4, Blocks.snow);
			world.setBlock(x+8, y+8, z+5, BlockRegister.LEAVES);
			world.setBlockMetadataWithNotify(x+8, y+8, z+5, 9, 9);
			world.setBlock(x+11, y+8, z+5, Blocks.snow);
			world.setBlock(x+12, y+8, z+5, Blocks.snow);
			world.setBlock(x+13, y+8, z+5, Blocks.snow);
			world.setBlock(x+14, y+8, z+5, Blocks.snow);
			world.setBlock(x+15, y+8, z+5, Blocks.snow);
			world.setBlock(x+16, y+8, z+5,Blocks.packed_ice);
			world.setBlock(x+17, y+8, z+5,Blocks.packed_ice);
			world.setBlock(x+19, y+8, z+5, BlockRegister.LEAVES);
			world.setBlockMetadataWithNotify(x+19, y+8, z+5, 1, 1);
			world.setBlock(x+20, y+8, z+5, BlockRegister.LEAVES);
			world.setBlockMetadataWithNotify(x+20, y+8, z+5, 1, 1);
			world.setBlock(x+9, y+8, z+6, Blocks.snow);
			world.setBlock(x+10, y+8, z+6, Blocks.snow);
			world.setBlock(x+11, y+8, z+6, Blocks.snow);
			world.setBlock(x+12, y+8, z+6, Blocks.snow);
			world.setBlock(x+13, y+8, z+6, Blocks.snow);
			world.setBlock(x+14, y+8, z+6, Blocks.snow);
			world.setBlock(x+15, y+8, z+6, Blocks.snow);
			world.setBlock(x+16, y+8, z+6, Blocks.snow);
			world.setBlock(x+17, y+8, z+6, Blocks.snow);
			world.setBlock(x+18, y+8, z+6, Blocks.snow);
			world.setBlock(x+19, y+8, z+6, Blocks.snow);
			world.setBlock(x+20, y+8, z+6, Blocks.snow);
			world.setBlock(x+22, y+8, z+6, BlockRegister.LEAVES);
			world.setBlockMetadataWithNotify(x+22, y+8, z+6, 1, 1);
			world.setBlock(x+5, y+8, z+7, BlockRegister.LEAVES);
			world.setBlockMetadataWithNotify(x+5, y+8, z+7, 7, 7);
			world.setBlock(x+6, y+8, z+7,Blocks.packed_ice);
			world.setBlock(x+8, y+8, z+7,Blocks.packed_ice);
			world.setBlock(x+9, y+8, z+7, Blocks.snow);
			world.setBlock(x+10, y+8, z+7, Blocks.snow);
			world.setBlock(x+11, y+8, z+7, Blocks.snow);
			world.setBlock(x+12, y+8, z+7, BlockRegister.PLANKS);
			world.setBlock(x+13, y+8, z+7, Block.getBlockById(85));
			world.setBlock(x+14, y+8, z+7, Block.getBlockById(17));
			world.setBlockMetadataWithNotify(x+14, y+8, z+7, 3, 3);
			world.setBlock(x+15, y+8, z+7, Block.getBlockById(85));
			world.setBlock(x+16, y+8, z+7, BlockRegister.PLANKS);
			world.setBlock(x+17, y+8, z+7, Blocks.snow);
			world.setBlock(x+18, y+8, z+7, Blocks.snow);
			world.setBlock(x+21, y+8, z+7, Blocks.snow);
			world.setBlock(x+23, y+8, z+7, BlockRegister.LEAVES);
			world.setBlockMetadataWithNotify(x+23, y+8, z+7, 2, 2);
			world.setBlock(x+5, y+8, z+8, Blocks.snow);
			world.setBlock(x+6, y+8, z+8, Blocks.snow);
			world.setBlock(x+7, y+8, z+8,Blocks.packed_ice);
			world.setBlock(x+8, y+8, z+8, Blocks.snow);
			world.setBlock(x+9, y+8, z+8, Blocks.snow);
			world.setBlock(x+10, y+8, z+8, BlockRegister.PLANKS);
			world.setBlock(x+11, y+8, z+8, Block.getBlockById(85));
			world.setBlock(x+12, y+8, z+8, BlockRegister.PLANKS);
			this.setChest(x+13, y+8, z+8);
			world.setBlockMetadataWithNotify(x+13, y+8, z+8, 3, 3);
			world.setBlock(x+14, y+8, z+8, Block.getBlockById(68));
			world.setBlockMetadataWithNotify(x+14, y+8, z+8, 3, 3);
			this.setChest(x+15, y+8, z+8);
			world.setBlockMetadataWithNotify(x+15, y+8, z+8, 3, 3);
			world.setBlock(x+16, y+8, z+8, BlockRegister.PLANKS);
			world.setBlock(x+17, y+8, z+8, Block.getBlockById(85));
			world.setBlock(x+18, y+8, z+8, BlockRegister.PLANKS);
			world.setBlock(x+19, y+8, z+8, Blocks.snow);
			world.setBlock(x+22, y+8, z+8,Blocks.packed_ice);
			world.setBlock(x+3, y+8, z+9, BlockRegister.LEAVES);
			world.setBlockMetadataWithNotify(x+3, y+8, z+9, 8, 8);
			world.setBlock(x+4, y+8, z+9, Blocks.snow);
			world.setBlock(x+5, y+8, z+9, Blocks.snow);
			world.setBlock(x+6, y+8, z+9, Blocks.snow);
			world.setBlock(x+8, y+8, z+9, Blocks.snow);
			world.setBlock(x+9, y+8, z+9, Block.getBlockById(85));
			this.setChest(x+10, y+8, z+9);
			world.setBlockMetadataWithNotify(x+10, y+8, z+9, 3, 3);
			this.setChest(x+11, y+8, z+9);
			world.setBlockMetadataWithNotify(x+11, y+8, z+9, 3, 3);
			this.setChest(x+17, y+8, z+9);
			world.setBlockMetadataWithNotify(x+17, y+8, z+9, 3, 3);
			this.setChest(x+18, y+8, z+9);
			world.setBlockMetadataWithNotify(x+18, y+8, z+9, 3, 3);
			world.setBlock(x+19, y+8, z+9, Block.getBlockById(85));
			world.setBlock(x+20, y+8, z+9, Blocks.snow);
			world.setBlock(x+21, y+8, z+9, Blocks.snow);
			world.setBlock(x+22, y+8, z+9,Blocks.packed_ice);
			world.setBlock(x+3, y+8, z+10, BlockRegister.LEAVES);
			world.setBlockMetadataWithNotify(x+3, y+8, z+10, 8, 8);
			world.setBlock(x+5, y+8, z+10, Blocks.snow);
			world.setBlock(x+7, y+8, z+10, Blocks.snow);
			world.setBlock(x+8, y+8, z+10, Block.getBlockById(85));
			world.setBlock(x+11, y+8, z+10, Block.getBlockById(68));
			world.setBlockMetadataWithNotify(x+11, y+8, z+10, 3, 3);
