package fr.toss.common.world.bioms.deco;

import java.util.Random;

import net.minecraft.block.Block;
import net.minecraft.enchantment.Enchantment;
import net.minecraft.enchantment.EnchantmentData;
import net.minecraft.init.Blocks;
import net.minecraft.init.Items;
import net.minecraft.item.ItemStack;
import net.minecraft.tileentity.TileEntityChest;
import net.minecraft.world.World;
import net.minecraft.world.chunk.IChunkProvider;
import cpw.mods.fml.common.IWorldGenerator;
import fr.toss.common.Main;
import fr.toss.common.entity.EntityVillagerDim;
import fr.toss.common.register.BlockRegister;
import fr.toss.common.register.ItemRegister;

public class WorldGenFloatingHouse2 implements IWorldGenerator {

	public void spawn(World world, int x, int y, int z) {

		world.setBlock(x+10, y+0, z+18, Block.getBlockById(9));
		world.setBlockMetadataWithNotify(x+10, y+0, z+18, 13, 13);
		world.setBlock(x+10, y+1, z+18, Block.getBlockById(9));
		world.setBlockMetadataWithNotify(x+10, y+1, z+18, 13, 13);
		world.setBlock(x+10, y+2, z+13, Block.getBlockById(106));
		world.setBlockMetadataWithNotify(x+10, y+2, z+13, 2, 2);
		world.setBlock(x+10, y+2, z+18, Block.getBlockById(9));
		world.setBlockMetadataWithNotify(x+10, y+2, z+18, 13, 13);
		world.setBlock(x+10, y+3, z+13, Block.getBlockById(106));
		world.setBlockMetadataWithNotify(x+10, y+3, z+13, 2, 2);
		world.setBlock(x+9, y+3, z+14, Block.getBlockById(106));
		world.setBlockMetadataWithNotify(x+9, y+3, z+14, 4, 4);
		world.setBlock(x+10, y+3, z+18, Block.getBlockById(9));
		world.setBlockMetadataWithNotify(x+10, y+3, z+18, 13, 13);
		world.setBlock(x+8, y+4, z+11, Block.getBlockById(106));
		world.setBlockMetadataWithNotify(x+8, y+4, z+11, 8, 8);
		world.setBlock(x+9, y+4, z+12, Block.getBlockById(106));
		world.setBlockMetadataWithNotify(x+9, y+4, z+12, 1, 1);
		world.setBlock(x+10, y+4, z+13, Block.getBlockById(106));
		world.setBlockMetadataWithNotify(x+10, y+4, z+13, 2, 2);
		world.setBlock(x+9, y+4, z+14, Block.getBlockById(106));
		world.setBlockMetadataWithNotify(x+9, y+4, z+14, 4, 4);
		world.setBlock(x+10, y+4, z+18, Block.getBlockById(9));
		world.setBlockMetadataWithNotify(x+10, y+4, z+18, 13, 13);
		world.setBlock(x+8, y+5, z+11, Block.getBlockById(106));
		world.setBlockMetadataWithNotify(x+8, y+5, z+11, 8, 8);
		world.setBlock(x+9, y+5, z+12, Block.getBlockById(106));
		world.setBlockMetadataWithNotify(x+9, y+5, z+12, 1, 1);
		world.setBlock(x+10, y+5, z+13, Block.getBlockById(106));
		world.setBlockMetadataWithNotify(x+10, y+5, z+13, 2, 2);
		world.setBlock(x+9, y+5, z+14, Block.getBlockById(106));
		world.setBlockMetadataWithNotify(x+9, y+5, z+14, 4, 4);
		world.setBlock(x+10, y+5, z+18, Block.getBlockById(9));
		world.setBlockMetadataWithNotify(x+10, y+5, z+18, 13, 13);
		world.setBlock(x+8, y+6, z+11, Block.getBlockById(106));
		world.setBlockMetadataWithNotify(x+8, y+6, z+11, 9, 9);
		world.setBlock(x+9, y+6, z+12, Block.getBlockById(106));
		world.setBlockMetadataWithNotify(x+9, y+6, z+12, 1, 1);
		world.setBlock(x+9, y+6, z+13, Block.getBlockById(1));
		world.setBlock(x+10, y+6, z+13, Block.getBlockById(106));
		world.setBlockMetadataWithNotify(x+10, y+6, z+13, 2, 2);
		world.setBlock(x+9, y+6, z+14, Block.getBlockById(106));
		world.setBlockMetadataWithNotify(x+9, y+6, z+14, 4, 4);
		world.setBlock(x+10, y+6, z+18, Block.getBlockById(9));
		world.setBlockMetadataWithNotify(x+10, y+6, z+18, 13, 13);
		world.setBlock(x+8, y+7, z+11, Block.getBlockById(106));
		world.setBlockMetadataWithNotify(x+8, y+7, z+11, 9, 9);
		world.setBlock(x+9, y+7, z+12, Block.getBlockById(106));
		world.setBlockMetadataWithNotify(x+9, y+7, z+12, 1, 1);
		world.setBlock(x+9, y+7, z+13, Block.getBlockById(1));
		world.setBlock(x+10, y+7, z+13, Block.getBlockById(106));
		world.setBlockMetadataWithNotify(x+10, y+7, z+13, 2, 2);
		world.setBlock(x+9, y+7, z+14, Block.getBlockById(106));
		world.setBlockMetadataWithNotify(x+9, y+7, z+14, 4, 4);
		world.setBlock(x+10, y+7, z+18, Block.getBlockById(9));
		world.setBlockMetadataWithNotify(x+10, y+7, z+18, 13, 13);
		world.setBlock(x+6, y+8, z+10, Block.getBlockById(106));
		world.setBlockMetadataWithNotify(x+6, y+8, z+10, 9, 9);
		world.setBlock(x+8, y+8, z+11, Block.getBlockById(106));
		world.setBlockMetadataWithNotify(x+8, y+8, z+11, 9, 9);
		world.setBlock(x+7, y+8, z+12, Block.getBlockById(106));
		world.setBlockMetadataWithNotify(x+7, y+8, z+12, 8, 8);
		world.setBlock(x+9, y+8, z+12, Block.getBlockById(1));
		world.setBlock(x+9, y+8, z+13, Block.getBlockById(1));
		world.setBlock(x+10, y+8, z+18, Block.getBlockById(9));
		world.setBlockMetadataWithNotify(x+10, y+8, z+18, 13, 13);
		world.setBlock(x+6, y+9, z+10, Block.getBlockById(106));
		world.setBlockMetadataWithNotify(x+6, y+9, z+10, 9, 9);
		world.setBlock(x+8, y+9, z+11, Block.getBlockById(106));
		world.setBlockMetadataWithNotify(x+8, y+9, z+11, 9, 9);
		world.setBlock(x+7, y+9, z+12, Block.getBlockById(106));
		world.setBlockMetadataWithNotify(x+7, y+9, z+12, 8, 8);
		world.setBlock(x+9, y+9, z+12, Block.getBlockById(1));
		world.setBlock(x+9, y+9, z+13, Block.getBlockById(1));
		world.setBlock(x+11, y+9, z+13, Block.getBlockById(106));
		world.setBlockMetadataWithNotify(x+11, y+9, z+13, 2, 2);
		world.setBlock(x+9, y+9, z+14, Block.getBlockById(106));
		world.setBlockMetadataWithNotify(x+9, y+9, z+14, 2, 2);
		world.setBlock(x+10, y+9, z+18, Block.getBlockById(9));
		world.setBlockMetadataWithNotify(x+10, y+9, z+18, 13, 13);
		world.setBlock(x+8, y+10, z+7, Block.getBlockById(106));
		world.setBlockMetadataWithNotify(x+8, y+10, z+7, 1, 1);
		world.setBlock(x+6, y+10, z+10, Block.getBlockById(106));
		world.setBlockMetadataWithNotify(x+6, y+10, z+10, 9, 9);
		world.setBlock(x+8, y+10, z+11, Block.getBlockById(106));
		world.setBlockMetadataWithNotify(x+8, y+10, z+11, 9, 9);
		world.setBlock(x+9, y+10, z+11, Block.getBlockById(1));
		world.setBlock(x+7, y+10, z+12, Block.getBlockById(106));
		world.setBlockMetadataWithNotify(x+7, y+10, z+12, 8, 8);
		world.setBlock(x+8, y+10, z+12, Block.getBlockById(1));
		world.setBlock(x+9, y+10, z+12, Block.getBlockById(1));
		world.setBlock(x+10, y+10, z+12, Block.getBlockById(1));
		world.setBlock(x+8, y+10, z+13, Block.getBlockById(1));
		world.setBlock(x+9, y+10, z+13, Block.getBlockById(1));
		world.setBlock(x+11, y+10, z+13, Block.getBlockById(106));
		world.setBlockMetadataWithNotify(x+11, y+10, z+13, 2, 2);
		world.setBlock(x+9, y+10, z+14, Block.getBlockById(106));
		world.setBlockMetadataWithNotify(x+9, y+10, z+14, 2, 2);
		world.setBlock(x+10, y+10, z+18, Block.getBlockById(9));
		world.setBlockMetadataWithNotify(x+10, y+10, z+18, 13, 13);
		world.setBlock(x+7, y+11, z+7, Block.getBlockById(106));
		world.setBlockMetadataWithNotify(x+7, y+11, z+7, 1, 1);
		world.setBlock(x+8, y+11, z+7, Block.getBlockById(106));
		world.setBlockMetadataWithNotify(x+8, y+11, z+7, 1, 1);
		world.setBlock(x+6, y+11, z+10, Block.getBlockById(106));
		world.setBlockMetadataWithNotify(x+6, y+11, z+10, 9, 9);
		world.setBlock(x+9, y+11, z+10, Block.getBlockById(1));
		world.setBlock(x+8, y+11, z+11, Block.getBlockById(106));
		world.setBlockMetadataWithNotify(x+8, y+11, z+11, 9, 9);
		world.setBlock(x+9, y+11, z+11, Block.getBlockById(1));
		world.setBlock(x+10, y+11, z+11, Block.getBlockById(1));
		world.setBlock(x+11, y+11, z+11, Block.getBlockById(1));
		world.setBlock(x+8, y+11, z+12, Block.getBlockById(1));
		world.setBlock(x+9, y+11, z+12, Block.getBlockById(1));
		world.setBlock(x+10, y+11, z+12, Block.getBlockById(1));
		world.setBlock(x+8, y+11, z+13, Block.getBlockById(1));
		world.setBlock(x+9, y+11, z+13, Block.getBlockById(1));
		world.setBlock(x+11, y+11, z+13, Block.getBlockById(106));
		world.setBlockMetadataWithNotify(x+11, y+11, z+13, 2, 2);
		world.setBlock(x+9, y+11, z+14, Block.getBlockById(106));
		world.setBlockMetadataWithNotify(x+9, y+11, z+14, 2, 2);
		world.setBlock(x+10, y+11, z+18, Block.getBlockById(9));
		world.setBlockMetadataWithNotify(x+10, y+11, z+18, 13, 13);
		world.setBlock(x+7, y+12, z+7, Block.getBlockById(106));
		world.setBlockMetadataWithNotify(x+7, y+12, z+7, 1, 1);
		world.setBlock(x+8, y+12, z+7, Block.getBlockById(106));
		world.setBlockMetadataWithNotify(x+8, y+12, z+7, 1, 1);
		world.setBlock(x+12, y+12, z+7, Block.getBlockById(106));
		world.setBlockMetadataWithNotify(x+12, y+12, z+7, 1, 1);
		world.setBlock(x+9, y+12, z+9, Block.getBlockById(1));
		world.setBlock(x+6, y+12, z+10, Block.getBlockById(106));
		world.setBlockMetadataWithNotify(x+6, y+12, z+10, 9, 9);
		world.setBlock(x+9, y+12, z+10, Block.getBlockById(1));
		world.setBlock(x+10, y+12, z+10, Block.getBlockById(1));
		world.setBlock(x+13, y+12, z+10, Block.getBlockById(106));
		world.setBlockMetadataWithNotify(x+13, y+12, z+10, 2, 2);
		world.setBlock(x+7, y+12, z+11, Block.getBlockById(106));
		world.setBlockMetadataWithNotify(x+7, y+12, z+11, 8, 8);
		world.setBlock(x+8, y+12, z+11, Block.getBlockById(1));
		world.setBlock(x+9, y+12, z+11, Block.getBlockById(3));
		world.setBlock(x+10, y+12, z+11, Block.getBlockById(3));
		world.setBlock(x+11, y+12, z+11, Block.getBlockById(1));
		world.setBlock(x+8, y+12, z+12, Block.getBlockById(1));
		world.setBlock(x+9, y+12, z+12, Block.getBlockById(3));
		world.setBlock(x+10, y+12, z+12, Block.getBlockById(1));
		world.setBlock(x+7, y+12, z+13, Block.getBlockById(1));
		world.setBlock(x+8, y+12, z+13, Block.getBlockById(1));
		world.setBlock(x+9, y+12, z+13, Block.getBlockById(1));
		world.setBlock(x+11, y+12, z+13, Block.getBlockById(106));
		world.setBlockMetadataWithNotify(x+11, y+12, z+13, 2, 2);
		world.setBlock(x+9, y+12, z+14, Block.getBlockById(106));
		world.setBlockMetadataWithNotify(x+9, y+12, z+14, 2, 2);
		world.setBlock(x+10, y+12, z+18, Block.getBlockById(9));
		world.setBlockMetadataWithNotify(x+10, y+12, z+18, 13, 13);
		world.setBlock(x+10, y+13, z+5, Block.getBlockById(106));
		world.setBlockMetadataWithNotify(x+10, y+13, z+5, 1, 1);
		world.setBlock(x+7, y+13, z+7, Block.getBlockById(106));
		world.setBlockMetadataWithNotify(x+7, y+13, z+7, 1, 1);
		world.setBlock(x+8, y+13, z+7, Block.getBlockById(106));
		world.setBlockMetadataWithNotify(x+8, y+13, z+7, 1, 1);
		world.setBlock(x+12, y+13, z+7, Block.getBlockById(106));
		world.setBlockMetadataWithNotify(x+12, y+13, z+7, 1, 1);
		world.setBlock(x+8, y+13, z+8, Block.getBlockById(1));
		world.setBlock(x+6, y+13, z+9, Block.getBlockById(106));
		world.setBlockMetadataWithNotify(x+6, y+13, z+9, 1, 1);
		world.setBlock(x+8, y+13, z+9, Block.getBlockById(1));
		world.setBlock(x+9, y+13, z+9, Block.getBlockById(1));
		world.setBlock(x+10, y+13, z+9, Block.getBlockById(1));
		world.setBlock(x+6, y+13, z+10, Block.getBlockById(106));
		world.setBlockMetadataWithNotify(x+6, y+13, z+10, 9, 9);
		world.setBlock(x+8, y+13, z+10, Block.getBlockById(1));
		world.setBlock(x+9, y+13, z+10, Block.getBlockById(3));
		world.setBlock(x+10, y+13, z+10, Block.getBlockById(3));
		world.setBlock(x+11, y+13, z+10, Block.getBlockById(16));
		world.setBlock(x+13, y+13, z+10, Block.getBlockById(106));
		world.setBlockMetadataWithNotify(x+13, y+13, z+10, 2, 2);
		world.setBlock(x+4, y+13, z+11, Block.getBlockById(106));
		world.setBlockMetadataWithNotify(x+4, y+13, z+11, 8, 8);
		world.setBlock(x+8, y+13, z+11, Block.getBlockById(1));
		world.setBlock(x+9, y+13, z+11, Block.getBlockById(3));
		world.setBlock(x+10, y+13, z+11, Block.getBlockById(3));
		world.setBlock(x+11, y+13, z+11, Block.getBlockById(1));
		world.setBlock(x+7, y+13, z+12, Block.getBlockById(1));
		world.setBlock(x+8, y+13, z+12, Block.getBlockById(3));
		world.setBlock(x+9, y+13, z+12, Block.getBlockById(3));
		world.setBlock(x+10, y+13, z+12, Block.getBlockById(1));
		world.setBlock(x+7, y+13, z+13, Block.getBlockById(1));
		world.setBlock(x+8, y+13, z+13, Block.getBlockById(1));
		world.setBlock(x+9, y+13, z+13, Block.getBlockById(1));
		world.setBlock(x+10, y+13, z+13, Block.getBlockById(1));
		world.setBlock(x+11, y+13, z+13, Block.getBlockById(106));
		world.setBlockMetadataWithNotify(x+11, y+13, z+13, 2, 2);
		world.setBlock(x+9, y+13, z+14, Block.getBlockById(106));
		world.setBlockMetadataWithNotify(x+9, y+13, z+14, 2, 2);
		world.setBlock(x+10, y+13, z+18, Block.getBlockById(9));
		world.setBlockMetadataWithNotify(x+10, y+13, z+18, 13, 13);
		world.setBlock(x+10, y+14, z+4, Block.getBlockById(106));
		world.setBlockMetadataWithNotify(x+10, y+14, z+4, 1, 1);
		world.setBlock(x+10, y+14, z+5, Block.getBlockById(106));
		world.setBlockMetadataWithNotify(x+10, y+14, z+5, 1, 1);
		world.setBlock(x+17, y+14, z+6, Block.getBlockById(106));
		world.setBlockMetadataWithNotify(x+17, y+14, z+6, 1, 1);
		world.setBlock(x+7, y+14, z+7, Block.getBlockById(106));
		world.setBlockMetadataWithNotify(x+7, y+14, z+7, 1, 1);
		world.setBlock(x+8, y+14, z+7, Block.getBlockById(106));
		world.setBlockMetadataWithNotify(x+8, y+14, z+7, 1, 1);
		world.setBlock(x+9, y+14, z+7, Block.getBlockById(1));
		world.setBlock(x+12, y+14, z+7, Block.getBlockById(106));
		world.setBlockMetadataWithNotify(x+12, y+14, z+7, 1, 1);
		world.setBlock(x+7, y+14, z+8, Block.getBlockById(1));
		world.setBlock(x+8, y+14, z+8, Block.getBlockById(1));
		world.setBlock(x+9, y+14, z+8, Block.getBlockById(1));
		world.setBlock(x+10, y+14, z+8, Block.getBlockById(1));
		world.setBlock(x+6, y+14, z+9, Block.getBlockById(106));
		world.setBlockMetadataWithNotify(x+6, y+14, z+9, 1, 1);
		world.setBlock(x+7, y+14, z+9, Block.getBlockById(1));
		world.setBlock(x+8, y+14, z+9, Block.getBlockById(3));
		world.setBlock(x+9, y+14, z+9, Block.getBlockById(3));
		world.setBlock(x+10, y+14, z+9, Block.getBlockById(1));
		world.setBlock(x+6, y+14, z+10, Block.getBlockById(106));
		world.setBlockMetadataWithNotify(x+6, y+14, z+10, 9, 9);
		world.setBlock(x+7, y+14, z+10, Block.getBlockById(1));
		world.setBlock(x+8, y+14, z+10, Block.getBlockById(3));
		world.setBlock(x+9, y+14, z+10, Block.getBlockById(3));
		world.setBlock(x+10, y+14, z+10, Block.getBlockById(3));
		world.setBlock(x+11, y+14, z+10, Block.getBlockById(1));
		world.setBlock(x+13, y+14, z+10, Block.getBlockById(106));
		world.setBlockMetadataWithNotify(x+13, y+14, z+10, 2, 2);
		world.setBlock(x+4, y+14, z+11, Block.getBlockById(106));
		world.setBlockMetadataWithNotify(x+4, y+14, z+11, 8, 8);
		world.setBlock(x+6, y+14, z+11, Block.getBlockById(1));
		world.setBlock(x+7, y+14, z+11, Block.getBlockById(1));
		world.setBlock(x+8, y+14, z+11, Block.getBlockById(3));
		world.setBlock(x+9, y+14, z+11, Block.getBlockById(3));
		world.setBlock(x+10, y+14, z+11, Block.getBlockById(3));
		world.setBlock(x+11, y+14, z+11, Block.getBlockById(1));
		world.setBlock(x+7, y+14, z+12, Block.getBlockById(16));
		world.setBlock(x+8, y+14, z+12, Block.getBlockById(3));
		world.setBlock(x+9, y+14, z+12, Block.getBlockById(3));
		world.setBlock(x+10, y+14, z+12, Block.getBlockById(1));
		world.setBlock(x+4, y+14, z+13, Block.getBlockById(106));
		world.setBlockMetadataWithNotify(x+4, y+14, z+13, 8, 8);
		world.setBlock(x+7, y+14, z+13, Block.getBlockById(1));
		world.setBlock(x+8, y+14, z+13, Block.getBlockById(1));
		world.setBlock(x+9, y+14, z+13, Block.getBlockById(3));
		world.setBlock(x+10, y+14, z+13, Block.getBlockById(1));
		world.setBlock(x+11, y+14, z+13, Block.getBlockById(106));
		world.setBlockMetadataWithNotify(x+11, y+14, z+13, 2, 2);
		world.setBlock(x+8, y+14, z+14, Block.getBlockById(1));
		world.setBlock(x+9, y+14, z+14, Block.getBlockById(106));
		world.setBlockMetadataWithNotify(x+9, y+14, z+14, 2, 2);
		world.setBlock(x+6, y+14, z+15, Block.getBlockById(106));
		world.setBlockMetadataWithNotify(x+6, y+14, z+15, 8, 8);
		world.setBlock(x+9, y+14, z+17, Block.getBlockById(106));
		world.setBlockMetadataWithNotify(x+9, y+14, z+17, 4, 4);
		world.setBlock(x+10, y+14, z+18, Block.getBlockById(9));
		world.setBlockMetadataWithNotify(x+10, y+14, z+18, 13, 13);
		world.setBlock(x+11, y+15, z+2, Block.getBlockById(106));
		world.setBlockMetadataWithNotify(x+11, y+15, z+2, 2, 2);
		world.setBlock(x+10, y+15, z+4, Block.getBlockById(106));
		world.setBlockMetadataWithNotify(x+10, y+15, z+4, 1, 1);
		world.setBlock(x+10, y+15, z+5, Block.getBlockById(106));
		world.setBlockMetadataWithNotify(x+10, y+15, z+5, 1, 1);
		world.setBlock(x+17, y+15, z+6, Block.getBlockById(106));
		world.setBlockMetadataWithNotify(x+17, y+15, z+6, 3, 3);
		world.setBlock(x+7, y+15, z+7, Block.getBlockById(1));
		world.setBlock(x+8, y+15, z+7, Block.getBlockById(1));
		world.setBlock(x+9, y+15, z+7, Block.getBlockById(1));
		world.setBlock(x+12, y+15, z+7, Block.getBlockById(106));
		world.setBlockMetadataWithNotify(x+12, y+15, z+7, 1, 1);
		world.setBlock(x+17, y+15, z+7, Block.getBlockById(106));
		world.setBlockMetadataWithNotify(x+17, y+15, z+7, 2, 2);
		world.setBlock(x+7, y+15, z+8, Block.getBlockById(1));
		world.setBlock(x+8, y+15, z+8, Block.getBlockById(3));
		world.setBlock(x+9, y+15, z+8, Block.getBlockById(3));
		world.setBlock(x+10, y+15, z+8, Block.getBlockById(1));
		world.setBlock(x+11, y+15, z+8, Block.getBlockById(1));
		world.setBlock(x+4, y+15, z+9, Block.getBlockById(106));
		world.setBlockMetadataWithNotify(x+4, y+15, z+9, 8, 8);
		world.setBlock(x+6, y+15, z+9, Block.getBlockById(106));
		world.setBlockMetadataWithNotify(x+6, y+15, z+9, 1, 1);
		world.setBlock(x+7, y+15, z+9, Block.getBlockById(1));
		world.setBlock(x+8, y+15, z+9, Block.getBlockById(3));
		world.setBlock(x+9, y+15, z+9, Block.getBlockById(3));
		world.setBlock(x+10, y+15, z+9, Block.getBlockById(3));
		world.setBlock(x+11, y+15, z+9, Block.getBlockById(1));
		world.setBlock(x+12, y+15, z+9, Block.getBlockById(1));
		world.setBlock(x+6, y+15, z+10, Block.getBlockById(1));
		world.setBlock(x+7, y+15, z+10, Block.getBlockById(3));
		world.setBlock(x+8, y+15, z+10, Block.getBlockById(3));
		world.setBlock(x+9, y+15, z+10, Block.getBlockById(3));
		world.setBlock(x+10, y+15, z+10, Block.getBlockById(3));
		world.setBlock(x+11, y+15, z+10, Block.getBlockById(1));
		world.setBlock(x+12, y+15, z+10, Block.getBlockById(3));
		world.setBlock(x+13, y+15, z+10, Block.getBlockById(106));
		world.setBlockMetadataWithNotify(x+13, y+15, z+10, 2, 2);
		world.setBlock(x+4, y+15, z+11, Block.getBlockById(106));
		world.setBlockMetadataWithNotify(x+4, y+15, z+11, 8, 8);
		world.setBlock(x+6, y+15, z+11, Block.getBlockById(1));
		world.setBlock(x+7, y+15, z+11, Block.getBlockById(3));
		world.setBlock(x+8, y+15, z+11, Block.getBlockById(3));
		world.setBlock(x+9, y+15, z+11, Block.getBlockById(3));
		world.setBlock(x+10, y+15, z+11, Block.getBlockById(3));
		world.setBlock(x+11, y+15, z+11, Block.getBlockById(3));
		world.setBlock(x+12, y+15, z+11, Block.getBlockById(3));
		world.setBlock(x+7, y+15, z+12, Block.getBlockById(16));
		world.setBlock(x+8, y+15, z+12, Block.getBlockById(3));
		world.setBlock(x+9, y+15, z+12, Block.getBlockById(3));
		world.setBlock(x+10, y+15, z+12, Block.getBlockById(3));
		world.setBlock(x+11, y+15, z+12, Block.getBlockById(1));
		world.setBlock(x+4, y+15, z+13, Block.getBlockById(106));
		world.setBlockMetadataWithNotify(x+4, y+15, z+13, 8, 8);
		world.setBlock(x+7, y+15, z+13, Block.getBlockById(1));
		world.setBlock(x+8, y+15, z+13, Block.getBlockById(3));
		world.setBlock(x+9, y+15, z+13, Block.getBlockById(3));
		world.setBlock(x+10, y+15, z+13, Block.getBlockById(1));
		world.setBlock(x+11, y+15, z+13, Block.getBlockById(106));
		world.setBlockMetadataWithNotify(x+11, y+15, z+13, 2, 2);
		world.setBlock(x+16, y+15, z+13, Block.getBlockById(106));
		world.setBlockMetadataWithNotify(x+16, y+15, z+13, 2, 2);
		world.setBlock(x+8, y+15, z+14, Block.getBlockById(3));
		world.setBlock(x+9, y+15, z+14, Block.getBlockById(3));
		world.setBlock(x+10, y+15, z+14, Block.getBlockById(3));
		world.setBlock(x+6, y+15, z+15, Block.getBlockById(106));
		world.setBlockMetadataWithNotify(x+6, y+15, z+15, 8, 8);
		world.setBlock(x+9, y+15, z+17, Block.getBlockById(106));
		world.setBlockMetadataWithNotify(x+9, y+15, z+17, 4, 4);
		world.setBlock(x+10, y+15, z+18, Block.getBlockById(9));
		world.setBlockMetadataWithNotify(x+10, y+15, z+18, 13, 13);
		world.setBlock(x+11, y+15, z+18, Block.getBlockById(106));
		world.setBlockMetadataWithNotify(x+11, y+15, z+18, 4, 4);
		world.setBlock(x+11, y+16, z+2, Block.getBlockById(106));
		world.setBlockMetadataWithNotify(x+11, y+16, z+2, 2, 2);
		world.setBlock(x+10, y+16, z+4, Block.getBlockById(106));
		world.setBlockMetadataWithNotify(x+10, y+16, z+4, 1, 1);
		world.setBlock(x+10, y+16, z+5, Block.getBlockById(106));
		world.setBlockMetadataWithNotify(x+10, y+16, z+5, 1, 1);
		world.setBlock(x+8, y+16, z+6, Block.getBlockById(1));
		world.setBlock(x+9, y+16, z+6, Block.getBlockById(1));
		world.setBlock(x+10, y+16, z+6, Block.getBlockById(1));
		world.setBlock(x+17, y+16, z+6, Block.getBlockById(106));
		world.setBlockMetadataWithNotify(x+17, y+16, z+6, 3, 3);
		world.setBlock(x+7, y+16, z+7, Block.getBlockById(16));
		world.setBlock(x+8, y+16, z+7, Block.getBlockById(3));
		world.setBlock(x+9, y+16, z+7, Block.getBlockById(3));
		world.setBlock(x+10, y+16, z+7, Block.getBlockById(1));
		world.setBlock(x+11, y+16, z+7, Block.getBlockById(1));
		world.setBlock(x+12, y+16, z+7, Block.getBlockById(106));
		world.setBlockMetadataWithNotify(x+12, y+16, z+7, 1, 1);
		world.setBlock(x+17, y+16, z+7, Block.getBlockById(106));
		world.setBlockMetadataWithNotify(x+17, y+16, z+7, 2, 2);
		world.setBlock(x+6, y+16, z+8, Block.getBlockById(1));
		world.setBlock(x+7, y+16, z+8, Block.getBlockById(3));
		world.setBlock(x+8, y+16, z+8, Block.getBlockById(3));
		world.setBlock(x+9, y+16, z+8, Block.getBlockById(3));
		world.setBlock(x+10, y+16, z+8, Block.getBlockById(3));
		world.setBlock(x+11, y+16, z+8, Block.getBlockById(3));
		world.setBlock(x+12, y+16, z+8, Block.getBlockById(1));
		world.setBlock(x+4, y+16, z+9, Block.getBlockById(106));
		world.setBlockMetadataWithNotify(x+4, y+16, z+9, 8, 8);
		world.setBlock(x+6, y+16, z+9, Block.getBlockById(1));
		world.setBlock(x+7, y+16, z+9, Block.getBlockById(3));
		world.setBlock(x+8, y+16, z+9, Block.getBlockById(3));
		world.setBlock(x+9, y+16, z+9, Block.getBlockById(3));
		world.setBlock(x+10, y+16, z+9, Block.getBlockById(3));
		world.setBlock(x+11, y+16, z+9, Block.getBlockById(3));
		world.setBlock(x+12, y+16, z+9, Block.getBlockById(3));
		world.setBlock(x+5, y+16, z+10, Block.getBlockById(1));
		world.setBlock(x+6, y+16, z+10, Block.getBlockById(3));
		world.setBlock(x+7, y+16, z+10, Block.getBlockById(3));
		world.setBlock(x+8, y+16, z+10, Block.getBlockById(3));
		world.setBlock(x+9, y+16, z+10, Block.getBlockById(3));
		world.setBlock(x+10, y+16, z+10, Block.getBlockById(3));
		world.setBlock(x+11, y+16, z+10, Block.getBlockById(3));
		world.setBlock(x+12, y+16, z+10, Block.getBlockById(3));
		world.setBlock(x+13, y+16, z+10, Block.getBlockById(106));
		world.setBlockMetadataWithNotify(x+13, y+16, z+10, 2, 2);
		world.setBlock(x+14, y+16, z+10, Block.getBlockById(106));
		world.setBlock(x+4, y+16, z+11, Block.getBlockById(106));
		world.setBlockMetadataWithNotify(x+4, y+16, z+11, 8, 8);
		world.setBlock(x+5, y+16, z+11, Block.getBlockById(3));
		world.setBlock(x+6, y+16, z+11, Block.getBlockById(3));
		world.setBlock(x+7, y+16, z+11, Block.getBlockById(3));
		world.setBlock(x+8, y+16, z+11, Block.getBlockById(3));
		world.setBlock(x+9, y+16, z+11, Block.getBlockById(3));
		world.setBlock(x+10, y+16, z+11, Block.getBlockById(3));
		world.setBlock(x+11, y+16, z+11, Block.getBlockById(3));
		world.setBlock(x+12, y+16, z+11, Block.getBlockById(3));
		world.setBlock(x+6, y+16, z+12, Block.getBlockById(3));
		world.setBlock(x+7, y+16, z+12, Block.getBlockById(3));
		world.setBlock(x+8, y+16, z+12, Block.getBlockById(3));
		world.setBlock(x+9, y+16, z+12, Block.getBlockById(3));
		world.setBlock(x+10, y+16, z+12, Block.getBlockById(3));
		world.setBlock(x+11, y+16, z+12, Block.getBlockById(3));
		world.setBlock(x+12, y+16, z+12, Block.getBlockById(3));
		world.setBlock(x+4, y+16, z+13, Block.getBlockById(106));
		world.setBlockMetadataWithNotify(x+4, y+16, z+13, 8, 8);
		world.setBlock(x+7, y+16, z+13, Block.getBlockById(3));
		world.setBlock(x+8, y+16, z+13, Block.getBlockById(3));
		world.setBlock(x+9, y+16, z+13, Block.getBlockById(3));
		world.setBlock(x+10, y+16, z+13, Block.getBlockById(3));
		world.setBlock(x+11, y+16, z+13, Block.getBlockById(3));
		world.setBlock(x+16, y+16, z+13, Block.getBlockById(106));
		world.setBlockMetadataWithNotify(x+16, y+16, z+13, 2, 2);
		world.setBlock(x+8, y+16, z+14, Block.getBlockById(3));
		world.setBlock(x+9, y+16, z+14, Block.getBlockById(3));
		world.setBlock(x+10, y+16, z+14, Block.getBlockById(3));
		world.setBlock(x+11, y+16, z+14, Block.getBlockById(3));
		world.setBlock(x+6, y+16, z+15, Block.getBlockById(106));
		world.setBlockMetadataWithNotify(x+6, y+16, z+15, 8, 8);
		world.setBlock(x+9, y+16, z+15, Block.getBlockById(3));
		world.setBlock(x+10, y+16, z+15, Block.getBlockById(3));
		world.setBlock(x+9, y+16, z+16, Block.getBlockById(3));
		world.setBlock(x+9, y+16, z+17, Block.getBlockById(106));
		world.setBlockMetadataWithNotify(x+9, y+16, z+17, 4, 4);
		world.setBlock(x+10, y+16, z+18, Block.getBlockById(9));
		world.setBlockMetadataWithNotify(x+10, y+16, z+18, 13, 13);
		world.setBlock(x+11, y+16, z+18, Block.getBlockById(106));
		world.setBlockMetadataWithNotify(x+11, y+16, z+18, 4, 4);
		world.setBlock(x+10, y+17, z+1, Block.getBlockById(106));
		world.setBlockMetadataWithNotify(x+10, y+17, z+1, 1, 1);
		world.setBlock(x+11, y+17, z+1, Block.getBlockById(106));
		world.setBlockMetadataWithNotify(x+11, y+17, z+1, 2, 2);
		world.setBlock(x+11, y+17, z+2, Block.getBlockById(106));
		world.setBlockMetadataWithNotify(x+11, y+17, z+2, 2, 2);
		world.setBlock(x+10, y+17, z+4, Block.getBlockById(106));
		world.setBlockMetadataWithNotify(x+10, y+17, z+4, 1, 1);
		world.setBlock(x+9, y+17, z+5, Block.getBlockById(106));
		world.setBlockMetadataWithNotify(x+9, y+17, z+5, 8, 8);
		world.setBlock(x+10, y+17, z+5, Block.getBlockById(1));
		world.setBlock(x+7, y+17, z+6, Block.getBlockById(1));
		world.setBlock(x+8, y+17, z+6, Block.getBlockById(1));
		world.setBlock(x+9, y+17, z+6, Block.getBlockById(1));
		world.setBlock(x+10, y+17, z+6, Block.getBlockById(3));
		world.setBlock(x+11, y+17, z+6, Block.getBlockById(3));
		world.setBlock(x+17, y+17, z+6, Block.getBlockById(106));
		world.setBlockMetadataWithNotify(x+17, y+17, z+6, 3, 3);
		world.setBlock(x+5, y+17, z+7, Block.getBlockById(1));
		world.setBlock(x+6, y+17, z+7, Block.getBlockById(1));
		world.setBlock(x+7, y+17, z+7, Block.getBlockById(3));
		world.setBlock(x+8, y+17, z+7, Block.getBlockById(3));
		world.setBlock(x+9, y+17, z+7, Block.getBlockById(3));
		world.setBlock(x+10, y+17, z+7, Block.getBlockById(3));
		world.setBlock(x+11, y+17, z+7, Block.getBlockById(3));
		world.setBlock(x+12, y+17, z+7, Block.getBlockById(3));
		world.setBlock(x+17, y+17, z+7, Block.getBlockById(106));
		world.setBlockMetadataWithNotify(x+17, y+17, z+7, 2, 2);
		world.setBlock(x+5, y+17, z+8, Block.getBlockById(1));
		world.setBlock(x+6, y+17, z+8, Block.getBlockById(3));
		world.setBlock(x+7, y+17, z+8, Block.getBlockById(3));
		world.setBlock(x+8, y+17, z+8, Block.getBlockById(3));
		world.setBlock(x+9, y+17, z+8, Block.getBlockById(3));
		world.setBlock(x+10, y+17, z+8, Block.getBlockById(3));
		world.setBlock(x+11, y+17, z+8, Block.getBlockById(3));
		world.setBlock(x+12, y+17, z+8, Block.getBlockById(3));
		world.setBlock(x+4, y+17, z+9, Block.getBlockById(106));
		world.setBlockMetadataWithNotify(x+4, y+17, z+9, 8, 8);
		world.setBlock(x+5, y+17, z+9, Block.getBlockById(1));
		world.setBlock(x+6, y+17, z+9, Block.getBlockById(3));
		world.setBlock(x+7, y+17, z+9, Block.getBlockById(3));
		world.setBlock(x+8, y+17, z+9, Block.getBlockById(3));
		world.setBlock(x+9, y+17, z+9, Block.getBlockById(3));
		world.setBlock(x+10, y+17, z+9, Block.getBlockById(3));
		world.setBlock(x+11, y+17, z+9, Block.getBlockById(3));
		world.setBlock(x+12, y+17, z+9, Block.getBlockById(3));
		world.setBlock(x+13, y+17, z+9, Block.getBlockById(3));
		world.setBlock(x+5, y+17, z+10, Block.getBlockById(1));
		world.setBlock(x+6, y+17, z+10, Block.getBlockById(3));
		world.setBlock(x+7, y+17, z+10, Block.getBlockById(3));
		world.setBlock(x+8, y+17, z+10, Block.getBlockById(3));
		world.setBlock(x+9, y+17, z+10, Block.getBlockById(3));
		world.setBlock(x+10, y+17, z+10, Block.getBlockById(3));
		world.setBlock(x+11, y+17, z+10, Block.getBlockById(3));
		world.setBlock(x+12, y+17, z+10, Block.getBlockById(3));
		world.setBlock(x+13, y+17, z+10, Block.getBlockById(3));
		world.setBlock(x+14, y+17, z+10, Block.getBlockById(3));
		world.setBlock(x+5, y+17, z+11, Block.getBlockById(1));
		world.setBlock(x+6, y+17, z+11, Block.getBlockById(3));
		world.setBlock(x+7, y+17, z+11, Block.getBlockById(3));
		world.setBlock(x+8, y+17, z+11, Block.getBlockById(3));
		world.setBlock(x+9, y+17, z+11, Block.getBlockById(3));
		world.setBlock(x+10, y+17, z+11, Block.getBlockById(3));
		world.setBlock(x+11, y+17, z+11, Block.getBlockById(3));
		world.setBlock(x+12, y+17, z+11, Block.getBlockById(3));
		world.setBlock(x+13, y+17, z+11, Block.getBlockById(3));
		world.setBlock(x+6, y+17, z+12, Block.getBlockById(3));
		world.setBlock(x+7, y+17, z+12, Block.getBlockById(3));
		world.setBlock(x+8, y+17, z+12, Block.getBlockById(3));
		world.setBlock(x+9, y+17, z+12, Block.getBlockById(3));
		world.setBlock(x+10, y+17, z+12, Block.getBlockById(3));
		world.setBlock(x+11, y+17, z+12, Block.getBlockById(3));
		world.setBlock(x+12, y+17, z+12, Block.getBlockById(3));
		world.setBlock(x+13, y+17, z+12, Block.getBlockById(3));
		world.setBlock(x+4, y+17, z+13, Block.getBlockById(106));
		world.setBlockMetadataWithNotify(x+4, y+17, z+13, 8, 8);
		world.setBlock(x+6, y+17, z+13, Block.getBlockById(3));
		world.setBlock(x+7, y+17, z+13, Block.getBlockById(3));
		world.setBlock(x+8, y+17, z+13, Block.getBlockById(3));
		world.setBlock(x+9, y+17, z+13, Block.getBlockById(3));
		world.setBlock(x+10, y+17, z+13, Block.getBlockById(3));
		world.setBlock(x+11, y+17, z+13, Block.getBlockById(3));
		world.setBlock(x+12, y+17, z+13, Block.getBlockById(3));
		world.setBlock(x+16, y+17, z+13, Block.getBlockById(106));
		world.setBlockMetadataWithNotify(x+16, y+17, z+13, 2, 2);
		world.setBlock(x+7, y+17, z+14, Block.getBlockById(3));
		world.setBlock(x+8, y+17, z+14, Block.getBlockById(3));
		world.setBlock(x+9, y+17, z+14, Block.getBlockById(3));
		world.setBlock(x+10, y+17, z+14, Block.getBlockById(3));
		world.setBlock(x+11, y+17, z+14, Block.getBlockById(3));
		world.setBlock(x+12, y+17, z+14, Block.getBlockById(3));
		world.setBlock(x+6, y+17, z+15, Block.getBlockById(106));
		world.setBlockMetadataWithNotify(x+6, y+17, z+15, 8, 8);
		world.setBlock(x+8, y+17, z+15, Block.getBlockById(3));
		world.setBlock(x+9, y+17, z+15, Block.getBlockById(3));
		world.setBlock(x+10, y+17, z+15, Block.getBlockById(3));
		world.setBlock(x+11, y+17, z+15, Block.getBlockById(3));
		world.setBlock(x+7, y+17, z+16, Block.getBlockById(106));
		world.setBlockMetadataWithNotify(x+7, y+17, z+16, 4, 4);
		world.setBlock(x+8, y+17, z+16, Block.getBlockById(3));
		world.setBlock(x+9, y+17, z+16, Block.getBlockById(3));
		world.setBlock(x+10, y+17, z+16, Block.getBlockById(3));
		world.setBlock(x+9, y+17, z+17, Block.getBlockById(106));
		world.setBlockMetadataWithNotify(x+9, y+17, z+17, 4, 4);
		world.setBlock(x+10, y+17, z+18, Block.getBlockById(9));
		world.setBlockMetadataWithNotify(x+10, y+17, z+18, 13, 13);
		world.setBlock(x+11, y+17, z+18, Block.getBlockById(106));
		world.setBlockMetadataWithNotify(x+11, y+17, z+18, 4, 4);
		world.setBlock(x+10, y+18, z+1, Block.getBlockById(106));
		world.setBlockMetadataWithNotify(x+10, y+18, z+1, 1, 1);
		world.setBlock(x+11, y+18, z+1, Block.getBlockById(106));
		world.setBlockMetadataWithNotify(x+11, y+18, z+1, 2, 2);
		world.setBlock(x+10, y+18, z+2, Block.getBlockById(17));
		world.setBlock(x+11, y+18, z+2, Block.getBlockById(106));
		world.setBlockMetadataWithNotify(x+11, y+18, z+2, 2, 2);
		world.setBlock(x+10, y+18, z+4, Block.getBlockById(3));
		world.setBlock(x+11, y+18, z+4, Block.getBlockById(3));
		world.setBlock(x+6, y+18, z+5, Block.getBlockById(3));
		world.setBlock(x+7, y+18, z+5, Block.getBlockById(3));
		world.setBlock(x+8, y+18, z+5, Block.getBlockById(3));
		world.setBlock(x+9, y+18, z+5, Block.getBlockById(3));
		world.setBlock(x+10, y+18, z+5, Block.getBlockById(3));
		world.setBlock(x+11, y+18, z+5, Block.getBlockById(3));
		world.setBlock(x+12, y+18, z+5, Block.getBlockById(3));
		world.setBlock(x+5, y+18, z+6, Block.getBlockById(3));
		world.setBlock(x+6, y+18, z+6, Block.getBlockById(3));
		world.setBlock(x+7, y+18, z+6, Block.getBlockById(3));
		world.setBlock(x+8, y+18, z+6, Block.getBlockById(3));
		world.setBlock(x+9, y+18, z+6, Block.getBlockById(3));
		world.setBlock(x+10, y+18, z+6, Block.getBlockById(3));
		world.setBlock(x+11, y+18, z+6, Block.getBlockById(3));
		world.setBlock(x+12, y+18, z+6, Block.getBlockById(3));
		world.setBlock(x+13, y+18, z+6, Block.getBlockById(3));
		world.setBlock(x+17, y+18, z+6, Block.getBlockById(106));
		world.setBlockMetadataWithNotify(x+17, y+18, z+6, 3, 3);
		world.setBlock(x+4, y+18, z+7, Block.getBlockById(3));
		world.setBlock(x+5, y+18, z+7, Block.getBlockById(3));
		world.setBlock(x+6, y+18, z+7, Block.getBlockById(3));
		world.setBlock(x+7, y+18, z+7, Block.getBlockById(3));
		world.setBlock(x+8, y+18, z+7, Block.getBlockById(3));
		world.setBlock(x+9, y+18, z+7, Block.getBlockById(3));
		world.setBlock(x+10, y+18, z+7, Block.getBlockById(3));
		world.setBlock(x+11, y+18, z+7, Block.getBlockById(3));
		world.setBlock(x+12, y+18, z+7, Block.getBlockById(3));
		world.setBlock(x+13, y+18, z+7, Block.getBlockById(3));
		world.setBlock(x+14, y+18, z+7, Block.getBlockById(3));
		world.setBlock(x+17, y+18, z+7, Block.getBlockById(106));
		world.setBlockMetadataWithNotify(x+17, y+18, z+7, 2, 2);
		world.setBlock(x+4, y+18, z+8, Block.getBlockById(3));
		world.setBlock(x+5, y+18, z+8, Block.getBlockById(3));
		world.setBlock(x+6, y+18, z+8, Block.getBlockById(3));
		world.setBlock(x+7, y+18, z+8, Block.getBlockById(3));
		world.setBlock(x+8, y+18, z+8, Block.getBlockById(3));
		world.setBlock(x+9, y+18, z+8, Block.getBlockById(3));
		world.setBlock(x+10, y+18, z+8, Block.getBlockById(3));
		world.setBlock(x+11, y+18, z+8, Block.getBlockById(3));
		world.setBlock(x+12, y+18, z+8, Block.getBlockById(3));
		world.setBlock(x+13, y+18, z+8, Block.getBlockById(3));
		world.setBlock(x+14, y+18, z+8, Block.getBlockById(3));
		world.setBlock(x+4, y+18, z+9, Block.getBlockById(3));
		world.setBlock(x+5, y+18, z+9, Block.getBlockById(3));
		world.setBlock(x+6, y+18, z+9, Block.getBlockById(3));
		world.setBlock(x+7, y+18, z+9, Block.getBlockById(3));
		world.setBlock(x+8, y+18, z+9, Block.getBlockById(3));
		world.setBlock(x+9, y+18, z+9, Block.getBlockById(3));
		world.setBlock(x+10, y+18, z+9, Block.getBlockById(3));
		world.setBlock(x+11, y+18, z+9, Block.getBlockById(3));
		world.setBlock(x+12, y+18, z+9, Block.getBlockById(3));
		world.setBlock(x+13, y+18, z+9, Block.getBlockById(3));
		world.setBlock(x+14, y+18, z+9, Block.getBlockById(3));
		world.setBlock(x+15, y+18, z+9, Block.getBlockById(3));
		world.setBlock(x+3, y+18, z+10, Block.getBlockById(3));
		world.setBlock(x+4, y+18, z+10, Block.getBlockById(3));
		world.setBlock(x+5, y+18, z+10, Block.getBlockById(3));
		world.setBlock(x+6, y+18, z+10, Block.getBlockById(3));
		world.setBlock(x+7, y+18, z+10, Block.getBlockById(3));
		world.setBlock(x+8, y+18, z+10, Block.getBlockById(3));
		world.setBlock(x+9, y+18, z+10, Block.getBlockById(3));
		world.setBlock(x+10, y+18, z+10, Block.getBlockById(3));
		world.setBlock(x+11, y+18, z+10, Block.getBlockById(3));
		world.setBlock(x+12, y+18, z+10, Block.getBlockById(3));
		world.setBlock(x+13, y+18, z+10, Block.getBlockById(3));
		world.setBlock(x+14, y+18, z+10, Block.getBlockById(3));
		world.setBlock(x+15, y+18, z+10, Block.getBlockById(3));
		world.setBlock(x+3, y+18, z+11, Block.getBlockById(3));
		world.setBlock(x+4, y+18, z+11, Block.getBlockById(3));
		world.setBlock(x+5, y+18, z+11, Block.getBlockById(3));
		world.setBlock(x+6, y+18, z+11, Block.getBlockById(3));
		world.setBlock(x+7, y+18, z+11, Block.getBlockById(3));
		world.setBlock(x+8, y+18, z+11, Block.getBlockById(3));
		world.setBlock(x+9, y+18, z+11, Block.getBlockById(3));
		world.setBlock(x+10, y+18, z+11, Block.getBlockById(3));
		world.setBlock(x+11, y+18, z+11, Block.getBlockById(3));
		world.setBlock(x+12, y+18, z+11, Block.getBlockById(3));
		world.setBlock(x+13, y+18, z+11, Block.getBlockById(3));
		world.setBlock(x+14, y+18, z+11, Block.getBlockById(3));
		world.setBlock(x+15, y+18, z+11, Block.getBlockById(3));
		world.setBlock(x+4, y+18, z+12, Block.getBlockById(3));
		world.setBlock(x+5, y+18, z+12, Block.getBlockById(3));
		world.setBlock(x+6, y+18, z+12, Block.getBlockById(3));
		world.setBlock(x+7, y+18, z+12, Block.getBlockById(3));
		world.setBlock(x+8, y+18, z+12, Block.getBlockById(3));
		world.setBlock(x+9, y+18, z+12, Block.getBlockById(3));
		world.setBlock(x+10, y+18, z+12, Block.getBlockById(3));
		world.setBlock(x+11, y+18, z+12, Block.getBlockById(3));
		world.setBlock(x+12, y+18, z+12, Block.getBlockById(3));
		world.setBlock(x+13, y+18, z+12, Block.getBlockById(3));
		world.setBlock(x+14, y+18, z+12, Block.getBlockById(3));
		world.setBlock(x+16, y+18, z+12, Block.getBlockById(106));
		world.setBlock(x+4, y+18, z+13, Block.getBlockById(106));
		world.setBlockMetadataWithNotify(x+4, y+18, z+13, 8, 8);
		world.setBlock(x+5, y+18, z+13, Block.getBlockById(3));
		world.setBlock(x+6, y+18, z+13, Block.getBlockById(3));
		world.setBlock(x+7, y+18, z+13, Block.getBlockById(3));
		world.setBlock(x+8, y+18, z+13, Block.getBlockById(3));
		world.setBlock(x+9, y+18, z+13, Block.getBlockById(3));
		world.setBlock(x+10, y+18, z+13, Block.getBlockById(3));
		world.setBlock(x+11, y+18, z+13, Block.getBlockById(3));
		world.setBlock(x+12, y+18, z+13, Block.getBlockById(3));
		world.setBlock(x+13, y+18, z+13, Block.getBlockById(3));
		world.setBlock(x+14, y+18, z+13, Block.getBlockById(3));
		world.setBlock(x+16, y+18, z+13, Block.getBlockById(106));
		world.setBlockMetadataWithNotify(x+16, y+18, z+13, 2, 2);
		world.setBlock(x+5, y+18, z+14, Block.getBlockById(3));
		world.setBlock(x+6, y+18, z+14, Block.getBlockById(3));
		world.setBlock(x+7, y+18, z+14, Block.getBlockById(3));
		world.setBlock(x+8, y+18, z+14, Block.getBlockById(3));
		world.setBlock(x+9, y+18, z+14, Block.getBlockById(3));
		world.setBlock(x+10, y+18, z+14, Block.getBlockById(3));
		world.setBlock(x+11, y+18, z+14, Block.getBlockById(3));
		world.setBlock(x+12, y+18, z+14, Block.getBlockById(3));
		world.setBlock(x+13, y+18, z+14, Block.getBlockById(3));
		world.setBlock(x+15, y+18, z+14, Block.getBlockById(106));
		world.setBlockMetadataWithNotify(x+15, y+18, z+14, 4, 4);
		world.setBlock(x+6, y+18, z+15, Block.getBlockById(106));
		world.setBlockMetadataWithNotify(x+6, y+18, z+15, 8, 8);
		world.setBlock(x+7, y+18, z+15, Block.getBlockById(3));
		world.setBlock(x+8, y+18, z+15, Block.getBlockById(3));
		world.setBlock(x+9, y+18, z+15, Block.getBlockById(3));
		world.setBlock(x+10, y+18, z+15, Block.getBlockById(3));
		world.setBlock(x+11, y+18, z+15, Block.getBlockById(3));
		world.setBlock(x+12, y+18, z+15, Block.getBlockById(3));
		world.setBlock(x+7, y+18, z+16, Block.getBlockById(106));
		world.setBlockMetadataWithNotify(x+7, y+18, z+16, 4, 4);
		world.setBlock(x+8, y+18, z+16, Block.getBlockById(3));
		world.setBlock(x+9, y+18, z+16, Block.getBlockById(3));
		world.setBlock(x+10, y+18, z+16, Block.getBlockById(3));
		world.setBlock(x+9, y+18, z+17, Block.getBlockById(106));
		world.setBlockMetadataWithNotify(x+9, y+18, z+17, 4, 4);
		world.setBlock(x+10, y+18, z+18, Block.getBlockById(9));
		world.setBlockMetadataWithNotify(x+10, y+18, z+18, 13, 13);
		world.setBlock(x+11, y+18, z+18, Block.getBlockById(106));
		world.setBlockMetadataWithNotify(x+11, y+18, z+18, 4, 4);
		world.setBlock(x+12, y+18, z+18, Block.getBlockById(106));
		world.setBlockMetadataWithNotify(x+12, y+18, z+18, 4, 4);
		world.setBlock(x+10, y+19, z+1, Block.getBlockById(17));
		world.setBlock(x+11, y+19, z+1, Block.getBlockById(106));
		world.setBlockMetadataWithNotify(x+11, y+19, z+1, 2, 2);
		world.setBlock(x+9, y+19, z+2, Block.getBlockById(3));
		world.setBlock(x+10, y+19, z+2, Block.getBlockById(3));
		world.setBlock(x+11, y+19, z+2, Block.getBlockById(106));
		world.setBlockMetadataWithNotify(x+11, y+19, z+2, 2, 2);
		world.setBlock(x+7, y+19, z+3, Block.getBlockById(3));
		world.setBlock(x+8, y+19, z+3, Block.getBlockById(3));
		world.setBlock(x+9, y+19, z+3, Block.getBlockById(3));
		world.setBlock(x+10, y+19, z+3, Block.getBlockById(3));
		world.setBlock(x+11, y+19, z+3, Block.getBlockById(3));
		world.setBlock(x+12, y+19, z+3, Block.getBlockById(3));
		world.setBlock(x+6, y+19, z+4, Block.getBlockById(3));
		world.setBlock(x+7, y+19, z+4, Block.getBlockById(3));
		world.setBlock(x+8, y+19, z+4, Block.getBlockById(3));
		world.setBlock(x+9, y+19, z+4, Block.getBlockById(3));
		world.setBlock(x+10, y+19, z+4, Block.getBlockById(3));
		world.setBlock(x+11, y+19, z+4, Block.getBlockById(3));
		world.setBlock(x+12, y+19, z+4, Block.getBlockById(3));
		world.setBlock(x+13, y+19, z+4, Block.getBlockById(3));
		world.setBlock(x+4, y+19, z+5, Block.getBlockById(3));
		world.setBlock(x+5, y+19, z+5, Block.getBlockById(3));
		world.setBlock(x+6, y+19, z+5, Block.getBlockById(3));
		world.setBlock(x+7, y+19, z+5, Block.getBlockById(3));
		world.setBlock(x+8, y+19, z+5, Block.getBlockById(3));
		world.setBlock(x+9, y+19, z+5, Block.getBlockById(3));
		world.setBlock(x+10, y+19, z+5, Block.getBlockById(3));
		world.setBlock(x+11, y+19, z+5, Block.getBlockById(3));
		world.setBlock(x+12, y+19, z+5, Block.getBlockById(3));
		world.setBlock(x+13, y+19, z+5, Block.getBlockById(3));
		world.setBlock(x+14, y+19, z+5, Block.getBlockById(3));
		world.setBlock(x+15, y+19, z+5, Block.getBlockById(3));
		world.setBlock(x+4, y+19, z+6, Block.getBlockById(3));
		world.setBlock(x+5, y+19, z+6, Block.getBlockById(3));
		world.setBlock(x+6, y+19, z+6, Block.getBlockById(3));
		world.setBlock(x+7, y+19, z+6, Block.getBlockById(3));
		world.setBlock(x+8, y+19, z+6, Block.getBlockById(3));
		world.setBlock(x+9, y+19, z+6, Block.getBlockById(3));
		world.setBlock(x+10, y+19, z+6, Block.getBlockById(3));
		world.setBlock(x+11, y+19, z+6, Block.getBlockById(3));
		world.setBlock(x+12, y+19, z+6, Block.getBlockById(3));
		world.setBlock(x+13, y+19, z+6, Block.getBlockById(3));
		world.setBlock(x+14, y+19, z+6, Block.getBlockById(3));
		world.setBlock(x+15, y+19, z+6, Block.getBlockById(3));
		world.setBlock(x+17, y+19, z+6, Block.getBlockById(106));
		world.setBlockMetadataWithNotify(x+17, y+19, z+6, 3, 3);
		world.setBlock(x+3, y+19, z+7, Block.getBlockById(3));
		world.setBlock(x+4, y+19, z+7, Block.getBlockById(3));
		world.setBlock(x+5, y+19, z+7, Block.getBlockById(3));
		world.setBlock(x+6, y+19, z+7, Block.getBlockById(3));
		world.setBlock(x+7, y+19, z+7, Block.getBlockById(3));
		world.setBlock(x+8, y+19, z+7, Block.getBlockById(3));
		world.setBlock(x+9, y+19, z+7, Block.getBlockById(3));
		world.setBlock(x+10, y+19, z+7, Block.getBlockById(3));
		world.setBlock(x+11, y+19, z+7, Block.getBlockById(3));
		world.setBlock(x+12, y+19, z+7, Block.getBlockById(3));
		world.setBlock(x+13, y+19, z+7, Block.getBlockById(3));
		world.setBlock(x+14, y+19, z+7, Block.getBlockById(3));
		world.setBlock(x+15, y+19, z+7, Block.getBlockById(3));
		world.setBlock(x+16, y+19, z+7, Block.getBlockById(3));
		world.setBlock(x+17, y+19, z+7, Block.getBlockById(106));
		world.setBlockMetadataWithNotify(x+17, y+19, z+7, 2, 2);
		world.setBlock(x+3, y+19, z+8, Block.getBlockById(3));
		world.setBlock(x+4, y+19, z+8, Block.getBlockById(3));
		world.setBlock(x+5, y+19, z+8, Block.getBlockById(3));
		world.setBlock(x+6, y+19, z+8, Block.getBlockById(3));
		world.setBlock(x+7, y+19, z+8, Block.getBlockById(3));
		world.setBlock(x+8, y+19, z+8, Block.getBlockById(3));
		world.setBlock(x+9, y+19, z+8, Block.getBlockById(3));
		world.setBlock(x+10, y+19, z+8, Block.getBlockById(3));
		world.setBlock(x+11, y+19, z+8, Block.getBlockById(3));
		world.setBlock(x+12, y+19, z+8, Block.getBlockById(3));
		world.setBlock(x+13, y+19, z+8, Block.getBlockById(3));
		world.setBlock(x+14, y+19, z+8, Block.getBlockById(3));
		world.setBlock(x+15, y+19, z+8, Block.getBlockById(3));
		world.setBlock(x+16, y+19, z+8, Block.getBlockById(3));
		world.setBlock(x+2, y+19, z+9, Block.getBlockById(3));
		world.setBlock(x+3, y+19, z+9, Block.getBlockById(3));
		world.setBlock(x+4, y+19, z+9, Block.getBlockById(3));
		world.setBlock(x+5, y+19, z+9, Block.getBlockById(3));
		world.setBlock(x+6, y+19, z+9, Block.getBlockById(3));
		world.setBlock(x+7, y+19, z+9, Block.getBlockById(3));
		world.setBlock(x+8, y+19, z+9, Block.getBlockById(3));
		world.setBlock(x+9, y+19, z+9, Block.getBlockById(3));
		world.setBlock(x+10, y+19, z+9, Block.getBlockById(3));
		world.setBlock(x+11, y+19, z+9, Block.getBlockById(3));
		world.setBlock(x+12, y+19, z+9, Block.getBlockById(3));
		world.setBlock(x+13, y+19, z+9, Block.getBlockById(3));
		world.setBlock(x+14, y+19, z+9, Block.getBlockById(3));
		world.setBlock(x+15, y+19, z+9, Block.getBlockById(3));
		world.setBlock(x+16, y+19, z+9, Block.getBlockById(3));
		world.setBlock(x+17, y+19, z+9, Block.getBlockById(3));
		world.setBlock(x+2, y+19, z+10, Block.getBlockById(3));
		world.setBlock(x+3, y+19, z+10, Block.getBlockById(3));
		world.setBlock(x+4, y+19, z+10, Block.getBlockById(3));
		world.setBlock(x+5, y+19, z+10, Block.getBlockById(3));
		world.setBlock(x+6, y+19, z+10, Block.getBlockById(3));
		world.setBlock(x+7, y+19, z+10, Block.getBlockById(3));
		world.setBlock(x+8, y+19, z+10, Block.getBlockById(3));
		world.setBlock(x+9, y+19, z+10, Block.getBlockById(3));
		world.setBlock(x+10, y+19, z+10, Block.getBlockById(3));
		world.setBlock(x+11, y+19, z+10, Block.getBlockById(3));
		world.setBlock(x+12, y+19, z+10, Block.getBlockById(3));
		world.setBlock(x+13, y+19, z+10, Block.getBlockById(3));
		world.setBlock(x+14, y+19, z+10, Block.getBlockById(3));
		world.setBlock(x+15, y+19, z+10, Block.getBlockById(3));
		world.setBlock(x+16, y+19, z+10, Block.getBlockById(3));
		world.setBlock(x+17, y+19, z+10, Block.getBlockById(3));
		world.setBlock(x+2, y+19, z+11, Block.getBlockById(3));
		world.setBlock(x+3, y+19, z+11, Block.getBlockById(3));
		world.setBlock(x+4, y+19, z+11, Block.getBlockById(3));
		world.setBlock(x+5, y+19, z+11, Block.getBlockById(3));
		world.setBlock(x+6, y+19, z+11, Block.getBlockById(3));
		world.setBlock(x+7, y+19, z+11, Block.getBlockById(3));
		world.setBlock(x+8, y+19, z+11, Block.getBlockById(3));
		world.setBlock(x+9, y+19, z+11, Block.getBlockById(3));
		world.setBlock(x+10, y+19, z+11, Block.getBlockById(3));
		world.setBlock(x+11, y+19, z+11, Block.getBlockById(3));
		world.setBlock(x+12, y+19, z+11, Block.getBlockById(3));
		world.setBlock(x+13, y+19, z+11, Block.getBlockById(3));
		world.setBlock(x+14, y+19, z+11, Block.getBlockById(3));
		world.setBlock(x+15, y+19, z+11, Block.getBlockById(3));
		world.setBlock(x+16, y+19, z+11, Block.getBlockById(3));
		world.setBlock(x+3, y+19, z+12, Block.getBlockById(3));
		world.setBlock(x+4, y+19, z+12, Block.getBlockById(3));
		world.setBlock(x+5, y+19, z+12, Block.getBlockById(3));
		world.setBlock(x+6, y+19, z+12, Block.getBlockById(3));
		world.setBlock(x+7, y+19, z+12, Block.getBlockById(3));
		world.setBlock(x+8, y+19, z+12, Block.getBlockById(3));
		world.setBlock(x+9, y+19, z+12, Block.getBlockById(3));
		world.setBlock(x+10, y+19, z+12, Block.getBlockById(3));
		world.setBlock(x+11, y+19, z+12, Block.getBlockById(3));
		world.setBlock(x+12, y+19, z+12, Block.getBlockById(3));
		world.setBlock(x+13, y+19, z+12, Block.getBlockById(3));
		world.setBlock(x+14, y+19, z+12, Block.getBlockById(3));
		world.setBlock(x+15, y+19, z+12, Block.getBlockById(3));
		world.setBlock(x+16, y+19, z+12, Block.getBlockById(3));
		world.setBlock(x+3, y+19, z+13, Block.getBlockById(3));
		world.setBlock(x+4, y+19, z+13, Block.getBlockById(3));
		world.setBlock(x+5, y+19, z+13, Block.getBlockById(3));
		world.setBlock(x+6, y+19, z+13, Block.getBlockById(3));
		world.setBlock(x+7, y+19, z+13, Block.getBlockById(3));
		world.setBlock(x+8, y+19, z+13, Block.getBlockById(3));
		world.setBlock(x+9, y+19, z+13, Block.getBlockById(3));
		world.setBlock(x+10, y+19, z+13, Block.getBlockById(2));
		world.setBlock(x+11, y+19, z+13, Block.getBlockById(3));
		world.setBlock(x+12, y+19, z+13, Block.getBlockById(3));
		world.setBlock(x+13, y+19, z+13, Block.getBlockById(3));
		world.setBlock(x+14, y+19, z+13, Block.getBlockById(3));
		world.setBlock(x+15, y+19, z+13, Block.getBlockById(3));
		world.setBlock(x+16, y+19, z+13, Block.getBlockById(106));
		world.setBlockMetadataWithNotify(x+16, y+19, z+13, 2, 2);
		world.setBlock(x+4, y+19, z+14, Block.getBlockById(3));
		world.setBlock(x+5, y+19, z+14, Block.getBlockById(3));
		world.setBlock(x+6, y+19, z+14, Block.getBlockById(3));
		world.setBlock(x+7, y+19, z+14, Block.getBlockById(3));
		world.setBlock(x+8, y+19, z+14, Block.getBlockById(3));
		world.setBlock(x+9, y+19, z+14, Block.getBlockById(3));
		world.setBlock(x+10, y+19, z+14, Block.getBlockById(2));
		world.setBlock(x+11, y+19, z+14, Block.getBlockById(3));
		world.setBlock(x+12, y+19, z+14, Block.getBlockById(3));
		world.setBlock(x+13, y+19, z+14, Block.getBlockById(3));
		world.setBlock(x+14, y+19, z+14, Block.getBlockById(3));
		world.setBlock(x+15, y+19, z+14, Block.getBlockById(106));
		world.setBlockMetadataWithNotify(x+15, y+19, z+14, 4, 4);
		world.setBlock(x+4, y+19, z+15, Block.getBlockById(3));
		world.setBlock(x+5, y+19, z+15, Block.getBlockById(3));
		world.setBlock(x+6, y+19, z+15, Block.getBlockById(3));
		world.setBlock(x+7, y+19, z+15, Block.getBlockById(3));
		world.setBlock(x+8, y+19, z+15, Block.getBlockById(3));
		world.setBlock(x+9, y+19, z+15, Block.getBlockById(3));
		world.setBlock(x+10, y+19, z+15, Block.getBlockById(2));
		world.setBlock(x+11, y+19, z+15, Block.getBlockById(3));
		world.setBlock(x+12, y+19, z+15, Block.getBlockById(3));
		world.setBlock(x+13, y+19, z+15, Block.getBlockById(3));
		world.setBlock(x+14, y+19, z+15, Block.getBlockById(3));
		world.setBlock(x+15, y+19, z+15, Block.getBlockById(106));
		world.setBlock(x+6, y+19, z+16, Block.getBlockById(3));
		world.setBlock(x+7, y+19, z+16, Block.getBlockById(3));
		world.setBlock(x+8, y+19, z+16, Block.getBlockById(3));
		world.setBlock(x+9, y+19, z+16, Block.getBlockById(3));
		world.setBlock(x+10, y+19, z+16, Block.getBlockById(2));
		world.setBlock(x+11, y+19, z+16, Block.getBlockById(3));
		world.setBlock(x+12, y+19, z+16, Block.getBlockById(3));
		world.setBlock(x+8, y+19, z+17, Block.getBlockById(3));
		world.setBlock(x+9, y+19, z+17, Block.getBlockById(3));
		world.setBlock(x+10, y+19, z+17, Block.getBlockById(2));
		world.setBlock(x+10, y+19, z+18, Block.getBlockById(9));
		world.setBlockMetadataWithNotify(x+10, y+19, z+18, 13, 13);
		world.setBlock(x+11, y+19, z+18, Block.getBlockById(106));
		world.setBlockMetadataWithNotify(x+11, y+19, z+18, 4, 4);
		world.setBlock(x+12, y+19, z+18, Block.getBlockById(106));
		world.setBlockMetadataWithNotify(x+12, y+19, z+18, 4, 4);
		world.setBlock(x+10, y+20, z+0, Block.getBlockById(106));
		world.setBlockMetadataWithNotify(x+10, y+20, z+0, 1, 1);
		world.setBlock(x+9, y+20, z+1, Block.getBlockById(2));
		world.setBlock(x+10, y+20, z+1, Block.getBlockById(17));
		world.setBlockMetadataWithNotify(x+10, y+20, z+1, 8, 8);
		world.setBlock(x+11, y+20, z+1, Block.getBlockById(106));
		world.setBlockMetadataWithNotify(x+11, y+20, z+1, 2, 2);
		world.setBlock(x+7, y+20, z+2, Block.getBlockById(2));
		world.setBlock(x+8, y+20, z+2, Block.getBlockById(2));
		world.setBlock(x+9, y+20, z+2, Block.getBlockById(17));
		world.setBlock(x+10, y+20, z+2, Block.getBlockById(3));
		world.setBlock(x+11, y+20, z+2, Block.getBlockById(2));
		world.setBlock(x+12, y+20, z+2, Block.getBlockById(2));
		world.setBlock(x+6, y+20, z+3, Block.getBlockById(2));
		world.setBlock(x+7, y+20, z+3, Block.getBlockById(2));
		world.setBlock(x+8, y+20, z+3, Block.getBlockById(2));
		world.setBlock(x+9, y+20, z+3, Block.getBlockById(3));
		world.setBlock(x+10, y+20, z+3, Block.getBlockById(3));
		world.setBlock(x+11, y+20, z+3, Block.getBlockById(2));
		world.setBlock(x+12, y+20, z+3, Block.getBlockById(2));
		world.setBlock(x+13, y+20, z+3, Block.getBlockById(2));
		world.setBlock(x+4, y+20, z+4, Block.getBlockById(2));
		world.setBlock(x+5, y+20, z+4, Block.getBlockById(2));
		world.setBlock(x+6, y+20, z+4, Block.getBlockById(2));
		world.setBlock(x+7, y+20, z+4, Block.getBlockById(2));
		world.setBlock(x+8, y+20, z+4, Block.getBlockById(2));
		world.setBlock(x+9, y+20, z+4, Block.getBlockById(2));
		world.setBlock(x+10, y+20, z+4, Block.getBlockById(2));
		world.setBlock(x+11, y+20, z+4, Block.getBlockById(2));
		world.setBlock(x+12, y+20, z+4, Block.getBlockById(2));
		world.setBlock(x+13, y+20, z+4, Block.getBlockById(2));
		world.setBlock(x+14, y+20, z+4, Block.getBlockById(2));
		world.setBlock(x+15, y+20, z+4, Block.getBlockById(2));
		world.setBlock(x+3, y+20, z+5, Block.getBlockById(2));
		world.setBlock(x+4, y+20, z+5, Block.getBlockById(2));
		world.setBlock(x+5, y+20, z+5, Block.getBlockById(2));
		world.setBlock(x+6, y+20, z+5, Block.getBlockById(2));
		world.setBlock(x+7, y+20, z+5, Block.getBlockById(2));
		world.setBlock(x+8, y+20, z+5, Block.getBlockById(2));
		world.setBlock(x+9, y+20, z+5, Block.getBlockById(2));
		world.setBlock(x+10, y+20, z+5, Block.getBlockById(2));
		world.setBlock(x+11, y+20, z+5, Block.getBlockById(2));
		world.setBlock(x+12, y+20, z+5, Block.getBlockById(2));
		world.setBlock(x+13, y+20, z+5, Block.getBlockById(2));
		world.setBlock(x+14, y+20, z+5, Block.getBlockById(2));
		world.setBlock(x+15, y+20, z+5, Block.getBlockById(2));
		world.setBlock(x+16, y+20, z+5, Block.getBlockById(2));
		world.setBlock(x+17, y+20, z+5, Block.getBlockById(106));
		world.setBlockMetadataWithNotify(x+17, y+20, z+5, 2, 2);
		world.setBlock(x+3, y+20, z+6, Block.getBlockById(2));
		world.setBlock(x+4, y+20, z+6, Block.getBlockById(2));
		world.setBlock(x+5, y+20, z+6, Block.getBlockById(2));
		world.setBlock(x+6, y+20, z+6, Block.getBlockById(2));
		world.setBlock(x+7, y+20, z+6, Block.getBlockById(2));
		world.setBlock(x+8, y+20, z+6, Block.getBlockById(2));
		world.setBlock(x+9, y+20, z+6, Block.getBlockById(2));
		world.setBlock(x+10, y+20, z+6, Block.getBlockById(2));
		world.setBlock(x+11, y+20, z+6, Block.getBlockById(2));
		world.setBlock(x+12, y+20, z+6, Block.getBlockById(2));
		world.setBlock(x+13, y+20, z+6, Block.getBlockById(2));
		world.setBlock(x+14, y+20, z+6, Block.getBlockById(2));
		world.setBlock(x+15, y+20, z+6, Block.getBlockById(2));
		world.setBlock(x+16, y+20, z+6, Block.getBlockById(2));
		world.setBlock(x+17, y+20, z+6, Block.getBlockById(106));
		world.setBlockMetadataWithNotify(x+17, y+20, z+6, 3, 3);
		world.setBlock(x+2, y+20, z+7, Block.getBlockById(2));
		world.setBlock(x+3, y+20, z+7, Block.getBlockById(2));
		world.setBlock(x+4, y+20, z+7, Block.getBlockById(2));
		world.setBlock(x+5, y+20, z+7, Block.getBlockById(2));
		world.setBlock(x+6, y+20, z+7, Block.getBlockById(2));
		world.setBlock(x+7, y+20, z+7, Block.getBlockById(2));
		world.setBlock(x+8, y+20, z+7, Block.getBlockById(2));
		world.setBlock(x+9, y+20, z+7, Block.getBlockById(3));
		world.setBlock(x+10, y+20, z+7, Block.getBlockById(3));
		world.setBlock(x+11, y+20, z+7, Block.getBlockById(3));
		world.setBlock(x+12, y+20, z+7, Block.getBlockById(2));
		world.setBlock(x+13, y+20, z+7, Block.getBlockById(2));
		world.setBlock(x+14, y+20, z+7, Block.getBlockById(2));
		world.setBlock(x+15, y+20, z+7, Block.getBlockById(2));
		world.setBlock(x+16, y+20, z+7, Block.getBlockById(2));
		world.setBlock(x+17, y+20, z+7, Block.getBlockById(2));
		world.setBlock(x+18, y+20, z+7, Block.getBlockById(106));
		world.setBlockMetadataWithNotify(x+18, y+20, z+7, 2, 2);
		world.setBlock(x+2, y+20, z+8, Block.getBlockById(2));
		world.setBlock(x+3, y+20, z+8, Block.getBlockById(2));
		world.setBlock(x+4, y+20, z+8, Block.getBlockById(2));
		world.setBlock(x+5, y+20, z+8, Block.getBlockById(2));
		world.setBlock(x+6, y+20, z+8, Block.getBlockById(2));
		world.setBlock(x+7, y+20, z+8, Block.getBlockById(3));
		world.setBlock(x+8, y+20, z+8, Block.getBlockById(3));
		world.setBlock(x+9, y+20, z+8, Block.getBlockById(3));
		world.setBlock(x+10, y+20, z+8, Block.getBlockById(3));
		world.setBlock(x+11, y+20, z+8, Block.getBlockById(3));
		world.setBlock(x+12, y+20, z+8, Block.getBlockById(3));
		world.setBlock(x+13, y+20, z+8, Block.getBlockById(2));
		world.setBlock(x+14, y+20, z+8, Block.getBlockById(2));
		world.setBlock(x+15, y+20, z+8, Block.getBlockById(2));
		world.setBlock(x+16, y+20, z+8, Block.getBlockById(2));
		world.setBlock(x+17, y+20, z+8, Block.getBlockById(2));
		world.setBlock(x+1, y+20, z+9, Block.getBlockById(2));
		world.setBlock(x+2, y+20, z+9, Block.getBlockById(2));
		world.setBlock(x+3, y+20, z+9, Block.getBlockById(2));
		world.setBlock(x+4, y+20, z+9, Block.getBlockById(2));
		world.setBlock(x+5, y+20, z+9, Block.getBlockById(2));
		world.setBlock(x+6, y+20, z+9, Block.getBlockById(2));
		world.setBlock(x+7, y+20, z+9, Block.getBlockById(3));
		world.setBlock(x+8, y+20, z+9, Block.getBlockById(3));
		world.setBlock(x+9, y+20, z+9, Block.getBlockById(3));
		world.setBlock(x+10, y+20, z+9, Block.getBlockById(3));
		world.setBlock(x+11, y+20, z+9, Block.getBlockById(3));
		world.setBlock(x+12, y+20, z+9, Block.getBlockById(3));
		world.setBlock(x+13, y+20, z+9, Block.getBlockById(3));
		world.setBlock(x+14, y+20, z+9, Block.getBlockById(2));
		world.setBlock(x+15, y+20, z+9, Block.getBlockById(2));
		world.setBlock(x+16, y+20, z+9, Block.getBlockById(2));
		world.setBlock(x+17, y+20, z+9, Block.getBlockById(2));
		world.setBlock(x+18, y+20, z+9, Block.getBlockById(2));
		world.setBlock(x+1, y+20, z+10, Block.getBlockById(2));
		world.setBlock(x+2, y+20, z+10, Block.getBlockById(2));
		world.setBlock(x+3, y+20, z+10, Block.getBlockById(2));
		world.setBlock(x+4, y+20, z+10, Block.getBlockById(2));
		world.setBlock(x+5, y+20, z+10, Block.getBlockById(2));
		world.setBlock(x+6, y+20, z+10, Block.getBlockById(2));
		world.setBlock(x+7, y+20, z+10, Block.getBlockById(3));
		world.setBlock(x+8, y+20, z+10, Block.getBlockById(3));
		world.setBlock(x+9, y+20, z+10, Block.getBlockById(3));
		world.setBlock(x+10, y+20, z+10, Block.getBlockById(3));
		world.setBlock(x+11, y+20, z+10, Block.getBlockById(3));
		world.setBlock(x+12, y+20, z+10, Block.getBlockById(3));
		world.setBlock(x+13, y+20, z+10, Block.getBlockById(3));
		world.setBlock(x+14, y+20, z+10, Block.getBlockById(2));
		world.setBlock(x+15, y+20, z+10, Block.getBlockById(2));
		world.setBlock(x+16, y+20, z+10, Block.getBlockById(2));
		world.setBlock(x+17, y+20, z+10, Block.getBlockById(2));
		world.setBlock(x+18, y+20, z+10, Block.getBlockById(2));
		world.setBlock(x+0, y+20, z+11, Block.getBlockById(2));
		world.setBlock(x+1, y+20, z+11, Block.getBlockById(2));
		world.setBlock(x+2, y+20, z+11, Block.getBlockById(2));
		world.setBlock(x+3, y+20, z+11, Block.getBlockById(2));
		world.setBlock(x+4, y+20, z+11, Block.getBlockById(2));
		world.setBlock(x+5, y+20, z+11, Block.getBlockById(2));
		world.setBlock(x+6, y+20, z+11, Block.getBlockById(2));
		world.setBlock(x+7, y+20, z+11, Block.getBlockById(3));
		world.setBlock(x+8, y+20, z+11, Block.getBlockById(3));
		world.setBlock(x+9, y+20, z+11, Block.getBlockById(3));
		world.setBlock(x+10, y+20, z+11, Block.getBlockById(3));
		world.setBlock(x+11, y+20, z+11, Block.getBlockById(3));
		world.setBlock(x+12, y+20, z+11, Block.getBlockById(3));
		world.setBlock(x+13, y+20, z+11, Block.getBlockById(2));
		world.setBlock(x+14, y+20, z+11, Block.getBlockById(2));
		world.setBlock(x+15, y+20, z+11, Block.getBlockById(2));
		world.setBlock(x+16, y+20, z+11, Block.getBlockById(2));
		world.setBlock(x+17, y+20, z+11, Block.getBlockById(2));
		world.setBlock(x+2, y+20, z+12, Block.getBlockById(2));
		world.setBlock(x+3, y+20, z+12, Block.getBlockById(2));
		world.setBlock(x+4, y+20, z+12, Block.getBlockById(2));
		world.setBlock(x+5, y+20, z+12, Block.getBlockById(2));
		world.setBlock(x+6, y+20, z+12, Block.getBlockById(2));
		world.setBlock(x+7, y+20, z+12, Block.getBlockById(2));
		world.setBlock(x+8, y+20, z+12, Block.getBlockById(2));
		world.setBlock(x+9, y+20, z+12, Block.getBlockById(5));
		world.setBlockMetadataWithNotify(x+9, y+20, z+12, 1, 1);
		world.setBlock(x+10, y+20, z+12, Block.getBlockById(5));
		world.setBlockMetadataWithNotify(x+10, y+20, z+12, 1, 1);
		world.setBlock(x+11, y+20, z+12, Block.getBlockById(2));
		world.setBlock(x+12, y+20, z+12, Block.getBlockById(2));
		world.setBlock(x+13, y+20, z+12, Block.getBlockById(2));
		world.setBlock(x+14, y+20, z+12, Block.getBlockById(2));
		world.setBlock(x+15, y+20, z+12, Block.getBlockById(2));
		world.setBlock(x+16, y+20, z+12, Block.getBlockById(2));
		world.setBlock(x+17, y+20, z+12, Block.getBlockById(2));
		world.setBlock(x+2, y+20, z+13, Block.getBlockById(2));
		world.setBlock(x+3, y+20, z+13, Block.getBlockById(2));
		world.setBlock(x+4, y+20, z+13, Block.getBlockById(2));
		world.setBlock(x+5, y+20, z+13, Block.getBlockById(2));
		world.setBlock(x+6, y+20, z+13, Block.getBlockById(2));
		world.setBlock(x+7, y+20, z+13, Block.getBlockById(2));
		world.setBlock(x+8, y+20, z+13, Block.getBlockById(2));
		world.setBlock(x+9, y+20, z+13, Block.getBlockById(60));
		world.setBlockMetadataWithNotify(x+9, y+20, z+13, 7, 7);
		world.setBlock(x+10, y+20, z+13, Block.getBlockById(9));
		world.setBlock(x+11, y+20, z+13, Block.getBlockById(60));
		world.setBlockMetadataWithNotify(x+11, y+20, z+13, 7, 7);
		world.setBlock(x+12, y+20, z+13, Block.getBlockById(2));
		world.setBlock(x+13, y+20, z+13, Block.getBlockById(2));
		world.setBlock(x+14, y+20, z+13, Block.getBlockById(2));
		world.setBlock(x+15, y+20, z+13, Block.getBlockById(2));
		world.setBlock(x+16, y+20, z+13, Block.getBlockById(2));
		world.setBlock(x+3, y+20, z+14, Block.getBlockById(2));
		world.setBlock(x+4, y+20, z+14, Block.getBlockById(2));
		world.setBlock(x+5, y+20, z+14, Block.getBlockById(2));
		world.setBlock(x+6, y+20, z+14, Block.getBlockById(2));
		world.setBlock(x+7, y+20, z+14, Block.getBlockById(2));
		world.setBlock(x+8, y+20, z+14, Block.getBlockById(2));
		world.setBlock(x+9, y+20, z+14, Block.getBlockById(60));
		world.setBlockMetadataWithNotify(x+9, y+20, z+14, 7, 7);
		world.setBlock(x+10, y+20, z+14, Block.getBlockById(9));
		world.setBlockMetadataWithNotify(x+10, y+20, z+14, 1, 1);
		world.setBlock(x+11, y+20, z+14, Block.getBlockById(60));
		world.setBlockMetadataWithNotify(x+11, y+20, z+14, 7, 7);
		world.setBlock(x+12, y+20, z+14, Block.getBlockById(2));
		world.setBlock(x+13, y+20, z+14, Block.getBlockById(2));
		world.setBlock(x+14, y+20, z+14, Block.getBlockById(2));
		world.setBlock(x+15, y+20, z+14, Block.getBlockById(2));
		world.setBlock(x+4, y+20, z+15, Block.getBlockById(2));
		world.setBlock(x+5, y+20, z+15, Block.getBlockById(2));
		world.setBlock(x+6, y+20, z+15, Block.getBlockById(2));
		world.setBlock(x+7, y+20, z+15, Block.getBlockById(2));
		world.setBlock(x+8, y+20, z+15, Block.getBlockById(2));
		world.setBlock(x+9, y+20, z+15, Block.getBlockById(125));
		world.setBlock(x+10, y+20, z+15, Block.getBlockById(9));
		world.setBlockMetadataWithNotify(x+10, y+20, z+15, 2, 2);
		world.setBlock(x+11, y+20, z+15, Block.getBlockById(125));
		world.setBlock(x+12, y+20, z+15, Block.getBlockById(2));
		world.setBlock(x+13, y+20, z+15, Block.getBlockById(2));
		world.setBlock(x+14, y+20, z+15, Block.getBlockById(2));
		world.setBlock(x+15, y+20, z+15, Block.getBlockById(2));
		world.setBlock(x+4, y+20, z+16, Block.getBlockById(2));
		world.setBlock(x+5, y+20, z+16, Block.getBlockById(2));
		world.setBlock(x+6, y+20, z+16, Block.getBlockById(2));
		world.setBlock(x+7, y+20, z+16, Block.getBlockById(2));
		world.setBlock(x+8, y+20, z+16, Block.getBlockById(2));
		world.setBlock(x+9, y+20, z+16, Block.getBlockById(2));
		world.setBlock(x+10, y+20, z+16, Block.getBlockById(9));
		world.setBlockMetadataWithNotify(x+10, y+20, z+16, 3, 3);
		world.setBlock(x+11, y+20, z+16, Block.getBlockById(2));
		world.setBlock(x+12, y+20, z+16, Block.getBlockById(2));
		world.setBlock(x+13, y+20, z+16, Block.getBlockById(2));
		world.setBlock(x+14, y+20, z+16, Block.getBlockById(2));
		world.setBlock(x+6, y+20, z+17, Block.getBlockById(2));
		world.setBlock(x+7, y+20, z+17, Block.getBlockById(2));
		world.setBlock(x+8, y+20, z+17, Block.getBlockById(2));
		world.setBlock(x+9, y+20, z+17, Block.getBlockById(2));
		world.setBlock(x+10, y+20, z+17, Block.getBlockById(9));
		world.setBlockMetadataWithNotify(x+10, y+20, z+17, 4, 4);
		world.setBlock(x+11, y+20, z+17, Block.getBlockById(2));
		world.setBlock(x+12, y+20, z+17, Block.getBlockById(2));
		world.setBlock(x+8, y+20, z+18, Block.getBlockById(2));
		world.setBlock(x+9, y+20, z+18, Block.getBlockById(2));
		world.setBlock(x+10, y+20, z+18, Block.getBlockById(9));
		world.setBlockMetadataWithNotify(x+10, y+20, z+18, 5, 5);
		world.setBlock(x+11, y+20, z+18, Block.getBlockById(106));
		world.setBlockMetadataWithNotify(x+11, y+20, z+18, 4, 4);
		world.setBlock(x+12, y+20, z+18, Block.getBlockById(106));
		world.setBlockMetadataWithNotify(x+12, y+20, z+18, 4, 4);
		world.setBlock(x+9, y+21, z+2, Block.getBlockById(106));
		world.setBlockMetadataWithNotify(x+9, y+21, z+2, 1, 1);
		world.setBlock(x+10, y+21, z+2, Block.getBlockById(17));
		world.setBlock(x+11, y+21, z+2, Block.getBlockById(31));
		world.setBlockMetadataWithNotify(x+11, y+21, z+2, 1, 1);
		world.setBlock(x+8, y+21, z+3, Block.getBlockById(31));
		world.setBlockMetadataWithNotify(x+8, y+21, z+3, 1, 1);
		world.setBlock(x+9, y+21, z+3, Block.getBlockById(17));
		world.setBlock(x+10, y+21, z+3, Block.getBlockById(17));
		world.setBlock(x+10, y+21, z+4, Block.getBlockById(31));
		world.setBlockMetadataWithNotify(x+10, y+21, z+4, 1, 1);
		world.setBlock(x+12, y+21, z+4, Block.getBlockById(31));
		world.setBlockMetadataWithNotify(x+12, y+21, z+4, 1, 1);
		world.setBlock(x+6, y+21, z+5, Block.getBlockById(31));
		world.setBlockMetadataWithNotify(x+6, y+21, z+5, 1, 1);
		world.setBlock(x+14, y+21, z+5, Block.getBlockById(31));
		world.setBlockMetadataWithNotify(x+14, y+21, z+5, 1, 1);
		world.setBlock(x+3, y+21, z+6, Block.getBlockById(31));
		world.setBlockMetadataWithNotify(x+3, y+21, z+6, 1, 1);
		world.setBlock(x+8, y+21, z+6, Block.getBlockById(126));
		world.setBlock(x+9, y+21, z+6, Block.getBlockById(126));
		world.setBlock(x+10, y+21, z+6, Block.getBlockById(126));
		world.setBlock(x+11, y+21, z+6, Block.getBlockById(126));
		world.setBlock(x+12, y+21, z+6, Block.getBlockById(126));
		world.setBlock(x+15, y+21, z+6, Block.getBlockById(31));
		world.setBlockMetadataWithNotify(x+15, y+21, z+6, 1, 1);
		world.setBlock(x+7, y+21, z+7, Block.getBlockById(126));
		world.setBlock(x+8, y+21, z+7, Block.getBlockById(125));
		world.setBlock(x+9, y+21, z+7, Block.getBlockById(5));
		world.setBlockMetadataWithNotify(x+9, y+21, z+7, 1, 1);
		world.setBlock(x+10, y+21, z+7, Block.getBlockById(5));
		world.setBlockMetadataWithNotify(x+10, y+21, z+7, 1, 1);
		world.setBlock(x+11, y+21, z+7, Block.getBlockById(5));
		world.setBlockMetadataWithNotify(x+11, y+21, z+7, 1, 1);
		world.setBlock(x+12, y+21, z+7, Block.getBlockById(125));
		world.setBlock(x+13, y+21, z+7, Block.getBlockById(126));
		world.setBlock(x+4, y+21, z+8, Block.getBlockById(31));
		world.setBlockMetadataWithNotify(x+4, y+21, z+8, 1, 1);
		world.setBlock(x+6, y+21, z+8, Block.getBlockById(31));
		world.setBlockMetadataWithNotify(x+6, y+21, z+8, 1, 1);
		world.setBlock(x+7, y+21, z+8, Block.getBlockById(5));
		world.setBlock(x+8, y+21, z+8, Block.getBlockById(5));
		world.setBlockMetadataWithNotify(x+8, y+21, z+8, 1, 1);
		world.setBlock(x+9, y+21, z+8, Block.getBlockById(5));
		world.setBlock(x+10, y+21, z+8, Block.getBlockById(5));
		world.setBlock(x+11, y+21, z+8, Block.getBlockById(5));
		world.setBlock(x+12, y+21, z+8, Block.getBlockById(5));
		world.setBlockMetadataWithNotify(x+12, y+21, z+8, 1, 1);
		world.setBlock(x+13, y+21, z+8, Block.getBlockById(125));
		world.setBlock(x+14, y+21, z+8, Block.getBlockById(126));
		world.setBlock(x+2, y+21, z+9, Block.getBlockById(31));
		world.setBlockMetadataWithNotify(x+2, y+21, z+9, 1, 1);
		world.setBlock(x+3, y+21, z+9, Block.getBlockById(31));
		world.setBlockMetadataWithNotify(x+3, y+21, z+9, 1, 1);
		world.setBlock(x+7, y+21, z+9, Block.getBlockById(53));
		world.setBlock(x+8, y+21, z+9, Block.getBlockById(5));
		world.setBlock(x+9, y+21, z+9, Block.getBlockById(5));
		world.setBlock(x+10, y+21, z+9, Block.getBlockById(5));
		world.setBlock(x+11, y+21, z+9, Block.getBlockById(5));
		world.setBlock(x+12, y+21, z+9, Block.getBlockById(5));
		world.setBlock(x+13, y+21, z+9, Block.getBlockById(5));
		world.setBlockMetadataWithNotify(x+13, y+21, z+9, 1, 1);
		world.setBlock(x+14, y+21, z+9, Block.getBlockById(126));
		world.setBlock(x+16, y+21, z+9, Block.getBlockById(31));
		world.setBlockMetadataWithNotify(x+16, y+21, z+9, 1, 1);
		world.setBlock(x+1, y+21, z+10, Block.getBlockById(31));
		world.setBlockMetadataWithNotify(x+1, y+21, z+10, 1, 1);
		world.setBlock(x+4, y+21, z+10, Block.getBlockById(31));
		world.setBlockMetadataWithNotify(x+4, y+21, z+10, 1, 1);
		world.setBlock(x+5, y+21, z+10, Block.getBlockById(31));
		world.setBlockMetadataWithNotify(x+5, y+21, z+10, 1, 1);
		world.setBlock(x+7, y+21, z+10, Block.getBlockById(53));
		world.setBlock(x+8, y+21, z+10, Block.getBlockById(5));
		world.setBlock(x+9, y+21, z+10, Block.getBlockById(5));
		world.setBlock(x+10, y+21, z+10, Block.getBlockById(5));
		world.setBlock(x+11, y+21, z+10, Block.getBlockById(5));
		world.setBlock(x+12, y+21, z+10, Block.getBlockById(5));
		world.setBlock(x+13, y+21, z+10, Block.getBlockById(5));
		world.setBlockMetadataWithNotify(x+13, y+21, z+10, 1, 1);
		world.setBlock(x+14, y+21, z+10, Block.getBlockById(126));
		world.setBlock(x+15, y+21, z+10, Block.getBlockById(31));
		world.setBlockMetadataWithNotify(x+15, y+21, z+10, 1, 1);
		world.setBlock(x+3, y+21, z+11, Block.getBlockById(31));
		world.setBlockMetadataWithNotify(x+3, y+21, z+11, 1, 1);
		world.setBlock(x+7, y+21, z+11, Block.getBlockById(5));
		world.setBlock(x+8, y+21, z+11, Block.getBlockById(5));
		world.setBlockMetadataWithNotify(x+8, y+21, z+11, 1, 1);
		world.setBlock(x+9, y+21, z+11, Block.getBlockById(5));
		world.setBlock(x+10, y+21, z+11, Block.getBlockById(5));
		world.setBlock(x+11, y+21, z+11, Block.getBlockById(5));
		world.setBlockMetadataWithNotify(x+11, y+21, z+11, 1, 1);
		world.setBlock(x+12, y+21, z+11, Block.getBlockById(5));
		world.setBlockMetadataWithNotify(x+12, y+21, z+11, 1, 1);
		world.setBlock(x+13, y+21, z+11, Block.getBlockById(125));
		world.setBlock(x+14, y+21, z+11, Block.getBlockById(126));
		world.setBlock(x+5, y+21, z+12, Block.getBlockById(31));
		world.setBlockMetadataWithNotify(x+5, y+21, z+12, 1, 1);
		world.setBlock(x+6, y+21, z+12, Block.getBlockById(31));
		world.setBlockMetadataWithNotify(x+6, y+21, z+12, 1, 1);
		world.setBlock(x+7, y+21, z+12, Block.getBlockById(126));
		world.setBlock(x+8, y+21, z+12, Block.getBlockById(125));
		world.setBlock(x+9, y+21, z+12, Block.getBlockById(5));
		world.setBlockMetadataWithNotify(x+9, y+21, z+12, 1, 1);
		world.setBlock(x+10, y+21, z+12, Block.getBlockById(5));
		world.setBlockMetadataWithNotify(x+10, y+21, z+12, 1, 1);
		world.setBlock(x+11, y+21, z+12, Block.getBlockById(125));
		world.setBlock(x+12, y+21, z+12, Block.getBlockById(126));
		world.setBlock(x+13, y+21, z+12, Block.getBlockById(126));
		world.setBlock(x+16, y+21, z+12, Block.getBlockById(31));
		world.setBlockMetadataWithNotify(x+16, y+21, z+12, 1, 1);
		world.setBlock(x+9, y+21, z+13, Block.getBlockById(142));
		world.setBlockMetadataWithNotify(x+9, y+21, z+13, 7, 7);
		world.setBlock(x+11, y+21, z+13, Block.getBlockById(141));
		world.setBlockMetadataWithNotify(x+11, y+21, z+13, 7, 7);
		world.setBlock(x+5, y+21, z+14, Block.getBlockById(31));
		world.setBlockMetadataWithNotify(x+5, y+21, z+14, 1, 1);
		world.setBlock(x+9, y+21, z+14, Block.getBlockById(142));
		world.setBlockMetadataWithNotify(x+9, y+21, z+14, 7, 7);
		world.setBlock(x+11, y+21, z+14, Block.getBlockById(141));
		world.setBlockMetadataWithNotify(x+11, y+21, z+14, 7, 7);
		world.setBlock(x+13, y+21, z+14, Block.getBlockById(31));
		world.setBlockMetadataWithNotify(x+13, y+21, z+14, 1, 1);
		world.setBlock(x+14, y+21, z+14, Block.getBlockById(31));
		world.setBlockMetadataWithNotify(x+14, y+21, z+14, 1, 1);
		world.setBlock(x+5, y+21, z+15, Block.getBlockById(31));
		world.setBlockMetadataWithNotify(x+5, y+21, z+15, 1, 1);
		world.setBlock(x+7, y+21, z+15, Block.getBlockById(31));
		world.setBlockMetadataWithNotify(x+7, y+21, z+15, 1, 1);
		world.setBlock(x+10, y+21, z+15, Block.getBlockById(126));
		world.setBlock(x+6, y+21, z+16, Block.getBlockById(31));
		world.setBlockMetadataWithNotify(x+6, y+21, z+16, 1, 1);
		world.setBlock(x+8, y+21, z+16, Block.getBlockById(31));
		world.setBlockMetadataWithNotify(x+8, y+21, z+16, 1, 1);
		world.setBlock(x+12, y+21, z+16, Block.getBlockById(31));
		world.setBlockMetadataWithNotify(x+12, y+21, z+16, 1, 1);
		world.setBlock(x+7, y+21, z+17, Block.getBlockById(31));
		world.setBlockMetadataWithNotify(x+7, y+21, z+17, 1, 1);
		world.setBlock(x+9, y+21, z+17, Block.getBlockById(31));
		world.setBlockMetadataWithNotify(x+9, y+21, z+17, 1, 1);
		world.setBlock(x+11, y+21, z+17, Block.getBlockById(31));
		world.setBlockMetadataWithNotify(x+11, y+21, z+17, 1, 1);
		world.setBlock(x+10, y+22, z+2, Block.getBlockById(106));
		world.setBlockMetadataWithNotify(x+10, y+22, z+2, 1, 1);
		world.setBlock(x+9, y+22, z+3, Block.getBlockById(106));
		world.setBlockMetadataWithNotify(x+9, y+22, z+3, 8, 8);
		world.setBlock(x+10, y+22, z+3, Block.getBlockById(17));
		world.setBlock(x+10, y+22, z+4, Block.getBlockById(106));
		world.setBlockMetadataWithNotify(x+10, y+22, z+4, 4, 4);
		world.setBlock(x+8, y+22, z+7, Block.getBlockById(85));
		world.setBlock(x+9, y+22, z+7, Block.getBlockById(5));
		world.setBlockMetadataWithNotify(x+9, y+22, z+7, 1, 1);
		world.setBlock(x+10, y+22, z+7, Block.getBlockById(5));
		world.setBlockMetadataWithNotify(x+10, y+22, z+7, 1, 1);
		world.setBlock(x+11, y+22, z+7, Block.getBlockById(5));
		world.setBlockMetadataWithNotify(x+11, y+22, z+7, 1, 1);
		world.setBlock(x+12, y+22, z+7, Block.getBlockById(85));
		world.setBlock(x+7, y+22, z+8, Block.getBlockById(140));
		world.setBlock(x+8, y+22, z+8, Block.getBlockById(5));
		world.setBlockMetadataWithNotify(x+8, y+22, z+8, 1, 1);
		world.setBlock(x+9, y+22, z+8, Block.getBlockById(58));
		world.setBlock(x+10, y+22, z+8, Block.getBlockById(26));
		world.setBlockMetadataWithNotify(x+10, y+22, z+8, 3, 3);
		world.setBlock(x+11, y+22, z+8, Block.getBlockById(26));
		world.setBlockMetadataWithNotify(x+11, y+22, z+8, 11, 11);
		world.setBlock(x+12, y+22, z+8, Block.getBlockById(5));
		world.setBlockMetadataWithNotify(x+12, y+22, z+8, 1, 1);
		world.setBlock(x+13, y+22, z+8, Block.getBlockById(85));
		this.setChest(x+12, y+22, z+9);
		world.setBlock(x+13, y+22, z+9, Block.getBlockById(5));
		world.setBlockMetadataWithNotify(x+13, y+22, z+9, 1, 1);
		this.setChest(x+12, y+22, z+10);
		world.setBlockMetadataWithNotify(x+12, y+22, z+10, 4, 4);
		world.setBlock(x+13, y+22, z+10, Block.getBlockById(5));
		world.setBlockMetadataWithNotify(x+13, y+22, z+10, 1, 1);
		world.setBlock(x+7, y+22, z+11, Block.getBlockById(140));
		world.setBlock(x+8, y+22, z+11, Block.getBlockById(5));
		world.setBlockMetadataWithNotify(x+8, y+22, z+11, 1, 1);
		world.setBlock(x+9, y+22, z+11, Block.getBlockById(61));
		world.setBlockMetadataWithNotify(x+9, y+22, z+11, 2, 2);
		world.setBlock(x+10, y+22, z+11, Block.getBlockById(61));
		world.setBlockMetadataWithNotify(x+10, y+22, z+11, 2, 2);
		world.setBlock(x+11, y+22, z+11, Block.getBlockById(5));
		world.setBlockMetadataWithNotify(x+11, y+22, z+11, 1, 1);
		world.setBlock(x+12, y+22, z+11, Block.getBlockById(5));
		world.setBlockMetadataWithNotify(x+12, y+22, z+11, 1, 1);
		world.setBlock(x+13, y+22, z+11, Block.getBlockById(85));
		world.setBlock(x+8, y+22, z+12, Block.getBlockById(85));
		world.setBlock(x+9, y+22, z+12, Block.getBlockById(5));
		world.setBlockMetadataWithNotify(x+9, y+22, z+12, 1, 1);
		world.setBlock(x+10, y+22, z+12, Block.getBlockById(5));
		world.setBlockMetadataWithNotify(x+10, y+22, z+12, 1, 1);
		world.setBlock(x+11, y+22, z+12, Block.getBlockById(85));
		world.setBlock(x+10, y+23, z+2, Block.getBlockById(106));
		world.setBlockMetadataWithNotify(x+10, y+23, z+2, 1, 1);
		world.setBlock(x+9, y+23, z+3, Block.getBlockById(106));
		world.setBlockMetadataWithNotify(x+9, y+23, z+3, 8, 8);
		world.setBlock(x+10, y+23, z+3, Block.getBlockById(17));
		world.setBlock(x+8, y+23, z+7, Block.getBlockById(85));
		world.setBlock(x+9, y+23, z+7, Block.getBlockById(5));
		world.setBlockMetadataWithNotify(x+9, y+23, z+7, 1, 1);
		world.setBlock(x+10, y+23, z+7, Block.getBlockById(5));
		world.setBlockMetadataWithNotify(x+10, y+23, z+7, 1, 1);
		world.setBlock(x+11, y+23, z+7, Block.getBlockById(5));
		world.setBlockMetadataWithNotify(x+11, y+23, z+7, 1, 1);
		world.setBlock(x+12, y+23, z+7, Block.getBlockById(85));
		world.setBlock(x+7, y+23, z+8, Block.getBlockById(50));
		world.setBlockMetadataWithNotify(x+7, y+23, z+8, 2, 2);
		world.setBlock(x+8, y+23, z+8, Block.getBlockById(5));
		world.setBlockMetadataWithNotify(x+8, y+23, z+8, 1, 1);
		world.setBlock(x+12, y+23, z+8, Block.getBlockById(5));
		world.setBlockMetadataWithNotify(x+12, y+23, z+8, 1, 1);
		world.setBlock(x+13, y+23, z+8, Block.getBlockById(85));
		world.setBlock(x+13, y+23, z+9, Block.getBlockById(85));
		world.setBlock(x+13, y+23, z+10, Block.getBlockById(85));
		world.setBlock(x+7, y+23, z+11, Block.getBlockById(50));
		world.setBlockMetadataWithNotify(x+7, y+23, z+11, 2, 2);
		world.setBlock(x+8, y+23, z+11, Block.getBlockById(5));
		world.setBlockMetadataWithNotify(x+8, y+23, z+11, 1, 1);
		world.setBlock(x+11, y+23, z+11, Block.getBlockById(5));
		world.setBlockMetadataWithNotify(x+11, y+23, z+11, 1, 1);
		world.setBlock(x+12, y+23, z+11, Block.getBlockById(5));
		world.setBlockMetadataWithNotify(x+12, y+23, z+11, 1, 1);
		world.setBlock(x+13, y+23, z+11, Block.getBlockById(85));
		world.setBlock(x+8, y+23, z+12, Block.getBlockById(85));
		world.setBlock(x+9, y+23, z+12, Block.getBlockById(5));
		world.setBlockMetadataWithNotify(x+9, y+23, z+12, 1, 1);
		world.setBlock(x+10, y+23, z+12, Block.getBlockById(5));
		world.setBlockMetadataWithNotify(x+10, y+23, z+12, 1, 1);
		world.setBlock(x+11, y+23, z+12, Block.getBlockById(85));
		world.setBlock(x+10, y+24, z+3, Block.getBlockById(17));
		world.setBlock(x+8, y+24, z+7, Block.getBlockById(85));
		world.setBlock(x+9, y+24, z+7, Block.getBlockById(5));
		world.setBlockMetadataWithNotify(x+9, y+24, z+7, 1, 1);
		world.setBlock(x+10, y+24, z+7, Block.getBlockById(5));
		world.setBlockMetadataWithNotify(x+10, y+24, z+7, 1, 1);
		world.setBlock(x+11, y+24, z+7, Block.getBlockById(5));
		world.setBlockMetadataWithNotify(x+11, y+24, z+7, 1, 1);
		world.setBlock(x+12, y+24, z+7, Block.getBlockById(85));
		world.setBlock(x+8, y+24, z+8, Block.getBlockById(5));
		world.setBlockMetadataWithNotify(x+8, y+24, z+8, 1, 1);
		world.setBlock(x+9, y+24, z+8, Block.getBlockById(50));
		world.setBlockMetadataWithNotify(x+9, y+24, z+8, 3, 3);
		world.setBlock(x+11, y+24, z+8, Block.getBlockById(50));
		world.setBlockMetadataWithNotify(x+11, y+24, z+8, 3, 3);
		world.setBlock(x+12, y+24, z+8, Block.getBlockById(5));
		world.setBlockMetadataWithNotify(x+12, y+24, z+8, 1, 1);
		world.setBlock(x+13, y+24, z+8, Block.getBlockById(85));
		world.setBlock(x+8, y+24, z+9, Block.getBlockById(5));
		world.setBlockMetadataWithNotify(x+8, y+24, z+9, 1, 1);
		world.setBlock(x+13, y+24, z+9, Block.getBlockById(5));
		world.setBlockMetadataWithNotify(x+13, y+24, z+9, 1, 1);
		world.setBlock(x+8, y+24, z+10, Block.getBlockById(5));
		world.setBlockMetadataWithNotify(x+8, y+24, z+10, 1, 1);
		world.setBlock(x+13, y+24, z+10, Block.getBlockById(5));
		world.setBlockMetadataWithNotify(x+13, y+24, z+10, 1, 1);
		world.setBlock(x+8, y+24, z+11, Block.getBlockById(5));
		world.setBlockMetadataWithNotify(x+8, y+24, z+11, 1, 1);
		world.setBlock(x+11, y+24, z+11, Block.getBlockById(5));
		world.setBlockMetadataWithNotify(x+11, y+24, z+11, 1, 1);
		world.setBlock(x+12, y+24, z+11, Block.getBlockById(5));
		world.setBlockMetadataWithNotify(x+12, y+24, z+11, 1, 1);
		world.setBlock(x+13, y+24, z+11, Block.getBlockById(85));
		world.setBlock(x+8, y+24, z+12, Block.getBlockById(85));
		world.setBlock(x+9, y+24, z+12, Block.getBlockById(5));
		world.setBlockMetadataWithNotify(x+9, y+24, z+12, 1, 1);
		world.setBlock(x+10, y+24, z+12, Block.getBlockById(5));
		world.setBlockMetadataWithNotify(x+10, y+24, z+12, 1, 1);
		world.setBlock(x+11, y+24, z+12, Block.getBlockById(85));
		world.setBlock(x+10, y+25, z+3, Block.getBlockById(17));
		world.setBlock(x+7, y+25, z+6, Block.getBlockById(126));
		world.setBlockMetadataWithNotify(x+7, y+25, z+6, 8, 8);
		world.setBlock(x+8, y+25, z+6, Block.getBlockById(126));
		world.setBlockMetadataWithNotify(x+8, y+25, z+6, 8, 8);
		world.setBlock(x+9, y+25, z+6, Block.getBlockById(126));
		world.setBlockMetadataWithNotify(x+9, y+25, z+6, 8, 8);
		world.setBlock(x+10, y+25, z+6, Block.getBlockById(126));
		world.setBlockMetadataWithNotify(x+10, y+25, z+6, 8, 8);
		world.setBlock(x+11, y+25, z+6, Block.getBlockById(126));
		world.setBlockMetadataWithNotify(x+11, y+25, z+6, 8, 8);
		world.setBlock(x+12, y+25, z+6, Block.getBlockById(126));
		world.setBlockMetadataWithNotify(x+12, y+25, z+6, 8, 8);
		world.setBlock(x+13, y+25, z+6, Block.getBlockById(126));
		world.setBlockMetadataWithNotify(x+13, y+25, z+6, 8, 8);
		world.setBlock(x+7, y+25, z+7, Block.getBlockById(126));
		world.setBlockMetadataWithNotify(x+7, y+25, z+7, 8, 8);
		world.setBlock(x+8, y+25, z+7, Block.getBlockById(125));
		world.setBlock(x+9, y+25, z+7, Block.getBlockById(5));
		world.setBlockMetadataWithNotify(x+9, y+25, z+7, 1, 1);
		world.setBlock(x+10, y+25, z+7, Block.getBlockById(5));
		world.setBlockMetadataWithNotify(x+10, y+25, z+7, 1, 1);
		world.setBlock(x+11, y+25, z+7, Block.getBlockById(5));
		world.setBlockMetadataWithNotify(x+11, y+25, z+7, 1, 1);
		world.setBlock(x+12, y+25, z+7, Block.getBlockById(125));
		world.setBlock(x+13, y+25, z+7, Block.getBlockById(126));
		world.setBlockMetadataWithNotify(x+13, y+25, z+7, 8, 8);
		world.setBlock(x+14, y+25, z+7, Block.getBlockById(126));
		world.setBlockMetadataWithNotify(x+14, y+25, z+7, 8, 8);
		world.setBlock(x+7, y+25, z+8, Block.getBlockById(126));
		world.setBlockMetadataWithNotify(x+7, y+25, z+8, 8, 8);
		world.setBlock(x+8, y+25, z+8, Block.getBlockById(5));
		world.setBlockMetadataWithNotify(x+8, y+25, z+8, 1, 1);
		world.setBlock(x+12, y+25, z+8, Block.getBlockById(5));
		world.setBlockMetadataWithNotify(x+12, y+25, z+8, 1, 1);
		world.setBlock(x+13, y+25, z+8, Block.getBlockById(125));
		world.setBlock(x+14, y+25, z+8, Block.getBlockById(126));
		world.setBlockMetadataWithNotify(x+14, y+25, z+8, 8, 8);
		world.setBlock(x+7, y+25, z+9, Block.getBlockById(126));
		world.setBlockMetadataWithNotify(x+7, y+25, z+9, 8, 8);
		world.setBlock(x+8, y+25, z+9, Block.getBlockById(5));
		world.setBlockMetadataWithNotify(x+8, y+25, z+9, 1, 1);
		world.setBlock(x+13, y+25, z+9, Block.getBlockById(5));
		world.setBlock(x+14, y+25, z+9, Block.getBlockById(126));
		world.setBlockMetadataWithNotify(x+14, y+25, z+9, 8, 8);
		world.setBlock(x+7, y+25, z+10, Block.getBlockById(126));
		world.setBlockMetadataWithNotify(x+7, y+25, z+10, 8, 8);
		world.setBlock(x+8, y+25, z+10, Block.getBlockById(5));
		world.setBlockMetadataWithNotify(x+8, y+25, z+10, 1, 1);
		world.setBlock(x+13, y+25, z+10, Block.getBlockById(5));
		world.setBlock(x+14, y+25, z+10, Block.getBlockById(126));
		world.setBlockMetadataWithNotify(x+14, y+25, z+10, 8, 8);
		world.setBlock(x+7, y+25, z+11, Block.getBlockById(126));
		world.setBlockMetadataWithNotify(x+7, y+25, z+11, 8, 8);
		world.setBlock(x+8, y+25, z+11, Block.getBlockById(5));
		world.setBlockMetadataWithNotify(x+8, y+25, z+11, 1, 1);
		world.setBlock(x+11, y+25, z+11, Block.getBlockById(5));
		world.setBlockMetadataWithNotify(x+11, y+25, z+11, 1, 1);
		world.setBlock(x+12, y+25, z+11, Block.getBlockById(5));
		world.setBlockMetadataWithNotify(x+12, y+25, z+11, 1, 1);
		world.setBlock(x+13, y+25, z+11, Block.getBlockById(125));
		world.setBlock(x+14, y+25, z+11, Block.getBlockById(126));
		world.setBlockMetadataWithNotify(x+14, y+25, z+11, 8, 8);
		world.setBlock(x+7, y+25, z+12, Block.getBlockById(126));
		world.setBlockMetadataWithNotify(x+7, y+25, z+12, 8, 8);
		world.setBlock(x+8, y+25, z+12, Block.getBlockById(125));
		world.setBlock(x+9, y+25, z+12, Block.getBlockById(5));
		world.setBlockMetadataWithNotify(x+9, y+25, z+12, 1, 1);
		world.setBlock(x+10, y+25, z+12, Block.getBlockById(5));
		world.setBlockMetadataWithNotify(x+10, y+25, z+12, 1, 1);
		world.setBlock(x+11, y+25, z+12, Block.getBlockById(125));
		world.setBlock(x+12, y+25, z+12, Block.getBlockById(126));
		world.setBlockMetadataWithNotify(x+12, y+25, z+12, 8, 8);
		world.setBlock(x+13, y+25, z+12, Block.getBlockById(126));
		world.setBlockMetadataWithNotify(x+13, y+25, z+12, 8, 8);
		world.setBlock(x+14, y+25, z+12, Block.getBlockById(126));
		world.setBlockMetadataWithNotify(x+14, y+25, z+12, 8, 8);
		world.setBlock(x+7, y+25, z+13, Block.getBlockById(126));
		world.setBlockMetadataWithNotify(x+7, y+25, z+13, 8, 8);
		world.setBlock(x+8, y+25, z+13, Block.getBlockById(126));
		world.setBlockMetadataWithNotify(x+8, y+25, z+13, 8, 8);
		world.setBlock(x+9, y+25, z+13, Block.getBlockById(126));
		world.setBlockMetadataWithNotify(x+9, y+25, z+13, 8, 8);
		world.setBlock(x+10, y+25, z+13, Block.getBlockById(126));
		world.setBlockMetadataWithNotify(x+10, y+25, z+13, 8, 8);
		world.setBlock(x+11, y+25, z+13, Block.getBlockById(126));
		world.setBlockMetadataWithNotify(x+11, y+25, z+13, 8, 8);
		world.setBlock(x+12, y+25, z+13, Block.getBlockById(126));
		world.setBlockMetadataWithNotify(x+12, y+25, z+13, 8, 8);
		world.setBlock(x+10, y+26, z+3, Block.getBlockById(17));
		world.setBlock(x+8, y+26, z+7, Block.getBlockById(53));
		world.setBlockMetadataWithNotify(x+8, y+26, z+7, 2, 2);
		world.setBlock(x+9, y+26, z+7, Block.getBlockById(53));
		world.setBlockMetadataWithNotify(x+9, y+26, z+7, 2, 2);
		world.setBlock(x+10, y+26, z+7, Block.getBlockById(53));
		world.setBlockMetadataWithNotify(x+10, y+26, z+7, 2, 2);
		world.setBlock(x+11, y+26, z+7, Block.getBlockById(53));
		world.setBlockMetadataWithNotify(x+11, y+26, z+7, 2, 2);
		world.setBlock(x+12, y+26, z+7, Block.getBlockById(53));
		world.setBlockMetadataWithNotify(x+12, y+26, z+7, 1, 1);
		world.setBlock(x+8, y+26, z+8, Block.getBlockById(53));
		world.setBlock(x+9, y+26, z+8, Block.getBlockById(5));
		world.setBlock(x+10, y+26, z+8, Block.getBlockById(5));
		world.setBlock(x+11, y+26, z+8, Block.getBlockById(5));
		world.setBlock(x+12, y+26, z+8, Block.getBlockById(53));
		world.setBlockMetadataWithNotify(x+12, y+26, z+8, 2, 2);
		world.setBlock(x+13, y+26, z+8, Block.getBlockById(53));
		world.setBlockMetadataWithNotify(x+13, y+26, z+8, 2, 2);
		world.setBlock(x+8, y+26, z+9, Block.getBlockById(53));
		world.setBlock(x+9, y+26, z+9, Block.getBlockById(5));
		world.setBlock(x+10, y+26, z+9, Block.getBlockById(5));
		world.setBlock(x+11, y+26, z+9, Block.getBlockById(5));
		world.setBlock(x+12, y+26, z+9, Block.getBlockById(5));
		world.setBlock(x+13, y+26, z+9, Block.getBlockById(53));
		world.setBlockMetadataWithNotify(x+13, y+26, z+9, 1, 1);
		world.setBlock(x+8, y+26, z+10, Block.getBlockById(53));
		world.setBlock(x+9, y+26, z+10, Block.getBlockById(5));
		world.setBlock(x+10, y+26, z+10, Block.getBlockById(5));
		world.setBlock(x+11, y+26, z+10, Block.getBlockById(5));
		world.setBlock(x+12, y+26, z+10, Block.getBlockById(5));
		world.setBlock(x+13, y+26, z+10, Block.getBlockById(53));
		world.setBlockMetadataWithNotify(x+13, y+26, z+10, 1, 1);
		world.setBlock(x+8, y+26, z+11, Block.getBlockById(53));
		world.setBlock(x+9, y+26, z+11, Block.getBlockById(5));
		world.setBlock(x+10, y+26, z+11, Block.getBlockById(5));
		world.setBlock(x+11, y+26, z+11, Block.getBlockById(53));
		world.setBlockMetadataWithNotify(x+11, y+26, z+11, 1, 1);
		world.setBlock(x+12, y+26, z+11, Block.getBlockById(53));
		world.setBlockMetadataWithNotify(x+12, y+26, z+11, 3, 3);
		world.setBlock(x+13, y+26, z+11, Block.getBlockById(53));
		world.setBlockMetadataWithNotify(x+13, y+26, z+11, 1, 1);
		world.setBlock(x+8, y+26, z+12, Block.getBlockById(53));
		world.setBlockMetadataWithNotify(x+8, y+26, z+12, 3, 3);
		world.setBlock(x+9, y+26, z+12, Block.getBlockById(53));
		world.setBlockMetadataWithNotify(x+9, y+26, z+12, 3, 3);
		world.setBlock(x+10, y+26, z+12, Block.getBlockById(53));
		world.setBlockMetadataWithNotify(x+10, y+26, z+12, 3, 3);
		world.setBlock(x+11, y+26, z+12, Block.getBlockById(53));
		world.setBlockMetadataWithNotify(x+11, y+26, z+12, 1, 1);
		world.setBlock(x+10, y+27, z+3, Block.getBlockById(17));
		world.setBlock(x+9, y+27, z+8, Block.getBlockById(126));
		world.setBlock(x+10, y+27, z+8, Block.getBlockById(126));
		world.setBlock(x+11, y+27, z+8, Block.getBlockById(126));
		world.setBlock(x+9, y+27, z+9, Block.getBlockById(126));
		world.setBlock(x+10, y+27, z+9, Block.getBlockById(126));
		world.setBlock(x+11, y+27, z+9, Block.getBlockById(126));
		world.setBlock(x+12, y+27, z+9, Block.getBlockById(126));
		world.setBlock(x+9, y+27, z+10, Block.getBlockById(126));
		world.setBlock(x+10, y+27, z+10, Block.getBlockById(126));
		world.setBlock(x+11, y+27, z+10, Block.getBlockById(126));
		world.setBlock(x+12, y+27, z+10, Block.getBlockById(126));
		world.setBlock(x+9, y+27, z+11, Block.getBlockById(126));
		world.setBlock(x+10, y+27, z+11, Block.getBlockById(126));
		world.setBlock(x+10, y+28, z+2, Block.getBlockById(18));
		world.setBlockMetadataWithNotify(x+10, y+28, z+2, 4, 4);
		world.setBlock(x+9, y+28, z+3, Block.getBlockById(18));
		world.setBlockMetadataWithNotify(x+9, y+28, z+3, 4, 4);
		world.setBlock(x+10, y+28, z+3, Block.getBlockById(17));
		world.setBlock(x+11, y+28, z+3, Block.getBlockById(18));
		world.setBlockMetadataWithNotify(x+11, y+28, z+3, 4, 4);
		world.setBlock(x+10, y+28, z+4, Block.getBlockById(18));
		world.setBlockMetadataWithNotify(x+10, y+28, z+4, 4, 4);
		world.setBlock(x+8, y+29, z+0, Block.getBlockById(18));
		world.setBlockMetadataWithNotify(x+8, y+29, z+0, 4, 4);
		world.setBlock(x+9, y+29, z+0, Block.getBlockById(18));
		world.setBlockMetadataWithNotify(x+9, y+29, z+0, 4, 4);
		world.setBlock(x+10, y+29, z+0, Block.getBlockById(18));
		world.setBlockMetadataWithNotify(x+10, y+29, z+0, 4, 4);
		world.setBlock(x+11, y+29, z+0, Block.getBlockById(18));
		world.setBlockMetadataWithNotify(x+11, y+29, z+0, 4, 4);
		world.setBlock(x+12, y+29, z+0, Block.getBlockById(18));
		world.setBlockMetadataWithNotify(x+12, y+29, z+0, 4, 4);
		world.setBlock(x+7, y+29, z+1, Block.getBlockById(18));
		world.setBlockMetadataWithNotify(x+7, y+29, z+1, 12, 12);
		world.setBlock(x+8, y+29, z+1, Block.getBlockById(18));
		world.setBlock(x+9, y+29, z+1, Block.getBlockById(18));
		world.setBlock(x+10, y+29, z+1, Block.getBlockById(18));
		world.setBlock(x+11, y+29, z+1, Block.getBlockById(18));
		world.setBlock(x+12, y+29, z+1, Block.getBlockById(18));
		world.setBlockMetadataWithNotify(x+12, y+29, z+1, 4, 4);
		world.setBlock(x+13, y+29, z+1, Block.getBlockById(18));
		world.setBlockMetadataWithNotify(x+13, y+29, z+1, 4, 4);
		world.setBlock(x+7, y+29, z+2, Block.getBlockById(18));
		world.setBlockMetadataWithNotify(x+7, y+29, z+2, 12, 12);
		world.setBlock(x+8, y+29, z+2, Block.getBlockById(18));
		world.setBlock(x+9, y+29, z+2, Block.getBlockById(18));
		world.setBlock(x+10, y+29, z+2, Block.getBlockById(18));
		world.setBlock(x+11, y+29, z+2, Block.getBlockById(18));
		world.setBlock(x+12, y+29, z+2, Block.getBlockById(18));
		world.setBlock(x+13, y+29, z+2, Block.getBlockById(18));
		world.setBlockMetadataWithNotify(x+13, y+29, z+2, 12, 12);
		world.setBlock(x+7, y+29, z+3, Block.getBlockById(18));
		world.setBlockMetadataWithNotify(x+7, y+29, z+3, 12, 12);
		world.setBlock(x+8, y+29, z+3, Block.getBlockById(18));
		world.setBlock(x+9, y+29, z+3, Block.getBlockById(18));
		world.setBlock(x+10, y+29, z+3, Block.getBlockById(17));
		world.setBlock(x+11, y+29, z+3, Block.getBlockById(18));
		world.setBlock(x+12, y+29, z+3, Block.getBlockById(18));
		world.setBlock(x+13, y+29, z+3, Block.getBlockById(18));
		world.setBlockMetadataWithNotify(x+13, y+29, z+3, 4, 4);
		world.setBlock(x+7, y+29, z+4, Block.getBlockById(18));
		world.setBlockMetadataWithNotify(x+7, y+29, z+4, 12, 12);
		world.setBlock(x+8, y+29, z+4, Block.getBlockById(18));
		world.setBlock(x+9, y+29, z+4, Block.getBlockById(18));
		world.setBlock(x+10, y+29, z+4, Block.getBlockById(18));
		world.setBlock(x+11, y+29, z+4, Block.getBlockById(18));
		world.setBlock(x+12, y+29, z+4, Block.getBlockById(18));
		world.setBlock(x+13, y+29, z+4, Block.getBlockById(18));
		world.setBlockMetadataWithNotify(x+13, y+29, z+4, 4, 4);
		world.setBlock(x+7, y+29, z+5, Block.getBlockById(18));
		world.setBlockMetadataWithNotify(x+7, y+29, z+5, 12, 12);
		world.setBlock(x+8, y+29, z+5, Block.getBlockById(18));
		world.setBlockMetadataWithNotify(x+8, y+29, z+5, 4, 4);
		world.setBlock(x+9, y+29, z+5, Block.getBlockById(18));
		world.setBlock(x+10, y+29, z+5, Block.getBlockById(18));
		world.setBlock(x+11, y+29, z+5, Block.getBlockById(18));
		world.setBlock(x+12, y+29, z+5, Block.getBlockById(18));
		world.setBlock(x+13, y+29, z+5, Block.getBlockById(18));
		world.setBlockMetadataWithNotify(x+13, y+29, z+5, 4, 4);
		world.setBlock(x+8, y+29, z+6, Block.getBlockById(18));
		world.setBlockMetadataWithNotify(x+8, y+29, z+6, 4, 4);
		world.setBlock(x+9, y+29, z+6, Block.getBlockById(18));
		world.setBlockMetadataWithNotify(x+9, y+29, z+6, 4, 4);
		world.setBlock(x+10, y+29, z+6, Block.getBlockById(18));
		world.setBlockMetadataWithNotify(x+10, y+29, z+6, 4, 4);
		world.setBlock(x+11, y+29, z+6, Block.getBlockById(18));
		world.setBlockMetadataWithNotify(x+11, y+29, z+6, 4, 4);
		world.setBlock(x+12, y+29, z+6, Block.getBlockById(18));
		world.setBlockMetadataWithNotify(x+12, y+29, z+6, 4, 4);
		world.setBlock(x+13, y+29, z+6, Block.getBlockById(18));
		world.setBlockMetadataWithNotify(x+13, y+29, z+6, 4, 4);
		world.setBlock(x+9, y+29, z+7, Block.getBlockById(18));
		world.setBlockMetadataWithNotify(x+9, y+29, z+7, 4, 4);
		world.setBlock(x+10, y+29, z+7, Block.getBlockById(18));
		world.setBlockMetadataWithNotify(x+10, y+29, z+7, 4, 4);
		world.setBlock(x+11, y+29, z+7, Block.getBlockById(18));
		world.setBlockMetadataWithNotify(x+11, y+29, z+7, 4, 4);
		world.setBlock(x+12, y+29, z+7, Block.getBlockById(18));
		world.setBlockMetadataWithNotify(x+12, y+29, z+7, 4, 4);
		world.setBlock(x+10, y+29, z+8, Block.getBlockById(18));
		world.setBlockMetadataWithNotify(x+10, y+29, z+8, 12, 12);
		world.setBlock(x+11, y+29, z+8, Block.getBlockById(18));
		world.setBlockMetadataWithNotify(x+11, y+29, z+8, 12, 12);
		world.setBlock(x+12, y+29, z+8, Block.getBlockById(18));
		world.setBlockMetadataWithNotify(x+12, y+29, z+8, 12, 12);
		world.setBlock(x+8, y+30, z+1, Block.getBlockById(18));
		world.setBlock(x+9, y+30, z+1, Block.getBlockById(18));
		world.setBlock(x+10, y+30, z+1, Block.getBlockById(18));
		world.setBlock(x+11, y+30, z+1, Block.getBlockById(18));
		world.setBlock(x+12, y+30, z+1, Block.getBlockById(18));
		world.setBlock(x+7, y+30, z+2, Block.getBlockById(18));
		world.setBlockMetadataWithNotify(x+7, y+30, z+2, 12, 12);
		world.setBlock(x+8, y+30, z+2, Block.getBlockById(18));
		world.setBlock(x+9, y+30, z+2, Block.getBlockById(18));
		world.setBlock(x+10, y+30, z+2, Block.getBlockById(18));
		world.setBlock(x+11, y+30, z+2, Block.getBlockById(18));
		world.setBlock(x+12, y+30, z+2, Block.getBlockById(18));
		world.setBlock(x+7, y+30, z+3, Block.getBlockById(18));
		world.setBlockMetadataWithNotify(x+7, y+30, z+3, 12, 12);
		world.setBlock(x+8, y+30, z+3, Block.getBlockById(18));
		world.setBlock(x+9, y+30, z+3, Block.getBlockById(18));
		world.setBlock(x+10, y+30, z+3, Block.getBlockById(17));
		world.setBlock(x+11, y+30, z+3, Block.getBlockById(18));
		world.setBlock(x+12, y+30, z+3, Block.getBlockById(18));
		world.setBlock(x+13, y+30, z+3, Block.getBlockById(18));
		world.setBlockMetadataWithNotify(x+13, y+30, z+3, 4, 4);
		world.setBlock(x+7, y+30, z+4, Block.getBlockById(18));
		world.setBlockMetadataWithNotify(x+7, y+30, z+4, 12, 12);
		world.setBlock(x+8, y+30, z+4, Block.getBlockById(18));
		world.setBlock(x+9, y+30, z+4, Block.getBlockById(18));
		world.setBlock(x+10, y+30, z+4, Block.getBlockById(18));
		world.setBlock(x+11, y+30, z+4, Block.getBlockById(18));
		world.setBlock(x+12, y+30, z+4, Block.getBlockById(18));
		world.setBlock(x+13, y+30, z+4, Block.getBlockById(18));
		world.setBlockMetadataWithNotify(x+13, y+30, z+4, 4, 4);
		world.setBlock(x+14, y+30, z+4, Block.getBlockById(18));
		world.setBlockMetadataWithNotify(x+14, y+30, z+4, 4, 4);
		world.setBlock(x+8, y+30, z+5, Block.getBlockById(18));
		world.setBlockMetadataWithNotify(x+8, y+30, z+5, 4, 4);
		world.setBlock(x+9, y+30, z+5, Block.getBlockById(18));
		world.setBlock(x+10, y+30, z+5, Block.getBlockById(18));
		world.setBlock(x+11, y+30, z+5, Block.getBlockById(18));
		world.setBlock(x+12, y+30, z+5, Block.getBlockById(18));
		world.setBlockMetadataWithNotify(x+12, y+30, z+5, 4, 4);
		world.setBlock(x+13, y+30, z+5, Block.getBlockById(18));
		world.setBlockMetadataWithNotify(x+13, y+30, z+5, 4, 4);
		world.setBlock(x+14, y+30, z+5, Block.getBlockById(18));
		world.setBlockMetadataWithNotify(x+14, y+30, z+5, 4, 4);
		world.setBlock(x+9, y+30, z+6, Block.getBlockById(18));
		world.setBlockMetadataWithNotify(x+9, y+30, z+6, 4, 4);
		world.setBlock(x+10, y+30, z+6, Block.getBlockById(18));
		world.setBlockMetadataWithNotify(x+10, y+30, z+6, 4, 4);
		world.setBlock(x+11, y+30, z+6, Block.getBlockById(18));
		world.setBlockMetadataWithNotify(x+11, y+30, z+6, 4, 4);
		world.setBlock(x+12, y+30, z+6, Block.getBlockById(18));
		world.setBlockMetadataWithNotify(x+12, y+30, z+6, 4, 4);
		world.setBlock(x+13, y+30, z+6, Block.getBlockById(18));
		world.setBlockMetadataWithNotify(x+13, y+30, z+6, 4, 4);
		world.setBlock(x+14, y+30, z+6, Block.getBlockById(18));
		world.setBlockMetadataWithNotify(x+14, y+30, z+6, 4, 4);
		world.setBlock(x+10, y+30, z+7, Block.getBlockById(18));
		world.setBlockMetadataWithNotify(x+10, y+30, z+7, 4, 4);
		world.setBlock(x+11, y+30, z+7, Block.getBlockById(18));
		world.setBlockMetadataWithNotify(x+11, y+30, z+7, 4, 4);
		world.setBlock(x+12, y+30, z+7, Block.getBlockById(18));
		world.setBlockMetadataWithNotify(x+12, y+30, z+7, 4, 4);
		world.setBlock(x+9, y+31, z+1, Block.getBlockById(18));
		world.setBlockMetadataWithNotify(x+9, y+31, z+1, 12, 12);
		world.setBlock(x+10, y+31, z+1, Block.getBlockById(18));
		world.setBlockMetadataWithNotify(x+10, y+31, z+1, 4, 4);
		world.setBlock(x+11, y+31, z+1, Block.getBlockById(18));
