package fr.toss.common.world.bioms.deco;

import java.util.Random;

import net.minecraft.block.Block;
import net.minecraft.world.World;
import net.minecraft.world.biome.BiomeGenBase;
import net.minecraft.world.chunk.IChunkProvider;
import cpw.mods.fml.common.IWorldGenerator;

public class WorldGenNordicCover implements IWorldGenerator {

	
	@Override
	public void generate(Random random, int chunkX, int chunkZ, World world, IChunkProvider chunkGenerator, IChunkProvider chunkProvider)
	{
		if (random.nextInt(20) == 0 && this.biomIsValid(world.getBiomeGenForCoords(chunkX, chunkZ)))
		{
			System.out.println("gen");

			int x = chunkX * 16;
			int z = chunkZ * 16;
			int y = world.getTopSolidOrLiquidBlock(x, z) - 3;
			WorldGenNordicCover.spawn(world, x, y, z);
			x -= (4 + world.rand.nextInt(20));
			z -= (4 + world.rand.nextInt(20));
			WorldGenMoulin.spawn(world, x, world.getTopSolidOrLiquidBlock(x, z) - 3, z);
		}
	}

	boolean biomIsValid(BiomeGenBase b)
	{
		return	(b.biomeID == BiomeGenBase.coldTaiga.biomeID) ||
				(b.biomeID == BiomeGenBase.icePlains.biomeID) ||
				(b.biomeID == BiomeGenBase.mesa.biomeID) ||
				(b.biomeID == BiomeGenBase.mesaPlateau.biomeID) ||
				(b.biomeID == BiomeGenBase.mesaPlateau_F.biomeID) ||
				(b.biomeID == BiomeGenBase.plains.biomeID) ||
				(b.biomeID == BiomeGenBase.savannaPlateau.biomeID) ||
				(b.biomeID == BiomeGenBase.savanna.biomeID);
	}
	
	public static void spawn(World world, int x, int y, int z)
	{
		world.setBlock(x+0, y+0, z+0, Block.getBlockById(1));
		world.setBlock(x+1, y+0, z+0, Block.getBlockById(1));
		world.setBlock(x+2, y+0, z+0, Block.getBlockById(1));
		world.setBlock(x+3, y+0, z+0, Block.getBlockById(1));
		world.setBlock(x+4, y+0, z+0, Block.getBlockById(1));
		world.setBlock(x+5, y+0, z+0, Block.getBlockById(1));
		world.setBlock(x+6, y+0, z+0, Block.getBlockById(1));
		world.setBlock(x+7, y+0, z+0, Block.getBlockById(1));
		world.setBlock(x+8, y+0, z+0, Block.getBlockById(1));
		world.setBlock(x+9, y+0, z+0, Block.getBlockById(1));
		world.setBlock(x+10, y+0, z+0, Block.getBlockById(1));
		world.setBlock(x+11, y+0, z+0, Block.getBlockById(1));
		world.setBlock(x+12, y+0, z+0, Block.getBlockById(1));
		world.setBlock(x+13, y+0, z+0, Block.getBlockById(1));
		world.setBlock(x+14, y+0, z+0, Block.getBlockById(1));
		world.setBlock(x+15, y+0, z+0, Block.getBlockById(1));
		world.setBlock(x+16, y+0, z+0, Block.getBlockById(1));
		world.setBlock(x+0, y+0, z+1, Block.getBlockById(1));
		world.setBlock(x+1, y+0, z+1, Block.getBlockById(1));
		world.setBlock(x+2, y+0, z+1, Block.getBlockById(1));
		world.setBlock(x+3, y+0, z+1, Block.getBlockById(1));
		world.setBlock(x+4, y+0, z+1, Block.getBlockById(1));
		world.setBlock(x+5, y+0, z+1, Block.getBlockById(1));
		world.setBlock(x+6, y+0, z+1, Block.getBlockById(1));
		world.setBlock(x+7, y+0, z+1, Block.getBlockById(1));
		world.setBlock(x+8, y+0, z+1, Block.getBlockById(1));
		world.setBlock(x+9, y+0, z+1, Block.getBlockById(1));
		world.setBlock(x+10, y+0, z+1, Block.getBlockById(1));
		world.setBlock(x+11, y+0, z+1, Block.getBlockById(1));
		world.setBlock(x+12, y+0, z+1, Block.getBlockById(1));
		world.setBlock(x+13, y+0, z+1, Block.getBlockById(1));
		world.setBlock(x+14, y+0, z+1, Block.getBlockById(1));
		world.setBlock(x+15, y+0, z+1, Block.getBlockById(1));
		world.setBlock(x+16, y+0, z+1, Block.getBlockById(1));
		world.setBlock(x+0, y+0, z+2, Block.getBlockById(1));
		world.setBlock(x+1, y+0, z+2, Block.getBlockById(1));
		world.setBlock(x+2, y+0, z+2, Block.getBlockById(1));
		world.setBlock(x+3, y+0, z+2, Block.getBlockById(1));
		world.setBlock(x+4, y+0, z+2, Block.getBlockById(1));
		world.setBlock(x+5, y+0, z+2, Block.getBlockById(1));
		world.setBlock(x+6, y+0, z+2, Block.getBlockById(1));
		world.setBlock(x+7, y+0, z+2, Block.getBlockById(1));
		world.setBlock(x+8, y+0, z+2, Block.getBlockById(1));
		world.setBlock(x+9, y+0, z+2, Block.getBlockById(1));
		world.setBlock(x+10, y+0, z+2, Block.getBlockById(1));
		world.setBlock(x+11, y+0, z+2, Block.getBlockById(1));
		world.setBlock(x+12, y+0, z+2, Block.getBlockById(1));
		world.setBlock(x+13, y+0, z+2, Block.getBlockById(1));
		world.setBlock(x+14, y+0, z+2, Block.getBlockById(1));
		world.setBlock(x+15, y+0, z+2, Block.getBlockById(1));
		world.setBlock(x+16, y+0, z+2, Block.getBlockById(1));
		world.setBlock(x+0, y+0, z+3, Block.getBlockById(1));
		world.setBlock(x+1, y+0, z+3, Block.getBlockById(1));
		world.setBlock(x+2, y+0, z+3, Block.getBlockById(1));
		world.setBlock(x+3, y+0, z+3, Block.getBlockById(1));
		world.setBlock(x+4, y+0, z+3, Block.getBlockById(1));
		world.setBlock(x+5, y+0, z+3, Block.getBlockById(1));
		world.setBlock(x+6, y+0, z+3, Block.getBlockById(1));
		world.setBlock(x+7, y+0, z+3, Block.getBlockById(1));
		world.setBlock(x+8, y+0, z+3, Block.getBlockById(1));
		world.setBlock(x+9, y+0, z+3, Block.getBlockById(1));
		world.setBlock(x+10, y+0, z+3, Block.getBlockById(1));
		world.setBlock(x+11, y+0, z+3, Block.getBlockById(1));
		world.setBlock(x+12, y+0, z+3, Block.getBlockById(1));
		world.setBlock(x+13, y+0, z+3, Block.getBlockById(1));
		world.setBlock(x+14, y+0, z+3, Block.getBlockById(1));
		world.setBlock(x+15, y+0, z+3, Block.getBlockById(1));
		world.setBlock(x+16, y+0, z+3, Block.getBlockById(1));
		world.setBlock(x+0, y+0, z+4, Block.getBlockById(1));
		world.setBlock(x+1, y+0, z+4, Block.getBlockById(1));
		world.setBlock(x+2, y+0, z+4, Block.getBlockById(1));
		world.setBlock(x+3, y+0, z+4, Block.getBlockById(1));
		world.setBlock(x+4, y+0, z+4, Block.getBlockById(1));
		world.setBlock(x+5, y+0, z+4, Block.getBlockById(1));
		world.setBlock(x+6, y+0, z+4, Block.getBlockById(1));
		world.setBlock(x+7, y+0, z+4, Block.getBlockById(1));
		world.setBlock(x+8, y+0, z+4, Block.getBlockById(1));
		world.setBlock(x+9, y+0, z+4, Block.getBlockById(1));
		world.setBlock(x+10, y+0, z+4, Block.getBlockById(1));
		world.setBlock(x+11, y+0, z+4, Block.getBlockById(1));
		world.setBlock(x+12, y+0, z+4, Block.getBlockById(1));
		world.setBlock(x+13, y+0, z+4, Block.getBlockById(1));
		world.setBlock(x+14, y+0, z+4, Block.getBlockById(1));
		world.setBlock(x+15, y+0, z+4, Block.getBlockById(1));
		world.setBlock(x+16, y+0, z+4, Block.getBlockById(1));
		world.setBlock(x+0, y+0, z+5, Block.getBlockById(1));
		world.setBlock(x+1, y+0, z+5, Block.getBlockById(1));
		world.setBlock(x+2, y+0, z+5, Block.getBlockById(1));
		world.setBlock(x+3, y+0, z+5, Block.getBlockById(1));
		world.setBlock(x+4, y+0, z+5, Block.getBlockById(1));
		world.setBlock(x+5, y+0, z+5, Block.getBlockById(1));
		world.setBlock(x+6, y+0, z+5, Block.getBlockById(1));
		world.setBlock(x+7, y+0, z+5, Block.getBlockById(1));
		world.setBlock(x+8, y+0, z+5, Block.getBlockById(1));
		world.setBlock(x+9, y+0, z+5, Block.getBlockById(1));
		world.setBlock(x+10, y+0, z+5, Block.getBlockById(1));
		world.setBlock(x+11, y+0, z+5, Block.getBlockById(1));
		world.setBlock(x+12, y+0, z+5, Block.getBlockById(1));
		world.setBlock(x+13, y+0, z+5, Block.getBlockById(1));
		world.setBlock(x+14, y+0, z+5, Block.getBlockById(1));
		world.setBlock(x+15, y+0, z+5, Block.getBlockById(1));
		world.setBlock(x+16, y+0, z+5, Block.getBlockById(1));
		world.setBlock(x+0, y+0, z+6, Block.getBlockById(1));
		world.setBlock(x+1, y+0, z+6, Block.getBlockById(1));
		world.setBlock(x+2, y+0, z+6, Block.getBlockById(1));
		world.setBlock(x+3, y+0, z+6, Block.getBlockById(1));
		world.setBlock(x+4, y+0, z+6, Block.getBlockById(1));
		world.setBlock(x+5, y+0, z+6, Block.getBlockById(1));
		world.setBlock(x+6, y+0, z+6, Block.getBlockById(1));
		world.setBlock(x+7, y+0, z+6, Block.getBlockById(1));
		world.setBlock(x+8, y+0, z+6, Block.getBlockById(1));
		world.setBlock(x+9, y+0, z+6, Block.getBlockById(1));
		world.setBlock(x+10, y+0, z+6, Block.getBlockById(1));
		world.setBlock(x+11, y+0, z+6, Block.getBlockById(1));
		world.setBlock(x+12, y+0, z+6, Block.getBlockById(1));
		world.setBlock(x+13, y+0, z+6, Block.getBlockById(1));
		world.setBlock(x+14, y+0, z+6, Block.getBlockById(1));
		world.setBlock(x+15, y+0, z+6, Block.getBlockById(1));
		world.setBlock(x+16, y+0, z+6, Block.getBlockById(1));
		world.setBlock(x+0, y+0, z+7, Block.getBlockById(1));
		world.setBlock(x+1, y+0, z+7, Block.getBlockById(1));
		world.setBlock(x+2, y+0, z+7, Block.getBlockById(1));
		world.setBlock(x+3, y+0, z+7, Block.getBlockById(1));
		world.setBlock(x+4, y+0, z+7, Block.getBlockById(1));
		world.setBlock(x+5, y+0, z+7, Block.getBlockById(1));
		world.setBlock(x+6, y+0, z+7, Block.getBlockById(1));
		world.setBlock(x+7, y+0, z+7, Block.getBlockById(1));
		world.setBlock(x+8, y+0, z+7, Block.getBlockById(1));
		world.setBlock(x+9, y+0, z+7, Block.getBlockById(1));
		world.setBlock(x+10, y+0, z+7, Block.getBlockById(1));
		world.setBlock(x+11, y+0, z+7, Block.getBlockById(1));
		world.setBlock(x+12, y+0, z+7, Block.getBlockById(1));
		world.setBlock(x+13, y+0, z+7, Block.getBlockById(1));
		world.setBlock(x+14, y+0, z+7, Block.getBlockById(1));
		world.setBlock(x+15, y+0, z+7, Block.getBlockById(1));
		world.setBlock(x+16, y+0, z+7, Block.getBlockById(1));
		world.setBlock(x+0, y+0, z+8, Block.getBlockById(1));
		world.setBlock(x+1, y+0, z+8, Block.getBlockById(1));
		world.setBlock(x+2, y+0, z+8, Block.getBlockById(1));
		world.setBlock(x+3, y+0, z+8, Block.getBlockById(1));
		world.setBlock(x+4, y+0, z+8, Block.getBlockById(1));
		world.setBlock(x+5, y+0, z+8, Block.getBlockById(1));
		world.setBlock(x+6, y+0, z+8, Block.getBlockById(1));
		world.setBlock(x+7, y+0, z+8, Block.getBlockById(1));
		world.setBlock(x+8, y+0, z+8, Block.getBlockById(1));
		world.setBlock(x+9, y+0, z+8, Block.getBlockById(1));
		world.setBlock(x+10, y+0, z+8, Block.getBlockById(1));
		world.setBlock(x+11, y+0, z+8, Block.getBlockById(1));
		world.setBlock(x+12, y+0, z+8, Block.getBlockById(1));
		world.setBlock(x+13, y+0, z+8, Block.getBlockById(1));
		world.setBlock(x+14, y+0, z+8, Block.getBlockById(1));
		world.setBlock(x+15, y+0, z+8, Block.getBlockById(1));
		world.setBlock(x+16, y+0, z+8, Block.getBlockById(1));
		world.setBlock(x+0, y+0, z+9, Block.getBlockById(1));
		world.setBlock(x+1, y+0, z+9, Block.getBlockById(1));
		world.setBlock(x+2, y+0, z+9, Block.getBlockById(1));
		world.setBlock(x+3, y+0, z+9, Block.getBlockById(1));
		world.setBlock(x+4, y+0, z+9, Block.getBlockById(1));
		world.setBlock(x+5, y+0, z+9, Block.getBlockById(1));
		world.setBlock(x+6, y+0, z+9, Block.getBlockById(1));
		world.setBlock(x+7, y+0, z+9, Block.getBlockById(1));
		world.setBlock(x+8, y+0, z+9, Block.getBlockById(1));
		world.setBlock(x+9, y+0, z+9, Block.getBlockById(1));
		world.setBlock(x+10, y+0, z+9, Block.getBlockById(1));
		world.setBlock(x+11, y+0, z+9, Block.getBlockById(1));
		world.setBlock(x+12, y+0, z+9, Block.getBlockById(1));
		world.setBlock(x+13, y+0, z+9, Block.getBlockById(1));
		world.setBlock(x+14, y+0, z+9, Block.getBlockById(1));
		world.setBlock(x+15, y+0, z+9, Block.getBlockById(1));
		world.setBlock(x+16, y+0, z+9, Block.getBlockById(1));
		world.setBlock(x+0, y+0, z+10, Block.getBlockById(1));
		world.setBlock(x+1, y+0, z+10, Block.getBlockById(1));
		world.setBlock(x+2, y+0, z+10, Block.getBlockById(1));
		world.setBlock(x+3, y+0, z+10, Block.getBlockById(1));
		world.setBlock(x+4, y+0, z+10, Block.getBlockById(1));
		world.setBlock(x+5, y+0, z+10, Block.getBlockById(1));
		world.setBlock(x+6, y+0, z+10, Block.getBlockById(1));
		world.setBlock(x+7, y+0, z+10, Block.getBlockById(1));
		world.setBlock(x+8, y+0, z+10, Block.getBlockById(1));
		world.setBlock(x+9, y+0, z+10, Block.getBlockById(1));
		world.setBlock(x+10, y+0, z+10, Block.getBlockById(1));
		world.setBlock(x+11, y+0, z+10, Block.getBlockById(1));
		world.setBlock(x+12, y+0, z+10, Block.getBlockById(1));
		world.setBlock(x+13, y+0, z+10, Block.getBlockById(1));
		world.setBlock(x+14, y+0, z+10, Block.getBlockById(1));
		world.setBlock(x+15, y+0, z+10, Block.getBlockById(1));
		world.setBlock(x+16, y+0, z+10, Block.getBlockById(1));
		world.setBlock(x+0, y+0, z+11, Block.getBlockById(1));
		world.setBlock(x+1, y+0, z+11, Block.getBlockById(1));
		world.setBlock(x+2, y+0, z+11, Block.getBlockById(1));
		world.setBlock(x+3, y+0, z+11, Block.getBlockById(1));
		world.setBlock(x+4, y+0, z+11, Block.getBlockById(1));
		world.setBlock(x+5, y+0, z+11, Block.getBlockById(1));
		world.setBlock(x+6, y+0, z+11, Block.getBlockById(1));
		world.setBlock(x+7, y+0, z+11, Block.getBlockById(1));
		world.setBlock(x+8, y+0, z+11, Block.getBlockById(1));
		world.setBlock(x+9, y+0, z+11, Block.getBlockById(1));
		world.setBlock(x+10, y+0, z+11, Block.getBlockById(1));
		world.setBlock(x+11, y+0, z+11, Block.getBlockById(1));
		world.setBlock(x+12, y+0, z+11, Block.getBlockById(1));
		world.setBlock(x+13, y+0, z+11, Block.getBlockById(1));
		world.setBlock(x+14, y+0, z+11, Block.getBlockById(1));
		world.setBlock(x+15, y+0, z+11, Block.getBlockById(1));
		world.setBlock(x+16, y+0, z+11, Block.getBlockById(1));
		world.setBlock(x+0, y+0, z+12, Block.getBlockById(1));
		world.setBlock(x+1, y+0, z+12, Block.getBlockById(1));
		world.setBlock(x+2, y+0, z+12, Block.getBlockById(1));
		world.setBlock(x+3, y+0, z+12, Block.getBlockById(1));
		world.setBlock(x+4, y+0, z+12, Block.getBlockById(1));
		world.setBlock(x+5, y+0, z+12, Block.getBlockById(1));
		world.setBlock(x+6, y+0, z+12, Block.getBlockById(1));
		world.setBlock(x+7, y+0, z+12, Block.getBlockById(1));
		world.setBlock(x+8, y+0, z+12, Block.getBlockById(1));
		world.setBlock(x+9, y+0, z+12, Block.getBlockById(1));
		world.setBlock(x+10, y+0, z+12, Block.getBlockById(1));
		world.setBlock(x+11, y+0, z+12, Block.getBlockById(1));
		world.setBlock(x+12, y+0, z+12, Block.getBlockById(1));
		world.setBlock(x+13, y+0, z+12, Block.getBlockById(1));
		world.setBlock(x+14, y+0, z+12, Block.getBlockById(1));
		world.setBlock(x+15, y+0, z+12, Block.getBlockById(1));
		world.setBlock(x+16, y+0, z+12, Block.getBlockById(1));
		world.setBlock(x+0, y+0, z+13, Block.getBlockById(1));
		world.setBlock(x+1, y+0, z+13, Block.getBlockById(1));
		world.setBlock(x+2, y+0, z+13, Block.getBlockById(1));
		world.setBlock(x+3, y+0, z+13, Block.getBlockById(1));
		world.setBlock(x+4, y+0, z+13, Block.getBlockById(1));
		world.setBlock(x+5, y+0, z+13, Block.getBlockById(1));
		world.setBlock(x+6, y+0, z+13, Block.getBlockById(1));
		world.setBlock(x+7, y+0, z+13, Block.getBlockById(1));
		world.setBlock(x+8, y+0, z+13, Block.getBlockById(1));
		world.setBlock(x+9, y+0, z+13, Block.getBlockById(1));
		world.setBlock(x+10, y+0, z+13, Block.getBlockById(1));
		world.setBlock(x+11, y+0, z+13, Block.getBlockById(1));
		world.setBlock(x+12, y+0, z+13, Block.getBlockById(1));
		world.setBlock(x+13, y+0, z+13, Block.getBlockById(1));
		world.setBlock(x+14, y+0, z+13, Block.getBlockById(1));
		world.setBlock(x+15, y+0, z+13, Block.getBlockById(1));
		world.setBlock(x+16, y+0, z+13, Block.getBlockById(1));
		world.setBlock(x+0, y+0, z+14, Block.getBlockById(1));
		world.setBlock(x+1, y+0, z+14, Block.getBlockById(1));
		world.setBlock(x+2, y+0, z+14, Block.getBlockById(1));
		world.setBlock(x+3, y+0, z+14, Block.getBlockById(1));
		world.setBlock(x+4, y+0, z+14, Block.getBlockById(1));
		world.setBlock(x+5, y+0, z+14, Block.getBlockById(1));
		world.setBlock(x+6, y+0, z+14, Block.getBlockById(1));
		world.setBlock(x+7, y+0, z+14, Block.getBlockById(1));
		world.setBlock(x+8, y+0, z+14, Block.getBlockById(1));
		world.setBlock(x+9, y+0, z+14, Block.getBlockById(1));
		world.setBlock(x+10, y+0, z+14, Block.getBlockById(1));
		world.setBlock(x+11, y+0, z+14, Block.getBlockById(1));
		world.setBlock(x+12, y+0, z+14, Block.getBlockById(1));
		world.setBlock(x+13, y+0, z+14, Block.getBlockById(1));
		world.setBlock(x+14, y+0, z+14, Block.getBlockById(1));
		world.setBlock(x+15, y+0, z+14, Block.getBlockById(1));
		world.setBlock(x+16, y+0, z+14, Block.getBlockById(1));
		world.setBlock(x+0, y+0, z+15, Block.getBlockById(1));
		world.setBlock(x+1, y+0, z+15, Block.getBlockById(1));
		world.setBlock(x+2, y+0, z+15, Block.getBlockById(1));
		world.setBlock(x+3, y+0, z+15, Block.getBlockById(1));
		world.setBlock(x+4, y+0, z+15, Block.getBlockById(1));
		world.setBlock(x+5, y+0, z+15, Block.getBlockById(1));
		world.setBlock(x+6, y+0, z+15, Block.getBlockById(1));
		world.setBlock(x+7, y+0, z+15, Block.getBlockById(1));
		world.setBlock(x+8, y+0, z+15, Block.getBlockById(1));
		world.setBlock(x+9, y+0, z+15, Block.getBlockById(1));
		world.setBlock(x+10, y+0, z+15, Block.getBlockById(1));
		world.setBlock(x+11, y+0, z+15, Block.getBlockById(1));
		world.setBlock(x+12, y+0, z+15, Block.getBlockById(1));
		world.setBlock(x+13, y+0, z+15, Block.getBlockById(1));
		world.setBlock(x+14, y+0, z+15, Block.getBlockById(1));
		world.setBlock(x+15, y+0, z+15, Block.getBlockById(1));
		world.setBlock(x+16, y+0, z+15, Block.getBlockById(1));
		world.setBlock(x+0, y+0, z+16, Block.getBlockById(1));
		world.setBlock(x+1, y+0, z+16, Block.getBlockById(1));
		world.setBlock(x+2, y+0, z+16, Block.getBlockById(1));
		world.setBlock(x+3, y+0, z+16, Block.getBlockById(1));
		world.setBlock(x+4, y+0, z+16, Block.getBlockById(1));
		world.setBlock(x+5, y+0, z+16, Block.getBlockById(1));
		world.setBlock(x+6, y+0, z+16, Block.getBlockById(1));
		world.setBlock(x+7, y+0, z+16, Block.getBlockById(1));
		world.setBlock(x+8, y+0, z+16, Block.getBlockById(1));
		world.setBlock(x+9, y+0, z+16, Block.getBlockById(1));
		world.setBlock(x+10, y+0, z+16, Block.getBlockById(1));
		world.setBlock(x+11, y+0, z+16, Block.getBlockById(1));
		world.setBlock(x+12, y+0, z+16, Block.getBlockById(1));
		world.setBlock(x+13, y+0, z+16, Block.getBlockById(1));
		world.setBlock(x+14, y+0, z+16, Block.getBlockById(1));
		world.setBlock(x+15, y+0, z+16, Block.getBlockById(1));
		world.setBlock(x+16, y+0, z+16, Block.getBlockById(1));
		world.setBlock(x+0, y+0, z+17, Block.getBlockById(1));
		world.setBlock(x+1, y+0, z+17, Block.getBlockById(1));
		world.setBlock(x+2, y+0, z+17, Block.getBlockById(1));
		world.setBlock(x+3, y+0, z+17, Block.getBlockById(1));
		world.setBlock(x+4, y+0, z+17, Block.getBlockById(1));
		world.setBlock(x+5, y+0, z+17, Block.getBlockById(1));
		world.setBlock(x+6, y+0, z+17, Block.getBlockById(1));
		world.setBlock(x+7, y+0, z+17, Block.getBlockById(1));
		world.setBlock(x+8, y+0, z+17, Block.getBlockById(1));
		world.setBlock(x+9, y+0, z+17, Block.getBlockById(1));
		world.setBlock(x+10, y+0, z+17, Block.getBlockById(1));
		world.setBlock(x+11, y+0, z+17, Block.getBlockById(1));
		world.setBlock(x+12, y+0, z+17, Block.getBlockById(1));
		world.setBlock(x+13, y+0, z+17, Block.getBlockById(1));
		world.setBlock(x+14, y+0, z+17, Block.getBlockById(1));
		world.setBlock(x+15, y+0, z+17, Block.getBlockById(1));
		world.setBlock(x+16, y+0, z+17, Block.getBlockById(1));
		world.setBlock(x+0, y+0, z+18, Block.getBlockById(1));
		world.setBlock(x+1, y+0, z+18, Block.getBlockById(1));
		world.setBlock(x+2, y+0, z+18, Block.getBlockById(1));
		world.setBlock(x+3, y+0, z+18, Block.getBlockById(1));
		world.setBlock(x+4, y+0, z+18, Block.getBlockById(1));
		world.setBlock(x+5, y+0, z+18, Block.getBlockById(1));
		world.setBlock(x+6, y+0, z+18, Block.getBlockById(1));
		world.setBlock(x+7, y+0, z+18, Block.getBlockById(1));
		world.setBlock(x+8, y+0, z+18, Block.getBlockById(1));
		world.setBlock(x+9, y+0, z+18, Block.getBlockById(1));
		world.setBlock(x+10, y+0, z+18, Block.getBlockById(1));
		world.setBlock(x+11, y+0, z+18, Block.getBlockById(1));
		world.setBlock(x+12, y+0, z+18, Block.getBlockById(1));
		world.setBlock(x+13, y+0, z+18, Block.getBlockById(1));
		world.setBlock(x+14, y+0, z+18, Block.getBlockById(1));
		world.setBlock(x+15, y+0, z+18, Block.getBlockById(1));
		world.setBlock(x+16, y+0, z+18, Block.getBlockById(1));
		world.setBlock(x+0, y+0, z+19, Block.getBlockById(1));
		world.setBlock(x+1, y+0, z+19, Block.getBlockById(1));
		world.setBlock(x+2, y+0, z+19, Block.getBlockById(1));
		world.setBlock(x+3, y+0, z+19, Block.getBlockById(1));
		world.setBlock(x+4, y+0, z+19, Block.getBlockById(1));
		world.setBlock(x+5, y+0, z+19, Block.getBlockById(1));
		world.setBlock(x+6, y+0, z+19, Block.getBlockById(1));
		world.setBlock(x+7, y+0, z+19, Block.getBlockById(1));
		world.setBlock(x+8, y+0, z+19, Block.getBlockById(1));
		world.setBlock(x+9, y+0, z+19, Block.getBlockById(1));
		world.setBlock(x+10, y+0, z+19, Block.getBlockById(1));
		world.setBlock(x+11, y+0, z+19, Block.getBlockById(1));
		world.setBlock(x+12, y+0, z+19, Block.getBlockById(1));
		world.setBlock(x+13, y+0, z+19, Block.getBlockById(1));
		world.setBlock(x+14, y+0, z+19, Block.getBlockById(1));
		world.setBlock(x+15, y+0, z+19, Block.getBlockById(1));
		world.setBlock(x+16, y+0, z+19, Block.getBlockById(1));
		world.setBlock(x+0, y+0, z+20, Block.getBlockById(1));
		world.setBlock(x+1, y+0, z+20, Block.getBlockById(1));
		world.setBlock(x+2, y+0, z+20, Block.getBlockById(1));
		world.setBlock(x+3, y+0, z+20, Block.getBlockById(1));
		world.setBlock(x+4, y+0, z+20, Block.getBlockById(1));
		world.setBlock(x+5, y+0, z+20, Block.getBlockById(1));
		world.setBlock(x+6, y+0, z+20, Block.getBlockById(1));
		world.setBlock(x+7, y+0, z+20, Block.getBlockById(1));
		world.setBlock(x+8, y+0, z+20, Block.getBlockById(1));
		world.setBlock(x+9, y+0, z+20, Block.getBlockById(1));
		world.setBlock(x+10, y+0, z+20, Block.getBlockById(1));
		world.setBlock(x+11, y+0, z+20, Block.getBlockById(1));
		world.setBlock(x+12, y+0, z+20, Block.getBlockById(1));
		world.setBlock(x+13, y+0, z+20, Block.getBlockById(1));
		world.setBlock(x+14, y+0, z+20, Block.getBlockById(1));
		world.setBlock(x+15, y+0, z+20, Block.getBlockById(1));
		world.setBlock(x+16, y+0, z+20, Block.getBlockById(1));
		world.setBlock(x+0, y+0, z+21, Block.getBlockById(1));
		world.setBlock(x+1, y+0, z+21, Block.getBlockById(1));
		world.setBlock(x+2, y+0, z+21, Block.getBlockById(1));
		world.setBlock(x+3, y+0, z+21, Block.getBlockById(1));
		world.setBlock(x+4, y+0, z+21, Block.getBlockById(1));
		world.setBlock(x+5, y+0, z+21, Block.getBlockById(1));
		world.setBlock(x+6, y+0, z+21, Block.getBlockById(1));
		world.setBlock(x+7, y+0, z+21, Block.getBlockById(1));
		world.setBlock(x+8, y+0, z+21, Block.getBlockById(1));
		world.setBlock(x+9, y+0, z+21, Block.getBlockById(1));
		world.setBlock(x+10, y+0, z+21, Block.getBlockById(1));
		world.setBlock(x+11, y+0, z+21, Block.getBlockById(1));
		world.setBlock(x+12, y+0, z+21, Block.getBlockById(1));
		world.setBlock(x+13, y+0, z+21, Block.getBlockById(1));
		world.setBlock(x+14, y+0, z+21, Block.getBlockById(1));
		world.setBlock(x+15, y+0, z+21, Block.getBlockById(1));
		world.setBlock(x+16, y+0, z+21, Block.getBlockById(1));
		world.setBlock(x+0, y+0, z+22, Block.getBlockById(1));
		world.setBlock(x+1, y+0, z+22, Block.getBlockById(1));
		world.setBlock(x+2, y+0, z+22, Block.getBlockById(1));
		world.setBlock(x+3, y+0, z+22, Block.getBlockById(1));
		world.setBlock(x+4, y+0, z+22, Block.getBlockById(1));
		world.setBlock(x+5, y+0, z+22, Block.getBlockById(1));
		world.setBlock(x+6, y+0, z+22, Block.getBlockById(1));
		world.setBlock(x+7, y+0, z+22, Block.getBlockById(1));
		world.setBlock(x+8, y+0, z+22, Block.getBlockById(1));
		world.setBlock(x+9, y+0, z+22, Block.getBlockById(1));
		world.setBlock(x+10, y+0, z+22, Block.getBlockById(1));
		world.setBlock(x+11, y+0, z+22, Block.getBlockById(1));
		world.setBlock(x+12, y+0, z+22, Block.getBlockById(1));
		world.setBlock(x+13, y+0, z+22, Block.getBlockById(1));
		world.setBlock(x+14, y+0, z+22, Block.getBlockById(1));
		world.setBlock(x+15, y+0, z+22, Block.getBlockById(1));
		world.setBlock(x+16, y+0, z+22, Block.getBlockById(1));
		world.setBlock(x+1, y+1, z+1, Block.getBlockById(4));
		world.setBlock(x+2, y+1, z+1, Block.getBlockById(4));
		world.setBlock(x+14, y+1, z+1, Block.getBlockById(4));
		world.setBlock(x+15, y+1, z+1, Block.getBlockById(4));
		world.setBlock(x+1, y+1, z+2, Block.getBlockById(4));
		world.setBlock(x+2, y+1, z+2, Block.getBlockById(4));
		world.setBlock(x+14, y+1, z+2, Block.getBlockById(4));
		world.setBlock(x+15, y+1, z+2, Block.getBlockById(4));
		world.setBlock(x+0, y+1, z+4, Block.getBlockById(78));
		world.setBlock(x+16, y+1, z+4, Block.getBlockById(78));
		world.setBlock(x+0, y+1, z+5, Block.getBlockById(78));
		world.setBlock(x+16, y+1, z+5, Block.getBlockById(78));
		world.setBlock(x+0, y+1, z+6, Block.getBlockById(78));
		world.setBlock(x+16, y+1, z+6, Block.getBlockById(78));
		world.setBlock(x+0, y+1, z+7, Block.getBlockById(78));
		world.setBlock(x+16, y+1, z+7, Block.getBlockById(78));
		world.setBlock(x+0, y+1, z+8, Block.getBlockById(78));
		world.setBlock(x+16, y+1, z+8, Block.getBlockById(78));
		world.setBlock(x+0, y+1, z+9, Block.getBlockById(78));
		world.setBlock(x+16, y+1, z+9, Block.getBlockById(78));
		world.setBlock(x+0, y+1, z+10, Block.getBlockById(78));
		world.setBlock(x+16, y+1, z+10, Block.getBlockById(78));
		world.setBlock(x+0, y+1, z+11, Block.getBlockById(78));
		world.setBlock(x+16, y+1, z+11, Block.getBlockById(78));
		world.setBlock(x+0, y+1, z+12, Block.getBlockById(78));
		world.setBlock(x+16, y+1, z+12, Block.getBlockById(78));
		world.setBlock(x+0, y+1, z+13, Block.getBlockById(78));
		world.setBlock(x+16, y+1, z+13, Block.getBlockById(78));
		world.setBlock(x+0, y+1, z+14, Block.getBlockById(78));
		world.setBlock(x+16, y+1, z+14, Block.getBlockById(78));
		world.setBlock(x+0, y+1, z+15, Block.getBlockById(78));
		world.setBlock(x+16, y+1, z+15, Block.getBlockById(78));
		world.setBlock(x+0, y+1, z+16, Block.getBlockById(78));
		world.setBlock(x+16, y+1, z+16, Block.getBlockById(78));
		world.setBlock(x+0, y+1, z+17, Block.getBlockById(78));
		world.setBlock(x+16, y+1, z+17, Block.getBlockById(78));
		world.setBlock(x+0, y+1, z+18, Block.getBlockById(78));
		world.setBlock(x+16, y+1, z+18, Block.getBlockById(78));
		world.setBlock(x+1, y+1, z+20, Block.getBlockById(4));
		world.setBlock(x+2, y+1, z+20, Block.getBlockById(4));
		world.setBlock(x+14, y+1, z+20, Block.getBlockById(4));
		world.setBlock(x+15, y+1, z+20, Block.getBlockById(4));
		world.setBlock(x+1, y+1, z+21, Block.getBlockById(4));
		world.setBlock(x+2, y+1, z+21, Block.getBlockById(4));
		world.setBlock(x+14, y+1, z+21, Block.getBlockById(4));
		world.setBlock(x+15, y+1, z+21, Block.getBlockById(4));
		world.setBlock(x+5, y+1, z+22, Block.getBlockById(78));
		world.setBlock(x+6, y+1, z+22, Block.getBlockById(78));
		world.setBlock(x+7, y+1, z+22, Block.getBlockById(78));
		world.setBlock(x+9, y+1, z+22, Block.getBlockById(78));
		world.setBlock(x+10, y+1, z+22, Block.getBlockById(78));
		world.setBlock(x+11, y+1, z+22, Block.getBlockById(78));
		world.setBlock(x+1, y+2, z+1, Block.getBlockById(4));
		world.setBlock(x+2, y+2, z+1, Block.getBlockById(4));
		world.setBlock(x+14, y+2, z+1, Block.getBlockById(4));
		world.setBlock(x+15, y+2, z+1, Block.getBlockById(4));
		world.setBlock(x+1, y+2, z+2, Block.getBlockById(4));
		world.setBlock(x+2, y+2, z+2, Block.getBlockById(4));
		world.setBlock(x+14, y+2, z+2, Block.getBlockById(4));
		world.setBlock(x+15, y+2, z+2, Block.getBlockById(4));
		world.setBlock(x+1, y+2, z+20, Block.getBlockById(4));
		world.setBlock(x+2, y+2, z+20, Block.getBlockById(4));
		world.setBlock(x+14, y+2, z+20, Block.getBlockById(4));
		world.setBlock(x+15, y+2, z+20, Block.getBlockById(4));
		world.setBlock(x+1, y+2, z+21, Block.getBlockById(4));
		world.setBlock(x+2, y+2, z+21, Block.getBlockById(4));
		world.setBlock(x+14, y+2, z+21, Block.getBlockById(4));
		world.setBlock(x+15, y+2, z+21, Block.getBlockById(4));
		world.setBlock(x+1, y+3, z+1, Block.getBlockById(4));
		world.setBlock(x+2, y+3, z+1, Block.getBlockById(4));
		world.setBlock(x+14, y+3, z+1, Block.getBlockById(4));
		world.setBlock(x+15, y+3, z+1, Block.getBlockById(4));
		world.setBlock(x+1, y+3, z+2, Block.getBlockById(4));
		world.setBlock(x+2, y+3, z+2, Block.getBlockById(4));
		world.setBlock(x+14, y+3, z+2, Block.getBlockById(4));
		world.setBlock(x+15, y+3, z+2, Block.getBlockById(4));
		world.setBlock(x+1, y+3, z+20, Block.getBlockById(4));
		world.setBlock(x+2, y+3, z+20, Block.getBlockById(4));
		world.setBlock(x+14, y+3, z+20, Block.getBlockById(4));
		world.setBlock(x+15, y+3, z+20, Block.getBlockById(4));
		world.setBlock(x+1, y+3, z+21, Block.getBlockById(4));
		world.setBlock(x+2, y+3, z+21, Block.getBlockById(4));
		world.setBlock(x+14, y+3, z+21, Block.getBlockById(4));
		world.setBlock(x+15, y+3, z+21, Block.getBlockById(4));
		world.setBlock(x+1, y+4, z+1, Block.getBlockById(4));
		world.setBlock(x+2, y+4, z+1, Block.getBlockById(4));
		world.setBlock(x+14, y+4, z+1, Block.getBlockById(4));
		world.setBlock(x+15, y+4, z+1, Block.getBlockById(4));
		world.setBlock(x+1, y+4, z+2, Block.getBlockById(4));
		world.setBlock(x+2, y+4, z+2, Block.getBlockById(4));
		world.setBlock(x+14, y+4, z+2, Block.getBlockById(4));
		world.setBlock(x+15, y+4, z+2, Block.getBlockById(4));
		world.setBlock(x+1, y+4, z+20, Block.getBlockById(4));
		world.setBlock(x+2, y+4, z+20, Block.getBlockById(4));
		world.setBlock(x+14, y+4, z+20, Block.getBlockById(4));
		world.setBlock(x+15, y+4, z+20, Block.getBlockById(4));
		world.setBlock(x+1, y+4, z+21, Block.getBlockById(4));
		world.setBlock(x+2, y+4, z+21, Block.getBlockById(4));
		world.setBlock(x+14, y+4, z+21, Block.getBlockById(4));
		world.setBlock(x+15, y+4, z+21, Block.getBlockById(4));
		world.setBlock(x+1, y+5, z+1, Block.getBlockById(4));
		world.setBlock(x+2, y+5, z+1, Block.getBlockById(4));
		world.setBlock(x+14, y+5, z+1, Block.getBlockById(4));
		world.setBlock(x+15, y+5, z+1, Block.getBlockById(4));
		world.setBlock(x+1, y+5, z+2, Block.getBlockById(4));
		world.setBlock(x+2, y+5, z+2, Block.getBlockById(4));
		world.setBlock(x+14, y+5, z+2, Block.getBlockById(4));
		world.setBlock(x+15, y+5, z+2, Block.getBlockById(4));
		world.setBlock(x+1, y+5, z+20, Block.getBlockById(4));
		world.setBlock(x+2, y+5, z+20, Block.getBlockById(4));
		world.setBlock(x+14, y+5, z+20, Block.getBlockById(4));
		world.setBlock(x+15, y+5, z+20, Block.getBlockById(4));
		world.setBlock(x+1, y+5, z+21, Block.getBlockById(4));
		world.setBlock(x+2, y+5, z+21, Block.getBlockById(4));
		world.setBlock(x+14, y+5, z+21, Block.getBlockById(4));
		world.setBlock(x+15, y+5, z+21, Block.getBlockById(4));
		world.setBlock(x+1, y+6, z+1, Block.getBlockById(4));
		world.setBlock(x+2, y+6, z+1, Block.getBlockById(4));
		world.setBlock(x+14, y+6, z+1, Block.getBlockById(4));
		world.setBlock(x+15, y+6, z+1, Block.getBlockById(4));
		world.setBlock(x+1, y+6, z+2, Block.getBlockById(4));
		world.setBlock(x+2, y+6, z+2, Block.getBlockById(4));
		world.setBlock(x+14, y+6, z+2, Block.getBlockById(4));
		world.setBlock(x+15, y+6, z+2, Block.getBlockById(4));
		world.setBlock(x+1, y+6, z+20, Block.getBlockById(4));
		world.setBlock(x+2, y+6, z+20, Block.getBlockById(4));
		world.setBlock(x+14, y+6, z+20, Block.getBlockById(4));
		world.setBlock(x+15, y+6, z+20, Block.getBlockById(4));
		world.setBlock(x+1, y+6, z+21, Block.getBlockById(4));
		world.setBlock(x+2, y+6, z+21, Block.getBlockById(4));
		world.setBlock(x+14, y+6, z+21, Block.getBlockById(4));
		world.setBlock(x+15, y+6, z+21, Block.getBlockById(4));
		world.setBlock(x+1, y+7, z+1, Block.getBlockById(4));
		world.setBlock(x+2, y+7, z+1, Block.getBlockById(4));
		world.setBlock(x+14, y+7, z+1, Block.getBlockById(4));
		world.setBlock(x+15, y+7, z+1, Block.getBlockById(4));
		world.setBlock(x+1, y+7, z+2, Block.getBlockById(4));
		world.setBlock(x+2, y+7, z+2, Block.getBlockById(4));
		world.setBlock(x+14, y+7, z+2, Block.getBlockById(4));
		world.setBlock(x+15, y+7, z+2, Block.getBlockById(4));
		world.setBlock(x+1, y+7, z+20, Block.getBlockById(4));
		world.setBlock(x+2, y+7, z+20, Block.getBlockById(4));
		world.setBlock(x+14, y+7, z+20, Block.getBlockById(4));
		world.setBlock(x+15, y+7, z+20, Block.getBlockById(4));
		world.setBlock(x+1, y+7, z+21, Block.getBlockById(4));
		world.setBlock(x+2, y+7, z+21, Block.getBlockById(4));
		world.setBlock(x+14, y+7, z+21, Block.getBlockById(4));
		world.setBlock(x+15, y+7, z+21, Block.getBlockById(4));
		world.setBlock(x+0, y+8, z+0, Block.getBlockById(53));
		world.setBlockMetadataWithNotify(x+0, y+8, z+0, 4, 4);
		world.setBlock(x+1, y+8, z+0, Block.getBlockById(53));
		world.setBlockMetadataWithNotify(x+1, y+8, z+0, 6, 6);
		world.setBlock(x+2, y+8, z+0, Block.getBlockById(53));
		world.setBlockMetadataWithNotify(x+2, y+8, z+0, 6, 6);
		world.setBlock(x+3, y+8, z+0, Block.getBlockById(53));
		world.setBlockMetadataWithNotify(x+3, y+8, z+0, 6, 6);
		world.setBlock(x+13, y+8, z+0, Block.getBlockById(53));
		world.setBlockMetadataWithNotify(x+13, y+8, z+0, 4, 4);
		world.setBlock(x+14, y+8, z+0, Block.getBlockById(53));
		world.setBlockMetadataWithNotify(x+14, y+8, z+0, 6, 6);
		world.setBlock(x+15, y+8, z+0, Block.getBlockById(53));
		world.setBlockMetadataWithNotify(x+15, y+8, z+0, 6, 6);
		world.setBlock(x+16, y+8, z+0, Block.getBlockById(53));
		world.setBlockMetadataWithNotify(x+16, y+8, z+0, 6, 6);
		world.setBlock(x+0, y+8, z+1, Block.getBlockById(53));
		world.setBlockMetadataWithNotify(x+0, y+8, z+1, 4, 4);
		world.setBlock(x+1, y+8, z+1, Block.getBlockById(4));
		world.setBlock(x+2, y+8, z+1, Block.getBlockById(4));
		world.setBlock(x+3, y+8, z+1, Block.getBlockById(53));
		world.setBlockMetadataWithNotify(x+3, y+8, z+1, 5, 5);
		world.setBlock(x+13, y+8, z+1, Block.getBlockById(53));
		world.setBlockMetadataWithNotify(x+13, y+8, z+1, 4, 4);
		world.setBlock(x+14, y+8, z+1, Block.getBlockById(4));
		world.setBlock(x+15, y+8, z+1, Block.getBlockById(4));
		world.setBlock(x+16, y+8, z+1, Block.getBlockById(53));
		world.setBlockMetadataWithNotify(x+16, y+8, z+1, 5, 5);
		world.setBlock(x+0, y+8, z+2, Block.getBlockById(53));
		world.setBlockMetadataWithNotify(x+0, y+8, z+2, 4, 4);
		world.setBlock(x+1, y+8, z+2, Block.getBlockById(4));
		world.setBlock(x+2, y+8, z+2, Block.getBlockById(4));
		world.setBlock(x+3, y+8, z+2, Block.getBlockById(53));
		world.setBlockMetadataWithNotify(x+3, y+8, z+2, 5, 5);
		world.setBlock(x+13, y+8, z+2, Block.getBlockById(53));
		world.setBlockMetadataWithNotify(x+13, y+8, z+2, 4, 4);
		world.setBlock(x+14, y+8, z+2, Block.getBlockById(4));
		world.setBlock(x+15, y+8, z+2, Block.getBlockById(4));
		world.setBlock(x+16, y+8, z+2, Block.getBlockById(53));
		world.setBlockMetadataWithNotify(x+16, y+8, z+2, 5, 5);
		world.setBlock(x+0, y+8, z+3, Block.getBlockById(53));
		world.setBlockMetadataWithNotify(x+0, y+8, z+3, 7, 7);
		world.setBlock(x+1, y+8, z+3, Block.getBlockById(53));
		world.setBlockMetadataWithNotify(x+1, y+8, z+3, 7, 7);
		world.setBlock(x+2, y+8, z+3, Block.getBlockById(53));
		world.setBlockMetadataWithNotify(x+2, y+8, z+3, 7, 7);
		world.setBlock(x+3, y+8, z+3, Block.getBlockById(53));
		world.setBlockMetadataWithNotify(x+3, y+8, z+3, 7, 7);
		world.setBlock(x+13, y+8, z+3, Block.getBlockById(53));
		world.setBlockMetadataWithNotify(x+13, y+8, z+3, 7, 7);
		world.setBlock(x+14, y+8, z+3, Block.getBlockById(53));
		world.setBlockMetadataWithNotify(x+14, y+8, z+3, 7, 7);
		world.setBlock(x+15, y+8, z+3, Block.getBlockById(53));
		world.setBlockMetadataWithNotify(x+15, y+8, z+3, 7, 7);
		world.setBlock(x+16, y+8, z+3, Block.getBlockById(53));
		world.setBlockMetadataWithNotify(x+16, y+8, z+3, 7, 7);
		world.setBlock(x+0, y+8, z+19, Block.getBlockById(53));
		world.setBlockMetadataWithNotify(x+0, y+8, z+19, 4, 4);
		world.setBlock(x+1, y+8, z+19, Block.getBlockById(53));
		world.setBlockMetadataWithNotify(x+1, y+8, z+19, 6, 6);
		world.setBlock(x+2, y+8, z+19, Block.getBlockById(53));
		world.setBlockMetadataWithNotify(x+2, y+8, z+19, 6, 6);
		world.setBlock(x+3, y+8, z+19, Block.getBlockById(53));
		world.setBlockMetadataWithNotify(x+3, y+8, z+19, 6, 6);
		world.setBlock(x+13, y+8, z+19, Block.getBlockById(53));
		world.setBlockMetadataWithNotify(x+13, y+8, z+19, 6, 6);
		world.setBlock(x+14, y+8, z+19, Block.getBlockById(53));
		world.setBlockMetadataWithNotify(x+14, y+8, z+19, 6, 6);
		world.setBlock(x+15, y+8, z+19, Block.getBlockById(53));
		world.setBlockMetadataWithNotify(x+15, y+8, z+19, 6, 6);
		world.setBlock(x+16, y+8, z+19, Block.getBlockById(53));
		world.setBlockMetadataWithNotify(x+16, y+8, z+19, 6, 6);
		world.setBlock(x+0, y+8, z+20, Block.getBlockById(53));
		world.setBlockMetadataWithNotify(x+0, y+8, z+20, 4, 4);
		world.setBlock(x+1, y+8, z+20, Block.getBlockById(4));
		world.setBlock(x+2, y+8, z+20, Block.getBlockById(4));
		world.setBlock(x+3, y+8, z+20, Block.getBlockById(53));
		world.setBlockMetadataWithNotify(x+3, y+8, z+20, 5, 5);
		world.setBlock(x+13, y+8, z+20, Block.getBlockById(53));
		world.setBlockMetadataWithNotify(x+13, y+8, z+20, 4, 4);
		world.setBlock(x+14, y+8, z+20, Block.getBlockById(4));
		world.setBlock(x+15, y+8, z+20, Block.getBlockById(4));
		world.setBlock(x+16, y+8, z+20, Block.getBlockById(53));
		world.setBlockMetadataWithNotify(x+16, y+8, z+20, 5, 5);
		world.setBlock(x+0, y+8, z+21, Block.getBlockById(53));
		world.setBlockMetadataWithNotify(x+0, y+8, z+21, 4, 4);
		world.setBlock(x+1, y+8, z+21, Block.getBlockById(4));
		world.setBlock(x+2, y+8, z+21, Block.getBlockById(4));
		world.setBlock(x+3, y+8, z+21, Block.getBlockById(53));
		world.setBlockMetadataWithNotify(x+3, y+8, z+21, 5, 5);
		world.setBlock(x+13, y+8, z+21, Block.getBlockById(53));
		world.setBlockMetadataWithNotify(x+13, y+8, z+21, 4, 4);
		world.setBlock(x+14, y+8, z+21, Block.getBlockById(4));
		world.setBlock(x+15, y+8, z+21, Block.getBlockById(4));
		world.setBlock(x+16, y+8, z+21, Block.getBlockById(53));
		world.setBlockMetadataWithNotify(x+16, y+8, z+21, 5, 5);
		world.setBlock(x+0, y+8, z+22, Block.getBlockById(53));
		world.setBlockMetadataWithNotify(x+0, y+8, z+22, 7, 7);
		world.setBlock(x+1, y+8, z+22, Block.getBlockById(53));
		world.setBlockMetadataWithNotify(x+1, y+8, z+22, 7, 7);
		world.setBlock(x+2, y+8, z+22, Block.getBlockById(53));
		world.setBlockMetadataWithNotify(x+2, y+8, z+22, 7, 7);
		world.setBlock(x+3, y+8, z+22, Block.getBlockById(53));
		world.setBlockMetadataWithNotify(x+3, y+8, z+22, 7, 7);
		world.setBlock(x+13, y+8, z+22, Block.getBlockById(53));
		world.setBlockMetadataWithNotify(x+13, y+8, z+22, 4, 4);
		world.setBlock(x+14, y+8, z+22, Block.getBlockById(53));
		world.setBlockMetadataWithNotify(x+14, y+8, z+22, 7, 7);
		world.setBlock(x+15, y+8, z+22, Block.getBlockById(53));
		world.setBlockMetadataWithNotify(x+15, y+8, z+22, 7, 7);
		world.setBlock(x+16, y+8, z+22, Block.getBlockById(53));
		world.setBlockMetadataWithNotify(x+16, y+8, z+22, 5, 5);
		world.setBlock(x+0, y+9, z+0, Block.getBlockById(53));
		world.setBlockMetadataWithNotify(x+0, y+9, z+0, 6, 6);
		world.setBlock(x+1, y+9, z+0, Block.getBlockById(53));
		world.setBlockMetadataWithNotify(x+1, y+9, z+0, 6, 6);
		world.setBlock(x+2, y+9, z+0, Block.getBlockById(53));
		world.setBlockMetadataWithNotify(x+2, y+9, z+0, 6, 6);
		world.setBlock(x+3, y+9, z+0, Block.getBlockById(53));
		world.setBlockMetadataWithNotify(x+3, y+9, z+0, 6, 6);
		world.setBlock(x+13, y+9, z+0, Block.getBlockById(53));
		world.setBlockMetadataWithNotify(x+13, y+9, z+0, 6, 6);
		world.setBlock(x+14, y+9, z+0, Block.getBlockById(53));
		world.setBlockMetadataWithNotify(x+14, y+9, z+0, 6, 6);
		world.setBlock(x+15, y+9, z+0, Block.getBlockById(53));
		world.setBlockMetadataWithNotify(x+15, y+9, z+0, 6, 6);
		world.setBlock(x+16, y+9, z+0, Block.getBlockById(53));
		world.setBlockMetadataWithNotify(x+16, y+9, z+0, 6, 6);
		world.setBlock(x+0, y+9, z+1, Block.getBlockById(53));
		world.setBlockMetadataWithNotify(x+0, y+9, z+1, 4, 4);
		world.setBlock(x+1, y+9, z+1, Block.getBlockById(4));
		world.setBlock(x+2, y+9, z+1, Block.getBlockById(4));
		world.setBlock(x+3, y+9, z+1, Block.getBlockById(53));
		world.setBlockMetadataWithNotify(x+3, y+9, z+1, 5, 5);
		world.setBlock(x+13, y+9, z+1, Block.getBlockById(53));
		world.setBlockMetadataWithNotify(x+13, y+9, z+1, 4, 4);
		world.setBlock(x+14, y+9, z+1, Block.getBlockById(4));
		world.setBlock(x+15, y+9, z+1, Block.getBlockById(4));
		world.setBlock(x+16, y+9, z+1, Block.getBlockById(53));
		world.setBlockMetadataWithNotify(x+16, y+9, z+1, 5, 5);
		world.setBlock(x+0, y+9, z+2, Block.getBlockById(53));
		world.setBlockMetadataWithNotify(x+0, y+9, z+2, 4, 4);
		world.setBlock(x+1, y+9, z+2, Block.getBlockById(4));
		world.setBlock(x+2, y+9, z+2, Block.getBlockById(4));
		world.setBlock(x+3, y+9, z+2, Block.getBlockById(53));
		world.setBlockMetadataWithNotify(x+3, y+9, z+2, 5, 5);
		world.setBlock(x+13, y+9, z+2, Block.getBlockById(53));
		world.setBlockMetadataWithNotify(x+13, y+9, z+2, 4, 4);
		world.setBlock(x+14, y+9, z+2, Block.getBlockById(4));
		world.setBlock(x+15, y+9, z+2, Block.getBlockById(4));
		world.setBlock(x+16, y+9, z+2, Block.getBlockById(53));
		world.setBlockMetadataWithNotify(x+16, y+9, z+2, 5, 5);
		world.setBlock(x+0, y+9, z+3, Block.getBlockById(53));
		world.setBlockMetadataWithNotify(x+0, y+9, z+3, 7, 7);
		world.setBlock(x+1, y+9, z+3, Block.getBlockById(53));
		world.setBlockMetadataWithNotify(x+1, y+9, z+3, 7, 7);
		world.setBlock(x+2, y+9, z+3, Block.getBlockById(53));
		world.setBlockMetadataWithNotify(x+2, y+9, z+3, 7, 7);
		world.setBlock(x+3, y+9, z+3, Block.getBlockById(53));
		world.setBlockMetadataWithNotify(x+3, y+9, z+3, 7, 7);
		world.setBlock(x+13, y+9, z+3, Block.getBlockById(53));
		world.setBlockMetadataWithNotify(x+13, y+9, z+3, 7, 7);
		world.setBlock(x+14, y+9, z+3, Block.getBlockById(53));
		world.setBlockMetadataWithNotify(x+14, y+9, z+3, 7, 7);
		world.setBlock(x+15, y+9, z+3, Block.getBlockById(53));
		world.setBlockMetadataWithNotify(x+15, y+9, z+3, 7, 7);
		world.setBlock(x+16, y+9, z+3, Block.getBlockById(53));
		world.setBlockMetadataWithNotify(x+16, y+9, z+3, 7, 7);
		world.setBlock(x+0, y+9, z+19, Block.getBlockById(53));
		world.setBlockMetadataWithNotify(x+0, y+9, z+19, 6, 6);
		world.setBlock(x+1, y+9, z+19, Block.getBlockById(53));
		world.setBlockMetadataWithNotify(x+1, y+9, z+19, 6, 6);
		world.setBlock(x+2, y+9, z+19, Block.getBlockById(53));
		world.setBlockMetadataWithNotify(x+2, y+9, z+19, 6, 6);
		world.setBlock(x+3, y+9, z+19, Block.getBlockById(53));
		world.setBlockMetadataWithNotify(x+3, y+9, z+19, 6, 6);
		world.setBlock(x+4, y+9, z+19, Block.getBlockById(53));
		world.setBlockMetadataWithNotify(x+4, y+9, z+19, 6, 6);
		world.setBlock(x+12, y+9, z+19, Block.getBlockById(53));
		world.setBlockMetadataWithNotify(x+12, y+9, z+19, 6, 6);
		world.setBlock(x+13, y+9, z+19, Block.getBlockById(53));
		world.setBlockMetadataWithNotify(x+13, y+9, z+19, 6, 6);
		world.setBlock(x+14, y+9, z+19, Block.getBlockById(53));
		world.setBlockMetadataWithNotify(x+14, y+9, z+19, 6, 6);
		world.setBlock(x+15, y+9, z+19, Block.getBlockById(53));
		world.setBlockMetadataWithNotify(x+15, y+9, z+19, 6, 6);
		world.setBlock(x+16, y+9, z+19, Block.getBlockById(53));
		world.setBlockMetadataWithNotify(x+16, y+9, z+19, 6, 6);
		world.setBlock(x+0, y+9, z+20, Block.getBlockById(53));
		world.setBlockMetadataWithNotify(x+0, y+9, z+20, 4, 4);
		world.setBlock(x+1, y+9, z+20, Block.getBlockById(4));
		world.setBlock(x+2, y+9, z+20, Block.getBlockById(4));
		world.setBlock(x+3, y+9, z+20, Block.getBlockById(4));
		world.setBlock(x+4, y+9, z+20, Block.getBlockById(53));
		world.setBlockMetadataWithNotify(x+4, y+9, z+20, 5, 5);
		world.setBlock(x+12, y+9, z+20, Block.getBlockById(53));
		world.setBlockMetadataWithNotify(x+12, y+9, z+20, 4, 4);
		world.setBlock(x+13, y+9, z+20, Block.getBlockById(4));
		world.setBlock(x+14, y+9, z+20, Block.getBlockById(4));
		world.setBlock(x+15, y+9, z+20, Block.getBlockById(4));
		world.setBlock(x+16, y+9, z+20, Block.getBlockById(53));
		world.setBlockMetadataWithNotify(x+16, y+9, z+20, 5, 5);
		world.setBlock(x+0, y+9, z+21, Block.getBlockById(53));
		world.setBlockMetadataWithNotify(x+0, y+9, z+21, 4, 4);
		world.setBlock(x+1, y+9, z+21, Block.getBlockById(4));
		world.setBlock(x+2, y+9, z+21, Block.getBlockById(4));
		world.setBlock(x+3, y+9, z+21, Block.getBlockById(4));
		world.setBlock(x+4, y+9, z+21, Block.getBlockById(53));
		world.setBlockMetadataWithNotify(x+4, y+9, z+21, 5, 5);
		world.setBlock(x+12, y+9, z+21, Block.getBlockById(53));
		world.setBlockMetadataWithNotify(x+12, y+9, z+21, 4, 4);
		world.setBlock(x+13, y+9, z+21, Block.getBlockById(4));
		world.setBlock(x+14, y+9, z+21, Block.getBlockById(4));
		world.setBlock(x+15, y+9, z+21, Block.getBlockById(4));
		world.setBlock(x+16, y+9, z+21, Block.getBlockById(53));
		world.setBlockMetadataWithNotify(x+16, y+9, z+21, 5, 5);
		world.setBlock(x+0, y+9, z+22, Block.getBlockById(53));
		world.setBlockMetadataWithNotify(x+0, y+9, z+22, 7, 7);
		world.setBlock(x+1, y+9, z+22, Block.getBlockById(53));
		world.setBlockMetadataWithNotify(x+1, y+9, z+22, 7, 7);
		world.setBlock(x+2, y+9, z+22, Block.getBlockById(53));
		world.setBlockMetadataWithNotify(x+2, y+9, z+22, 7, 7);
		world.setBlock(x+3, y+9, z+22, Block.getBlockById(53));
		world.setBlockMetadataWithNotify(x+3, y+9, z+22, 7, 7);
		world.setBlock(x+4, y+9, z+22, Block.getBlockById(53));
		world.setBlockMetadataWithNotify(x+4, y+9, z+22, 7, 7);
		world.setBlock(x+12, y+9, z+22, Block.getBlockById(53));
		world.setBlockMetadataWithNotify(x+12, y+9, z+22, 7, 7);
		world.setBlock(x+13, y+9, z+22, Block.getBlockById(53));
		world.setBlockMetadataWithNotify(x+13, y+9, z+22, 7, 7);
		world.setBlock(x+14, y+9, z+22, Block.getBlockById(53));
		world.setBlockMetadataWithNotify(x+14, y+9, z+22, 7, 7);
		world.setBlock(x+15, y+9, z+22, Block.getBlockById(53));
		world.setBlockMetadataWithNotify(x+15, y+9, z+22, 7, 7);
		world.setBlock(x+16, y+9, z+22, Block.getBlockById(53));
		world.setBlockMetadataWithNotify(x+16, y+9, z+22, 7, 7);
		world.setBlock(x+0, y+10, z+0, Block.getBlockById(53));
		world.setBlockMetadataWithNotify(x+0, y+10, z+0, 2, 2);
		world.setBlock(x+1, y+10, z+0, Block.getBlockById(53));
		world.setBlockMetadataWithNotify(x+1, y+10, z+0, 2, 2);
		world.setBlock(x+2, y+10, z+0, Block.getBlockById(53));
		world.setBlockMetadataWithNotify(x+2, y+10, z+0, 2, 2);
		world.setBlock(x+3, y+10, z+0, Block.getBlockById(134));
		world.setBlockMetadataWithNotify(x+3, y+10, z+0, 4, 4);
		world.setBlock(x+4, y+10, z+0, Block.getBlockById(134));
		world.setBlockMetadataWithNotify(x+4, y+10, z+0, 6, 6);
		world.setBlock(x+5, y+10, z+0, Block.getBlockById(134));
		world.setBlockMetadataWithNotify(x+5, y+10, z+0, 6, 6);
		world.setBlock(x+6, y+10, z+0, Block.getBlockById(134));
		world.setBlockMetadataWithNotify(x+6, y+10, z+0, 6, 6);
		world.setBlock(x+7, y+10, z+0, Block.getBlockById(134));
		world.setBlockMetadataWithNotify(x+7, y+10, z+0, 6, 6);
		world.setBlock(x+8, y+10, z+0, Block.getBlockById(134));
		world.setBlockMetadataWithNotify(x+8, y+10, z+0, 6, 6);
		world.setBlock(x+9, y+10, z+0, Block.getBlockById(134));
		world.setBlockMetadataWithNotify(x+9, y+10, z+0, 6, 6);
		world.setBlock(x+10, y+10, z+0, Block.getBlockById(134));
		world.setBlockMetadataWithNotify(x+10, y+10, z+0, 6, 6);
		world.setBlock(x+11, y+10, z+0, Block.getBlockById(134));
		world.setBlockMetadataWithNotify(x+11, y+10, z+0, 6, 6);
		world.setBlock(x+12, y+10, z+0, Block.getBlockById(134));
		world.setBlockMetadataWithNotify(x+12, y+10, z+0, 6, 6);
		world.setBlock(x+13, y+10, z+0, Block.getBlockById(134));
		world.setBlockMetadataWithNotify(x+13, y+10, z+0, 5, 5);
		world.setBlock(x+14, y+10, z+0, Block.getBlockById(53));
		world.setBlockMetadataWithNotify(x+14, y+10, z+0, 2, 2);
		world.setBlock(x+15, y+10, z+0, Block.getBlockById(53));
		world.setBlockMetadataWithNotify(x+15, y+10, z+0, 2, 2);
		world.setBlock(x+16, y+10, z+0, Block.getBlockById(53));
		world.setBlockMetadataWithNotify(x+16, y+10, z+0, 2, 2);
		world.setBlock(x+0, y+10, z+1, Block.getBlockById(53));
		world.setBlockMetadataWithNotify(x+0, y+10, z+1, 1, 1);
		world.setBlock(x+1, y+10, z+1, Block.getBlockById(53));
		world.setBlock(x+2, y+10, z+1, Block.getBlockById(5));
		world.setBlock(x+3, y+10, z+1, Block.getBlockById(53));
		world.setBlock(x+4, y+10, z+1, Block.getBlockById(5));
		world.setBlock(x+5, y+10, z+1, Block.getBlockById(5));
		world.setBlock(x+6, y+10, z+1, Block.getBlockById(5));
		world.setBlock(x+7, y+10, z+1, Block.getBlockById(5));
		world.setBlock(x+8, y+10, z+1, Block.getBlockById(5));
		world.setBlock(x+9, y+10, z+1, Block.getBlockById(5));
		world.setBlock(x+10, y+10, z+1, Block.getBlockById(5));
		world.setBlock(x+11, y+10, z+1, Block.getBlockById(5));
		world.setBlock(x+12, y+10, z+1, Block.getBlockById(5));
		world.setBlock(x+13, y+10, z+1, Block.getBlockById(5));
		world.setBlock(x+14, y+10, z+1, Block.getBlockById(5));
		world.setBlock(x+15, y+10, z+1, Block.getBlockById(5));
		world.setBlock(x+16, y+10, z+1, Block.getBlockById(53));
		world.setBlockMetadataWithNotify(x+16, y+10, z+1, 1, 1);
		world.setBlock(x+0, y+10, z+2, Block.getBlockById(53));
		world.setBlockMetadataWithNotify(x+0, y+10, z+2, 1, 1);
		world.setBlock(x+1, y+10, z+2, Block.getBlockById(53));
		world.setBlock(x+2, y+10, z+2, Block.getBlockById(5));
		world.setBlock(x+3, y+10, z+2, Block.getBlockById(53));
		world.setBlockMetadataWithNotify(x+3, y+10, z+2, 1, 1);
		world.setBlock(x+13, y+10, z+2, Block.getBlockById(53));
		world.setBlock(x+14, y+10, z+2, Block.getBlockById(5));
		world.setBlock(x+15, y+10, z+2, Block.getBlockById(5));
		world.setBlock(x+16, y+10, z+2, Block.getBlockById(53));
		world.setBlockMetadataWithNotify(x+16, y+10, z+2, 1, 1);
		world.setBlock(x+0, y+10, z+3, Block.getBlockById(53));
		world.setBlockMetadataWithNotify(x+0, y+10, z+3, 3, 3);
		world.setBlock(x+1, y+10, z+3, Block.getBlockById(53));
		world.setBlockMetadataWithNotify(x+1, y+10, z+3, 3, 3);
		world.setBlock(x+2, y+10, z+3, Block.getBlockById(5));
		world.setBlock(x+3, y+10, z+3, Block.getBlockById(53));
		world.setBlockMetadataWithNotify(x+3, y+10, z+3, 3, 3);
		world.setBlock(x+13, y+10, z+3, Block.getBlockById(53));
		world.setBlockMetadataWithNotify(x+13, y+10, z+3, 3, 3);
		world.setBlock(x+14, y+10, z+3, Block.getBlockById(5));
		world.setBlock(x+15, y+10, z+3, Block.getBlockById(53));
		world.setBlockMetadataWithNotify(x+15, y+10, z+3, 3, 3);
		world.setBlock(x+16, y+10, z+3, Block.getBlockById(53));
		world.setBlockMetadataWithNotify(x+16, y+10, z+3, 3, 3);
		world.setBlock(x+1, y+10, z+4, Block.getBlockById(134));
		world.setBlock(x+2, y+10, z+4, Block.getBlockById(5));
		world.setBlock(x+14, y+10, z+4, Block.getBlockById(5));
		world.setBlock(x+15, y+10, z+4, Block.getBlockById(134));
		world.setBlockMetadataWithNotify(x+15, y+10, z+4, 1, 1);
		world.setBlock(x+1, y+10, z+5, Block.getBlockById(134));
		world.setBlock(x+2, y+10, z+5, Block.getBlockById(5));
		world.setBlock(x+14, y+10, z+5, Block.getBlockById(5));
		world.setBlock(x+15, y+10, z+5, Block.getBlockById(134));
		world.setBlockMetadataWithNotify(x+15, y+10, z+5, 1, 1);
		world.setBlock(x+1, y+10, z+6, Block.getBlockById(134));
		world.setBlock(x+2, y+10, z+6, Block.getBlockById(5));
		world.setBlock(x+14, y+10, z+6, Block.getBlockById(5));
		world.setBlock(x+15, y+10, z+6, Block.getBlockById(134));
		world.setBlockMetadataWithNotify(x+15, y+10, z+6, 1, 1);
		world.setBlock(x+1, y+10, z+7, Block.getBlockById(134));
		world.setBlock(x+2, y+10, z+7, Block.getBlockById(5));
		world.setBlock(x+14, y+10, z+7, Block.getBlockById(5));
		world.setBlock(x+15, y+10, z+7, Block.getBlockById(134));
		world.setBlockMetadataWithNotify(x+15, y+10, z+7, 1, 1);
		world.setBlock(x+1, y+10, z+8, Block.getBlockById(134));
		world.setBlock(x+2, y+10, z+8, Block.getBlockById(5));
		world.setBlock(x+14, y+10, z+8, Block.getBlockById(5));
		world.setBlock(x+15, y+10, z+8, Block.getBlockById(134));
		world.setBlockMetadataWithNotify(x+15, y+10, z+8, 1, 1);
		world.setBlock(x+1, y+10, z+9, Block.getBlockById(134));
		world.setBlock(x+2, y+10, z+9, Block.getBlockById(5));
		world.setBlock(x+14, y+10, z+9, Block.getBlockById(5));
		world.setBlock(x+15, y+10, z+9, Block.getBlockById(134));
		world.setBlockMetadataWithNotify(x+15, y+10, z+9, 1, 1);
		world.setBlock(x+1, y+10, z+10, Block.getBlockById(134));
		world.setBlock(x+2, y+10, z+10, Block.getBlockById(5));
		world.setBlock(x+14, y+10, z+10, Block.getBlockById(5));
		world.setBlock(x+15, y+10, z+10, Block.getBlockById(134));
		world.setBlockMetadataWithNotify(x+15, y+10, z+10, 1, 1);
		world.setBlock(x+1, y+10, z+11, Block.getBlockById(134));
		world.setBlock(x+2, y+10, z+11, Block.getBlockById(5));
		world.setBlock(x+14, y+10, z+11, Block.getBlockById(5));
		world.setBlock(x+15, y+10, z+11, Block.getBlockById(134));
		world.setBlockMetadataWithNotify(x+15, y+10, z+11, 1, 1);
		world.setBlock(x+1, y+10, z+12, Block.getBlockById(134));
		world.setBlock(x+2, y+10, z+12, Block.getBlockById(5));
		world.setBlock(x+14, y+10, z+12, Block.getBlockById(5));
		world.setBlock(x+15, y+10, z+12, Block.getBlockById(134));
		world.setBlockMetadataWithNotify(x+15, y+10, z+12, 1, 1);
		world.setBlock(x+1, y+10, z+13, Block.getBlockById(134));
		world.setBlock(x+2, y+10, z+13, Block.getBlockById(5));
		world.setBlock(x+14, y+10, z+13, Block.getBlockById(5));
		world.setBlock(x+15, y+10, z+13, Block.getBlockById(134));
		world.setBlockMetadataWithNotify(x+15, y+10, z+13, 1, 1);
		world.setBlock(x+1, y+10, z+14, Block.getBlockById(134));
		world.setBlock(x+2, y+10, z+14, Block.getBlockById(5));
		world.setBlock(x+14, y+10, z+14, Block.getBlockById(5));
		world.setBlock(x+15, y+10, z+14, Block.getBlockById(134));
		world.setBlockMetadataWithNotify(x+15, y+10, z+14, 1, 1);
		world.setBlock(x+1, y+10, z+15, Block.getBlockById(134));
		world.setBlock(x+2, y+10, z+15, Block.getBlockById(5));
		world.setBlock(x+14, y+10, z+15, Block.getBlockById(5));
		world.setBlock(x+15, y+10, z+15, Block.getBlockById(134));
		world.setBlockMetadataWithNotify(x+15, y+10, z+15, 1, 1);
		world.setBlock(x+1, y+10, z+16, Block.getBlockById(134));
		world.setBlock(x+2, y+10, z+16, Block.getBlockById(5));
		world.setBlock(x+14, y+10, z+16, Block.getBlockById(5));
		world.setBlock(x+15, y+10, z+16, Block.getBlockById(134));
		world.setBlockMetadataWithNotify(x+15, y+10, z+16, 1, 1);
		world.setBlock(x+1, y+10, z+17, Block.getBlockById(134));
		world.setBlock(x+2, y+10, z+17, Block.getBlockById(5));
		world.setBlock(x+14, y+10, z+17, Block.getBlockById(5));
		world.setBlock(x+15, y+10, z+17, Block.getBlockById(134));
		world.setBlockMetadataWithNotify(x+15, y+10, z+17, 1, 1);
		world.setBlock(x+1, y+10, z+18, Block.getBlockById(134));
		world.setBlock(x+2, y+10, z+18, Block.getBlockById(5));
		world.setBlock(x+14, y+10, z+18, Block.getBlockById(5));
		world.setBlock(x+15, y+10, z+18, Block.getBlockById(134));
		world.setBlockMetadataWithNotify(x+15, y+10, z+18, 1, 1);
		world.setBlock(x+0, y+10, z+19, Block.getBlockById(53));
		world.setBlockMetadataWithNotify(x+0, y+10, z+19, 2, 2);
		world.setBlock(x+1, y+10, z+19, Block.getBlockById(5));
		world.setBlock(x+2, y+10, z+19, Block.getBlockById(5));
		world.setBlock(x+3, y+10, z+19, Block.getBlockById(5));
		world.setBlock(x+4, y+10, z+19, Block.getBlockById(53));
		world.setBlockMetadataWithNotify(x+4, y+10, z+19, 2, 2);
		world.setBlock(x+12, y+10, z+19, Block.getBlockById(53));
		world.setBlockMetadataWithNotify(x+12, y+10, z+19, 2, 2);
		world.setBlock(x+13, y+10, z+19, Block.getBlockById(5));
		world.setBlock(x+14, y+10, z+19, Block.getBlockById(5));
		world.setBlock(x+15, y+10, z+19, Block.getBlockById(5));
		world.setBlock(x+16, y+10, z+19, Block.getBlockById(53));
		world.setBlockMetadataWithNotify(x+16, y+10, z+19, 2, 2);
		world.setBlock(x+0, y+10, z+20, Block.getBlockById(53));
		world.setBlockMetadataWithNotify(x+0, y+10, z+20, 1, 1);
		world.setBlock(x+1, y+10, z+20, Block.getBlockById(53));
		world.setBlock(x+2, y+10, z+20, Block.getBlockById(5));
		world.setBlock(x+3, y+10, z+20, Block.getBlockById(53));
		world.setBlock(x+4, y+10, z+20, Block.getBlockById(53));
		world.setBlockMetadataWithNotify(x+4, y+10, z+20, 5, 5);
		world.setBlock(x+12, y+10, z+20, Block.getBlockById(53));
		world.setBlockMetadataWithNotify(x+12, y+10, z+20, 4, 4);
		world.setBlock(x+13, y+10, z+20, Block.getBlockById(53));
		world.setBlockMetadataWithNotify(x+13, y+10, z+20, 1, 1);
		world.setBlock(x+14, y+10, z+20, Block.getBlockById(5));
		world.setBlock(x+15, y+10, z+20, Block.getBlockById(53));
		world.setBlockMetadataWithNotify(x+15, y+10, z+20, 1, 1);
		world.setBlock(x+16, y+10, z+20, Block.getBlockById(53));
		world.setBlock(x+0, y+10, z+21, Block.getBlockById(53));
		world.setBlockMetadataWithNotify(x+0, y+10, z+21, 1, 1);
		world.setBlock(x+1, y+10, z+21, Block.getBlockById(53));
		world.setBlock(x+2, y+10, z+21, Block.getBlockById(5));
		world.setBlock(x+3, y+10, z+21, Block.getBlockById(53));
		world.setBlock(x+4, y+10, z+21, Block.getBlockById(53));
		world.setBlockMetadataWithNotify(x+4, y+10, z+21, 5, 5);
		world.setBlock(x+12, y+10, z+21, Block.getBlockById(53));
		world.setBlockMetadataWithNotify(x+12, y+10, z+21, 4, 4);
		world.setBlock(x+13, y+10, z+21, Block.getBlockById(53));
		world.setBlockMetadataWithNotify(x+13, y+10, z+21, 1, 1);
		world.setBlock(x+14, y+10, z+21, Block.getBlockById(5));
		world.setBlock(x+15, y+10, z+21, Block.getBlockById(53));
		world.setBlockMetadataWithNotify(x+15, y+10, z+21, 1, 1);
		world.setBlock(x+16, y+10, z+21, Block.getBlockById(53));
		world.setBlock(x+0, y+10, z+22, Block.getBlockById(53));
		world.setBlockMetadataWithNotify(x+0, y+10, z+22, 3, 3);
		world.setBlock(x+1, y+10, z+22, Block.getBlockById(53));
		world.setBlockMetadataWithNotify(x+1, y+10, z+22, 3, 3);
		world.setBlock(x+2, y+10, z+22, Block.getBlockById(53));
		world.setBlockMetadataWithNotify(x+2, y+10, z+22, 3, 3);
		world.setBlock(x+3, y+10, z+22, Block.getBlockById(53));
		world.setBlockMetadataWithNotify(x+3, y+10, z+22, 3, 3);
		world.setBlock(x+4, y+10, z+22, Block.getBlockById(53));
		world.setBlockMetadataWithNotify(x+4, y+10, z+22, 3, 3);
		world.setBlock(x+12, y+10, z+22, Block.getBlockById(53));
		world.setBlockMetadataWithNotify(x+12, y+10, z+22, 3, 3);
		world.setBlock(x+13, y+10, z+22, Block.getBlockById(53));
		world.setBlockMetadataWithNotify(x+13, y+10, z+22, 3, 3);
		world.setBlock(x+14, y+10, z+22, Block.getBlockById(53));
		world.setBlockMetadataWithNotify(x+14, y+10, z+22, 3, 3);
		world.setBlock(x+15, y+10, z+22, Block.getBlockById(53));
		world.setBlockMetadataWithNotify(x+15, y+10, z+22, 3, 3);
		world.setBlock(x+16, y+10, z+22, Block.getBlockById(53));
		world.setBlockMetadataWithNotify(x+16, y+10, z+22, 3, 3);
		world.setBlock(x+3, y+11, z+0, Block.getBlockById(134));
		world.setBlockMetadataWithNotify(x+3, y+11, z+0, 4, 4);
		world.setBlock(x+4, y+11, z+0, Block.getBlockById(134));
		world.setBlockMetadataWithNotify(x+4, y+11, z+0, 6, 6);
		world.setBlock(x+5, y+11, z+0, Block.getBlockById(134));
		world.setBlockMetadataWithNotify(x+5, y+11, z+0, 6, 6);
		world.setBlock(x+6, y+11, z+0, Block.getBlockById(134));
		world.setBlockMetadataWithNotify(x+6, y+11, z+0, 6, 6);
		world.setBlock(x+7, y+11, z+0, Block.getBlockById(134));
		world.setBlockMetadataWithNotify(x+7, y+11, z+0, 6, 6);
		world.setBlock(x+8, y+11, z+0, Block.getBlockById(134));
		world.setBlockMetadataWithNotify(x+8, y+11, z+0, 6, 6);
		world.setBlock(x+9, y+11, z+0, Block.getBlockById(134));
		world.setBlockMetadataWithNotify(x+9, y+11, z+0, 6, 6);
		world.setBlock(x+10, y+11, z+0, Block.getBlockById(134));
		world.setBlockMetadataWithNotify(x+10, y+11, z+0, 6, 6);
		world.setBlock(x+11, y+11, z+0, Block.getBlockById(134));
		world.setBlockMetadataWithNotify(x+11, y+11, z+0, 6, 6);
		world.setBlock(x+12, y+11, z+0, Block.getBlockById(134));
		world.setBlockMetadataWithNotify(x+12, y+11, z+0, 6, 6);
		world.setBlock(x+13, y+11, z+0, Block.getBlockById(134));
		world.setBlockMetadataWithNotify(x+13, y+11, z+0, 5, 5);
		world.setBlock(x+1, y+11, z+1, Block.getBlockById(134));
		world.setBlock(x+2, y+11, z+1, Block.getBlockById(5));
		world.setBlock(x+3, y+11, z+1, Block.getBlockById(5));
		world.setBlock(x+4, y+11, z+1, Block.getBlockById(5));
		world.setBlock(x+5, y+11, z+1, Block.getBlockById(5));
		world.setBlock(x+6, y+11, z+1, Block.getBlockById(5));
		world.setBlock(x+7, y+11, z+1, Block.getBlockById(5));
		world.setBlock(x+8, y+11, z+1, Block.getBlockById(5));
		world.setBlock(x+9, y+11, z+1, Block.getBlockById(5));
		world.setBlock(x+10, y+11, z+1, Block.getBlockById(5));
		world.setBlock(x+11, y+11, z+1, Block.getBlockById(5));
		world.setBlock(x+12, y+11, z+1, Block.getBlockById(5));
		world.setBlock(x+13, y+11, z+1, Block.getBlockById(5));
		world.setBlock(x+14, y+11, z+1, Block.getBlockById(5));
		world.setBlock(x+15, y+11, z+1, Block.getBlockById(134));
		world.setBlockMetadataWithNotify(x+15, y+11, z+1, 1, 1);
		world.setBlock(x+1, y+11, z+2, Block.getBlockById(134));
		world.setBlock(x+2, y+11, z+2, Block.getBlockById(5));
		world.setBlock(x+14, y+11, z+2, Block.getBlockById(5));
		world.setBlock(x+15, y+11, z+2, Block.getBlockById(134));
		world.setBlockMetadataWithNotify(x+15, y+11, z+2, 1, 1);
		world.setBlock(x+1, y+11, z+3, Block.getBlockById(134));
		world.setBlock(x+2, y+11, z+3, Block.getBlockById(5));
		world.setBlock(x+14, y+11, z+3, Block.getBlockById(5));
		world.setBlock(x+15, y+11, z+3, Block.getBlockById(134));
		world.setBlockMetadataWithNotify(x+15, y+11, z+3, 1, 1);
		world.setBlock(x+1, y+11, z+4, Block.getBlockById(134));
		world.setBlock(x+2, y+11, z+4, Block.getBlockById(5));
		world.setBlock(x+14, y+11, z+4, Block.getBlockById(5));
		world.setBlock(x+15, y+11, z+4, Block.getBlockById(134));
		world.setBlockMetadataWithNotify(x+15, y+11, z+4, 1, 1);
		world.setBlock(x+1, y+11, z+5, Block.getBlockById(134));
		world.setBlock(x+2, y+11, z+5, Block.getBlockById(5));
		world.setBlock(x+14, y+11, z+5, Block.getBlockById(5));
		world.setBlock(x+15, y+11, z+5, Block.getBlockById(134));
		world.setBlockMetadataWithNotify(x+15, y+11, z+5, 1, 1);
		world.setBlock(x+1, y+11, z+6, Block.getBlockById(134));
		world.setBlock(x+2, y+11, z+6, Block.getBlockById(5));
		world.setBlock(x+14, y+11, z+6, Block.getBlockById(5));
		world.setBlock(x+15, y+11, z+6, Block.getBlockById(134));
		world.setBlockMetadataWithNotify(x+15, y+11, z+6, 1, 1);
		world.setBlock(x+1, y+11, z+7, Block.getBlockById(134));
		world.setBlock(x+2, y+11, z+7, Block.getBlockById(5));
		world.setBlock(x+14, y+11, z+7, Block.getBlockById(5));
		world.setBlock(x+15, y+11, z+7, Block.getBlockById(134));
		world.setBlockMetadataWithNotify(x+15, y+11, z+7, 1, 1);
		world.setBlock(x+1, y+11, z+8, Block.getBlockById(134));
		world.setBlock(x+2, y+11, z+8, Block.getBlockById(5));
		world.setBlock(x+14, y+11, z+8, Block.getBlockById(5));
		world.setBlock(x+15, y+11, z+8, Block.getBlockById(134));
		world.setBlockMetadataWithNotify(x+15, y+11, z+8, 1, 1);
		world.setBlock(x+1, y+11, z+9, Block.getBlockById(134));
		world.setBlock(x+2, y+11, z+9, Block.getBlockById(5));
		world.setBlock(x+14, y+11, z+9, Block.getBlockById(5));
		world.setBlock(x+15, y+11, z+9, Block.getBlockById(134));
		world.setBlockMetadataWithNotify(x+15, y+11, z+9, 1, 1);
		world.setBlock(x+1, y+11, z+10, Block.getBlockById(134));
		world.setBlock(x+2, y+11, z+10, Block.getBlockById(5));
		world.setBlock(x+14, y+11, z+10, Block.getBlockById(5));
		world.setBlock(x+15, y+11, z+10, Block.getBlockById(134));
		world.setBlockMetadataWithNotify(x+15, y+11, z+10, 1, 1);
		world.setBlock(x+1, y+11, z+11, Block.getBlockById(134));
		world.setBlock(x+2, y+11, z+11, Block.getBlockById(5));
		world.setBlock(x+14, y+11, z+11, Block.getBlockById(5));
		world.setBlock(x+15, y+11, z+11, Block.getBlockById(134));
		world.setBlockMetadataWithNotify(x+15, y+11, z+11, 1, 1);
		world.setBlock(x+1, y+11, z+12, Block.getBlockById(134));
		world.setBlock(x+2, y+11, z+12, Block.getBlockById(5));
		world.setBlock(x+14, y+11, z+12, Block.getBlockById(5));
		world.setBlock(x+15, y+11, z+12, Block.getBlockById(134));
		world.setBlockMetadataWithNotify(x+15, y+11, z+12, 1, 1);
		world.setBlock(x+1, y+11, z+13, Block.getBlockById(134));
		world.setBlock(x+2, y+11, z+13, Block.getBlockById(5));
		world.setBlock(x+14, y+11, z+13, Block.getBlockById(5));
		world.setBlock(x+15, y+11, z+13, Block.getBlockById(134));
		world.setBlockMetadataWithNotify(x+15, y+11, z+13, 1, 1);
		world.setBlock(x+1, y+11, z+14, Block.getBlockById(134));
		world.setBlock(x+2, y+11, z+14, Block.getBlockById(5));
		world.setBlock(x+14, y+11, z+14, Block.getBlockById(5));
		world.setBlock(x+15, y+11, z+14, Block.getBlockById(134));
		world.setBlockMetadataWithNotify(x+15, y+11, z+14, 1, 1);
		world.setBlock(x+1, y+11, z+15, Block.getBlockById(134));
		world.setBlock(x+2, y+11, z+15, Block.getBlockById(5));
		world.setBlock(x+14, y+11, z+15, Block.getBlockById(5));
		world.setBlock(x+15, y+11, z+15, Block.getBlockById(134));
		world.setBlockMetadataWithNotify(x+15, y+11, z+15, 1, 1);
		world.setBlock(x+1, y+11, z+16, Block.getBlockById(134));
		world.setBlock(x+2, y+11, z+16, Block.getBlockById(5));
		world.setBlock(x+14, y+11, z+16, Block.getBlockById(5));
		world.setBlock(x+15, y+11, z+16, Block.getBlockById(134));
		world.setBlockMetadataWithNotify(x+15, y+11, z+16, 1, 1);
		world.setBlock(x+1, y+11, z+17, Block.getBlockById(134));
		world.setBlock(x+2, y+11, z+17, Block.getBlockById(5));
		world.setBlock(x+14, y+11, z+17, Block.getBlockById(5));
		world.setBlock(x+15, y+11, z+17, Block.getBlockById(134));
		world.setBlockMetadataWithNotify(x+15, y+11, z+17, 1, 1);
		world.setBlock(x+1, y+11, z+18, Block.getBlockById(134));
		world.setBlock(x+2, y+11, z+18, Block.getBlockById(5));
		world.setBlock(x+14, y+11, z+18, Block.getBlockById(5));
		world.setBlock(x+15, y+11, z+18, Block.getBlockById(134));
		world.setBlockMetadataWithNotify(x+15, y+11, z+18, 1, 1);
		world.setBlock(x+1, y+11, z+19, Block.getBlockById(134));
		world.setBlock(x+2, y+11, z+19, Block.getBlockById(5));
		world.setBlock(x+3, y+11, z+19, Block.getBlockById(5));
		world.setBlock(x+4, y+11, z+19, Block.getBlockById(113));
		world.setBlock(x+5, y+11, z+19, Block.getBlockById(113));
		world.setBlock(x+11, y+11, z+19, Block.getBlockById(113));
		world.setBlock(x+12, y+11, z+19, Block.getBlockById(113));
		world.setBlock(x+13, y+11, z+19, Block.getBlockById(5));
		world.setBlock(x+14, y+11, z+19, Block.getBlockById(5));
		world.setBlockMetadataWithNotify(x+14, y+11, z+19, 1, 1);
		world.setBlock(x+15, y+11, z+19, Block.getBlockById(134));
		world.setBlockMetadataWithNotify(x+15, y+11, z+19, 1, 1);
		world.setBlock(x+1, y+11, z+20, Block.getBlockById(134));
		world.setBlock(x+2, y+11, z+20, Block.getBlockById(113));
		world.setBlock(x+3, y+11, z+20, Block.getBlockById(113));
		world.setBlock(x+4, y+11, z+20, Block.getBlockById(53));
		world.setBlock(x+5, y+11, z+20, Block.getBlockById(53));
		world.setBlockMetadataWithNotify(x+5, y+11, z+20, 5, 5);
		world.setBlock(x+11, y+11, z+20, Block.getBlockById(53));
		world.setBlockMetadataWithNotify(x+11, y+11, z+20, 4, 4);
		world.setBlock(x+12, y+11, z+20, Block.getBlockById(53));
		world.setBlockMetadataWithNotify(x+12, y+11, z+20, 1, 1);
		world.setBlock(x+13, y+11, z+20, Block.getBlockById(113));
		world.setBlock(x+14, y+11, z+20, Block.getBlockById(113));
		world.setBlock(x+15, y+11, z+20, Block.getBlockById(134));
		world.setBlockMetadataWithNotify(x+15, y+11, z+20, 1, 1);
		world.setBlock(x+2, y+11, z+21, Block.getBlockById(5));
		world.setBlock(x+3, y+11, z+21, Block.getBlockById(113));
		world.setBlock(x+4, y+11, z+21, Block.getBlockById(53));
		world.setBlock(x+5, y+11, z+21, Block.getBlockById(53));
		world.setBlockMetadataWithNotify(x+5, y+11, z+21, 5, 5);
		world.setBlock(x+11, y+11, z+21, Block.getBlockById(53));
		world.setBlockMetadataWithNotify(x+11, y+11, z+21, 4, 4);
		world.setBlock(x+12, y+11, z+21, Block.getBlockById(53));
		world.setBlockMetadataWithNotify(x+12, y+11, z+21, 1, 1);
		world.setBlock(x+13, y+11, z+21, Block.getBlockById(113));
		world.setBlock(x+14, y+11, z+21, Block.getBlockById(5));
		world.setBlock(x+3, y+12, z+0, Block.getBlockById(53));
		world.setBlockMetadataWithNotify(x+3, y+12, z+0, 2, 2);
		world.setBlock(x+4, y+12, z+0, Block.getBlockById(134));
		world.setBlock(x+12, y+12, z+0, Block.getBlockById(134));
		world.setBlockMetadataWithNotify(x+12, y+12, z+0, 1, 1);
		world.setBlock(x+13, y+12, z+0, Block.getBlockById(53));
		world.setBlockMetadataWithNotify(x+13, y+12, z+0, 2, 2);
		world.setBlock(x+2, y+12, z+1, Block.getBlockById(5));
		world.setBlock(x+3, y+12, z+1, Block.getBlockById(5));
		world.setBlock(x+4, y+12, z+1, Block.getBlockById(5));
		world.setBlock(x+5, y+12, z+1, Block.getBlockById(113));
		world.setBlock(x+6, y+12, z+1, Block.getBlockById(113));
		world.setBlock(x+7, y+12, z+1, Block.getBlockById(113));
		world.setBlock(x+8, y+12, z+1, Block.getBlockById(113));
		world.setBlock(x+9, y+12, z+1, Block.getBlockById(113));
		world.setBlock(x+10, y+12, z+1, Block.getBlockById(113));
		world.setBlock(x+11, y+12, z+1, Block.getBlockById(113));
		world.setBlock(x+12, y+12, z+1, Block.getBlockById(5));
		world.setBlock(x+13, y+12, z+1, Block.getBlockById(5));
		world.setBlock(x+14, y+12, z+1, Block.getBlockById(5));
		world.setBlock(x+2, y+12, z+2, Block.getBlockById(134));
		world.setBlock(x+14, y+12, z+2, Block.getBlockById(134));
		world.setBlockMetadataWithNotify(x+14, y+12, z+2, 1, 1);
		world.setBlock(x+2, y+12, z+3, Block.getBlockById(134));
		world.setBlock(x+14, y+12, z+3, Block.getBlockById(134));
		world.setBlockMetadataWithNotify(x+14, y+12, z+3, 1, 1);
		world.setBlock(x+2, y+12, z+4, Block.getBlockById(5));
		world.setBlock(x+14, y+12, z+4, Block.getBlockById(5));
		world.setBlock(x+2, y+12, z+5, Block.getBlockById(5));
		world.setBlock(x+14, y+12, z+5, Block.getBlockById(5));
		world.setBlock(x+2, y+12, z+6, Block.getBlockById(5));
		world.setBlock(x+14, y+12, z+6, Block.getBlockById(5));
		world.setBlock(x+2, y+12, z+7, Block.getBlockById(5));
		world.setBlock(x+14, y+12, z+7, Block.getBlockById(5));
		world.setBlock(x+2, y+12, z+8, Block.getBlockById(5));
		world.setBlock(x+14, y+12, z+8, Block.getBlockById(5));
		world.setBlock(x+2, y+12, z+9, Block.getBlockById(5));
		world.setBlock(x+14, y+12, z+9, Block.getBlockById(5));
		world.setBlock(x+2, y+12, z+10, Block.getBlockById(5));
		world.setBlock(x+14, y+12, z+10, Block.getBlockById(5));
		world.setBlock(x+2, y+12, z+11, Block.getBlockById(5));
		world.setBlock(x+14, y+12, z+11, Block.getBlockById(5));
		world.setBlock(x+2, y+12, z+12, Block.getBlockById(5));
		world.setBlock(x+14, y+12, z+12, Block.getBlockById(5));
		world.setBlock(x+2, y+12, z+13, Block.getBlockById(5));
		world.setBlock(x+14, y+12, z+13, Block.getBlockById(5));
		world.setBlock(x+2, y+12, z+14, Block.getBlockById(5));
		world.setBlock(x+14, y+12, z+14, Block.getBlockById(5));
		world.setBlock(x+2, y+12, z+15, Block.getBlockById(5));
		world.setBlock(x+14, y+12, z+15, Block.getBlockById(5));
		world.setBlock(x+2, y+12, z+16, Block.getBlockById(5));
		world.setBlock(x+14, y+12, z+16, Block.getBlockById(5));
		world.setBlock(x+2, y+12, z+17, Block.getBlockById(5));
		world.setBlock(x+14, y+12, z+17, Block.getBlockById(5));
		world.setBlock(x+2, y+12, z+18, Block.getBlockById(5));
		world.setBlock(x+14, y+12, z+18, Block.getBlockById(5));
		world.setBlock(x+2, y+12, z+19, Block.getBlockById(134));
		world.setBlock(x+3, y+12, z+19, Block.getBlockById(5));
		world.setBlockMetadataWithNotify(x+3, y+12, z+19, 1, 1);
		world.setBlock(x+4, y+12, z+19, Block.getBlockById(113));
		world.setBlock(x+5, y+12, z+19, Block.getBlockById(113));
		world.setBlock(x+11, y+12, z+19, Block.getBlockById(113));
		world.setBlock(x+12, y+12, z+19, Block.getBlockById(113));
		world.setBlock(x+13, y+12, z+19, Block.getBlockById(5));
		world.setBlockMetadataWithNotify(x+13, y+12, z+19, 1, 1);
		world.setBlock(x+14, y+12, z+19, Block.getBlockById(134));
		world.setBlockMetadataWithNotify(x+14, y+12, z+19, 1, 1);
		world.setBlock(x+2, y+12, z+20, Block.getBlockById(134));
		world.setBlock(x+3, y+12, z+20, Block.getBlockById(113));
		world.setBlock(x+4, y+12, z+20, Block.getBlockById(113));
		world.setBlock(x+5, y+12, z+20, Block.getBlockById(5));
		world.setBlock(x+11, y+12, z+20, Block.getBlockById(5));
		world.setBlock(x+12, y+12, z+20, Block.getBlockById(113));
		world.setBlock(x+13, y+12, z+20, Block.getBlockById(113));
		world.setBlock(x+14, y+12, z+20, Block.getBlockById(134));
		world.setBlockMetadataWithNotify(x+14, y+12, z+20, 1, 1);
		world.setBlock(x+2, y+12, z+21, Block.getBlockById(53));
		world.setBlock(x+3, y+12, z+21, Block.getBlockById(53));
		world.setBlockMetadataWithNotify(x+3, y+12, z+21, 5, 5);
		world.setBlock(x+4, y+12, z+21, Block.getBlockById(113));
		world.setBlock(x+5, y+12, z+21, Block.getBlockById(5));
		world.setBlock(x+11, y+12, z+21, Block.getBlockById(5));
		world.setBlock(x+12, y+12, z+21, Block.getBlockById(113));
		world.setBlock(x+13, y+12, z+21, Block.getBlockById(53));
		world.setBlockMetadataWithNotify(x+13, y+12, z+21, 4, 4);
		world.setBlock(x+14, y+12, z+21, Block.getBlockById(53));
		world.setBlockMetadataWithNotify(x+14, y+12, z+21, 1, 1);
		world.setBlock(x+4, y+13, z+0, Block.getBlockById(134));
		world.setBlock(x+12, y+13, z+0, Block.getBlockById(134));
		world.setBlockMetadataWithNotify(x+12, y+13, z+0, 1, 1);
		world.setBlock(x+2, y+13, z+1, Block.getBlockById(134));
		world.setBlock(x+3, y+13, z+1, Block.getBlockById(5));
		world.setBlock(x+4, y+13, z+1, Block.getBlockById(5));
		world.setBlock(x+5, y+13, z+1, Block.getBlockById(113));
		world.setBlock(x+6, y+13, z+1, Block.getBlockById(113));
		world.setBlock(x+7, y+13, z+1, Block.getBlockById(113));
		world.setBlock(x+8, y+13, z+1, Block.getBlockById(113));
		world.setBlock(x+9, y+13, z+1, Block.getBlockById(113));
		world.setBlock(x+10, y+13, z+1, Block.getBlockById(113));
		world.setBlock(x+11, y+13, z+1, Block.getBlockById(113));
		world.setBlock(x+12, y+13, z+1, Block.getBlockById(5));
		world.setBlock(x+13, y+13, z+1, Block.getBlockById(5));
		world.setBlock(x+14, y+13, z+1, Block.getBlockById(134));
		world.setBlockMetadataWithNotify(x+14, y+13, z+1, 1, 1);
		world.setBlock(x+2, y+13, z+2, Block.getBlockById(134));
		world.setBlock(x+14, y+13, z+2, Block.getBlockById(134));
		world.setBlockMetadataWithNotify(x+14, y+13, z+2, 1, 1);
		world.setBlock(x+2, y+13, z+3, Block.getBlockById(134));
		world.setBlock(x+14, y+13, z+3, Block.getBlockById(134));
		world.setBlockMetadataWithNotify(x+14, y+13, z+3, 1, 1);
		world.setBlock(x+2, y+13, z+4, Block.getBlockById(134));
		world.setBlock(x+14, y+13, z+4, Block.getBlockById(134));
		world.setBlockMetadataWithNotify(x+14, y+13, z+4, 1, 1);
		world.setBlock(x+2, y+13, z+5, Block.getBlockById(134));
		world.setBlock(x+14, y+13, z+5, Block.getBlockById(134));
		world.setBlockMetadataWithNotify(x+14, y+13, z+5, 1, 1);
		world.setBlock(x+2, y+13, z+6, Block.getBlockById(134));
		world.setBlock(x+14, y+13, z+6, Block.getBlockById(134));
		world.setBlockMetadataWithNotify(x+14, y+13, z+6, 1, 1);
		world.setBlock(x+2, y+13, z+7, Block.getBlockById(134));
		world.setBlock(x+14, y+13, z+7, Block.getBlockById(134));
		world.setBlockMetadataWithNotify(x+14, y+13, z+7, 1, 1);
		world.setBlock(x+2, y+13, z+8, Block.getBlockById(134));
		world.setBlock(x+14, y+13, z+8, Block.getBlockById(134));
		world.setBlockMetadataWithNotify(x+14, y+13, z+8, 1, 1);
		world.setBlock(x+2, y+13, z+9, Block.getBlockById(134));
		world.setBlock(x+14, y+13, z+9, Block.getBlockById(134));
		world.setBlockMetadataWithNotify(x+14, y+13, z+9, 1, 1);
		world.setBlock(x+2, y+13, z+10, Block.getBlockById(134));
		world.setBlock(x+14, y+13, z+10, Block.getBlockById(134));
		world.setBlockMetadataWithNotify(x+14, y+13, z+10, 1, 1);
		world.setBlock(x+2, y+13, z+11, Block.getBlockById(134));
		world.setBlock(x+14, y+13, z+11, Block.getBlockById(134));
		world.setBlockMetadataWithNotify(x+14, y+13, z+11, 1, 1);
		world.setBlock(x+2, y+13, z+12, Block.getBlockById(134));
		world.setBlock(x+14, y+13, z+12, Block.getBlockById(134));
		world.setBlockMetadataWithNotify(x+14, y+13, z+12, 1, 1);
		world.setBlock(x+2, y+13, z+13, Block.getBlockById(134));
		world.setBlock(x+14, y+13, z+13, Block.getBlockById(134));
		world.setBlockMetadataWithNotify(x+14, y+13, z+13, 1, 1);
		world.setBlock(x+2, y+13, z+14, Block.getBlockById(134));
		world.setBlock(x+14, y+13, z+14, Block.getBlockById(134));
		world.setBlockMetadataWithNotify(x+14, y+13, z+14, 1, 1);
		world.setBlock(x+2, y+13, z+15, Block.getBlockById(134));
		world.setBlock(x+14, y+13, z+15, Block.getBlockById(134));
		world.setBlockMetadataWithNotify(x+14, y+13, z+15, 1, 1);
		world.setBlock(x+2, y+13, z+16, Block.getBlockById(134));
		world.setBlock(x+14, y+13, z+16, Block.getBlockById(134));
		world.setBlockMetadataWithNotify(x+14, y+13, z+16, 1, 1);
		world.setBlock(x+2, y+13, z+17, Block.getBlockById(134));
		world.setBlock(x+14, y+13, z+17, Block.getBlockById(134));
		world.setBlockMetadataWithNotify(x+14, y+13, z+17, 1, 1);
		world.setBlock(x+2, y+13, z+18, Block.getBlockById(134));
		world.setBlock(x+14, y+13, z+18, Block.getBlockById(134));
		world.setBlockMetadataWithNotify(x+14, y+13, z+18, 1, 1);
		world.setBlock(x+2, y+13, z+19, Block.getBlockById(134));
		world.setBlock(x+3, y+13, z+19, Block.getBlockById(5));
		world.setBlockMetadataWithNotify(x+3, y+13, z+19, 1, 1);
		world.setBlock(x+4, y+13, z+19, Block.getBlockById(113));
		world.setBlock(x+5, y+13, z+19, Block.getBlockById(113));
		world.setBlock(x+6, y+13, z+19, Block.getBlockById(113));
		world.setBlock(x+10, y+13, z+19, Block.getBlockById(113));
		world.setBlock(x+11, y+13, z+19, Block.getBlockById(113));
		world.setBlock(x+12, y+13, z+19, Block.getBlockById(113));
		world.setBlock(x+13, y+13, z+19, Block.getBlockById(5));
		world.setBlockMetadataWithNotify(x+13, y+13, z+19, 1, 1);
		world.setBlock(x+14, y+13, z+19, Block.getBlockById(134));
		world.setBlockMetadataWithNotify(x+14, y+13, z+19, 1, 1);

		
		spawn1(world, x, y, z);
	}

		private static void spawn1(World world, int x, int y, int z)
		{
			world.setBlock(x+11, y+18, z+19, Block.getBlockById(134));
			world.setBlockMetadataWithNotify(x+11, y+18, z+19, 1, 1);
			world.setBlock(x+5, y+18, z+20, Block.getBlockById(134));
			world.setBlock(x+6, y+18, z+20, Block.getBlockById(113));
			world.setBlock(x+7, y+18, z+20, Block.getBlockById(113));
			world.setBlock(x+8, y+18, z+20, Block.getBlockById(5));
			world.setBlockMetadataWithNotify(x+8, y+18, z+20, 1, 1);
			world.setBlock(x+9, y+18, z+20, Block.getBlockById(113));
			world.setBlock(x+10, y+18, z+20, Block.getBlockById(113));
			world.setBlock(x+11, y+18, z+20, Block.getBlockById(134));
			world.setBlockMetadataWithNotify(x+11, y+18, z+20, 1, 1);
			world.setBlock(x+5, y+18, z+21, Block.getBlockById(53));
			world.setBlock(x+6, y+18, z+21, Block.getBlockById(53));
			world.setBlockMetadataWithNotify(x+6, y+18, z+21, 5, 5);
			world.setBlock(x+7, y+18, z+21, Block.getBlockById(113));
			world.setBlock(x+8, y+18, z+21, Block.getBlockById(5));
			world.setBlockMetadataWithNotify(x+8, y+18, z+21, 1, 1);
			world.setBlock(x+9, y+18, z+21, Block.getBlockById(113));
			world.setBlock(x+10, y+18, z+21, Block.getBlockById(53));
			world.setBlockMetadataWithNotify(x+10, y+18, z+21, 4, 4);
			world.setBlock(x+11, y+18, z+21, Block.getBlockById(53));
			world.setBlockMetadataWithNotify(x+11, y+18, z+21, 1, 1);
			world.setBlock(x+8, y+18, z+22, Block.getBlockById(134));
			world.setBlockMetadataWithNotify(x+8, y+18, z+22, 7, 7);
			world.setBlock(x+6, y+19, z+0, Block.getBlockById(53));
			world.setBlockMetadataWithNotify(x+6, y+19, z+0, 2, 2);
			world.setBlock(x+7, y+19, z+0, Block.getBlockById(134));
			world.setBlock(x+9, y+19, z+0, Block.getBlockById(134));
			world.setBlockMetadataWithNotify(x+9, y+19, z+0, 1, 1);
			world.setBlock(x+10, y+19, z+0, Block.getBlockById(53));
			world.setBlockMetadataWithNotify(x+10, y+19, z+0, 2, 2);
			world.setBlock(x+5, y+19, z+1, Block.getBlockById(134));
			world.setBlock(x+6, y+19, z+1, Block.getBlockById(5));
			world.setBlock(x+7, y+19, z+1, Block.getBlockById(5));
			world.setBlock(x+8, y+19, z+1, Block.getBlockById(113));
			world.setBlock(x+9, y+19, z+1, Block.getBlockById(5));
			world.setBlock(x+10, y+19, z+1, Block.getBlockById(5));
			world.setBlock(x+11, y+19, z+1, Block.getBlockById(134));
			world.setBlockMetadataWithNotify(x+11, y+19, z+1, 1, 1);
			world.setBlock(x+5, y+19, z+2, Block.getBlockById(134));
			world.setBlock(x+11, y+19, z+2, Block.getBlockById(134));
			world.setBlockMetadataWithNotify(x+11, y+19, z+2, 1, 1);
			world.setBlock(x+5, y+19, z+3, Block.getBlockById(134));
			world.setBlock(x+11, y+19, z+3, Block.getBlockById(134));
			world.setBlockMetadataWithNotify(x+11, y+19, z+3, 1, 1);
			world.setBlock(x+5, y+19, z+4, Block.getBlockById(134));
			world.setBlock(x+11, y+19, z+4, Block.getBlockById(134));
			world.setBlockMetadataWithNotify(x+11, y+19, z+4, 1, 1);
			world.setBlock(x+5, y+19, z+5, Block.getBlockById(134));
			world.setBlock(x+11, y+19, z+5, Block.getBlockById(134));
			world.setBlockMetadataWithNotify(x+11, y+19, z+5, 1, 1);
			world.setBlock(x+5, y+19, z+6, Block.getBlockById(134));
			world.setBlock(x+11, y+19, z+6, Block.getBlockById(134));
			world.setBlockMetadataWithNotify(x+11, y+19, z+6, 1, 1);
			world.setBlock(x+5, y+19, z+7, Block.getBlockById(134));
			world.setBlock(x+11, y+19, z+7, Block.getBlockById(134));
			world.setBlockMetadataWithNotify(x+11, y+19, z+7, 1, 1);
			world.setBlock(x+5, y+19, z+8, Block.getBlockById(134));
			world.setBlock(x+11, y+19, z+8, Block.getBlockById(134));
			world.setBlockMetadataWithNotify(x+11, y+19, z+8, 1, 1);
			world.setBlock(x+5, y+19, z+9, Block.getBlockById(134));
			world.setBlock(x+11, y+19, z+9, Block.getBlockById(134));
			world.setBlockMetadataWithNotify(x+11, y+19, z+9, 1, 1);
			world.setBlock(x+5, y+19, z+10, Block.getBlockById(134));
			world.setBlock(x+11, y+19, z+10, Block.getBlockById(134));
			world.setBlockMetadataWithNotify(x+11, y+19, z+10, 1, 1);
			world.setBlock(x+5, y+19, z+11, Block.getBlockById(134));
			world.setBlock(x+11, y+19, z+11, Block.getBlockById(134));
			world.setBlockMetadataWithNotify(x+11, y+19, z+11, 1, 1);
			world.setBlock(x+5, y+19, z+12, Block.getBlockById(134));
			world.setBlock(x+11, y+19, z+12, Block.getBlockById(134));
			world.setBlockMetadataWithNotify(x+11, y+19, z+12, 1, 1);
			world.setBlock(x+5, y+19, z+13, Block.getBlockById(134));
			world.setBlock(x+11, y+19, z+13, Block.getBlockById(134));
			world.setBlockMetadataWithNotify(x+11, y+19, z+13, 1, 1);
			world.setBlock(x+5, y+19, z+14, Block.getBlockById(134));
			world.setBlock(x+11, y+19, z+14, Block.getBlockById(134));
			world.setBlockMetadataWithNotify(x+11, y+19, z+14, 1, 1);
			world.setBlock(x+5, y+19, z+15, Block.getBlockById(134));
			world.setBlock(x+11, y+19, z+15, Block.getBlockById(134));
			world.setBlockMetadataWithNotify(x+11, y+19, z+15, 1, 1);
			world.setBlock(x+5, y+19, z+16, Block.getBlockById(134));
			world.setBlock(x+11, y+19, z+16, Block.getBlockById(134));
			world.setBlockMetadataWithNotify(x+11, y+19, z+16, 1, 1);
			world.setBlock(x+5, y+19, z+17, Block.getBlockById(134));
			world.setBlock(x+11, y+19, z+17, Block.getBlockById(134));
			world.setBlockMetadataWithNotify(x+11, y+19, z+17, 1, 1);
			world.setBlock(x+5, y+19, z+18, Block.getBlockById(134));
			world.setBlock(x+11, y+19, z+18, Block.getBlockById(134));
			world.setBlockMetadataWithNotify(x+11, y+19, z+18, 1, 1);
			world.setBlock(x+5, y+19, z+19, Block.getBlockById(134));
			world.setBlock(x+6, y+19, z+19, Block.getBlockById(5));
			world.setBlockMetadataWithNotify(x+6, y+19, z+19, 1, 1);
			world.setBlock(x+7, y+19, z+19, Block.getBlockById(113));
			world.setBlock(x+8, y+19, z+19, Block.getBlockById(113));
			world.setBlock(x+9, y+19, z+19, Block.getBlockById(113));
			world.setBlock(x+10, y+19, z+19, Block.getBlockById(5));
			world.setBlockMetadataWithNotify(x+10, y+19, z+19, 1, 1);
			world.setBlock(x+11, y+19, z+19, Block.getBlockById(134));
			world.setBlockMetadataWithNotify(x+11, y+19, z+19, 1, 1);
			world.setBlock(x+5, y+19, z+20, Block.getBlockById(134));
			world.setBlock(x+6, y+19, z+20, Block.getBlockById(113));
			world.setBlock(x+7, y+19, z+20, Block.getBlockById(113));
			world.setBlock(x+8, y+19, z+20, Block.getBlockById(113));
			world.setBlock(x+9, y+19, z+20, Block.getBlockById(113));
			world.setBlock(x+10, y+19, z+20, Block.getBlockById(113));
			world.setBlock(x+11, y+19, z+20, Block.getBlockById(134));
			world.setBlockMetadataWithNotify(x+11, y+19, z+20, 1, 1);
			world.setBlock(x+6, y+19, z+21, Block.getBlockById(5));
			world.setBlock(x+7, y+19, z+21, Block.getBlockById(113));
			world.setBlock(x+8, y+19, z+21, Block.getBlockById(113));
			world.setBlock(x+9, y+19, z+21, Block.getBlockById(113));
			world.setBlock(x+10, y+19, z+21, Block.getBlockById(5));
			world.setBlock(x+7, y+20, z+0, Block.getBlockById(134));
			world.setBlock(x+9, y+20, z+0, Block.getBlockById(134));
			world.setBlockMetadataWithNotify(x+9, y+20, z+0, 1, 1);
			world.setBlock(x+6, y+20, z+1, Block.getBlockById(5));
			world.setBlock(x+7, y+20, z+1, Block.getBlockById(5));
			world.setBlock(x+8, y+20, z+1, Block.getBlockById(113));
			world.setBlock(x+9, y+20, z+1, Block.getBlockById(5));
			world.setBlock(x+10, y+20, z+1, Block.getBlockById(5));
			world.setBlock(x+6, y+20, z+2, Block.getBlockById(134));
			world.setBlock(x+10, y+20, z+2, Block.getBlockById(134));
			world.setBlockMetadataWithNotify(x+10, y+20, z+2, 1, 1);
			world.setBlock(x+6, y+20, z+3, Block.getBlockById(134));
			world.setBlock(x+10, y+20, z+3, Block.getBlockById(134));
			world.setBlockMetadataWithNotify(x+10, y+20, z+3, 1, 1);
			world.setBlock(x+6, y+20, z+4, Block.getBlockById(5));
			world.setBlock(x+10, y+20, z+4, Block.getBlockById(5));
			world.setBlock(x+6, y+20, z+5, Block.getBlockById(5));
			world.setBlock(x+10, y+20, z+5, Block.getBlockById(5));
			world.setBlock(x+6, y+20, z+6, Block.getBlockById(5));
			world.setBlock(x+10, y+20, z+6, Block.getBlockById(5));
			world.setBlock(x+6, y+20, z+7, Block.getBlockById(5));
			world.setBlock(x+10, y+20, z+7, Block.getBlockById(5));
			world.setBlock(x+6, y+20, z+8, Block.getBlockById(5));
			world.setBlock(x+10, y+20, z+8, Block.getBlockById(5));
			world.setBlock(x+6, y+20, z+9, Block.getBlockById(5));
			world.setBlock(x+10, y+20, z+9, Block.getBlockById(5));
			world.setBlock(x+6, y+20, z+10, Block.getBlockById(5));
			world.setBlock(x+10, y+20, z+10, Block.getBlockById(5));
			world.setBlock(x+6, y+20, z+11, Block.getBlockById(5));
			world.setBlock(x+10, y+20, z+11, Block.getBlockById(5));
			world.setBlock(x+6, y+20, z+12, Block.getBlockById(5));
			world.setBlock(x+10, y+20, z+12, Block.getBlockById(5));
			world.setBlock(x+6, y+20, z+13, Block.getBlockById(5));
			world.setBlock(x+10, y+20, z+13, Block.getBlockById(5));
			world.setBlock(x+6, y+20, z+14, Block.getBlockById(5));
			world.setBlock(x+10, y+20, z+14, Block.getBlockById(5));
			world.setBlock(x+6, y+20, z+15, Block.getBlockById(5));
			world.setBlock(x+10, y+20, z+15, Block.getBlockById(5));
			world.setBlock(x+6, y+20, z+16, Block.getBlockById(5));
			world.setBlock(x+10, y+20, z+16, Block.getBlockById(5));
			world.setBlock(x+6, y+20, z+17, Block.getBlockById(5));
			world.setBlock(x+10, y+20, z+17, Block.getBlockById(5));
			world.setBlock(x+6, y+20, z+18, Block.getBlockById(5));
			world.setBlock(x+10, y+20, z+18, Block.getBlockById(5));
			world.setBlock(x+6, y+20, z+19, Block.getBlockById(134));
			world.setBlock(x+7, y+20, z+19, Block.getBlockById(5));
			world.setBlockMetadataWithNotify(x+7, y+20, z+19, 1, 1);
			world.setBlock(x+8, y+20, z+19, Block.getBlockById(113));
			world.setBlock(x+9, y+20, z+19, Block.getBlockById(5));
			world.setBlockMetadataWithNotify(x+9, y+20, z+19, 1, 1);
			world.setBlock(x+10, y+20, z+19, Block.getBlockById(134));
			world.setBlockMetadataWithNotify(x+10, y+20, z+19, 1, 1);
			world.setBlock(x+6, y+20, z+20, Block.getBlockById(134));
			world.setBlock(x+7, y+20, z+20, Block.getBlockById(113));
			world.setBlock(x+8, y+20, z+20, Block.getBlockById(113));
			world.setBlock(x+9, y+20, z+20, Block.getBlockById(113));
			world.setBlock(x+10, y+20, z+20, Block.getBlockById(134));
			world.setBlockMetadataWithNotify(x+10, y+20, z+20, 1, 1);
			world.setBlock(x+6, y+20, z+21, Block.getBlockById(53));
			world.setBlock(x+7, y+20, z+21, Block.getBlockById(53));
			world.setBlockMetadataWithNotify(x+7, y+20, z+21, 5, 5);
			world.setBlock(x+8, y+20, z+21, Block.getBlockById(113));
			world.setBlock(x+9, y+20, z+21, Block.getBlockById(53));
			world.setBlockMetadataWithNotify(x+9, y+20, z+21, 4, 4);
			world.setBlock(x+10, y+20, z+21, Block.getBlockById(53));
			world.setBlockMetadataWithNotify(x+10, y+20, z+21, 1, 1);
			world.setBlock(x+7, y+21, z+0, Block.getBlockById(134));
			world.setBlock(x+8, y+21, z+0, Block.getBlockById(134));
			world.setBlockMetadataWithNotify(x+8, y+21, z+0, 6, 6);
			world.setBlock(x+9, y+21, z+0, Block.getBlockById(134));
			world.setBlockMetadataWithNotify(x+9, y+21, z+0, 1, 1);
			world.setBlock(x+6, y+21, z+1, Block.getBlockById(134));
			world.setBlock(x+7, y+21, z+1, Block.getBlockById(5));
			world.setBlock(x+8, y+21, z+1, Block.getBlockById(5));
			world.setBlock(x+9, y+21, z+1, Block.getBlockById(5));
			world.setBlock(x+10, y+21, z+1, Block.getBlockById(134));
			world.setBlockMetadataWithNotify(x+10, y+21, z+1, 1, 1);
			world.setBlock(x+6, y+21, z+2, Block.getBlockById(134));
			world.setBlock(x+10, y+21, z+2, Block.getBlockById(134));
			world.setBlockMetadataWithNotify(x+10, y+21, z+2, 1, 1);
			world.setBlock(x+6, y+21, z+3, Block.getBlockById(134));
			world.setBlock(x+10, y+21, z+3, Block.getBlockById(134));
			world.setBlockMetadataWithNotify(x+10, y+21, z+3, 1, 1);
			world.setBlock(x+6, y+21, z+4, Block.getBlockById(134));
			world.setBlock(x+10, y+21, z+4, Block.getBlockById(134));
			world.setBlockMetadataWithNotify(x+10, y+21, z+4, 1, 1);
			world.setBlock(x+6, y+21, z+5, Block.getBlockById(134));
			world.setBlock(x+10, y+21, z+5, Block.getBlockById(134));
			world.setBlockMetadataWithNotify(x+10, y+21, z+5, 1, 1);
			world.setBlock(x+6, y+21, z+6, Block.getBlockById(134));
			world.setBlock(x+10, y+21, z+6, Block.getBlockById(134));
			world.setBlockMetadataWithNotify(x+10, y+21, z+6, 1, 1);
			world.setBlock(x+6, y+21, z+7, Block.getBlockById(134));
			world.setBlock(x+10, y+21, z+7, Block.getBlockById(134));
			world.setBlockMetadataWithNotify(x+10, y+21, z+7, 1, 1);
			world.setBlock(x+6, y+21, z+8, Block.getBlockById(134));
			
			spawn2(world, x, y, z);
		}

		private static void spawn2(World world, int x, int y, int z)
		{
			spawn3(world, x, y, z);
			world.setBlockMetadataWithNotify(x+11, y+16, z+0, 1, 1);
			world.setBlock(x+4, y+16, z+1, Block.getBlockById(5));
			world.setBlock(x+5, y+16, z+1, Block.getBlockById(5));
			world.setBlock(x+6, y+16, z+1, Block.getBlockById(5));
			world.setBlock(x+7, y+16, z+1, Block.getBlockById(113));
			world.setBlock(x+8, y+16, z+1, Block.getBlockById(113));
			world.setBlock(x+9, y+16, z+1, Block.getBlockById(113));
			world.setBlock(x+10, y+16, z+1, Block.getBlockById(5));
			world.setBlock(x+11, y+16, z+1, Block.getBlockById(5));
			world.setBlock(x+12, y+16, z+1, Block.getBlockById(5));
			world.setBlock(x+4, y+16, z+2, Block.getBlockById(134));
			world.setBlock(x+12, y+16, z+2, Block.getBlockById(134));
			world.setBlockMetadataWithNotify(x+12, y+16, z+2, 1, 1);
			world.setBlock(x+4, y+16, z+3, Block.getBlockById(134));
			world.setBlock(x+12, y+16, z+3, Block.getBlockById(134));
			world.setBlockMetadataWithNotify(x+12, y+16, z+3, 1, 1);
			world.setBlock(x+4, y+16, z+4, Block.getBlockById(5));
			world.setBlock(x+12, y+16, z+4, Block.getBlockById(5));
			world.setBlock(x+4, y+16, z+5, Block.getBlockById(5));
			world.setBlock(x+12, y+16, z+5, Block.getBlockById(5));
			world.setBlock(x+4, y+16, z+6, Block.getBlockById(5));
			world.setBlock(x+12, y+16, z+6, Block.getBlockById(5));
			world.setBlock(x+4, y+16, z+7, Block.getBlockById(5));
			world.setBlock(x+12, y+16, z+7, Block.getBlockById(5));
			world.setBlock(x+4, y+16, z+8, Block.getBlockById(5));
			world.setBlock(x+12, y+16, z+8, Block.getBlockById(5));
			world.setBlock(x+4, y+16, z+9, Block.getBlockById(5));
			world.setBlock(x+12, y+16, z+9, Block.getBlockById(5));
			world.setBlock(x+4, y+16, z+10, Block.getBlockById(5));
			world.setBlock(x+12, y+16, z+10, Block.getBlockById(5));
			world.setBlock(x+4, y+16, z+11, Block.getBlockById(5));
			world.setBlock(x+12, y+16, z+11, Block.getBlockById(5));
			world.setBlock(x+4, y+16, z+12, Block.getBlockById(5));
			world.setBlock(x+12, y+16, z+12, Block.getBlockById(5));
			world.setBlock(x+4, y+16, z+13, Block.getBlockById(5));
			world.setBlock(x+12, y+16, z+13, Block.getBlockById(5));
			world.setBlock(x+4, y+16, z+14, Block.getBlockById(5));
			world.setBlock(x+12, y+16, z+14, Block.getBlockById(5));
			world.setBlock(x+4, y+16, z+15, Block.getBlockById(5));
			world.setBlock(x+12, y+16, z+15, Block.getBlockById(5));
			world.setBlock(x+4, y+16, z+16, Block.getBlockById(5));
			world.setBlock(x+12, y+16, z+16, Block.getBlockById(5));
			world.setBlock(x+4, y+16, z+17, Block.getBlockById(5));
			world.setBlock(x+12, y+16, z+17, Block.getBlockById(5));
			world.setBlock(x+4, y+16, z+18, Block.getBlockById(5));
			world.setBlock(x+12, y+16, z+18, Block.getBlockById(5));
			world.setBlock(x+4, y+16, z+19, Block.getBlockById(134));
			world.setBlock(x+5, y+16, z+19, Block.getBlockById(5));
			world.setBlockMetadataWithNotify(x+5, y+16, z+19, 1, 1);
			world.setBlock(x+6, y+16, z+19, Block.getBlockById(113));
			world.setBlock(x+7, y+16, z+19, Block.getBlockById(113));
			world.setBlock(x+9, y+16, z+19, Block.getBlockById(113));
			world.setBlock(x+10, y+16, z+19, Block.getBlockById(113));
			world.setBlock(x+11, y+16, z+19, Block.getBlockById(5));
			world.setBlockMetadataWithNotify(x+11, y+16, z+19, 1, 1);
			world.setBlock(x+12, y+16, z+19, Block.getBlockById(134));
			world.setBlockMetadataWithNotify(x+12, y+16, z+19, 1, 1);
			world.setBlock(x+4, y+16, z+20, Block.getBlockById(134));
			world.setBlock(x+5, y+16, z+20, Block.getBlockById(113));
			world.setBlock(x+6, y+16, z+20, Block.getBlockById(113));
			world.setBlock(x+7, y+16, z+20, Block.getBlockById(5));
			world.setBlock(x+8, y+16, z+20, Block.getBlockById(134));
			world.setBlockMetadataWithNotify(x+8, y+16, z+20, 6, 6);
			world.setBlock(x+9, y+16, z+20, Block.getBlockById(5));
			world.setBlock(x+10, y+16, z+20, Block.getBlockById(113));
			world.setBlock(x+11, y+16, z+20, Block.getBlockById(113));
			world.setBlock(x+12, y+16, z+20, Block.getBlockById(134));
			world.setBlockMetadataWithNotify(x+12, y+16, z+20, 1, 1);
			world.setBlock(x+4, y+16, z+21, Block.getBlockById(53));
			world.setBlock(x+5, y+16, z+21, Block.getBlockById(53));
			world.setBlockMetadataWithNotify(x+5, y+16, z+21, 5, 5);
			world.setBlock(x+6, y+16, z+21, Block.getBlockById(113));
			world.setBlock(x+7, y+16, z+21, Block.getBlockById(5));
			world.setBlock(x+8, y+16, z+21, Block.getBlockById(134));
			world.setBlockMetadataWithNotify(x+8, y+16, z+21, 7, 7);
			world.setBlock(x+9, y+16, z+21, Block.getBlockById(5));
			world.setBlock(x+10, y+16, z+21, Block.getBlockById(113));
			world.setBlock(x+11, y+16, z+21, Block.getBlockById(53));
			world.setBlockMetadataWithNotify(x+11, y+16, z+21, 4, 4);
			world.setBlock(x+12, y+16, z+21, Block.getBlockById(53));
			world.setBlockMetadataWithNotify(x+12, y+16, z+21, 1, 1);
			world.setBlock(x+6, y+17, z+0, Block.getBlockById(134));
			world.setBlock(x+10, y+17, z+0, Block.getBlockById(134));
			world.setBlockMetadataWithNotify(x+10, y+17, z+0, 1, 1);
			world.setBlock(x+4, y+17, z+1, Block.getBlockById(134));
			world.setBlock(x+5, y+17, z+1, Block.getBlockById(5));
			world.setBlock(x+6, y+17, z+1, Block.getBlockById(5));
			world.setBlock(x+7, y+17, z+1, Block.getBlockById(113));
			world.setBlock(x+8, y+17, z+1, Block.getBlockById(113));
			world.setBlock(x+9, y+17, z+1, Block.getBlockById(113));
			world.setBlock(x+10, y+17, z+1, Block.getBlockById(5));
			world.setBlock(x+11, y+17, z+1, Block.getBlockById(5));
			world.setBlock(x+12, y+17, z+1, Block.getBlockById(134));
			world.setBlockMetadataWithNotify(x+12, y+17, z+1, 1, 1);
			world.setBlock(x+4, y+17, z+2, Block.getBlockById(134));
			world.setBlock(x+12, y+17, z+2, Block.getBlockById(134));
			world.setBlockMetadataWithNotify(x+12, y+17, z+2, 1, 1);
			world.setBlock(x+4, y+17, z+3, Block.getBlockById(134));
			world.setBlock(x+12, y+17, z+3, Block.getBlockById(134));
			world.setBlockMetadataWithNotify(x+12, y+17, z+3, 1, 1);
			world.setBlock(x+4, y+17, z+4, Block.getBlockById(134));
			world.setBlock(x+12, y+17, z+4, Block.getBlockById(134));
			world.setBlockMetadataWithNotify(x+12, y+17, z+4, 1, 1);
			world.setBlock(x+4, y+17, z+5, Block.getBlockById(134));
			world.setBlock(x+12, y+17, z+5, Block.getBlockById(134));
			world.setBlockMetadataWithNotify(x+12, y+17, z+5, 1, 1);
			world.setBlock(x+4, y+17, z+6, Block.getBlockById(134));
			world.setBlock(x+12, y+17, z+6, Block.getBlockById(134));
			world.setBlockMetadataWithNotify(x+12, y+17, z+6, 1, 1);
			world.setBlock(x+4, y+17, z+7, Block.getBlockById(134));
			world.setBlock(x+12, y+17, z+7, Block.getBlockById(134));
			world.setBlockMetadataWithNotify(x+12, y+17, z+7, 1, 1);
			world.setBlock(x+4, y+17, z+8, Block.getBlockById(134));
			world.setBlock(x+12, y+17, z+8, Block.getBlockById(134));
			world.setBlockMetadataWithNotify(x+12, y+17, z+8, 1, 1);
			world.setBlock(x+4, y+17, z+9, Block.getBlockById(134));
			world.setBlock(x+12, y+17, z+9, Block.getBlockById(134));
			world.setBlockMetadataWithNotify(x+12, y+17, z+9, 1, 1);
			world.setBlock(x+4, y+17, z+10, Block.getBlockById(134));
			world.setBlock(x+12, y+17, z+10, Block.getBlockById(134));
			world.setBlockMetadataWithNotify(x+12, y+17, z+10, 1, 1);
			world.setBlock(x+4, y+17, z+11, Block.getBlockById(134));
			world.setBlock(x+12, y+17, z+11, Block.getBlockById(134));
			world.setBlockMetadataWithNotify(x+12, y+17, z+11, 1, 1);
			world.setBlock(x+4, y+17, z+12, Block.getBlockById(134));
			world.setBlock(x+12, y+17, z+12, Block.getBlockById(134));
			world.setBlockMetadataWithNotify(x+12, y+17, z+12, 1, 1);
			world.setBlock(x+4, y+17, z+13, Block.getBlockById(134));
			world.setBlock(x+12, y+17, z+13, Block.getBlockById(134));
			world.setBlockMetadataWithNotify(x+12, y+17, z+13, 1, 1);
			world.setBlock(x+4, y+17, z+14, Block.getBlockById(134));
			world.setBlock(x+12, y+17, z+14, Block.getBlockById(134));
			world.setBlockMetadataWithNotify(x+12, y+17, z+14, 1, 1);
			world.setBlock(x+4, y+17, z+15, Block.getBlockById(134));
			world.setBlock(x+12, y+17, z+15, Block.getBlockById(134));
			world.setBlockMetadataWithNotify(x+12, y+17, z+15, 1, 1);
			world.setBlock(x+4, y+17, z+16, Block.getBlockById(134));
			world.setBlock(x+12, y+17, z+16, Block.getBlockById(134));
			world.setBlockMetadataWithNotify(x+12, y+17, z+16, 1, 1);
			world.setBlock(x+4, y+17, z+17, Block.getBlockById(134));
			world.setBlock(x+12, y+17, z+17, Block.getBlockById(134));
			world.setBlockMetadataWithNotify(x+12, y+17, z+17, 1, 1);
			world.setBlock(x+4, y+17, z+18, Block.getBlockById(134));
			world.setBlock(x+12, y+17, z+18, Block.getBlockById(134));
			world.setBlockMetadataWithNotify(x+12, y+17, z+18, 1, 1);
			world.setBlock(x+4, y+17, z+19, Block.getBlockById(134));
			world.setBlock(x+5, y+17, z+19, Block.getBlockById(5));
			world.setBlockMetadataWithNotify(x+5, y+17, z+19, 1, 1);
			world.setBlock(x+6, y+17, z+19, Block.getBlockById(113));
			world.setBlock(x+7, y+17, z+19, Block.getBlockById(113));
