package fr.toss.common.world.bioms.deco;

import java.util.Random;

import net.minecraft.block.Block;
import net.minecraft.entity.player.EntityPlayer;
import net.minecraft.util.ChatComponentText;
import net.minecraft.world.World;
import net.minecraft.world.biome.BiomeGenBase;
import net.minecraft.world.chunk.IChunkProvider;
import cpw.mods.fml.common.IWorldGenerator;
import fr.toss.common.Main;
import fr.toss.common.command.ChatColor;
import fr.toss.common.entity.EntityOrc;
import fr.toss.common.register.BlockRegister;

public class WorldGenOrc implements IWorldGenerator {
	
	@Override
	public void generate(Random random, int chunkX, int chunkZ, World world, IChunkProvider chunkGenerator, IChunkProvider chunkProvider)
	{
		int x = chunkX * 16 + random.nextInt(16);
		int z = chunkZ * 16 + random.nextInt(16);
		
		
		if (random.nextInt(200) == 0 && world.provider.dimensionId == 0 && this.biomIsValid(world.getBiomeGenForCoords(x, z)))
		{
			int y = world.getTopSolidOrLiquidBlock(x, z) - 4;
						
			for (Object obj : world.playerEntities)
				((EntityPlayer)obj).addChatComponentMessage(new ChatComponentText(ChatColor.AQUA + "A dungeon portal has been generated at: X:" + x + " Y:" + y + " Z:" + z + ChatColor.RESET));
			
			EntityOrc orc[];
			
			orc = new EntityOrc[8];
				
			for (int i = 0; i < 8; i++)
			{	
				orc[i] = new EntityOrc(world);
				x = x - 8 + random.nextInt(16);
				z = z - 8 + random.nextInt(16);
				orc[i].setLocationAndAngles(x, world.getTopSolidOrLiquidBlock(x, z) + 2, z, 0, 0);
				world.spawnEntityInWorld(orc[i]);
			}
			
			spawn(world, x, y, z);
			
			for (int i = 0; i < 12; i++)
				for (int j = 0; j < 8; j++)
					world.setBlock(x+19+j, y-2 + i, z+7, BlockRegister.PORTAL_DUNGEON[0]);
		}
	}

	boolean biomIsValid(BiomeGenBase b)
	{
		return (b.biomeID == BiomeGenBase.birchForest.biomeID) || 
				(b.biomeID == BiomeGenBase.coldTaiga.biomeID) ||
				(b.biomeID == BiomeGenBase.forest.biomeID) ||
				(b.biomeID == BiomeGenBase.icePlains.biomeID) ||
				(b.biomeID == BiomeGenBase.megaTaiga.biomeID) ||
				(b.biomeID == BiomeGenBase.mesa.biomeID) ||
				(b.biomeID == BiomeGenBase.mesaPlateau.biomeID) ||
				(b.biomeID == BiomeGenBase.mesaPlateau_F.biomeID) ||
				(b.biomeID == BiomeGenBase.desert.biomeID) ||
				(b.biomeID == BiomeGenBase.forestHills.biomeID) ||
				(b.biomeID == BiomeGenBase.swampland.biomeID) ||
				(b.biomeID == BiomeGenBase.plains.biomeID) ||
				(b.biomeID == BiomeGenBase.taiga.biomeID) ||
				(b.biomeID == BiomeGenBase.plains.biomeID) ||
				(b.biomeID == BiomeGenBase.roofedForest.biomeID) ||
				(b.biomeID == BiomeGenBase.savannaPlateau.biomeID) ||
				(b.biomeID == BiomeGenBase.savanna.biomeID);
	}

	public static void spawn(World world, int x, int y, int z)
	{
		world.setBlock(x+5, y+0, z+0, Block.getBlockById(98));
		world.setBlock(x+6, y+0, z+0, Block.getBlockById(98));
		world.setBlock(x+7, y+0, z+0, Block.getBlockById(98));
		world.setBlock(x+8, y+0, z+0, Block.getBlockById(98));
		world.setBlock(x+9, y+0, z+0, Block.getBlockById(98));
		world.setBlock(x+10, y+0, z+0, Block.getBlockById(98));
		world.setBlock(x+11, y+0, z+0, Block.getBlockById(98));
		world.setBlock(x+18, y+0, z+0, Block.getBlockById(1));
		world.setBlock(x+19, y+0, z+0, Block.getBlockById(159));
		world.setBlockMetadataWithNotify(x+19, y+0, z+0, 8, 8);
		world.setBlock(x+20, y+0, z+0, Block.getBlockById(159));
		world.setBlockMetadataWithNotify(x+20, y+0, z+0, 8, 8);
		world.setBlock(x+21, y+0, z+0, Block.getBlockById(159));
		world.setBlockMetadataWithNotify(x+21, y+0, z+0, 8, 8);
		world.setBlock(x+22, y+0, z+0, Block.getBlockById(159));
		world.setBlockMetadataWithNotify(x+22, y+0, z+0, 8, 8);
		world.setBlock(x+23, y+0, z+0, Block.getBlockById(159));
		world.setBlockMetadataWithNotify(x+23, y+0, z+0, 8, 8);
		world.setBlock(x+24, y+0, z+0, Block.getBlockById(159));
		world.setBlockMetadataWithNotify(x+24, y+0, z+0, 8, 8);
		world.setBlock(x+25, y+0, z+0, Block.getBlockById(159));
		world.setBlockMetadataWithNotify(x+25, y+0, z+0, 8, 8);
		world.setBlock(x+26, y+0, z+0, Block.getBlockById(1));
		world.setBlock(x+33, y+0, z+0, Block.getBlockById(98));
		world.setBlock(x+34, y+0, z+0, Block.getBlockById(98));
		world.setBlock(x+35, y+0, z+0, Block.getBlockById(98));
		world.setBlock(x+36, y+0, z+0, Block.getBlockById(98));
		world.setBlock(x+37, y+0, z+0, Block.getBlockById(98));
		world.setBlock(x+38, y+0, z+0, Block.getBlockById(98));
		world.setBlock(x+39, y+0, z+0, Block.getBlockById(98));
		world.setBlock(x+3, y+0, z+1, Block.getBlockById(98));
		world.setBlock(x+4, y+0, z+1, Block.getBlockById(98));
		world.setBlock(x+5, y+0, z+1, Block.getBlockById(98));
		world.setBlock(x+6, y+0, z+1, Block.getBlockById(1));
		world.setBlock(x+7, y+0, z+1, Block.getBlockById(1));
		world.setBlock(x+8, y+0, z+1, Block.getBlockById(1));
		world.setBlock(x+9, y+0, z+1, Block.getBlockById(1));
		world.setBlock(x+10, y+0, z+1, Block.getBlockById(1));
		world.setBlock(x+11, y+0, z+1, Block.getBlockById(98));
		world.setBlock(x+12, y+0, z+1, Block.getBlockById(98));
		world.setBlock(x+13, y+0, z+1, Block.getBlockById(98));
		world.setBlock(x+18, y+0, z+1, Block.getBlockById(1));
		world.setBlock(x+19, y+0, z+1, Block.getBlockById(159));
		world.setBlockMetadataWithNotify(x+19, y+0, z+1, 8, 8);
		world.setBlock(x+20, y+0, z+1, Block.getBlockById(159));
		world.setBlockMetadataWithNotify(x+20, y+0, z+1, 8, 8);
		world.setBlock(x+21, y+0, z+1, Block.getBlockById(159));
		world.setBlockMetadataWithNotify(x+21, y+0, z+1, 8, 8);
		world.setBlock(x+22, y+0, z+1, Block.getBlockById(159));
		world.setBlockMetadataWithNotify(x+22, y+0, z+1, 8, 8);
		world.setBlock(x+23, y+0, z+1, Block.getBlockById(159));
		world.setBlockMetadataWithNotify(x+23, y+0, z+1, 8, 8);
		world.setBlock(x+24, y+0, z+1, Block.getBlockById(159));
		world.setBlockMetadataWithNotify(x+24, y+0, z+1, 8, 8);
		world.setBlock(x+25, y+0, z+1, Block.getBlockById(159));
		world.setBlockMetadataWithNotify(x+25, y+0, z+1, 8, 8);
		world.setBlock(x+26, y+0, z+1, Block.getBlockById(1));
		world.setBlock(x+31, y+0, z+1, Block.getBlockById(98));
		world.setBlock(x+32, y+0, z+1, Block.getBlockById(98));
		world.setBlock(x+33, y+0, z+1, Block.getBlockById(98));
		world.setBlock(x+34, y+0, z+1, Block.getBlockById(12));
		world.setBlock(x+35, y+0, z+1, Block.getBlockById(12));
		world.setBlock(x+36, y+0, z+1, Block.getBlockById(12));
		world.setBlock(x+37, y+0, z+1, Block.getBlockById(12));
		world.setBlock(x+38, y+0, z+1, Block.getBlockById(12));
		world.setBlock(x+39, y+0, z+1, Block.getBlockById(98));
		world.setBlock(x+40, y+0, z+1, Block.getBlockById(98));
		world.setBlock(x+41, y+0, z+1, Block.getBlockById(98));
		world.setBlock(x+2, y+0, z+2, Block.getBlockById(98));
		world.setBlock(x+3, y+0, z+2, Block.getBlockById(98));
		world.setBlock(x+4, y+0, z+2, Block.getBlockById(1));
		world.setBlock(x+5, y+0, z+2, Block.getBlockById(1));
		world.setBlock(x+6, y+0, z+2, Block.getBlockById(1));
		world.setBlockMetadataWithNotify(x+6, y+0, z+2, 3, 3);
		world.setBlock(x+7, y+0, z+2, Block.getBlockById(1));
		world.setBlockMetadataWithNotify(x+7, y+0, z+2, 3, 3);
		world.setBlock(x+8, y+0, z+2, Block.getBlockById(1));
		world.setBlockMetadataWithNotify(x+8, y+0, z+2, 3, 3);
		world.setBlock(x+9, y+0, z+2, Block.getBlockById(1));
		world.setBlockMetadataWithNotify(x+9, y+0, z+2, 3, 3);
		world.setBlock(x+10, y+0, z+2, Block.getBlockById(1));
		world.setBlockMetadataWithNotify(x+10, y+0, z+2, 3, 3);
		world.setBlock(x+11, y+0, z+2, Block.getBlockById(1));
		world.setBlock(x+12, y+0, z+2, Block.getBlockById(1));
		world.setBlock(x+13, y+0, z+2, Block.getBlockById(98));
		world.setBlock(x+14, y+0, z+2, Block.getBlockById(98));
		world.setBlock(x+18, y+0, z+2, Block.getBlockById(1));
		world.setBlock(x+19, y+0, z+2, Block.getBlockById(159));
		world.setBlockMetadataWithNotify(x+19, y+0, z+2, 8, 8);
		world.setBlock(x+20, y+0, z+2, Block.getBlockById(159));
		world.setBlockMetadataWithNotify(x+20, y+0, z+2, 8, 8);
		world.setBlock(x+21, y+0, z+2, Block.getBlockById(159));
		world.setBlockMetadataWithNotify(x+21, y+0, z+2, 8, 8);
		world.setBlock(x+22, y+0, z+2, Block.getBlockById(159));
		world.setBlockMetadataWithNotify(x+22, y+0, z+2, 8, 8);
		world.setBlock(x+23, y+0, z+2, Block.getBlockById(159));
		world.setBlockMetadataWithNotify(x+23, y+0, z+2, 8, 8);
		world.setBlock(x+24, y+0, z+2, Block.getBlockById(159));
		world.setBlockMetadataWithNotify(x+24, y+0, z+2, 8, 8);
		world.setBlock(x+25, y+0, z+2, Block.getBlockById(159));
		world.setBlockMetadataWithNotify(x+25, y+0, z+2, 8, 8);
		world.setBlock(x+26, y+0, z+2, Block.getBlockById(1));
		world.setBlock(x+30, y+0, z+2, Block.getBlockById(98));
		world.setBlock(x+31, y+0, z+2, Block.getBlockById(98));
		world.setBlock(x+32, y+0, z+2, Block.getBlockById(12));
		world.setBlock(x+33, y+0, z+2, Block.getBlockById(12));
		world.setBlock(x+34, y+0, z+2, Block.getBlockById(12));
		world.setBlock(x+35, y+0, z+2, Block.getBlockById(12));
		world.setBlock(x+36, y+0, z+2, Block.getBlockById(12));
		world.setBlock(x+37, y+0, z+2, Block.getBlockById(12));
		world.setBlock(x+38, y+0, z+2, Block.getBlockById(12));
		world.setBlock(x+39, y+0, z+2, Block.getBlockById(12));
		world.setBlock(x+40, y+0, z+2, Block.getBlockById(12));
		world.setBlock(x+41, y+0, z+2, Block.getBlockById(98));
		world.setBlock(x+42, y+0, z+2, Block.getBlockById(98));
		world.setBlock(x+1, y+0, z+3, Block.getBlockById(98));
		world.setBlock(x+2, y+0, z+3, Block.getBlockById(98));
		world.setBlock(x+3, y+0, z+3, Block.getBlockById(1));
		world.setBlock(x+4, y+0, z+3, Block.getBlockById(1));
		world.setBlockMetadataWithNotify(x+4, y+0, z+3, 3, 3);
		world.setBlock(x+5, y+0, z+3, Block.getBlockById(1));
		world.setBlockMetadataWithNotify(x+5, y+0, z+3, 3, 3);
		world.setBlock(x+6, y+0, z+3, Block.getBlockById(1));
		world.setBlockMetadataWithNotify(x+6, y+0, z+3, 3, 3);
		world.setBlock(x+7, y+0, z+3, Block.getBlockById(1));
		world.setBlockMetadataWithNotify(x+7, y+0, z+3, 3, 3);
		world.setBlock(x+8, y+0, z+3, Block.getBlockById(1));
		world.setBlockMetadataWithNotify(x+8, y+0, z+3, 3, 3);
		world.setBlock(x+9, y+0, z+3, Block.getBlockById(1));
		world.setBlockMetadataWithNotify(x+9, y+0, z+3, 3, 3);
		world.setBlock(x+10, y+0, z+3, Block.getBlockById(1));
		world.setBlockMetadataWithNotify(x+10, y+0, z+3, 3, 3);
		world.setBlock(x+11, y+0, z+3, Block.getBlockById(1));
		world.setBlockMetadataWithNotify(x+11, y+0, z+3, 3, 3);
		world.setBlock(x+12, y+0, z+3, Block.getBlockById(1));
		world.setBlockMetadataWithNotify(x+12, y+0, z+3, 3, 3);
		world.setBlock(x+13, y+0, z+3, Block.getBlockById(1));
		world.setBlock(x+14, y+0, z+3, Block.getBlockById(98));
		world.setBlock(x+15, y+0, z+3, Block.getBlockById(98));
		world.setBlock(x+18, y+0, z+3, Block.getBlockById(1));
		world.setBlock(x+19, y+0, z+3, Block.getBlockById(159));
		world.setBlockMetadataWithNotify(x+19, y+0, z+3, 8, 8);
		world.setBlock(x+20, y+0, z+3, Block.getBlockById(159));
		world.setBlockMetadataWithNotify(x+20, y+0, z+3, 8, 8);
		world.setBlock(x+21, y+0, z+3, Block.getBlockById(159));
		world.setBlockMetadataWithNotify(x+21, y+0, z+3, 8, 8);
		world.setBlock(x+22, y+0, z+3, Block.getBlockById(159));
		world.setBlockMetadataWithNotify(x+22, y+0, z+3, 8, 8);
		world.setBlock(x+23, y+0, z+3, Block.getBlockById(159));
		world.setBlockMetadataWithNotify(x+23, y+0, z+3, 8, 8);
		world.setBlock(x+24, y+0, z+3, Block.getBlockById(159));
		world.setBlockMetadataWithNotify(x+24, y+0, z+3, 8, 8);
		world.setBlock(x+25, y+0, z+3, Block.getBlockById(159));
		world.setBlockMetadataWithNotify(x+25, y+0, z+3, 8, 8);
		world.setBlock(x+26, y+0, z+3, Block.getBlockById(1));
		world.setBlock(x+29, y+0, z+3, Block.getBlockById(98));
		world.setBlock(x+30, y+0, z+3, Block.getBlockById(98));
		world.setBlock(x+31, y+0, z+3, Block.getBlockById(12));
		world.setBlock(x+32, y+0, z+3, Block.getBlockById(12));
		world.setBlock(x+33, y+0, z+3, Block.getBlockById(12));
		world.setBlock(x+34, y+0, z+3, Block.getBlockById(12));
		world.setBlock(x+35, y+0, z+3, Block.getBlockById(12));
		world.setBlock(x+36, y+0, z+3, Block.getBlockById(12));
		world.setBlock(x+37, y+0, z+3, Block.getBlockById(12));
		world.setBlock(x+38, y+0, z+3, Block.getBlockById(12));
		world.setBlock(x+39, y+0, z+3, Block.getBlockById(12));
		world.setBlock(x+40, y+0, z+3, Block.getBlockById(12));
		world.setBlock(x+41, y+0, z+3, Block.getBlockById(98));
		world.setBlock(x+42, y+0, z+3, Block.getBlockById(98));
		world.setBlock(x+43, y+0, z+3, Block.getBlockById(98));
		world.setBlock(x+1, y+0, z+4, Block.getBlockById(98));
		world.setBlock(x+2, y+0, z+4, Block.getBlockById(1));
		world.setBlock(x+3, y+0, z+4, Block.getBlockById(1));
		world.setBlockMetadataWithNotify(x+3, y+0, z+4, 3, 3);
		world.setBlock(x+4, y+0, z+4, Block.getBlockById(1));
		world.setBlockMetadataWithNotify(x+4, y+0, z+4, 3, 3);
		world.setBlock(x+5, y+0, z+4, Block.getBlockById(1));
		world.setBlockMetadataWithNotify(x+5, y+0, z+4, 3, 3);
		world.setBlock(x+6, y+0, z+4, Block.getBlockById(1));
		world.setBlockMetadataWithNotify(x+6, y+0, z+4, 3, 3);
		world.setBlock(x+7, y+0, z+4, Block.getBlockById(1));
		world.setBlockMetadataWithNotify(x+7, y+0, z+4, 3, 3);
		world.setBlock(x+8, y+0, z+4, Block.getBlockById(1));
		world.setBlockMetadataWithNotify(x+8, y+0, z+4, 3, 3);
		world.setBlock(x+9, y+0, z+4, Block.getBlockById(1));
		world.setBlockMetadataWithNotify(x+9, y+0, z+4, 3, 3);
		world.setBlock(x+10, y+0, z+4, Block.getBlockById(1));
		world.setBlockMetadataWithNotify(x+10, y+0, z+4, 3, 3);
		world.setBlock(x+11, y+0, z+4, Block.getBlockById(1));
		world.setBlockMetadataWithNotify(x+11, y+0, z+4, 3, 3);
		world.setBlock(x+12, y+0, z+4, Block.getBlockById(1));
		world.setBlockMetadataWithNotify(x+12, y+0, z+4, 3, 3);
		world.setBlock(x+13, y+0, z+4, Block.getBlockById(1));
		world.setBlockMetadataWithNotify(x+13, y+0, z+4, 3, 3);
		world.setBlock(x+14, y+0, z+4, Block.getBlockById(1));
		world.setBlock(x+15, y+0, z+4, Block.getBlockById(98));
		world.setBlock(x+18, y+0, z+4, Block.getBlockById(1));
		world.setBlock(x+19, y+0, z+4, Block.getBlockById(159));
		world.setBlockMetadataWithNotify(x+19, y+0, z+4, 8, 8);
		world.setBlock(x+20, y+0, z+4, Block.getBlockById(159));
		world.setBlockMetadataWithNotify(x+20, y+0, z+4, 8, 8);
		world.setBlock(x+21, y+0, z+4, Block.getBlockById(159));
		world.setBlockMetadataWithNotify(x+21, y+0, z+4, 8, 8);
		world.setBlock(x+22, y+0, z+4, Block.getBlockById(159));
		world.setBlockMetadataWithNotify(x+22, y+0, z+4, 8, 8);
		world.setBlock(x+23, y+0, z+4, Block.getBlockById(159));
		world.setBlockMetadataWithNotify(x+23, y+0, z+4, 8, 8);
		world.setBlock(x+24, y+0, z+4, Block.getBlockById(159));
		world.setBlockMetadataWithNotify(x+24, y+0, z+4, 8, 8);
		world.setBlock(x+25, y+0, z+4, Block.getBlockById(159));
		world.setBlockMetadataWithNotify(x+25, y+0, z+4, 8, 8);
		world.setBlock(x+26, y+0, z+4, Block.getBlockById(1));
		world.setBlock(x+29, y+0, z+4, Block.getBlockById(98));
		world.setBlock(x+30, y+0, z+4, Block.getBlockById(12));
		world.setBlock(x+31, y+0, z+4, Block.getBlockById(12));
		world.setBlock(x+32, y+0, z+4, Block.getBlockById(1));
		world.setBlockMetadataWithNotify(x+32, y+0, z+4, 3, 3);
		world.setBlock(x+33, y+0, z+4, Block.getBlockById(1));
		world.setBlockMetadataWithNotify(x+33, y+0, z+4, 3, 3);
		world.setBlock(x+34, y+0, z+4, Block.getBlockById(1));
		world.setBlockMetadataWithNotify(x+34, y+0, z+4, 3, 3);
		world.setBlock(x+35, y+0, z+4, Block.getBlockById(1));
		world.setBlockMetadataWithNotify(x+35, y+0, z+4, 3, 3);
		world.setBlock(x+36, y+0, z+4, Block.getBlockById(1));
		world.setBlockMetadataWithNotify(x+36, y+0, z+4, 3, 3);
		world.setBlock(x+37, y+0, z+4, Block.getBlockById(1));
		world.setBlockMetadataWithNotify(x+37, y+0, z+4, 3, 3);
		world.setBlock(x+38, y+0, z+4, Block.getBlockById(1));
		world.setBlockMetadataWithNotify(x+38, y+0, z+4, 3, 3);
		world.setBlock(x+39, y+0, z+4, Block.getBlockById(1));
		world.setBlockMetadataWithNotify(x+39, y+0, z+4, 3, 3);
		world.setBlock(x+40, y+0, z+4, Block.getBlockById(1));
		world.setBlockMetadataWithNotify(x+40, y+0, z+4, 3, 3);
		world.setBlock(x+41, y+0, z+4, Block.getBlockById(1));
		world.setBlockMetadataWithNotify(x+41, y+0, z+4, 3, 3);
		world.setBlock(x+42, y+0, z+4, Block.getBlockById(98));
		world.setBlock(x+43, y+0, z+4, Block.getBlockById(98));
		world.setBlock(x+0, y+0, z+5, Block.getBlockById(98));
		world.setBlock(x+1, y+0, z+5, Block.getBlockById(98));
		world.setBlock(x+2, y+0, z+5, Block.getBlockById(1));
		world.setBlock(x+3, y+0, z+5, Block.getBlockById(1));
		world.setBlockMetadataWithNotify(x+3, y+0, z+5, 3, 3);
		world.setBlock(x+4, y+0, z+5, Block.getBlockById(1));
		world.setBlockMetadataWithNotify(x+4, y+0, z+5, 3, 3);
		world.setBlock(x+5, y+0, z+5, Block.getBlockById(1));
		world.setBlockMetadataWithNotify(x+5, y+0, z+5, 3, 3);
		world.setBlock(x+6, y+0, z+5, Block.getBlockById(1));
		world.setBlockMetadataWithNotify(x+6, y+0, z+5, 3, 3);
		world.setBlock(x+7, y+0, z+5, Block.getBlockById(1));
		world.setBlockMetadataWithNotify(x+7, y+0, z+5, 3, 3);
		world.setBlock(x+8, y+0, z+5, Block.getBlockById(1));
		world.setBlockMetadataWithNotify(x+8, y+0, z+5, 3, 3);
		world.setBlock(x+9, y+0, z+5, Block.getBlockById(1));
		world.setBlockMetadataWithNotify(x+9, y+0, z+5, 3, 3);
		world.setBlock(x+10, y+0, z+5, Block.getBlockById(1));
		world.setBlockMetadataWithNotify(x+10, y+0, z+5, 3, 3);
		world.setBlock(x+11, y+0, z+5, Block.getBlockById(1));
		world.setBlockMetadataWithNotify(x+11, y+0, z+5, 3, 3);
		world.setBlock(x+12, y+0, z+5, Block.getBlockById(1));
		world.setBlockMetadataWithNotify(x+12, y+0, z+5, 3, 3);
		world.setBlock(x+13, y+0, z+5, Block.getBlockById(1));
		world.setBlockMetadataWithNotify(x+13, y+0, z+5, 3, 3);
		world.setBlock(x+14, y+0, z+5, Block.getBlockById(1));
		world.setBlock(x+15, y+0, z+5, Block.getBlockById(98));
		world.setBlock(x+16, y+0, z+5, Block.getBlockById(98));
		world.setBlock(x+17, y+0, z+5, Block.getBlockById(98));
		world.setBlock(x+18, y+0, z+5, Block.getBlockById(1));
		world.setBlock(x+19, y+0, z+5, Block.getBlockById(1));
		world.setBlock(x+20, y+0, z+5, Block.getBlockById(1));
		world.setBlockMetadataWithNotify(x+20, y+0, z+5, 6, 6);
		world.setBlock(x+21, y+0, z+5, Block.getBlockById(1));
		world.setBlockMetadataWithNotify(x+21, y+0, z+5, 6, 6);
		world.setBlock(x+22, y+0, z+5, Block.getBlockById(1));
		world.setBlockMetadataWithNotify(x+22, y+0, z+5, 6, 6);
		world.setBlock(x+23, y+0, z+5, Block.getBlockById(1));
		world.setBlockMetadataWithNotify(x+23, y+0, z+5, 6, 6);
		world.setBlock(x+24, y+0, z+5, Block.getBlockById(1));
		world.setBlockMetadataWithNotify(x+24, y+0, z+5, 6, 6);
		world.setBlock(x+25, y+0, z+5, Block.getBlockById(1));
		world.setBlockMetadataWithNotify(x+25, y+0, z+5, 6, 6);
		world.setBlock(x+26, y+0, z+5, Block.getBlockById(1));
		world.setBlock(x+27, y+0, z+5, Block.getBlockById(98));
		world.setBlock(x+28, y+0, z+5, Block.getBlockById(98));
		world.setBlock(x+29, y+0, z+5, Block.getBlockById(98));
		world.setBlock(x+30, y+0, z+5, Block.getBlockById(12));
		world.setBlock(x+31, y+0, z+5, Block.getBlockById(12));
		world.setBlock(x+32, y+0, z+5, Block.getBlockById(1));
		world.setBlockMetadataWithNotify(x+32, y+0, z+5, 3, 3);
		world.setBlock(x+33, y+0, z+5, Block.getBlockById(1));
		world.setBlockMetadataWithNotify(x+33, y+0, z+5, 3, 3);
		world.setBlock(x+34, y+0, z+5, Block.getBlockById(1));
		world.setBlockMetadataWithNotify(x+34, y+0, z+5, 3, 3);
		world.setBlock(x+35, y+0, z+5, Block.getBlockById(1));
		world.setBlockMetadataWithNotify(x+35, y+0, z+5, 3, 3);
		world.setBlock(x+36, y+0, z+5, Block.getBlockById(1));
		world.setBlockMetadataWithNotify(x+36, y+0, z+5, 3, 3);
		world.setBlock(x+37, y+0, z+5, Block.getBlockById(1));
		world.setBlockMetadataWithNotify(x+37, y+0, z+5, 3, 3);
		world.setBlock(x+38, y+0, z+5, Block.getBlockById(1));
		world.setBlockMetadataWithNotify(x+38, y+0, z+5, 3, 3);
		world.setBlock(x+39, y+0, z+5, Block.getBlockById(1));
		world.setBlockMetadataWithNotify(x+39, y+0, z+5, 3, 3);
		world.setBlock(x+40, y+0, z+5, Block.getBlockById(1));
		world.setBlockMetadataWithNotify(x+40, y+0, z+5, 3, 3);
		world.setBlock(x+41, y+0, z+5, Block.getBlockById(1));
		world.setBlockMetadataWithNotify(x+41, y+0, z+5, 3, 3);
		world.setBlock(x+42, y+0, z+5, Block.getBlockById(98));
		world.setBlock(x+43, y+0, z+5, Block.getBlockById(98));
		world.setBlock(x+44, y+0, z+5, Block.getBlockById(98));
		world.setBlock(x+0, y+0, z+6, Block.getBlockById(98));
		world.setBlock(x+1, y+0, z+6, Block.getBlockById(1));
		world.setBlock(x+2, y+0, z+6, Block.getBlockById(1));
		world.setBlockMetadataWithNotify(x+2, y+0, z+6, 3, 3);
		world.setBlock(x+3, y+0, z+6, Block.getBlockById(1));
		world.setBlockMetadataWithNotify(x+3, y+0, z+6, 3, 3);
		world.setBlock(x+4, y+0, z+6, Block.getBlockById(1));
		world.setBlockMetadataWithNotify(x+4, y+0, z+6, 3, 3);
		world.setBlock(x+5, y+0, z+6, Block.getBlockById(1));
		world.setBlockMetadataWithNotify(x+5, y+0, z+6, 3, 3);
		world.setBlock(x+6, y+0, z+6, Block.getBlockById(1));
		world.setBlockMetadataWithNotify(x+6, y+0, z+6, 3, 3);
		world.setBlock(x+7, y+0, z+6, Block.getBlockById(1));
		world.setBlockMetadataWithNotify(x+7, y+0, z+6, 3, 3);
		world.setBlock(x+8, y+0, z+6, Block.getBlockById(1));
		world.setBlockMetadataWithNotify(x+8, y+0, z+6, 3, 3);
		world.setBlock(x+9, y+0, z+6, Block.getBlockById(1));
		world.setBlockMetadataWithNotify(x+9, y+0, z+6, 3, 3);
		world.setBlock(x+10, y+0, z+6, Block.getBlockById(1));
		world.setBlockMetadataWithNotify(x+10, y+0, z+6, 3, 3);
		world.setBlock(x+11, y+0, z+6, Block.getBlockById(1));
		world.setBlockMetadataWithNotify(x+11, y+0, z+6, 3, 3);
		world.setBlock(x+12, y+0, z+6, Block.getBlockById(1));
		world.setBlockMetadataWithNotify(x+12, y+0, z+6, 3, 3);
		world.setBlock(x+13, y+0, z+6, Block.getBlockById(1));
		world.setBlockMetadataWithNotify(x+13, y+0, z+6, 3, 3);
		world.setBlock(x+14, y+0, z+6, Block.getBlockById(1));
		world.setBlockMetadataWithNotify(x+14, y+0, z+6, 3, 3);
		world.setBlock(x+15, y+0, z+6, Block.getBlockById(1));
		world.setBlock(x+16, y+0, z+6, Block.getBlockById(1));
		world.setBlock(x+17, y+0, z+6, Block.getBlockById(1));
		world.setBlock(x+18, y+0, z+6, Block.getBlockById(1));
		world.setBlock(x+19, y+0, z+6, Block.getBlockById(1));
		world.setBlock(x+20, y+0, z+6, Block.getBlockById(1));
		world.setBlockMetadataWithNotify(x+20, y+0, z+6, 6, 6);
		world.setBlock(x+21, y+0, z+6, Block.getBlockById(1));
		world.setBlockMetadataWithNotify(x+21, y+0, z+6, 6, 6);
		world.setBlock(x+22, y+0, z+6, Block.getBlockById(1));
		world.setBlockMetadataWithNotify(x+22, y+0, z+6, 6, 6);
		world.setBlock(x+23, y+0, z+6, Block.getBlockById(1));
		world.setBlockMetadataWithNotify(x+23, y+0, z+6, 6, 6);
		world.setBlock(x+24, y+0, z+6, Block.getBlockById(1));
		world.setBlockMetadataWithNotify(x+24, y+0, z+6, 6, 6);
		world.setBlock(x+25, y+0, z+6, Block.getBlockById(1));
		world.setBlockMetadataWithNotify(x+25, y+0, z+6, 6, 6);
		world.setBlock(x+26, y+0, z+6, Block.getBlockById(1));
		world.setBlock(x+27, y+0, z+6, Block.getBlockById(12));
		world.setBlock(x+28, y+0, z+6, Block.getBlockById(12));
		world.setBlock(x+29, y+0, z+6, Block.getBlockById(12));
		world.setBlock(x+30, y+0, z+6, Block.getBlockById(12));
		world.setBlock(x+31, y+0, z+6, Block.getBlockById(12));
		world.setBlock(x+32, y+0, z+6, Block.getBlockById(1));
		world.setBlockMetadataWithNotify(x+32, y+0, z+6, 3, 3);
		world.setBlock(x+33, y+0, z+6, Block.getBlockById(1));
		world.setBlockMetadataWithNotify(x+33, y+0, z+6, 3, 3);
		world.setBlock(x+34, y+0, z+6, Block.getBlockById(1));
		world.setBlockMetadataWithNotify(x+34, y+0, z+6, 3, 3);
		world.setBlock(x+35, y+0, z+6, Block.getBlockById(1));
		world.setBlockMetadataWithNotify(x+35, y+0, z+6, 3, 3);
		world.setBlock(x+36, y+0, z+6, Block.getBlockById(1));
		world.setBlockMetadataWithNotify(x+36, y+0, z+6, 3, 3);
		world.setBlock(x+37, y+0, z+6, Block.getBlockById(1));
		world.setBlockMetadataWithNotify(x+37, y+0, z+6, 3, 3);
		world.setBlock(x+38, y+0, z+6, Block.getBlockById(1));
		world.setBlockMetadataWithNotify(x+38, y+0, z+6, 3, 3);
		world.setBlock(x+39, y+0, z+6, Block.getBlockById(1));
		world.setBlockMetadataWithNotify(x+39, y+0, z+6, 3, 3);
		world.setBlock(x+40, y+0, z+6, Block.getBlockById(1));
		world.setBlockMetadataWithNotify(x+40, y+0, z+6, 3, 3);
		world.setBlock(x+41, y+0, z+6, Block.getBlockById(1));
		world.setBlockMetadataWithNotify(x+41, y+0, z+6, 3, 3);
		world.setBlock(x+42, y+0, z+6, Block.getBlockById(1));
		world.setBlockMetadataWithNotify(x+42, y+0, z+6, 3, 3);
		world.setBlock(x+43, y+0, z+6, Block.getBlockById(98));
		world.setBlock(x+44, y+0, z+6, Block.getBlockById(98));
		world.setBlock(x+0, y+0, z+7, Block.getBlockById(98));
		world.setBlock(x+1, y+0, z+7, Block.getBlockById(1));
		world.setBlock(x+2, y+0, z+7, Block.getBlockById(1));
		world.setBlockMetadataWithNotify(x+2, y+0, z+7, 3, 3);
		world.setBlock(x+3, y+0, z+7, Block.getBlockById(1));
		world.setBlockMetadataWithNotify(x+3, y+0, z+7, 3, 3);
		world.setBlock(x+4, y+0, z+7, Block.getBlockById(1));
		world.setBlockMetadataWithNotify(x+4, y+0, z+7, 3, 3);
		world.setBlock(x+5, y+0, z+7, Block.getBlockById(1));
		world.setBlockMetadataWithNotify(x+5, y+0, z+7, 3, 3);
		world.setBlock(x+6, y+0, z+7, Block.getBlockById(1));
		world.setBlockMetadataWithNotify(x+6, y+0, z+7, 3, 3);
		world.setBlock(x+7, y+0, z+7, Block.getBlockById(1));
		world.setBlockMetadataWithNotify(x+7, y+0, z+7, 3, 3);
		world.setBlock(x+8, y+0, z+7, Block.getBlockById(1));
		world.setBlockMetadataWithNotify(x+8, y+0, z+7, 3, 3);
		world.setBlock(x+9, y+0, z+7, Block.getBlockById(1));
		world.setBlockMetadataWithNotify(x+9, y+0, z+7, 3, 3);
		world.setBlock(x+10, y+0, z+7, Block.getBlockById(1));
		world.setBlockMetadataWithNotify(x+10, y+0, z+7, 3, 3);
		world.setBlock(x+11, y+0, z+7, Block.getBlockById(1));
		world.setBlockMetadataWithNotify(x+11, y+0, z+7, 3, 3);
		world.setBlock(x+12, y+0, z+7, Block.getBlockById(1));
		world.setBlockMetadataWithNotify(x+12, y+0, z+7, 3, 3);
		world.setBlock(x+13, y+0, z+7, Block.getBlockById(1));
		world.setBlockMetadataWithNotify(x+13, y+0, z+7, 3, 3);
		world.setBlock(x+14, y+0, z+7, Block.getBlockById(1));
		world.setBlockMetadataWithNotify(x+14, y+0, z+7, 3, 3);
		world.setBlock(x+15, y+0, z+7, Block.getBlockById(1));
		world.setBlockMetadataWithNotify(x+15, y+0, z+7, 3, 3);
		world.setBlock(x+16, y+0, z+7, Block.getBlockById(1));
		world.setBlockMetadataWithNotify(x+16, y+0, z+7, 3, 3);
		world.setBlock(x+17, y+0, z+7, Block.getBlockById(1));
		world.setBlockMetadataWithNotify(x+17, y+0, z+7, 3, 3);
		world.setBlock(x+18, y+0, z+7, Block.getBlockById(1));
		world.setBlock(x+19, y+0, z+7, Block.getBlockById(1));
		world.setBlock(x+20, y+0, z+7, Block.getBlockById(1));
		world.setBlockMetadataWithNotify(x+20, y+0, z+7, 6, 6);
		world.setBlock(x+21, y+0, z+7, Block.getBlockById(1));
		world.setBlockMetadataWithNotify(x+21, y+0, z+7, 6, 6);
		world.setBlock(x+22, y+0, z+7, Block.getBlockById(1));
		world.setBlockMetadataWithNotify(x+22, y+0, z+7, 6, 6);
		world.setBlock(x+23, y+0, z+7, Block.getBlockById(1));
		world.setBlockMetadataWithNotify(x+23, y+0, z+7, 6, 6);
		world.setBlock(x+24, y+0, z+7, Block.getBlockById(1));
		world.setBlockMetadataWithNotify(x+24, y+0, z+7, 6, 6);
		world.setBlock(x+25, y+0, z+7, Block.getBlockById(1));
		world.setBlockMetadataWithNotify(x+25, y+0, z+7, 6, 6);
		world.setBlock(x+26, y+0, z+7, Block.getBlockById(1));
		world.setBlock(x+27, y+0, z+7, Block.getBlockById(1));
		world.setBlockMetadataWithNotify(x+27, y+0, z+7, 3, 3);
		world.setBlock(x+28, y+0, z+7, Block.getBlockById(1));
		world.setBlockMetadataWithNotify(x+28, y+0, z+7, 3, 3);
		world.setBlock(x+29, y+0, z+7, Block.getBlockById(1));
		world.setBlockMetadataWithNotify(x+29, y+0, z+7, 3, 3);
		world.setBlock(x+30, y+0, z+7, Block.getBlockById(1));
		world.setBlockMetadataWithNotify(x+30, y+0, z+7, 3, 3);
		world.setBlock(x+31, y+0, z+7, Block.getBlockById(1));
		world.setBlockMetadataWithNotify(x+31, y+0, z+7, 3, 3);
		world.setBlock(x+32, y+0, z+7, Block.getBlockById(1));
		world.setBlockMetadataWithNotify(x+32, y+0, z+7, 3, 3);
		world.setBlock(x+33, y+0, z+7, Block.getBlockById(1));
		world.setBlockMetadataWithNotify(x+33, y+0, z+7, 3, 3);
		world.setBlock(x+34, y+0, z+7, Block.getBlockById(1));
		world.setBlockMetadataWithNotify(x+34, y+0, z+7, 3, 3);
		world.setBlock(x+35, y+0, z+7, Block.getBlockById(1));
		world.setBlockMetadataWithNotify(x+35, y+0, z+7, 3, 3);
		world.setBlock(x+36, y+0, z+7, Block.getBlockById(1));
		world.setBlockMetadataWithNotify(x+36, y+0, z+7, 3, 3);
		world.setBlock(x+37, y+0, z+7, Block.getBlockById(1));
		world.setBlockMetadataWithNotify(x+37, y+0, z+7, 3, 3);
		world.setBlock(x+38, y+0, z+7, Block.getBlockById(1));
		world.setBlockMetadataWithNotify(x+38, y+0, z+7, 3, 3);
		world.setBlock(x+39, y+0, z+7, Block.getBlockById(1));
		world.setBlockMetadataWithNotify(x+39, y+0, z+7, 3, 3);
		world.setBlock(x+40, y+0, z+7, Block.getBlockById(1));
		world.setBlockMetadataWithNotify(x+40, y+0, z+7, 3, 3);
		world.setBlock(x+41, y+0, z+7, Block.getBlockById(1));
		world.setBlockMetadataWithNotify(x+41, y+0, z+7, 3, 3);
		world.setBlock(x+42, y+0, z+7, Block.getBlockById(1));
		world.setBlockMetadataWithNotify(x+42, y+0, z+7, 3, 3);
		world.setBlock(x+43, y+0, z+7, Block.getBlockById(98));
		world.setBlock(x+44, y+0, z+7, Block.getBlockById(98));
		world.setBlock(x+0, y+0, z+8, Block.getBlockById(98));
		world.setBlock(x+1, y+0, z+8, Block.getBlockById(1));
		world.setBlock(x+2, y+0, z+8, Block.getBlockById(1));
		world.setBlockMetadataWithNotify(x+2, y+0, z+8, 3, 3);
		world.setBlock(x+3, y+0, z+8, Block.getBlockById(1));
		world.setBlockMetadataWithNotify(x+3, y+0, z+8, 3, 3);
		world.setBlock(x+4, y+0, z+8, Block.getBlockById(1));
		world.setBlockMetadataWithNotify(x+4, y+0, z+8, 3, 3);
		world.setBlock(x+5, y+0, z+8, Block.getBlockById(1));
		world.setBlockMetadataWithNotify(x+5, y+0, z+8, 3, 3);
		world.setBlock(x+6, y+0, z+8, Block.getBlockById(1));
		world.setBlockMetadataWithNotify(x+6, y+0, z+8, 3, 3);
		world.setBlock(x+7, y+0, z+8, Block.getBlockById(1));
		world.setBlockMetadataWithNotify(x+7, y+0, z+8, 3, 3);
		world.setBlock(x+8, y+0, z+8, Block.getBlockById(124));
		world.setBlock(x+9, y+0, z+8, Block.getBlockById(1));
		world.setBlockMetadataWithNotify(x+9, y+0, z+8, 3, 3);
		world.setBlock(x+10, y+0, z+8, Block.getBlockById(1));
		world.setBlockMetadataWithNotify(x+10, y+0, z+8, 3, 3);
		world.setBlock(x+11, y+0, z+8, Block.getBlockById(1));
		world.setBlockMetadataWithNotify(x+11, y+0, z+8, 3, 3);
		world.setBlock(x+12, y+0, z+8, Block.getBlockById(1));
		world.setBlockMetadataWithNotify(x+12, y+0, z+8, 3, 3);
		world.setBlock(x+13, y+0, z+8, Block.getBlockById(1));
		world.setBlockMetadataWithNotify(x+13, y+0, z+8, 3, 3);
		world.setBlock(x+14, y+0, z+8, Block.getBlockById(1));
		world.setBlockMetadataWithNotify(x+14, y+0, z+8, 3, 3);
		world.setBlock(x+15, y+0, z+8, Block.getBlockById(1));
		world.setBlockMetadataWithNotify(x+15, y+0, z+8, 3, 3);
		world.setBlock(x+16, y+0, z+8, Block.getBlockById(1));
		world.setBlockMetadataWithNotify(x+16, y+0, z+8, 3, 3);
		world.setBlock(x+17, y+0, z+8, Block.getBlockById(1));
		world.setBlockMetadataWithNotify(x+17, y+0, z+8, 3, 3);
		world.setBlock(x+18, y+0, z+8, Block.getBlockById(1));
		world.setBlock(x+19, y+0, z+8, Block.getBlockById(1));
		world.setBlock(x+20, y+0, z+8, Block.getBlockById(1));
		world.setBlockMetadataWithNotify(x+20, y+0, z+8, 6, 6);
		world.setBlock(x+21, y+0, z+8, Block.getBlockById(1));
		world.setBlockMetadataWithNotify(x+21, y+0, z+8, 6, 6);
		world.setBlock(x+22, y+0, z+8, Block.getBlockById(1));
		world.setBlockMetadataWithNotify(x+22, y+0, z+8, 6, 6);
		world.setBlock(x+23, y+0, z+8, Block.getBlockById(1));
		world.setBlockMetadataWithNotify(x+23, y+0, z+8, 6, 6);
		world.setBlock(x+24, y+0, z+8, Block.getBlockById(1));
		world.setBlockMetadataWithNotify(x+24, y+0, z+8, 6, 6);
		world.setBlock(x+25, y+0, z+8, Block.getBlockById(1));
		world.setBlockMetadataWithNotify(x+25, y+0, z+8, 6, 6);
		world.setBlock(x+26, y+0, z+8, Block.getBlockById(1));
		world.setBlock(x+27, y+0, z+8, Block.getBlockById(1));
		world.setBlockMetadataWithNotify(x+27, y+0, z+8, 3, 3);
		world.setBlock(x+28, y+0, z+8, Block.getBlockById(1));
		world.setBlockMetadataWithNotify(x+28, y+0, z+8, 3, 3);
		world.setBlock(x+29, y+0, z+8, Block.getBlockById(1));
		world.setBlockMetadataWithNotify(x+29, y+0, z+8, 3, 3);
		world.setBlock(x+30, y+0, z+8, Block.getBlockById(1));
		world.setBlockMetadataWithNotify(x+30, y+0, z+8, 3, 3);
		world.setBlock(x+31, y+0, z+8, Block.getBlockById(1));
		world.setBlockMetadataWithNotify(x+31, y+0, z+8, 3, 3);
		world.setBlock(x+32, y+0, z+8, Block.getBlockById(1));
		world.setBlockMetadataWithNotify(x+32, y+0, z+8, 3, 3);
		world.setBlock(x+33, y+0, z+8, Block.getBlockById(1));
		world.setBlockMetadataWithNotify(x+33, y+0, z+8, 3, 3);
		world.setBlock(x+34, y+0, z+8, Block.getBlockById(1));
		world.setBlockMetadataWithNotify(x+34, y+0, z+8, 3, 3);
		world.setBlock(x+35, y+0, z+8, Block.getBlockById(1));
		world.setBlockMetadataWithNotify(x+35, y+0, z+8, 3, 3);
		world.setBlock(x+36, y+0, z+8, Block.getBlockById(124));
		world.setBlock(x+37, y+0, z+8, Block.getBlockById(1));
		world.setBlockMetadataWithNotify(x+37, y+0, z+8, 3, 3);
		world.setBlock(x+38, y+0, z+8, Block.getBlockById(1));
		world.setBlockMetadataWithNotify(x+38, y+0, z+8, 3, 3);
		world.setBlock(x+39, y+0, z+8, Block.getBlockById(1));
		world.setBlockMetadataWithNotify(x+39, y+0, z+8, 3, 3);
		world.setBlock(x+40, y+0, z+8, Block.getBlockById(1));
		world.setBlockMetadataWithNotify(x+40, y+0, z+8, 3, 3);
		world.setBlock(x+41, y+0, z+8, Block.getBlockById(1));
		world.setBlockMetadataWithNotify(x+41, y+0, z+8, 3, 3);
		world.setBlock(x+42, y+0, z+8, Block.getBlockById(1));
		world.setBlockMetadataWithNotify(x+42, y+0, z+8, 3, 3);
		world.setBlock(x+43, y+0, z+8, Block.getBlockById(98));
		world.setBlock(x+44, y+0, z+8, Block.getBlockById(98));
		world.setBlock(x+0, y+0, z+9, Block.getBlockById(98));
		world.setBlock(x+1, y+0, z+9, Block.getBlockById(1));
		world.setBlock(x+2, y+0, z+9, Block.getBlockById(1));
		world.setBlockMetadataWithNotify(x+2, y+0, z+9, 3, 3);
		world.setBlock(x+3, y+0, z+9, Block.getBlockById(1));
		world.setBlockMetadataWithNotify(x+3, y+0, z+9, 3, 3);
		world.setBlock(x+4, y+0, z+9, Block.getBlockById(1));
		world.setBlockMetadataWithNotify(x+4, y+0, z+9, 3, 3);
		world.setBlock(x+5, y+0, z+9, Block.getBlockById(1));
		world.setBlockMetadataWithNotify(x+5, y+0, z+9, 3, 3);
		world.setBlock(x+6, y+0, z+9, Block.getBlockById(1));
		world.setBlockMetadataWithNotify(x+6, y+0, z+9, 3, 3);
		world.setBlock(x+7, y+0, z+9, Block.getBlockById(1));
		world.setBlockMetadataWithNotify(x+7, y+0, z+9, 3, 3);
		world.setBlock(x+8, y+0, z+9, Block.getBlockById(1));
		world.setBlockMetadataWithNotify(x+8, y+0, z+9, 3, 3);
		world.setBlock(x+9, y+0, z+9, Block.getBlockById(1));
		world.setBlockMetadataWithNotify(x+9, y+0, z+9, 3, 3);
		world.setBlock(x+10, y+0, z+9, Block.getBlockById(1));
		world.setBlockMetadataWithNotify(x+10, y+0, z+9, 3, 3);
		world.setBlock(x+11, y+0, z+9, Block.getBlockById(1));
		world.setBlockMetadataWithNotify(x+11, y+0, z+9, 3, 3);
		world.setBlock(x+12, y+0, z+9, Block.getBlockById(1));
		world.setBlockMetadataWithNotify(x+12, y+0, z+9, 3, 3);
		world.setBlock(x+13, y+0, z+9, Block.getBlockById(1));
		world.setBlockMetadataWithNotify(x+13, y+0, z+9, 3, 3);
		world.setBlock(x+14, y+0, z+9, Block.getBlockById(1));
		world.setBlockMetadataWithNotify(x+14, y+0, z+9, 3, 3);
		world.setBlock(x+15, y+0, z+9, Block.getBlockById(12));
		world.setBlock(x+16, y+0, z+9, Block.getBlockById(98));
		world.setBlock(x+17, y+0, z+9, Block.getBlockById(98));
		world.setBlock(x+18, y+0, z+9, Block.getBlockById(1));
		world.setBlock(x+19, y+0, z+9, Block.getBlockById(1));
		world.setBlock(x+20, y+0, z+9, Block.getBlockById(1));
		world.setBlockMetadataWithNotify(x+20, y+0, z+9, 6, 6);
		world.setBlock(x+21, y+0, z+9, Block.getBlockById(1));
		world.setBlockMetadataWithNotify(x+21, y+0, z+9, 6, 6);
		world.setBlock(x+22, y+0, z+9, Block.getBlockById(1));
		world.setBlockMetadataWithNotify(x+22, y+0, z+9, 6, 6);
		world.setBlock(x+23, y+0, z+9, Block.getBlockById(1));
		world.setBlockMetadataWithNotify(x+23, y+0, z+9, 6, 6);
		world.setBlock(x+24, y+0, z+9, Block.getBlockById(1));
		world.setBlockMetadataWithNotify(x+24, y+0, z+9, 6, 6);
		world.setBlock(x+25, y+0, z+9, Block.getBlockById(1));
		world.setBlockMetadataWithNotify(x+25, y+0, z+9, 6, 6);
		world.setBlock(x+26, y+0, z+9, Block.getBlockById(1));
		world.setBlock(x+27, y+0, z+9, Block.getBlockById(98));
		world.setBlock(x+28, y+0, z+9, Block.getBlockById(98));
		world.setBlock(x+29, y+0, z+9, Block.getBlockById(12));
		world.setBlock(x+30, y+0, z+9, Block.getBlockById(12));
		world.setBlock(x+31, y+0, z+9, Block.getBlockById(12));
		world.setBlock(x+32, y+0, z+9, Block.getBlockById(1));
		world.setBlockMetadataWithNotify(x+32, y+0, z+9, 3, 3);
		world.setBlock(x+33, y+0, z+9, Block.getBlockById(1));
		world.setBlockMetadataWithNotify(x+33, y+0, z+9, 3, 3);
		world.setBlock(x+34, y+0, z+9, Block.getBlockById(1));
		world.setBlockMetadataWithNotify(x+34, y+0, z+9, 3, 3);
		world.setBlock(x+35, y+0, z+9, Block.getBlockById(1));
		world.setBlockMetadataWithNotify(x+35, y+0, z+9, 3, 3);
		world.setBlock(x+36, y+0, z+9, Block.getBlockById(1));
		world.setBlockMetadataWithNotify(x+36, y+0, z+9, 3, 3);
		world.setBlock(x+37, y+0, z+9, Block.getBlockById(1));
		world.setBlockMetadataWithNotify(x+37, y+0, z+9, 3, 3);
		world.setBlock(x+38, y+0, z+9, Block.getBlockById(1));
		world.setBlockMetadataWithNotify(x+38, y+0, z+9, 3, 3);
		world.setBlock(x+39, y+0, z+9, Block.getBlockById(1));
		world.setBlockMetadataWithNotify(x+39, y+0, z+9, 3, 3);
		world.setBlock(x+40, y+0, z+9, Block.getBlockById(1));
		world.setBlockMetadataWithNotify(x+40, y+0, z+9, 3, 3);
		world.setBlock(x+41, y+0, z+9, Block.getBlockById(1));
		world.setBlockMetadataWithNotify(x+41, y+0, z+9, 3, 3);
		world.setBlock(x+42, y+0, z+9, Block.getBlockById(1));
		world.setBlockMetadataWithNotify(x+42, y+0, z+9, 3, 3);
		world.setBlock(x+43, y+0, z+9, Block.getBlockById(98));
		world.setBlock(x+44, y+0, z+9, Block.getBlockById(98));
		world.setBlock(x+0, y+0, z+10, Block.getBlockById(98));
		world.setBlock(x+1, y+0, z+10, Block.getBlockById(1));
		world.setBlock(x+2, y+0, z+10, Block.getBlockById(1));
		world.setBlockMetadataWithNotify(x+2, y+0, z+10, 3, 3);
		world.setBlock(x+3, y+0, z+10, Block.getBlockById(1));
		world.setBlockMetadataWithNotify(x+3, y+0, z+10, 3, 3);
		world.setBlock(x+4, y+0, z+10, Block.getBlockById(1));
		world.setBlockMetadataWithNotify(x+4, y+0, z+10, 3, 3);
		world.setBlock(x+5, y+0, z+10, Block.getBlockById(1));
		world.setBlockMetadataWithNotify(x+5, y+0, z+10, 3, 3);
		world.setBlock(x+6, y+0, z+10, Block.getBlockById(1));
		world.setBlockMetadataWithNotify(x+6, y+0, z+10, 3, 3);
		world.setBlock(x+7, y+0, z+10, Block.getBlockById(1));
		world.setBlockMetadataWithNotify(x+7, y+0, z+10, 3, 3);
		world.setBlock(x+8, y+0, z+10, Block.getBlockById(1));
		world.setBlockMetadataWithNotify(x+8, y+0, z+10, 3, 3);
		world.setBlock(x+9, y+0, z+10, Block.getBlockById(1));
		world.setBlockMetadataWithNotify(x+9, y+0, z+10, 3, 3);
		world.setBlock(x+10, y+0, z+10, Block.getBlockById(1));
		world.setBlockMetadataWithNotify(x+10, y+0, z+10, 3, 3);
		world.setBlock(x+11, y+0, z+10, Block.getBlockById(1));
		world.setBlockMetadataWithNotify(x+11, y+0, z+10, 3, 3);
		world.setBlock(x+12, y+0, z+10, Block.getBlockById(1));
		world.setBlockMetadataWithNotify(x+12, y+0, z+10, 3, 3);
		world.setBlock(x+13, y+0, z+10, Block.getBlockById(1));
		world.setBlockMetadataWithNotify(x+13, y+0, z+10, 3, 3);
		world.setBlock(x+14, y+0, z+10, Block.getBlockById(1));
		world.setBlockMetadataWithNotify(x+14, y+0, z+10, 3, 3);
		world.setBlock(x+15, y+0, z+10, Block.getBlockById(12));
		world.setBlock(x+16, y+0, z+10, Block.getBlockById(98));
		world.setBlock(x+19, y+0, z+10, Block.getBlockById(1));
		world.setBlockMetadataWithNotify(x+19, y+0, z+10, 5, 5);
		world.setBlock(x+20, y+0, z+10, Block.getBlockById(159));
		world.setBlockMetadataWithNotify(x+20, y+0, z+10, 8, 8);
		world.setBlock(x+21, y+0, z+10, Block.getBlockById(159));
		world.setBlockMetadataWithNotify(x+21, y+0, z+10, 8, 8);
		world.setBlock(x+22, y+0, z+10, Block.getBlockById(159));
		world.setBlockMetadataWithNotify(x+22, y+0, z+10, 8, 8);
		world.setBlock(x+23, y+0, z+10, Block.getBlockById(159));
		world.setBlockMetadataWithNotify(x+23, y+0, z+10, 8, 8);
		world.setBlock(x+24, y+0, z+10, Block.getBlockById(159));
		world.setBlockMetadataWithNotify(x+24, y+0, z+10, 8, 8);
		world.setBlock(x+25, y+0, z+10, Block.getBlockById(1));
		world.setBlockMetadataWithNotify(x+25, y+0, z+10, 5, 5);
		world.setBlock(x+28, y+0, z+10, Block.getBlockById(98));
		world.setBlock(x+29, y+0, z+10, Block.getBlockById(12));
		world.setBlock(x+30, y+0, z+10, Block.getBlockById(12));
		world.setBlock(x+31, y+0, z+10, Block.getBlockById(12));
		world.setBlock(x+32, y+0, z+10, Block.getBlockById(1));
		world.setBlockMetadataWithNotify(x+32, y+0, z+10, 3, 3);
		world.setBlock(x+33, y+0, z+10, Block.getBlockById(1));
		world.setBlockMetadataWithNotify(x+33, y+0, z+10, 3, 3);
		world.setBlock(x+34, y+0, z+10, Block.getBlockById(1));
		world.setBlockMetadataWithNotify(x+34, y+0, z+10, 3, 3);
		world.setBlock(x+35, y+0, z+10, Block.getBlockById(1));
		world.setBlockMetadataWithNotify(x+35, y+0, z+10, 3, 3);
		world.setBlock(x+36, y+0, z+10, Block.getBlockById(1));
		world.setBlockMetadataWithNotify(x+36, y+0, z+10, 3, 3);
		world.setBlock(x+37, y+0, z+10, Block.getBlockById(1));
		world.setBlockMetadataWithNotify(x+37, y+0, z+10, 3, 3);
		world.setBlock(x+38, y+0, z+10, Block.getBlockById(1));
		world.setBlockMetadataWithNotify(x+38, y+0, z+10, 3, 3);
		world.setBlock(x+39, y+0, z+10, Block.getBlockById(1));
		world.setBlockMetadataWithNotify(x+39, y+0, z+10, 3, 3);
		world.setBlock(x+40, y+0, z+10, Block.getBlockById(1));
		world.setBlockMetadataWithNotify(x+40, y+0, z+10, 3, 3);
		world.setBlock(x+41, y+0, z+10, Block.getBlockById(1));
		world.setBlockMetadataWithNotify(x+41, y+0, z+10, 3, 3);
		world.setBlock(x+42, y+0, z+10, Block.getBlockById(1));
		world.setBlockMetadataWithNotify(x+42, y+0, z+10, 3, 3);
		world.setBlock(x+43, y+0, z+10, Block.getBlockById(98));
		world.setBlock(x+44, y+0, z+10, Block.getBlockById(98));
		world.setBlock(x+0, y+0, z+11, Block.getBlockById(98));
		world.setBlock(x+1, y+0, z+11, Block.getBlockById(98));
		world.setBlock(x+2, y+0, z+11, Block.getBlockById(1));
		world.setBlock(x+3, y+0, z+11, Block.getBlockById(1));
		world.setBlockMetadataWithNotify(x+3, y+0, z+11, 3, 3);
		world.setBlock(x+4, y+0, z+11, Block.getBlockById(1));
		world.setBlockMetadataWithNotify(x+4, y+0, z+11, 3, 3);
		world.setBlock(x+5, y+0, z+11, Block.getBlockById(1));
		world.setBlockMetadataWithNotify(x+5, y+0, z+11, 3, 3);
		world.setBlock(x+6, y+0, z+11, Block.getBlockById(1));
		world.setBlockMetadataWithNotify(x+6, y+0, z+11, 3, 3);
		world.setBlock(x+7, y+0, z+11, Block.getBlockById(1));
		world.setBlockMetadataWithNotify(x+7, y+0, z+11, 3, 3);
		world.setBlock(x+8, y+0, z+11, Block.getBlockById(1));
		world.setBlockMetadataWithNotify(x+8, y+0, z+11, 3, 3);
		world.setBlock(x+9, y+0, z+11, Block.getBlockById(1));
		world.setBlockMetadataWithNotify(x+9, y+0, z+11, 3, 3);
		world.setBlock(x+10, y+0, z+11, Block.getBlockById(1));
		world.setBlockMetadataWithNotify(x+10, y+0, z+11, 3, 3);
		world.setBlock(x+11, y+0, z+11, Block.getBlockById(1));
		world.setBlockMetadataWithNotify(x+11, y+0, z+11, 3, 3);
		world.setBlock(x+12, y+0, z+11, Block.getBlockById(1));
		world.setBlockMetadataWithNotify(x+12, y+0, z+11, 3, 3);
		world.setBlock(x+13, y+0, z+11, Block.getBlockById(1));
		world.setBlockMetadataWithNotify(x+13, y+0, z+11, 3, 3);
		world.setBlock(x+14, y+0, z+11, Block.getBlockById(12));
		world.setBlock(x+15, y+0, z+11, Block.getBlockById(98));
		world.setBlock(x+16, y+0, z+11, Block.getBlockById(98));
		world.setBlock(x+19, y+0, z+11, Block.getBlockById(1));
		world.setBlockMetadataWithNotify(x+19, y+0, z+11, 5, 5);
		world.setBlock(x+20, y+0, z+11, Block.getBlockById(159));
		world.setBlockMetadataWithNotify(x+20, y+0, z+11, 8, 8);
		world.setBlock(x+21, y+0, z+11, Block.getBlockById(159));
		world.setBlockMetadataWithNotify(x+21, y+0, z+11, 8, 8);
		world.setBlock(x+22, y+0, z+11, Block.getBlockById(159));
		world.setBlockMetadataWithNotify(x+22, y+0, z+11, 8, 8);
		world.setBlock(x+23, y+0, z+11, Block.getBlockById(159));
		world.setBlockMetadataWithNotify(x+23, y+0, z+11, 8, 8);
		world.setBlock(x+24, y+0, z+11, Block.getBlockById(159));
		world.setBlockMetadataWithNotify(x+24, y+0, z+11, 8, 8);
		world.setBlock(x+25, y+0, z+11, Block.getBlockById(1));
		world.setBlockMetadataWithNotify(x+25, y+0, z+11, 5, 5);
		world.setBlock(x+28, y+0, z+11, Block.getBlockById(98));
		world.setBlock(x+29, y+0, z+11, Block.getBlockById(98));
		world.setBlock(x+30, y+0, z+11, Block.getBlockById(12));
		world.setBlock(x+31, y+0, z+11, Block.getBlockById(12));
		world.setBlock(x+32, y+0, z+11, Block.getBlockById(1));
		world.setBlockMetadataWithNotify(x+32, y+0, z+11, 3, 3);
		world.setBlock(x+33, y+0, z+11, Block.getBlockById(1));
		world.setBlockMetadataWithNotify(x+33, y+0, z+11, 3, 3);
		world.setBlock(x+34, y+0, z+11, Block.getBlockById(1));
		world.setBlockMetadataWithNotify(x+34, y+0, z+11, 3, 3);
		world.setBlock(x+35, y+0, z+11, Block.getBlockById(1));
		world.setBlockMetadataWithNotify(x+35, y+0, z+11, 3, 3);
		world.setBlock(x+36, y+0, z+11, Block.getBlockById(1));
		world.setBlockMetadataWithNotify(x+36, y+0, z+11, 3, 3);
		world.setBlock(x+37, y+0, z+11, Block.getBlockById(1));
		world.setBlockMetadataWithNotify(x+37, y+0, z+11, 3, 3);
		world.setBlock(x+38, y+0, z+11, Block.getBlockById(1));
		world.setBlockMetadataWithNotify(x+38, y+0, z+11, 3, 3);
		world.setBlock(x+39, y+0, z+11, Block.getBlockById(1));
		world.setBlockMetadataWithNotify(x+39, y+0, z+11, 3, 3);
		world.setBlock(x+40, y+0, z+11, Block.getBlockById(1));
		world.setBlockMetadataWithNotify(x+40, y+0, z+11, 3, 3);
		world.setBlock(x+41, y+0, z+11, Block.getBlockById(1));
		world.setBlockMetadataWithNotify(x+41, y+0, z+11, 3, 3);
		world.setBlock(x+42, y+0, z+11, Block.getBlockById(98));
		world.setBlock(x+43, y+0, z+11, Block.getBlockById(98));
		world.setBlock(x+44, y+0, z+11, Block.getBlockById(98));
		world.setBlock(x+1, y+0, z+12, Block.getBlockById(98));
		world.setBlock(x+2, y+0, z+12, Block.getBlockById(1));
		world.setBlock(x+3, y+0, z+12, Block.getBlockById(1));
		world.setBlockMetadataWithNotify(x+3, y+0, z+12, 3, 3);
		world.setBlock(x+4, y+0, z+12, Block.getBlockById(1));
		world.setBlockMetadataWithNotify(x+4, y+0, z+12, 3, 3);
		world.setBlock(x+5, y+0, z+12, Block.getBlockById(1));
		world.setBlockMetadataWithNotify(x+5, y+0, z+12, 3, 3);
		world.setBlock(x+6, y+0, z+12, Block.getBlockById(1));
		world.setBlockMetadataWithNotify(x+6, y+0, z+12, 3, 3);
		world.setBlock(x+7, y+0, z+12, Block.getBlockById(1));
		world.setBlockMetadataWithNotify(x+7, y+0, z+12, 3, 3);
		world.setBlock(x+8, y+0, z+12, Block.getBlockById(1));
		world.setBlockMetadataWithNotify(x+8, y+0, z+12, 3, 3);
		world.setBlock(x+9, y+0, z+12, Block.getBlockById(1));
		world.setBlockMetadataWithNotify(x+9, y+0, z+12, 3, 3);
		world.setBlock(x+10, y+0, z+12, Block.getBlockById(1));
		world.setBlockMetadataWithNotify(x+10, y+0, z+12, 3, 3);
		world.setBlock(x+11, y+0, z+12, Block.getBlockById(1));
		world.setBlockMetadataWithNotify(x+11, y+0, z+12, 3, 3);
		world.setBlock(x+12, y+0, z+12, Block.getBlockById(1));
		world.setBlockMetadataWithNotify(x+12, y+0, z+12, 3, 3);
		world.setBlock(x+13, y+0, z+12, Block.getBlockById(1));
		world.setBlockMetadataWithNotify(x+13, y+0, z+12, 3, 3);
		world.setBlock(x+14, y+0, z+12, Block.getBlockById(12));
		world.setBlock(x+15, y+0, z+12, Block.getBlockById(98));
		world.setBlock(x+19, y+0, z+12, Block.getBlockById(1));
		world.setBlockMetadataWithNotify(x+19, y+0, z+12, 5, 5);
		world.setBlock(x+20, y+0, z+12, Block.getBlockById(159));
		world.setBlockMetadataWithNotify(x+20, y+0, z+12, 8, 8);
		world.setBlock(x+21, y+0, z+12, Block.getBlockById(159));
		world.setBlockMetadataWithNotify(x+21, y+0, z+12, 8, 8);
		world.setBlock(x+22, y+0, z+12, Block.getBlockById(159));
		world.setBlockMetadataWithNotify(x+22, y+0, z+12, 8, 8);
		world.setBlock(x+23, y+0, z+12, Block.getBlockById(159));
		world.setBlockMetadataWithNotify(x+23, y+0, z+12, 8, 8);
		world.setBlock(x+24, y+0, z+12, Block.getBlockById(159));
		world.setBlockMetadataWithNotify(x+24, y+0, z+12, 8, 8);
		world.setBlock(x+25, y+0, z+12, Block.getBlockById(1));
		world.setBlockMetadataWithNotify(x+25, y+0, z+12, 5, 5);
		world.setBlock(x+29, y+0, z+12, Block.getBlockById(98));
		world.setBlock(x+30, y+0, z+12, Block.getBlockById(12));
		world.setBlock(x+31, y+0, z+12, Block.getBlockById(12));
		world.setBlock(x+32, y+0, z+12, Block.getBlockById(12));
		world.setBlock(x+33, y+0, z+12, Block.getBlockById(1));
		world.setBlockMetadataWithNotify(x+33, y+0, z+12, 3, 3);
		world.setBlock(x+34, y+0, z+12, Block.getBlockById(1));
		world.setBlockMetadataWithNotify(x+34, y+0, z+12, 3, 3);
		world.setBlock(x+35, y+0, z+12, Block.getBlockById(1));
		world.setBlockMetadataWithNotify(x+35, y+0, z+12, 3, 3);
		world.setBlock(x+36, y+0, z+12, Block.getBlockById(1));
		world.setBlockMetadataWithNotify(x+36, y+0, z+12, 3, 3);
		world.setBlock(x+37, y+0, z+12, Block.getBlockById(1));
		world.setBlockMetadataWithNotify(x+37, y+0, z+12, 3, 3);
		world.setBlock(x+38, y+0, z+12, Block.getBlockById(1));
		world.setBlockMetadataWithNotify(x+38, y+0, z+12, 3, 3);
		world.setBlock(x+39, y+0, z+12, Block.getBlockById(1));
		world.setBlockMetadataWithNotify(x+39, y+0, z+12, 3, 3);
		world.setBlock(x+40, y+0, z+12, Block.getBlockById(1));
		world.setBlockMetadataWithNotify(x+40, y+0, z+12, 3, 3);
		world.setBlock(x+41, y+0, z+12, Block.getBlockById(1));
		world.setBlockMetadataWithNotify(x+41, y+0, z+12, 3, 3);
		world.setBlock(x+42, y+0, z+12, Block.getBlockById(98));
		world.setBlock(x+43, y+0, z+12, Block.getBlockById(98));
		world.setBlock(x+1, y+0, z+13, Block.getBlockById(98));
		world.setBlock(x+2, y+0, z+13, Block.getBlockById(98));
		world.setBlock(x+3, y+0, z+13, Block.getBlockById(1));
		world.setBlock(x+4, y+0, z+13, Block.getBlockById(1));
		world.setBlockMetadataWithNotify(x+4, y+0, z+13, 3, 3);
		world.setBlock(x+5, y+0, z+13, Block.getBlockById(1));
		world.setBlockMetadataWithNotify(x+5, y+0, z+13, 3, 3);
		world.setBlock(x+6, y+0, z+13, Block.getBlockById(1));
		world.setBlockMetadataWithNotify(x+6, y+0, z+13, 3, 3);
		world.setBlock(x+7, y+0, z+13, Block.getBlockById(1));
		world.setBlockMetadataWithNotify(x+7, y+0, z+13, 3, 3);
		world.setBlock(x+8, y+0, z+13, Block.getBlockById(1));
		world.setBlockMetadataWithNotify(x+8, y+0, z+13, 3, 3);
		world.setBlock(x+9, y+0, z+13, Block.getBlockById(1));
		world.setBlockMetadataWithNotify(x+9, y+0, z+13, 3, 3);
		world.setBlock(x+10, y+0, z+13, Block.getBlockById(1));
		world.setBlockMetadataWithNotify(x+10, y+0, z+13, 3, 3);
		world.setBlock(x+11, y+0, z+13, Block.getBlockById(1));
		world.setBlockMetadataWithNotify(x+11, y+0, z+13, 3, 3);
		world.setBlock(x+12, y+0, z+13, Block.getBlockById(1));
		world.setBlockMetadataWithNotify(x+12, y+0, z+13, 3, 3);
		world.setBlock(x+13, y+0, z+13, Block.getBlockById(12));
		world.setBlock(x+14, y+0, z+13, Block.getBlockById(98));
		world.setBlock(x+15, y+0, z+13, Block.getBlockById(98));
		world.setBlock(x+19, y+0, z+13, Block.getBlockById(1));
		world.setBlockMetadataWithNotify(x+19, y+0, z+13, 5, 5);
		world.setBlock(x+20, y+0, z+13, Block.getBlockById(159));
		world.setBlockMetadataWithNotify(x+20, y+0, z+13, 8, 8);
		world.setBlock(x+21, y+0, z+13, Block.getBlockById(159));
		world.setBlockMetadataWithNotify(x+21, y+0, z+13, 8, 8);
		world.setBlock(x+22, y+0, z+13, Block.getBlockById(159));
		world.setBlockMetadataWithNotify(x+22, y+0, z+13, 8, 8);
		world.setBlock(x+23, y+0, z+13, Block.getBlockById(159));
		world.setBlockMetadataWithNotify(x+23, y+0, z+13, 8, 8);
		world.setBlock(x+24, y+0, z+13, Block.getBlockById(159));
		world.setBlockMetadataWithNotify(x+24, y+0, z+13, 8, 8);
		world.setBlock(x+25, y+0, z+13, Block.getBlockById(1));
		world.setBlockMetadataWithNotify(x+25, y+0, z+13, 5, 5);
		world.setBlock(x+29, y+0, z+13, Block.getBlockById(98));
		world.setBlock(x+30, y+0, z+13, Block.getBlockById(98));
		world.setBlock(x+31, y+0, z+13, Block.getBlockById(97));
		world.setBlockMetadataWithNotify(x+31, y+0, z+13, 2, 2);
		world.setBlock(x+32, y+0, z+13, Block.getBlockById(12));
		world.setBlock(x+33, y+0, z+13, Block.getBlockById(12));
		world.setBlock(x+34, y+0, z+13, Block.getBlockById(12));
		world.setBlock(x+35, y+0, z+13, Block.getBlockById(1));
		world.setBlockMetadataWithNotify(x+35, y+0, z+13, 3, 3);
		world.setBlock(x+36, y+0, z+13, Block.getBlockById(1));
		world.setBlockMetadataWithNotify(x+36, y+0, z+13, 3, 3);
		world.setBlock(x+37, y+0, z+13, Block.getBlockById(1));
		world.setBlockMetadataWithNotify(x+37, y+0, z+13, 3, 3);
		world.setBlock(x+38, y+0, z+13, Block.getBlockById(1));
		world.setBlockMetadataWithNotify(x+38, y+0, z+13, 3, 3);
		world.setBlock(x+39, y+0, z+13, Block.getBlockById(1));
		world.setBlockMetadataWithNotify(x+39, y+0, z+13, 3, 3);
		world.setBlock(x+40, y+0, z+13, Block.getBlockById(1));
		world.setBlockMetadataWithNotify(x+40, y+0, z+13, 3, 3);
		world.setBlock(x+41, y+0, z+13, Block.getBlockById(98));
		world.setBlock(x+42, y+0, z+13, Block.getBlockById(98));
		world.setBlock(x+43, y+0, z+13, Block.getBlockById(98));
		world.setBlock(x+2, y+0, z+14, Block.getBlockById(98));
		world.setBlock(x+3, y+0, z+14, Block.getBlockById(98));
		world.setBlock(x+4, y+0, z+14, Block.getBlockById(1));
		world.setBlock(x+5, y+0, z+14, Block.getBlockById(1));
		world.setBlock(x+6, y+0, z+14, Block.getBlockById(1));
		world.setBlockMetadataWithNotify(x+6, y+0, z+14, 3, 3);
		world.setBlock(x+7, y+0, z+14, Block.getBlockById(1));
		world.setBlockMetadataWithNotify(x+7, y+0, z+14, 3, 3);
		world.setBlock(x+8, y+0, z+14, Block.getBlockById(1));
		world.setBlockMetadataWithNotify(x+8, y+0, z+14, 3, 3);
		world.setBlock(x+9, y+0, z+14, Block.getBlockById(1));
		world.setBlockMetadataWithNotify(x+9, y+0, z+14, 3, 3);
		world.setBlock(x+10, y+0, z+14, Block.getBlockById(1));
		world.setBlockMetadataWithNotify(x+10, y+0, z+14, 3, 3);
		world.setBlock(x+11, y+0, z+14, Block.getBlockById(98));
		world.setBlock(x+12, y+0, z+14, Block.getBlockById(98));
		world.setBlock(x+13, y+0, z+14, Block.getBlockById(98));
		world.setBlock(x+14, y+0, z+14, Block.getBlockById(98));
		world.setBlock(x+19, y+0, z+14, Block.getBlockById(1));
		world.setBlockMetadataWithNotify(x+19, y+0, z+14, 5, 5);
		world.setBlock(x+20, y+0, z+14, Block.getBlockById(159));
		world.setBlockMetadataWithNotify(x+20, y+0, z+14, 8, 8);
		world.setBlock(x+21, y+0, z+14, Block.getBlockById(159));
		world.setBlockMetadataWithNotify(x+21, y+0, z+14, 8, 8);
		world.setBlock(x+22, y+0, z+14, Block.getBlockById(159));
		world.setBlockMetadataWithNotify(x+22, y+0, z+14, 8, 8);
		world.setBlock(x+23, y+0, z+14, Block.getBlockById(159));
		world.setBlockMetadataWithNotify(x+23, y+0, z+14, 8, 8);
		world.setBlock(x+24, y+0, z+14, Block.getBlockById(159));
		world.setBlockMetadataWithNotify(x+24, y+0, z+14, 8, 8);
		world.setBlock(x+25, y+0, z+14, Block.getBlockById(1));
		world.setBlockMetadataWithNotify(x+25, y+0, z+14, 5, 5);
		world.setBlock(x+30, y+0, z+14, Block.getBlockById(98));
		world.setBlock(x+31, y+0, z+14, Block.getBlockById(98));
		world.setBlock(x+32, y+0, z+14, Block.getBlockById(98));
		world.setBlock(x+33, y+0, z+14, Block.getBlockById(98));
		world.setBlock(x+34, y+0, z+14, Block.getBlockById(12));
		world.setBlock(x+35, y+0, z+14, Block.getBlockById(1));
		world.setBlockMetadataWithNotify(x+35, y+0, z+14, 3, 3);
		world.setBlock(x+36, y+0, z+14, Block.getBlockById(1));
		world.setBlockMetadataWithNotify(x+36, y+0, z+14, 3, 3);
		world.setBlock(x+37, y+0, z+14, Block.getBlockById(1));
		world.setBlockMetadataWithNotify(x+37, y+0, z+14, 3, 3);
		world.setBlock(x+38, y+0, z+14, Block.getBlockById(1));
		world.setBlockMetadataWithNotify(x+38, y+0, z+14, 3, 3);
		world.setBlock(x+39, y+0, z+14, Block.getBlockById(98));
		world.setBlock(x+40, y+0, z+14, Block.getBlockById(98));
		world.setBlock(x+41, y+0, z+14, Block.getBlockById(98));
		world.setBlock(x+42, y+0, z+14, Block.getBlockById(98));
		world.setBlock(x+3, y+0, z+15, Block.getBlockById(98));
		world.setBlock(x+4, y+0, z+15, Block.getBlockById(98));
		world.setBlock(x+5, y+0, z+15, Block.getBlockById(98));
		world.setBlock(x+6, y+0, z+15, Block.getBlockById(1));
		world.setBlock(x+7, y+0, z+15, Block.getBlockById(1));
		world.setBlock(x+8, y+0, z+15, Block.getBlockById(1));
		world.setBlock(x+9, y+0, z+15, Block.getBlockById(98));
		world.setBlock(x+10, y+0, z+15, Block.getBlockById(98));
		world.setBlock(x+11, y+0, z+15, Block.getBlockById(98));
		world.setBlock(x+12, y+0, z+15, Block.getBlockById(98));
		world.setBlock(x+13, y+0, z+15, Block.getBlockById(98));
		world.setBlock(x+19, y+0, z+15, Block.getBlockById(1));
		world.setBlockMetadataWithNotify(x+19, y+0, z+15, 5, 5);
		world.setBlock(x+20, y+0, z+15, Block.getBlockById(159));
		world.setBlockMetadataWithNotify(x+20, y+0, z+15, 8, 8);
		world.setBlock(x+21, y+0, z+15, Block.getBlockById(159));
		world.setBlockMetadataWithNotify(x+21, y+0, z+15, 8, 8);
		world.setBlock(x+22, y+0, z+15, Block.getBlockById(159));
		world.setBlockMetadataWithNotify(x+22, y+0, z+15, 8, 8);
		world.setBlock(x+23, y+0, z+15, Block.getBlockById(159));
		world.setBlockMetadataWithNotify(x+23, y+0, z+15, 8, 8);
		world.setBlock(x+24, y+0, z+15, Block.getBlockById(159));
		world.setBlockMetadataWithNotify(x+24, y+0, z+15, 8, 8);
		world.setBlock(x+25, y+0, z+15, Block.getBlockById(1));
		world.setBlockMetadataWithNotify(x+25, y+0, z+15, 5, 5);
		world.setBlock(x+31, y+0, z+15, Block.getBlockById(98));
		world.setBlock(x+32, y+0, z+15, Block.getBlockById(98));
		world.setBlock(x+33, y+0, z+15, Block.getBlockById(98));
		world.setBlock(x+34, y+0, z+15, Block.getBlockById(98));
		world.setBlock(x+35, y+0, z+15, Block.getBlockById(98));
		world.setBlock(x+36, y+0, z+15, Block.getBlockById(98));
		world.setBlock(x+37, y+0, z+15, Block.getBlockById(98));
		world.setBlock(x+38, y+0, z+15, Block.getBlockById(98));
		world.setBlock(x+39, y+0, z+15, Block.getBlockById(98));
		world.setBlock(x+40, y+0, z+15, Block.getBlockById(98));
		world.setBlock(x+41, y+0, z+15, Block.getBlockById(98));
		world.setBlock(x+5, y+0, z+16, Block.getBlockById(98));
		world.setBlock(x+6, y+0, z+16, Block.getBlockById(98));
		world.setBlock(x+7, y+0, z+16, Block.getBlockById(98));
		world.setBlock(x+8, y+0, z+16, Block.getBlockById(98));
		world.setBlock(x+9, y+0, z+16, Block.getBlockById(98));
		world.setBlock(x+10, y+0, z+16, Block.getBlockById(98));
		world.setBlock(x+11, y+0, z+16, Block.getBlockById(98));
		world.setBlock(x+19, y+0, z+16, Block.getBlockById(1));
		world.setBlockMetadataWithNotify(x+19, y+0, z+16, 5, 5);
		world.setBlock(x+20, y+0, z+16, Block.getBlockById(159));
		world.setBlockMetadataWithNotify(x+20, y+0, z+16, 8, 8);
		world.setBlock(x+21, y+0, z+16, Block.getBlockById(159));
		world.setBlockMetadataWithNotify(x+21, y+0, z+16, 8, 8);
		world.setBlock(x+22, y+0, z+16, Block.getBlockById(159));
		world.setBlockMetadataWithNotify(x+22, y+0, z+16, 8, 8);
		world.setBlock(x+23, y+0, z+16, Block.getBlockById(159));
		world.setBlockMetadataWithNotify(x+23, y+0, z+16, 8, 8);
		world.setBlock(x+24, y+0, z+16, Block.getBlockById(159));
		world.setBlockMetadataWithNotify(x+24, y+0, z+16, 8, 8);
		world.setBlock(x+25, y+0, z+16, Block.getBlockById(1));
		world.setBlockMetadataWithNotify(x+25, y+0, z+16, 5, 5);
		world.setBlock(x+33, y+0, z+16, Block.getBlockById(98));
		world.setBlock(x+34, y+0, z+16, Block.getBlockById(98));
		world.setBlock(x+35, y+0, z+16, Block.getBlockById(98));
		world.setBlock(x+36, y+0, z+16, Block.getBlockById(98));
		world.setBlock(x+37, y+0, z+16, Block.getBlockById(98));
		spawn4(world, x, y, z);
	}
	
	private static void spawn4(World world, int x, int y, int z)
	{
		world.setBlock(x+38, y+0, z+16, Block.getBlockById(98));
		world.setBlock(x+39, y+0, z+16, Block.getBlockById(98));
		world.setBlock(x+18, y+1, z+0, Block.getBlockById(44));
		world.setBlock(x+26, y+1, z+0, Block.getBlockById(44));
		world.setBlock(x+6, y+1, z+1, Block.getBlockById(98));
		world.setBlock(x+7, y+1, z+1, Block.getBlockById(98));
		world.setBlock(x+8, y+1, z+1, Block.getBlockById(98));
		world.setBlock(x+9, y+1, z+1, Block.getBlockById(98));
		world.setBlock(x+10, y+1, z+1, Block.getBlockById(98));
		world.setBlock(x+18, y+1, z+1, Block.getBlockById(44));
		world.setBlock(x+26, y+1, z+1, Block.getBlockById(44));
		world.setBlock(x+34, y+1, z+1, Block.getBlockById(98));
		world.setBlock(x+35, y+1, z+1, Block.getBlockById(98));
		world.setBlock(x+36, y+1, z+1, Block.getBlockById(98));
		world.setBlock(x+37, y+1, z+1, Block.getBlockById(98));
		world.setBlock(x+38, y+1, z+1, Block.getBlockById(98));
		world.setBlock(x+4, y+1, z+2, Block.getBlockById(98));
		world.setBlock(x+5, y+1, z+2, Block.getBlockById(98));
		world.setBlock(x+6, y+1, z+2, Block.getBlockById(98));
		world.setBlock(x+7, y+1, z+2, Block.getBlockById(98));
		world.setBlock(x+8, y+1, z+2, Block.getBlockById(98));
		world.setBlock(x+9, y+1, z+2, Block.getBlockById(98));
		world.setBlock(x+10, y+1, z+2, Block.getBlockById(98));
		world.setBlock(x+11, y+1, z+2, Block.getBlockById(98));
		world.setBlock(x+12, y+1, z+2, Block.getBlockById(98));
		world.setBlock(x+18, y+1, z+2, Block.getBlockById(44));
		world.setBlock(x+26, y+1, z+2, Block.getBlockById(44));
		world.setBlock(x+32, y+1, z+2, Block.getBlockById(98));
		world.setBlock(x+33, y+1, z+2, Block.getBlockById(98));
		world.setBlock(x+34, y+1, z+2, Block.getBlockById(98));
		world.setBlock(x+35, y+1, z+2, Block.getBlockById(98));
		world.setBlock(x+36, y+1, z+2, Block.getBlockById(98));
		world.setBlock(x+37, y+1, z+2, Block.getBlockById(98));
		world.setBlock(x+38, y+1, z+2, Block.getBlockById(98));
		world.setBlock(x+39, y+1, z+2, Block.getBlockById(98));
		world.setBlock(x+40, y+1, z+2, Block.getBlockById(98));
		world.setBlock(x+3, y+1, z+3, Block.getBlockById(98));
		world.setBlock(x+4, y+1, z+3, Block.getBlockById(98));
		world.setBlock(x+5, y+1, z+3, Block.getBlockById(98));
		world.setBlock(x+6, y+1, z+3, Block.getBlockById(98));
		world.setBlock(x+7, y+1, z+3, Block.getBlockById(98));
		world.setBlock(x+8, y+1, z+3, Block.getBlockById(98));
		world.setBlock(x+9, y+1, z+3, Block.getBlockById(98));
		world.setBlock(x+10, y+1, z+3, Block.getBlockById(98));
		world.setBlock(x+11, y+1, z+3, Block.getBlockById(98));
		world.setBlock(x+12, y+1, z+3, Block.getBlockById(98));
		world.setBlock(x+13, y+1, z+3, Block.getBlockById(98));
		world.setBlock(x+18, y+1, z+3, Block.getBlockById(44));
		world.setBlock(x+26, y+1, z+3, Block.getBlockById(44));
		world.setBlock(x+31, y+1, z+3, Block.getBlockById(98));
		world.setBlock(x+32, y+1, z+3, Block.getBlockById(98));
		world.setBlock(x+33, y+1, z+3, Block.getBlockById(98));
		world.setBlock(x+34, y+1, z+3, Block.getBlockById(98));
		world.setBlock(x+35, y+1, z+3, Block.getBlockById(98));
		world.setBlock(x+36, y+1, z+3, Block.getBlockById(98));
		world.setBlock(x+37, y+1, z+3, Block.getBlockById(98));
		world.setBlock(x+38, y+1, z+3, Block.getBlockById(98));
		world.setBlock(x+39, y+1, z+3, Block.getBlockById(98));
		world.setBlock(x+40, y+1, z+3, Block.getBlockById(98));
		world.setBlock(x+41, y+1, z+3, Block.getBlockById(98));
		world.setBlock(x+2, y+1, z+4, Block.getBlockById(98));
		world.setBlock(x+3, y+1, z+4, Block.getBlockById(98));
		world.setBlock(x+4, y+1, z+4, Block.getBlockById(98));
		world.setBlock(x+13, y+1, z+4, Block.getBlockById(98));
		world.setBlock(x+14, y+1, z+4, Block.getBlockById(98));
		world.setBlock(x+18, y+1, z+4, Block.getBlockById(44));
		world.setBlock(x+26, y+1, z+4, Block.getBlockById(44));
		world.setBlock(x+30, y+1, z+4, Block.getBlockById(98));
		world.setBlock(x+31, y+1, z+4, Block.getBlockById(98));
		world.setBlock(x+40, y+1, z+4, Block.getBlockById(98));
		world.setBlock(x+41, y+1, z+4, Block.getBlockById(98));
		world.setBlock(x+42, y+1, z+4, Block.getBlockById(98));
		world.setBlock(x+2, y+1, z+5, Block.getBlockById(98));
		world.setBlock(x+3, y+1, z+5, Block.getBlockById(98));
		world.setBlock(x+13, y+1, z+5, Block.getBlockById(98));
		world.setBlock(x+14, y+1, z+5, Block.getBlockById(98));
		world.setBlock(x+18, y+1, z+5, Block.getBlockById(1));
		world.setBlockMetadataWithNotify(x+18, y+1, z+5, 6, 6);
		world.setBlock(x+26, y+1, z+5, Block.getBlockById(1));
		world.setBlock(x+30, y+1, z+5, Block.getBlockById(98));
		world.setBlock(x+31, y+1, z+5, Block.getBlockById(98));
		world.setBlock(x+41, y+1, z+5, Block.getBlockById(98));
		world.setBlock(x+42, y+1, z+5, Block.getBlockById(98));
		world.setBlock(x+1, y+1, z+6, Block.getBlockById(98));
		world.setBlock(x+2, y+1, z+6, Block.getBlockById(98));
		world.setBlock(x+3, y+1, z+6, Block.getBlockById(98));
		world.setBlock(x+13, y+1, z+6, Block.getBlockById(98));
		world.setBlock(x+14, y+1, z+6, Block.getBlockById(98));
		world.setBlock(x+15, y+1, z+6, Block.getBlockById(98));
		world.setBlock(x+16, y+1, z+6, Block.getBlockById(98));
		world.setBlock(x+17, y+1, z+6, Block.getBlockById(98));
		world.setBlock(x+18, y+1, z+6, Block.getBlockById(98));
		world.setBlock(x+26, y+1, z+6, Block.getBlockById(98));
		world.setBlock(x+27, y+1, z+6, Block.getBlockById(98));
		world.setBlock(x+28, y+1, z+6, Block.getBlockById(98));
		world.setBlock(x+29, y+1, z+6, Block.getBlockById(98));
		world.setBlock(x+30, y+1, z+6, Block.getBlockById(98));
		world.setBlock(x+31, y+1, z+6, Block.getBlockById(98));
		world.setBlock(x+41, y+1, z+6, Block.getBlockById(98));
		world.setBlock(x+42, y+1, z+6, Block.getBlockById(98));
		world.setBlock(x+43, y+1, z+6, Block.getBlockById(98));
		world.setBlock(x+1, y+1, z+7, Block.getBlockById(98));
		world.setBlock(x+2, y+1, z+7, Block.getBlockById(98));
		world.setBlock(x+3, y+1, z+7, Block.getBlockById(98));
		world.setBlock(x+18, y+1, z+7, Block.getBlockById(98));
		world.setBlock(x+26, y+1, z+7, Block.getBlockById(98));
		world.setBlock(x+41, y+1, z+7, Block.getBlockById(98));
		world.setBlock(x+42, y+1, z+7, Block.getBlockById(98));
		world.setBlock(x+43, y+1, z+7, Block.getBlockById(98));
		world.setBlock(x+1, y+1, z+8, Block.getBlockById(98));
		world.setBlock(x+2, y+1, z+8, Block.getBlockById(98));
		world.setBlock(x+3, y+1, z+8, Block.getBlockById(98));
		world.setBlock(x+18, y+1, z+8, Block.getBlockById(98));
		world.setBlock(x+26, y+1, z+8, Block.getBlockById(98));
		world.setBlock(x+41, y+1, z+8, Block.getBlockById(98));
		world.setBlock(x+42, y+1, z+8, Block.getBlockById(98));
		world.setBlock(x+43, y+1, z+8, Block.getBlockById(98));
		world.setBlock(x+1, y+1, z+9, Block.getBlockById(98));
		world.setBlock(x+2, y+1, z+9, Block.getBlockById(98));
		world.setBlock(x+3, y+1, z+9, Block.getBlockById(98));
		world.setBlock(x+13, y+1, z+9, Block.getBlockById(98));
		world.setBlock(x+14, y+1, z+9, Block.getBlockById(98));
		world.setBlock(x+15, y+1, z+9, Block.getBlockById(98));
		world.setBlock(x+18, y+1, z+9, Block.getBlockById(1));
		world.setBlockMetadataWithNotify(x+18, y+1, z+9, 6, 6);
		world.setBlock(x+26, y+1, z+9, Block.getBlockById(1));
		world.setBlock(x+29, y+1, z+9, Block.getBlockById(98));
		world.setBlock(x+30, y+1, z+9, Block.getBlockById(98));
		world.setBlock(x+31, y+1, z+9, Block.getBlockById(98));
		world.setBlock(x+41, y+1, z+9, Block.getBlockById(98));
		world.setBlock(x+42, y+1, z+9, Block.getBlockById(98));
		world.setBlock(x+43, y+1, z+9, Block.getBlockById(98));
		world.setBlock(x+1, y+1, z+10, Block.getBlockById(98));
		world.setBlock(x+2, y+1, z+10, Block.getBlockById(98));
		world.setBlock(x+3, y+1, z+10, Block.getBlockById(98));
		world.setBlock(x+13, y+1, z+10, Block.getBlockById(98));
		world.setBlock(x+14, y+1, z+10, Block.getBlockById(98));
		world.setBlock(x+15, y+1, z+10, Block.getBlockById(98));
		world.setBlock(x+29, y+1, z+10, Block.getBlockById(98));
		world.setBlock(x+30, y+1, z+10, Block.getBlockById(98));
		world.setBlock(x+31, y+1, z+10, Block.getBlockById(98));
		world.setBlock(x+41, y+1, z+10, Block.getBlockById(98));
		world.setBlock(x+42, y+1, z+10, Block.getBlockById(98));
		world.setBlock(x+43, y+1, z+10, Block.getBlockById(98));
		world.setBlock(x+2, y+1, z+11, Block.getBlockById(98));
		world.setBlock(x+3, y+1, z+11, Block.getBlockById(98));
		world.setBlock(x+7, y+1, z+11, Block.getBlockById(44));
		world.setBlock(x+8, y+1, z+11, Block.getBlockById(44));
		world.setBlockMetadataWithNotify(x+8, y+1, z+11, 8, 8);
		world.setBlock(x+13, y+1, z+11, Block.getBlockById(98));
		world.setBlock(x+14, y+1, z+11, Block.getBlockById(98));
		world.setBlock(x+30, y+1, z+11, Block.getBlockById(98));
		world.setBlock(x+31, y+1, z+11, Block.getBlockById(98));
		world.setBlock(x+36, y+1, z+11, Block.getBlockById(44));
		world.setBlockMetadataWithNotify(x+36, y+1, z+11, 8, 8);
		world.setBlock(x+37, y+1, z+11, Block.getBlockById(44));
		world.setBlock(x+41, y+1, z+11, Block.getBlockById(98));
		world.setBlock(x+42, y+1, z+11, Block.getBlockById(98));
		world.setBlock(x+2, y+1, z+12, Block.getBlockById(98));
		world.setBlock(x+3, y+1, z+12, Block.getBlockById(98));
		world.setBlock(x+4, y+1, z+12, Block.getBlockById(98));
		world.setBlock(x+7, y+1, z+12, Block.getBlockById(44));
		world.setBlock(x+8, y+1, z+12, Block.getBlockById(44));
		world.setBlockMetadataWithNotify(x+8, y+1, z+12, 8, 8);
		world.setBlock(x+12, y+1, z+12, Block.getBlockById(98));
		world.setBlock(x+13, y+1, z+12, Block.getBlockById(98));
		world.setBlock(x+14, y+1, z+12, Block.getBlockById(98));
		world.setBlock(x+30, y+1, z+12, Block.getBlockById(98));
		world.setBlock(x+31, y+1, z+12, Block.getBlockById(98));
		world.setBlock(x+32, y+1, z+12, Block.getBlockById(98));
		world.setBlock(x+36, y+1, z+12, Block.getBlockById(44));
		world.setBlockMetadataWithNotify(x+36, y+1, z+12, 8, 8);
		world.setBlock(x+37, y+1, z+12, Block.getBlockById(44));
		world.setBlock(x+40, y+1, z+12, Block.getBlockById(98));
		world.setBlock(x+41, y+1, z+12, Block.getBlockById(98));
		world.setBlock(x+42, y+1, z+12, Block.getBlockById(98));
		world.setBlock(x+3, y+1, z+13, Block.getBlockById(98));
		world.setBlock(x+4, y+1, z+13, Block.getBlockById(98));
		world.setBlock(x+5, y+1, z+13, Block.getBlockById(98));
		world.setBlock(x+6, y+1, z+13, Block.getBlockById(98));
		world.setBlock(x+7, y+1, z+13, Block.getBlockById(98));
		world.setBlock(x+8, y+1, z+13, Block.getBlockById(98));
		world.setBlock(x+9, y+1, z+13, Block.getBlockById(98));
		world.setBlock(x+10, y+1, z+13, Block.getBlockById(98));
		world.setBlock(x+11, y+1, z+13, Block.getBlockById(98));
		world.setBlock(x+12, y+1, z+13, Block.getBlockById(98));
		world.setBlock(x+13, y+1, z+13, Block.getBlockById(98));
		world.setBlock(x+31, y+1, z+13, Block.getBlockById(98));
		world.setBlock(x+32, y+1, z+13, Block.getBlockById(98));
		world.setBlock(x+33, y+1, z+13, Block.getBlockById(98));
		world.setBlock(x+34, y+1, z+13, Block.getBlockById(98));
		world.setBlock(x+35, y+1, z+13, Block.getBlockById(98));
		world.setBlock(x+36, y+1, z+13, Block.getBlockById(98));
		world.setBlock(x+37, y+1, z+13, Block.getBlockById(98));
		world.setBlock(x+38, y+1, z+13, Block.getBlockById(98));
		world.setBlock(x+39, y+1, z+13, Block.getBlockById(98));
		world.setBlock(x+40, y+1, z+13, Block.getBlockById(98));
		world.setBlock(x+41, y+1, z+13, Block.getBlockById(98));
		world.setBlock(x+4, y+1, z+14, Block.getBlockById(98));
		world.setBlock(x+5, y+1, z+14, Block.getBlockById(98));
		world.setBlock(x+6, y+1, z+14, Block.getBlockById(98));
		world.setBlock(x+7, y+1, z+14, Block.getBlockById(98));
		world.setBlock(x+8, y+1, z+14, Block.getBlockById(98));
		world.setBlock(x+9, y+1, z+14, Block.getBlockById(98));
		world.setBlock(x+10, y+1, z+14, Block.getBlockById(98));
		world.setBlock(x+11, y+1, z+14, Block.getBlockById(98));
		world.setBlock(x+12, y+1, z+14, Block.getBlockById(98));
		world.setBlock(x+32, y+1, z+14, Block.getBlockById(98));
		world.setBlock(x+33, y+1, z+14, Block.getBlockById(98));
		world.setBlock(x+34, y+1, z+14, Block.getBlockById(98));
		world.setBlock(x+35, y+1, z+14, Block.getBlockById(98));
		world.setBlock(x+36, y+1, z+14, Block.getBlockById(98));
		world.setBlock(x+37, y+1, z+14, Block.getBlockById(98));
		world.setBlock(x+38, y+1, z+14, Block.getBlockById(98));
		world.setBlock(x+39, y+1, z+14, Block.getBlockById(98));
		world.setBlock(x+40, y+1, z+14, Block.getBlockById(98));
		world.setBlock(x+6, y+1, z+15, Block.getBlockById(98));
		world.setBlock(x+7, y+1, z+15, Block.getBlockById(98));
		world.setBlock(x+8, y+1, z+15, Block.getBlockById(98));
		world.setBlock(x+9, y+1, z+15, Block.getBlockById(98));
		world.setBlock(x+10, y+1, z+15, Block.getBlockById(98));
		world.setBlock(x+34, y+1, z+15, Block.getBlockById(98));
		world.setBlock(x+35, y+1, z+15, Block.getBlockById(98));
		world.setBlock(x+36, y+1, z+15, Block.getBlockById(98));
		world.setBlock(x+37, y+1, z+15, Block.getBlockById(98));
		world.setBlock(x+38, y+1, z+15, Block.getBlockById(98));
		world.setBlock(x+6, y+2, z+1, Block.getBlockById(98));
		world.setBlock(x+7, y+2, z+1, Block.getBlockById(98));
		world.setBlock(x+8, y+2, z+1, Block.getBlockById(98));
		world.setBlock(x+9, y+2, z+1, Block.getBlockById(98));
		world.setBlock(x+10, y+2, z+1, Block.getBlockById(98));
		world.setBlock(x+34, y+2, z+1, Block.getBlockById(98));
		world.setBlock(x+35, y+2, z+1, Block.getBlockById(98));
		world.setBlock(x+36, y+2, z+1, Block.getBlockById(98));
		world.setBlock(x+37, y+2, z+1, Block.getBlockById(98));
		world.setBlock(x+38, y+2, z+1, Block.getBlockById(98));
		world.setBlock(x+4, y+2, z+2, Block.getBlockById(98));
		world.setBlock(x+5, y+2, z+2, Block.getBlockById(98));
		world.setBlock(x+6, y+2, z+2, Block.getBlockById(98));
		world.setBlock(x+7, y+2, z+2, Block.getBlockById(98));
		world.setBlock(x+8, y+2, z+2, Block.getBlockById(98));
		world.setBlock(x+9, y+2, z+2, Block.getBlockById(98));
		world.setBlock(x+10, y+2, z+2, Block.getBlockById(98));
		world.setBlock(x+11, y+2, z+2, Block.getBlockById(98));
		world.setBlock(x+12, y+2, z+2, Block.getBlockById(98));
		world.setBlock(x+32, y+2, z+2, Block.getBlockById(98));
		world.setBlock(x+33, y+2, z+2, Block.getBlockById(98));
		world.setBlock(x+34, y+2, z+2, Block.getBlockById(98));
		world.setBlock(x+35, y+2, z+2, Block.getBlockById(98));
		world.setBlock(x+36, y+2, z+2, Block.getBlockById(98));
		world.setBlock(x+37, y+2, z+2, Block.getBlockById(98));
		world.setBlock(x+38, y+2, z+2, Block.getBlockById(98));
		world.setBlock(x+39, y+2, z+2, Block.getBlockById(98));
		world.setBlock(x+40, y+2, z+2, Block.getBlockById(98));
		world.setBlock(x+3, y+2, z+3, Block.getBlockById(98));
		world.setBlock(x+4, y+2, z+3, Block.getBlockById(98));
		world.setBlock(x+5, y+2, z+3, Block.getBlockById(98));
		world.setBlock(x+6, y+2, z+3, Block.getBlockById(98));
		world.setBlock(x+7, y+2, z+3, Block.getBlockById(98));
		world.setBlock(x+8, y+2, z+3, Block.getBlockById(98));
		world.setBlock(x+9, y+2, z+3, Block.getBlockById(98));
		world.setBlock(x+10, y+2, z+3, Block.getBlockById(98));
		world.setBlock(x+11, y+2, z+3, Block.getBlockById(98));
		world.setBlock(x+12, y+2, z+3, Block.getBlockById(98));
		world.setBlock(x+13, y+2, z+3, Block.getBlockById(98));
		world.setBlock(x+31, y+2, z+3, Block.getBlockById(98));
		world.setBlock(x+32, y+2, z+3, Block.getBlockById(98));
		world.setBlock(x+33, y+2, z+3, Block.getBlockById(98));
		world.setBlock(x+34, y+2, z+3, Block.getBlockById(98));
		world.setBlock(x+35, y+2, z+3, Block.getBlockById(98));
		world.setBlock(x+36, y+2, z+3, Block.getBlockById(98));
		world.setBlock(x+37, y+2, z+3, Block.getBlockById(98));
		world.setBlock(x+38, y+2, z+3, Block.getBlockById(98));
		world.setBlock(x+39, y+2, z+3, Block.getBlockById(98));
		world.setBlock(x+40, y+2, z+3, Block.getBlockById(98));
		world.setBlock(x+41, y+2, z+3, Block.getBlockById(98));
		world.setBlock(x+2, y+2, z+4, Block.getBlockById(98));
		world.setBlock(x+3, y+2, z+4, Block.getBlockById(98));
		world.setBlock(x+4, y+2, z+4, Block.getBlockById(98));
		world.setBlock(x+13, y+2, z+4, Block.getBlockById(98));
		world.setBlock(x+14, y+2, z+4, Block.getBlockById(98));
		world.setBlock(x+30, y+2, z+4, Block.getBlockById(98));
		world.setBlock(x+31, y+2, z+4, Block.getBlockById(98));
		world.setBlock(x+40, y+2, z+4, Block.getBlockById(98));
		world.setBlock(x+41, y+2, z+4, Block.getBlockById(98));
		world.setBlock(x+42, y+2, z+4, Block.getBlockById(98));
		world.setBlock(x+2, y+2, z+5, Block.getBlockById(98));
		world.setBlock(x+3, y+2, z+5, Block.getBlockById(98));
		world.setBlock(x+13, y+2, z+5, Block.getBlockById(98));
		world.setBlock(x+14, y+2, z+5, Block.getBlockById(98));
		world.setBlock(x+18, y+2, z+5, Block.getBlockById(1));
		world.setBlockMetadataWithNotify(x+18, y+2, z+5, 6, 6);
		world.setBlock(x+26, y+2, z+5, Block.getBlockById(1));
		world.setBlockMetadataWithNotify(x+26, y+2, z+5, 6, 6);
		world.setBlock(x+30, y+2, z+5, Block.getBlockById(98));
		world.setBlock(x+31, y+2, z+5, Block.getBlockById(98));
		world.setBlock(x+41, y+2, z+5, Block.getBlockById(98));
		world.setBlock(x+42, y+2, z+5, Block.getBlockById(98));
		world.setBlock(x+1, y+2, z+6, Block.getBlockById(98));
		world.setBlock(x+2, y+2, z+6, Block.getBlockById(98));
		world.setBlock(x+3, y+2, z+6, Block.getBlockById(98));
		world.setBlock(x+13, y+2, z+6, Block.getBlockById(98));
		world.setBlock(x+14, y+2, z+6, Block.getBlockById(98));
		world.setBlock(x+15, y+2, z+6, Block.getBlockById(98));
		world.setBlock(x+16, y+2, z+6, Block.getBlockById(98));
		world.setBlock(x+17, y+2, z+6, Block.getBlockById(98));
		world.setBlock(x+18, y+2, z+6, Block.getBlockById(98));
		world.setBlock(x+26, y+2, z+6, Block.getBlockById(98));
		world.setBlock(x+27, y+2, z+6, Block.getBlockById(98));
		world.setBlock(x+28, y+2, z+6, Block.getBlockById(98));
		world.setBlock(x+29, y+2, z+6, Block.getBlockById(98));
		world.setBlock(x+30, y+2, z+6, Block.getBlockById(98));
		world.setBlock(x+31, y+2, z+6, Block.getBlockById(98));
		world.setBlock(x+41, y+2, z+6, Block.getBlockById(98));
		world.setBlock(x+42, y+2, z+6, Block.getBlockById(98));
		world.setBlock(x+43, y+2, z+6, Block.getBlockById(98));
		world.setBlock(x+1, y+2, z+7, Block.getBlockById(98));
		world.setBlock(x+2, y+2, z+7, Block.getBlockById(98));
		world.setBlock(x+3, y+2, z+7, Block.getBlockById(98));
		world.setBlock(x+16, y+2, z+7, Block.getBlockById(50));
		world.setBlockMetadataWithNotify(x+16, y+2, z+7, 3, 3);
		world.setBlock(x+18, y+2, z+7, Block.getBlockById(98));
		world.setBlock(x+26, y+2, z+7, Block.getBlockById(98));
		world.setBlock(x+28, y+2, z+7, Block.getBlockById(50));
		world.setBlockMetadataWithNotify(x+28, y+2, z+7, 3, 3);
		world.setBlock(x+41, y+2, z+7, Block.getBlockById(98));
		world.setBlock(x+42, y+2, z+7, Block.getBlockById(98));
		world.setBlock(x+43, y+2, z+7, Block.getBlockById(98));
		world.setBlock(x+1, y+2, z+8, Block.getBlockById(98));
		world.setBlock(x+2, y+2, z+8, Block.getBlockById(98));
		world.setBlock(x+3, y+2, z+8, Block.getBlockById(98));
		world.setBlock(x+18, y+2, z+8, Block.getBlockById(98));
		world.setBlock(x+26, y+2, z+8, Block.getBlockById(98));
		world.setBlock(x+41, y+2, z+8, Block.getBlockById(98));
		world.setBlock(x+42, y+2, z+8, Block.getBlockById(98));
		world.setBlock(x+43, y+2, z+8, Block.getBlockById(98));
		world.setBlock(x+1, y+2, z+9, Block.getBlockById(98));
		world.setBlock(x+2, y+2, z+9, Block.getBlockById(98));
		world.setBlock(x+3, y+2, z+9, Block.getBlockById(98));
		world.setBlock(x+13, y+2, z+9, Block.getBlockById(98));
		world.setBlock(x+14, y+2, z+9, Block.getBlockById(98));
		world.setBlock(x+15, y+2, z+9, Block.getBlockById(98));
		world.setBlock(x+18, y+2, z+9, Block.getBlockById(1));
		world.setBlockMetadataWithNotify(x+18, y+2, z+9, 6, 6);
		world.setBlock(x+26, y+2, z+9, Block.getBlockById(1));
		world.setBlockMetadataWithNotify(x+26, y+2, z+9, 6, 6);
		world.setBlock(x+29, y+2, z+9, Block.getBlockById(98));
		world.setBlock(x+30, y+2, z+9, Block.getBlockById(98));
		world.setBlock(x+31, y+2, z+9, Block.getBlockById(98));
		world.setBlock(x+41, y+2, z+9, Block.getBlockById(98));
		world.setBlock(x+42, y+2, z+9, Block.getBlockById(98));
		world.setBlock(x+43, y+2, z+9, Block.getBlockById(98));
		world.setBlock(x+1, y+2, z+10, Block.getBlockById(98));
		world.setBlock(x+2, y+2, z+10, Block.getBlockById(98));
		world.setBlock(x+3, y+2, z+10, Block.getBlockById(98));
		world.setBlock(x+11, y+2, z+10, Block.getBlockById(44));
		world.setBlockMetadataWithNotify(x+11, y+2, z+10, 8, 8);
		world.setBlock(x+12, y+2, z+10, Block.getBlockById(44));
		world.setBlockMetadataWithNotify(x+12, y+2, z+10, 8, 8);
		world.setBlock(x+13, y+2, z+10, Block.getBlockById(98));
		world.setBlock(x+14, y+2, z+10, Block.getBlockById(98));
		world.setBlock(x+15, y+2, z+10, Block.getBlockById(98));
		world.setBlock(x+29, y+2, z+10, Block.getBlockById(98));
		world.setBlock(x+30, y+2, z+10, Block.getBlockById(98));
		world.setBlock(x+31, y+2, z+10, Block.getBlockById(98));
		world.setBlock(x+32, y+2, z+10, Block.getBlockById(44));
		world.setBlockMetadataWithNotify(x+32, y+2, z+10, 8, 8);
		world.setBlock(x+33, y+2, z+10, Block.getBlockById(44));
		world.setBlockMetadataWithNotify(x+33, y+2, z+10, 8, 8);
		world.setBlock(x+41, y+2, z+10, Block.getBlockById(98));
		world.setBlock(x+42, y+2, z+10, Block.getBlockById(98));
		world.setBlock(x+43, y+2, z+10, Block.getBlockById(98));
		world.setBlock(x+2, y+2, z+11, Block.getBlockById(98));
		world.setBlock(x+3, y+2, z+11, Block.getBlockById(98));
		world.setBlock(x+9, y+2, z+11, Block.getBlockById(44));
		world.setBlock(x+10, y+2, z+11, Block.getBlockById(44));
		world.setBlockMetadataWithNotify(x+10, y+2, z+11, 8, 8);
		world.setBlock(x+11, y+2, z+11, Block.getBlockById(44));
		world.setBlockMetadataWithNotify(x+11, y+2, z+11, 8, 8);
		world.setBlock(x+12, y+2, z+11, Block.getBlockById(44));
		world.setBlockMetadataWithNotify(x+12, y+2, z+11, 8, 8);
		world.setBlock(x+13, y+2, z+11, Block.getBlockById(98));
		world.setBlock(x+14, y+2, z+11, Block.getBlockById(98));
		world.setBlock(x+30, y+2, z+11, Block.getBlockById(98));
		world.setBlock(x+31, y+2, z+11, Block.getBlockById(98));
		world.setBlock(x+32, y+2, z+11, Block.getBlockById(44));
		world.setBlockMetadataWithNotify(x+32, y+2, z+11, 8, 8);
		world.setBlock(x+33, y+2, z+11, Block.getBlockById(44));
		world.setBlockMetadataWithNotify(x+33, y+2, z+11, 8, 8);
		world.setBlock(x+34, y+2, z+11, Block.getBlockById(44));
		world.setBlockMetadataWithNotify(x+34, y+2, z+11, 8, 8);
		world.setBlock(x+35, y+2, z+11, Block.getBlockById(44));
		world.setBlock(x+41, y+2, z+11, Block.getBlockById(98));
		world.setBlock(x+42, y+2, z+11, Block.getBlockById(98));
		world.setBlock(x+2, y+2, z+12, Block.getBlockById(98));
		world.setBlock(x+3, y+2, z+12, Block.getBlockById(98));
		world.setBlock(x+4, y+2, z+12, Block.getBlockById(98));
		world.setBlock(x+9, y+2, z+12, Block.getBlockById(44));
		world.setBlock(x+10, y+2, z+12, Block.getBlockById(44));
		world.setBlockMetadataWithNotify(x+10, y+2, z+12, 8, 8);
		world.setBlock(x+11, y+2, z+12, Block.getBlockById(44));
		world.setBlockMetadataWithNotify(x+11, y+2, z+12, 8, 8);
		world.setBlock(x+12, y+2, z+12, Block.getBlockById(98));
		world.setBlock(x+13, y+2, z+12, Block.getBlockById(98));
		world.setBlock(x+14, y+2, z+12, Block.getBlockById(98));
		world.setBlock(x+30, y+2, z+12, Block.getBlockById(98));
		world.setBlock(x+31, y+2, z+12, Block.getBlockById(98));
		world.setBlock(x+32, y+2, z+12, Block.getBlockById(98));
		world.setBlock(x+33, y+2, z+12, Block.getBlockById(44));
		world.setBlockMetadataWithNotify(x+33, y+2, z+12, 8, 8);
		world.setBlock(x+34, y+2, z+12, Block.getBlockById(44));
		world.setBlockMetadataWithNotify(x+34, y+2, z+12, 8, 8);
		world.setBlock(x+35, y+2, z+12, Block.getBlockById(44));
		world.setBlock(x+40, y+2, z+12, Block.getBlockById(98));
		world.setBlock(x+41, y+2, z+12, Block.getBlockById(98));
		world.setBlock(x+42, y+2, z+12, Block.getBlockById(98));
		world.setBlock(x+3, y+2, z+13, Block.getBlockById(98));
		world.setBlock(x+4, y+2, z+13, Block.getBlockById(98));
		world.setBlock(x+5, y+2, z+13, Block.getBlockById(98));
		world.setBlock(x+6, y+2, z+13, Block.getBlockById(98));
		world.setBlock(x+7, y+2, z+13, Block.getBlockById(98));
		world.setBlock(x+8, y+2, z+13, Block.getBlockById(98));
		world.setBlock(x+9, y+2, z+13, Block.getBlockById(98));
		world.setBlock(x+10, y+2, z+13, Block.getBlockById(98));
		world.setBlock(x+11, y+2, z+13, Block.getBlockById(98));
		world.setBlock(x+12, y+2, z+13, Block.getBlockById(98));
		world.setBlock(x+13, y+2, z+13, Block.getBlockById(98));
		world.setBlock(x+31, y+2, z+13, Block.getBlockById(98));
		world.setBlock(x+32, y+2, z+13, Block.getBlockById(98));
		world.setBlock(x+33, y+2, z+13, Block.getBlockById(98));
		world.setBlock(x+34, y+2, z+13, Block.getBlockById(98));
		world.setBlock(x+35, y+2, z+13, Block.getBlockById(98));
		world.setBlock(x+36, y+2, z+13, Block.getBlockById(98));
		world.setBlock(x+37, y+2, z+13, Block.getBlockById(98));
		world.setBlock(x+38, y+2, z+13, Block.getBlockById(98));
		world.setBlock(x+39, y+2, z+13, Block.getBlockById(98));
		world.setBlock(x+40, y+2, z+13, Block.getBlockById(98));
		world.setBlock(x+41, y+2, z+13, Block.getBlockById(98));
		world.setBlock(x+4, y+2, z+14, Block.getBlockById(98));
		world.setBlock(x+5, y+2, z+14, Block.getBlockById(98));
		world.setBlock(x+6, y+2, z+14, Block.getBlockById(98));
		world.setBlock(x+7, y+2, z+14, Block.getBlockById(98));
		world.setBlock(x+8, y+2, z+14, Block.getBlockById(98));
		world.setBlock(x+9, y+2, z+14, Block.getBlockById(98));
		world.setBlock(x+10, y+2, z+14, Block.getBlockById(98));
		world.setBlock(x+11, y+2, z+14, Block.getBlockById(98));
		world.setBlock(x+12, y+2, z+14, Block.getBlockById(98));
		world.setBlock(x+32, y+2, z+14, Block.getBlockById(98));
		world.setBlock(x+33, y+2, z+14, Block.getBlockById(98));
		world.setBlock(x+34, y+2, z+14, Block.getBlockById(98));
		world.setBlock(x+35, y+2, z+14, Block.getBlockById(98));
		world.setBlock(x+36, y+2, z+14, Block.getBlockById(98));
		world.setBlock(x+37, y+2, z+14, Block.getBlockById(98));
		world.setBlock(x+38, y+2, z+14, Block.getBlockById(98));
		world.setBlock(x+39, y+2, z+14, Block.getBlockById(98));
		world.setBlock(x+40, y+2, z+14, Block.getBlockById(98));
		world.setBlock(x+6, y+2, z+15, Block.getBlockById(98));
		world.setBlock(x+7, y+2, z+15, Block.getBlockById(98));
		world.setBlock(x+8, y+2, z+15, Block.getBlockById(98));
		world.setBlock(x+9, y+2, z+15, Block.getBlockById(98));
		world.setBlock(x+10, y+2, z+15, Block.getBlockById(98));
		world.setBlock(x+34, y+2, z+15, Block.getBlockById(98));
		world.setBlock(x+35, y+2, z+15, Block.getBlockById(98));
		world.setBlock(x+36, y+2, z+15, Block.getBlockById(98));
		world.setBlock(x+37, y+2, z+15, Block.getBlockById(98));
		world.setBlock(x+38, y+2, z+15, Block.getBlockById(98));
		world.setBlock(x+6, y+3, z+1, Block.getBlockById(98));
		world.setBlock(x+7, y+3, z+1, Block.getBlockById(98));
		world.setBlock(x+8, y+3, z+1, Block.getBlockById(98));
		world.setBlock(x+9, y+3, z+1, Block.getBlockById(98));
		world.setBlock(x+10, y+3, z+1, Block.getBlockById(98));
		world.setBlock(x+34, y+3, z+1, Block.getBlockById(98));
		world.setBlock(x+35, y+3, z+1, Block.getBlockById(98));
		world.setBlock(x+36, y+3, z+1, Block.getBlockById(98));
		world.setBlock(x+37, y+3, z+1, Block.getBlockById(98));
		world.setBlock(x+38, y+3, z+1, Block.getBlockById(98));
		world.setBlock(x+4, y+3, z+2, Block.getBlockById(98));
		world.setBlock(x+5, y+3, z+2, Block.getBlockById(98));
		world.setBlock(x+6, y+3, z+2, Block.getBlockById(98));
		world.setBlock(x+7, y+3, z+2, Block.getBlockById(98));
		world.setBlock(x+8, y+3, z+2, Block.getBlockById(98));
		world.setBlock(x+9, y+3, z+2, Block.getBlockById(98));
		world.setBlock(x+10, y+3, z+2, Block.getBlockById(98));
		world.setBlock(x+11, y+3, z+2, Block.getBlockById(98));
		world.setBlock(x+12, y+3, z+2, Block.getBlockById(98));
		world.setBlock(x+32, y+3, z+2, Block.getBlockById(98));
		world.setBlock(x+33, y+3, z+2, Block.getBlockById(98));
		world.setBlock(x+34, y+3, z+2, Block.getBlockById(98));
		world.setBlock(x+35, y+3, z+2, Block.getBlockById(98));
		world.setBlock(x+36, y+3, z+2, Block.getBlockById(98));
		world.setBlock(x+37, y+3, z+2, Block.getBlockById(98));
		world.setBlock(x+38, y+3, z+2, Block.getBlockById(98));
		world.setBlock(x+39, y+3, z+2, Block.getBlockById(98));
		world.setBlock(x+40, y+3, z+2, Block.getBlockById(98));
		world.setBlock(x+3, y+3, z+3, Block.getBlockById(98));
		world.setBlock(x+4, y+3, z+3, Block.getBlockById(98));
		world.setBlock(x+5, y+3, z+3, Block.getBlockById(98));
		world.setBlock(x+6, y+3, z+3, Block.getBlockById(98));
		world.setBlock(x+7, y+3, z+3, Block.getBlockById(98));
		world.setBlock(x+8, y+3, z+3, Block.getBlockById(98));
		world.setBlock(x+9, y+3, z+3, Block.getBlockById(98));
		world.setBlock(x+10, y+3, z+3, Block.getBlockById(98));
		world.setBlock(x+11, y+3, z+3, Block.getBlockById(98));
		world.setBlock(x+12, y+3, z+3, Block.getBlockById(98));
		world.setBlock(x+13, y+3, z+3, Block.getBlockById(98));
		world.setBlock(x+31, y+3, z+3, Block.getBlockById(98));
		world.setBlock(x+32, y+3, z+3, Block.getBlockById(98));
		world.setBlock(x+33, y+3, z+3, Block.getBlockById(98));
		world.setBlock(x+34, y+3, z+3, Block.getBlockById(98));
		world.setBlock(x+35, y+3, z+3, Block.getBlockById(98));
		world.setBlock(x+36, y+3, z+3, Block.getBlockById(98));
		world.setBlock(x+37, y+3, z+3, Block.getBlockById(98));
		world.setBlock(x+38, y+3, z+3, Block.getBlockById(98));
		world.setBlock(x+39, y+3, z+3, Block.getBlockById(98));
		world.setBlock(x+40, y+3, z+3, Block.getBlockById(98));
		world.setBlock(x+41, y+3, z+3, Block.getBlockById(98));
		world.setBlock(x+2, y+3, z+4, Block.getBlockById(98));
		world.setBlock(x+3, y+3, z+4, Block.getBlockById(98));
		world.setBlock(x+4, y+3, z+4, Block.getBlockById(98));
		world.setBlock(x+13, y+3, z+4, Block.getBlockById(98));
		world.setBlock(x+14, y+3, z+4, Block.getBlockById(98));
		world.setBlock(x+30, y+3, z+4, Block.getBlockById(98));
		world.setBlock(x+31, y+3, z+4, Block.getBlockById(98));
		world.setBlock(x+40, y+3, z+4, Block.getBlockById(98));
		world.setBlock(x+41, y+3, z+4, Block.getBlockById(98));
		world.setBlock(x+42, y+3, z+4, Block.getBlockById(98));
		world.setBlock(x+2, y+3, z+5, Block.getBlockById(98));
		world.setBlock(x+3, y+3, z+5, Block.getBlockById(98));
		world.setBlock(x+13, y+3, z+5, Block.getBlockById(98));
		world.setBlock(x+14, y+3, z+5, Block.getBlockById(98));
		world.setBlock(x+18, y+3, z+5, Block.getBlockById(1));
		world.setBlockMetadataWithNotify(x+18, y+3, z+5, 6, 6);
		world.setBlock(x+26, y+3, z+5, Block.getBlockById(1));
		world.setBlockMetadataWithNotify(x+26, y+3, z+5, 6, 6);
		world.setBlock(x+30, y+3, z+5, Block.getBlockById(98));
		world.setBlock(x+31, y+3, z+5, Block.getBlockById(98));
		world.setBlock(x+41, y+3, z+5, Block.getBlockById(98));
		world.setBlock(x+42, y+3, z+5, Block.getBlockById(98));
		world.setBlock(x+1, y+3, z+6, Block.getBlockById(98));
		world.setBlock(x+2, y+3, z+6, Block.getBlockById(98));
		world.setBlock(x+3, y+3, z+6, Block.getBlockById(98));
		world.setBlock(x+13, y+3, z+6, Block.getBlockById(98));
		world.setBlock(x+14, y+3, z+6, Block.getBlockById(98));
		world.setBlock(x+15, y+3, z+6, Block.getBlockById(98));
		world.setBlock(x+16, y+3, z+6, Block.getBlockById(98));
		world.setBlock(x+17, y+3, z+6, Block.getBlockById(98));
		world.setBlock(x+18, y+3, z+6, Block.getBlockById(98));
		world.setBlock(x+26, y+3, z+6, Block.getBlockById(98));
		world.setBlock(x+27, y+3, z+6, Block.getBlockById(98));
		world.setBlock(x+28, y+3, z+6, Block.getBlockById(98));
		world.setBlock(x+29, y+3, z+6, Block.getBlockById(98));
		world.setBlock(x+30, y+3, z+6, Block.getBlockById(98));
		world.setBlock(x+31, y+3, z+6, Block.getBlockById(98));
		world.setBlock(x+41, y+3, z+6, Block.getBlockById(98));
		world.setBlock(x+42, y+3, z+6, Block.getBlockById(98));
		world.setBlock(x+43, y+3, z+6, Block.getBlockById(98));
		world.setBlock(x+1, y+3, z+7, Block.getBlockById(98));
		world.setBlock(x+2, y+3, z+7, Block.getBlockById(98));
		world.setBlock(x+3, y+3, z+7, Block.getBlockById(98));
		world.setBlock(x+18, y+3, z+7, Block.getBlockById(98));
		world.setBlock(x+19, y+3, z+7, Block.getBlockById(50));
		world.setBlockMetadataWithNotify(x+19, y+3, z+7, 1, 1);
		world.setBlock(x+25, y+3, z+7, Block.getBlockById(50));
		world.setBlockMetadataWithNotify(x+25, y+3, z+7, 2, 2);
		world.setBlock(x+26, y+3, z+7, Block.getBlockById(98));
		world.setBlock(x+41, y+3, z+7, Block.getBlockById(98));
		world.setBlock(x+42, y+3, z+7, Block.getBlockById(98));
		world.setBlock(x+43, y+3, z+7, Block.getBlockById(98));
		world.setBlock(x+1, y+3, z+8, Block.getBlockById(98));
		world.setBlock(x+2, y+3, z+8, Block.getBlockById(98));
		world.setBlock(x+3, y+3, z+8, Block.getBlockById(98));
		world.setBlock(x+11, y+3, z+8, Block.getBlockById(44));
		world.setBlockMetadataWithNotify(x+11, y+3, z+8, 8, 8);
		world.setBlock(x+12, y+3, z+8, Block.getBlockById(44));
		world.setBlockMetadataWithNotify(x+12, y+3, z+8, 8, 8);
		world.setBlock(x+18, y+3, z+8, Block.getBlockById(98));
		world.setBlock(x+26, y+3, z+8, Block.getBlockById(98));
		world.setBlock(x+32, y+3, z+8, Block.getBlockById(44));
		world.setBlockMetadataWithNotify(x+32, y+3, z+8, 8, 8);
		world.setBlock(x+33, y+3, z+8, Block.getBlockById(44));
		world.setBlockMetadataWithNotify(x+33, y+3, z+8, 8, 8);
		world.setBlock(x+41, y+3, z+8, Block.getBlockById(98));
		world.setBlock(x+42, y+3, z+8, Block.getBlockById(98));
		world.setBlock(x+43, y+3, z+8, Block.getBlockById(98));
		world.setBlock(x+1, y+3, z+9, Block.getBlockById(98));
		world.setBlock(x+2, y+3, z+9, Block.getBlockById(98));
		world.setBlock(x+3, y+3, z+9, Block.getBlockById(98));
		world.setBlock(x+11, y+3, z+9, Block.getBlockById(44));
		world.setBlock(x+12, y+3, z+9, Block.getBlockById(44));
		world.setBlock(x+13, y+3, z+9, Block.getBlockById(98));
		world.setBlock(x+14, y+3, z+9, Block.getBlockById(98));
		world.setBlock(x+15, y+3, z+9, Block.getBlockById(98));
		world.setBlock(x+16, y+3, z+9, Block.getBlockById(44));
		world.setBlockMetadataWithNotify(x+16, y+3, z+9, 13, 13);
		world.setBlock(x+17, y+3, z+9, Block.getBlockById(44));
		world.setBlockMetadataWithNotify(x+17, y+3, z+9, 13, 13);
		world.setBlock(x+18, y+3, z+9, Block.getBlockById(1));
		world.setBlockMetadataWithNotify(x+18, y+3, z+9, 6, 6);
		world.setBlock(x+26, y+3, z+9, Block.getBlockById(1));
		world.setBlockMetadataWithNotify(x+26, y+3, z+9, 6, 6);
		world.setBlock(x+27, y+3, z+9, Block.getBlockById(44));
		world.setBlockMetadataWithNotify(x+27, y+3, z+9, 13, 13);
		world.setBlock(x+28, y+3, z+9, Block.getBlockById(44));
		world.setBlockMetadataWithNotify(x+28, y+3, z+9, 13, 13);
		world.setBlock(x+29, y+3, z+9, Block.getBlockById(98));
		world.setBlock(x+30, y+3, z+9, Block.getBlockById(98));
		world.setBlock(x+31, y+3, z+9, Block.getBlockById(98));
		world.setBlock(x+32, y+3, z+9, Block.getBlockById(44));
		world.setBlock(x+33, y+3, z+9, Block.getBlockById(44));
		world.setBlock(x+41, y+3, z+9, Block.getBlockById(98));
		world.setBlock(x+42, y+3, z+9, Block.getBlockById(98));
		world.setBlock(x+43, y+3, z+9, Block.getBlockById(98));
		world.setBlock(x+1, y+3, z+10, Block.getBlockById(98));
		world.setBlock(x+2, y+3, z+10, Block.getBlockById(98));
		world.setBlock(x+3, y+3, z+10, Block.getBlockById(98));
		world.setBlock(x+13, y+3, z+10, Block.getBlockById(98));
		world.setBlock(x+14, y+3, z+10, Block.getBlockById(98));
		world.setBlock(x+15, y+3, z+10, Block.getBlockById(98));
		world.setBlock(x+29, y+3, z+10, Block.getBlockById(98));
		world.setBlock(x+30, y+3, z+10, Block.getBlockById(98));
		world.setBlock(x+31, y+3, z+10, Block.getBlockById(98));
		world.setBlock(x+41, y+3, z+10, Block.getBlockById(98));
		world.setBlock(x+42, y+3, z+10, Block.getBlockById(98));
		world.setBlock(x+43, y+3, z+10, Block.getBlockById(98));
		world.setBlock(x+2, y+3, z+11, Block.getBlockById(98));
		world.setBlock(x+3, y+3, z+11, Block.getBlockById(98));
		world.setBlock(x+13, y+3, z+11, Block.getBlockById(98));
		world.setBlock(x+14, y+3, z+11, Block.getBlockById(98));
		world.setBlock(x+30, y+3, z+11, Block.getBlockById(98));
		world.setBlock(x+31, y+3, z+11, Block.getBlockById(98));
		world.setBlock(x+41, y+3, z+11, Block.getBlockById(98));
		world.setBlock(x+42, y+3, z+11, Block.getBlockById(98));
		world.setBlock(x+2, y+3, z+12, Block.getBlockById(98));
		world.setBlock(x+3, y+3, z+12, Block.getBlockById(98));
		world.setBlock(x+4, y+3, z+12, Block.getBlockById(98));
		world.setBlock(x+12, y+3, z+12, Block.getBlockById(98));
		world.setBlock(x+13, y+3, z+12, Block.getBlockById(98));
		world.setBlock(x+14, y+3, z+12, Block.getBlockById(98));
		world.setBlock(x+30, y+3, z+12, Block.getBlockById(98));
		world.setBlock(x+31, y+3, z+12, Block.getBlockById(98));
		world.setBlock(x+32, y+3, z+12, Block.getBlockById(98));
		world.setBlock(x+40, y+3, z+12, Block.getBlockById(98));
		world.setBlock(x+41, y+3, z+12, Block.getBlockById(98));
		world.setBlock(x+42, y+3, z+12, Block.getBlockById(98));
		world.setBlock(x+3, y+3, z+13, Block.getBlockById(98));
		world.setBlock(x+4, y+3, z+13, Block.getBlockById(98));
		world.setBlock(x+5, y+3, z+13, Block.getBlockById(98));
		world.setBlock(x+6, y+3, z+13, Block.getBlockById(98));
		world.setBlock(x+7, y+3, z+13, Block.getBlockById(98));
		world.setBlock(x+8, y+3, z+13, Block.getBlockById(98));
		world.setBlock(x+9, y+3, z+13, Block.getBlockById(98));
		world.setBlock(x+10, y+3, z+13, Block.getBlockById(98));
		world.setBlock(x+11, y+3, z+13, Block.getBlockById(98));
		world.setBlock(x+12, y+3, z+13, Block.getBlockById(98));
		world.setBlock(x+13, y+3, z+13, Block.getBlockById(98));
		world.setBlock(x+31, y+3, z+13, Block.getBlockById(98));
		world.setBlock(x+32, y+3, z+13, Block.getBlockById(98));
		world.setBlock(x+33, y+3, z+13, Block.getBlockById(98));
		world.setBlock(x+34, y+3, z+13, Block.getBlockById(98));
		world.setBlock(x+35, y+3, z+13, Block.getBlockById(98));
		world.setBlock(x+36, y+3, z+13, Block.getBlockById(98));
		world.setBlock(x+37, y+3, z+13, Block.getBlockById(98));
		world.setBlock(x+38, y+3, z+13, Block.getBlockById(98));
		world.setBlock(x+39, y+3, z+13, Block.getBlockById(98));
		world.setBlock(x+40, y+3, z+13, Block.getBlockById(98));
		world.setBlock(x+41, y+3, z+13, Block.getBlockById(98));
		world.setBlock(x+4, y+3, z+14, Block.getBlockById(98));
		world.setBlock(x+5, y+3, z+14, Block.getBlockById(98));
		world.setBlock(x+6, y+3, z+14, Block.getBlockById(98));
		world.setBlock(x+7, y+3, z+14, Block.getBlockById(98));
		world.setBlock(x+8, y+3, z+14, Block.getBlockById(98));
		world.setBlock(x+9, y+3, z+14, Block.getBlockById(98));
		world.setBlock(x+10, y+3, z+14, Block.getBlockById(98));
		world.setBlock(x+11, y+3, z+14, Block.getBlockById(98));
		world.setBlock(x+12, y+3, z+14, Block.getBlockById(98));
		world.setBlock(x+32, y+3, z+14, Block.getBlockById(98));
