package fr.toss.common.world.bioms.deco;

import net.minecraft.block.Block;
import net.minecraft.world.World;

public class WorldGenMoulin {

		public static void spawn(World world, int x, int y, int z) {

			world.setBlock(x+0, y+0, z+0, Block.getBlockById(2));
			world.setBlock(x+1, y+0, z+0, Block.getBlockById(2));
			world.setBlock(x+2, y+0, z+0, Block.getBlockById(2));
			world.setBlock(x+3, y+0, z+0, Block.getBlockById(3));
			world.setBlock(x+4, y+0, z+0, Block.getBlockById(3));
			world.setBlock(x+5, y+0, z+0, Block.getBlockById(2));
			world.setBlock(x+6, y+0, z+0, Block.getBlockById(2));
			world.setBlock(x+7, y+0, z+0, Block.getBlockById(2));
			world.setBlock(x+8, y+0, z+0, Block.getBlockById(2));
			world.setBlock(x+9, y+0, z+0, Block.getBlockById(2));
			world.setBlock(x+10, y+0, z+0, Block.getBlockById(2));
			world.setBlock(x+0, y+0, z+1, Block.getBlockById(2));
			world.setBlock(x+1, y+0, z+1, Block.getBlockById(2));
			world.setBlock(x+2, y+0, z+1, Block.getBlockById(2));
			world.setBlock(x+3, y+0, z+1, Block.getBlockById(2));
			world.setBlock(x+4, y+0, z+1, Block.getBlockById(5));
			world.setBlockMetadataWithNotify(x+4, y+0, z+1, 1, 1);
			world.setBlock(x+5, y+0, z+1, Block.getBlockById(5));
			world.setBlockMetadataWithNotify(x+5, y+0, z+1, 1, 1);
			world.setBlock(x+6, y+0, z+1, Block.getBlockById(5));
			world.setBlockMetadataWithNotify(x+6, y+0, z+1, 1, 1);
			world.setBlock(x+8, y+0, z+1, Block.getBlockById(31));
			world.setBlockMetadataWithNotify(x+8, y+0, z+1, 1, 1);
			world.setBlock(x+9, y+0, z+1, Block.getBlockById(2));
			world.setBlock(x+10, y+0, z+1, Block.getBlockById(2));
			world.setBlock(x+0, y+0, z+2, Block.getBlockById(2));
			world.setBlock(x+1, y+0, z+2, Block.getBlockById(2));
			world.setBlock(x+2, y+0, z+2, Block.getBlockById(2));
			world.setBlock(x+3, y+0, z+2, Block.getBlockById(5));
			world.setBlockMetadataWithNotify(x+3, y+0, z+2, 1, 1);
			world.setBlock(x+4, y+0, z+2, Block.getBlockById(17));
			world.setBlock(x+5, y+0, z+2, Block.getBlockById(17));
			world.setBlock(x+6, y+0, z+2, Block.getBlockById(17));
			world.setBlock(x+7, y+0, z+2, Block.getBlockById(5));
			world.setBlockMetadataWithNotify(x+7, y+0, z+2, 1, 1);
			world.setBlock(x+8, y+0, z+2, Block.getBlockById(31));
			world.setBlockMetadataWithNotify(x+8, y+0, z+2, 1, 1);
			world.setBlock(x+10, y+0, z+2, Block.getBlockById(2));
			world.setBlock(x+0, y+0, z+3, Block.getBlockById(2));
			world.setBlock(x+1, y+0, z+3, Block.getBlockById(2));
			world.setBlock(x+2, y+0, z+3, Block.getBlockById(5));
			world.setBlockMetadataWithNotify(x+2, y+0, z+3, 1, 1);
			world.setBlock(x+3, y+0, z+3, Block.getBlockById(17));
			world.setBlock(x+4, y+0, z+3, Block.getBlockById(17));
			world.setBlock(x+5, y+0, z+3, Block.getBlockById(17));
			world.setBlock(x+6, y+0, z+3, Block.getBlockById(17));
			world.setBlock(x+7, y+0, z+3, Block.getBlockById(17));
			world.setBlock(x+8, y+0, z+3, Block.getBlockById(5));
			world.setBlockMetadataWithNotify(x+8, y+0, z+3, 1, 1);
			world.setBlock(x+9, y+0, z+3, Block.getBlockById(31));
			world.setBlockMetadataWithNotify(x+9, y+0, z+3, 1, 1);
			world.setBlock(x+10, y+0, z+3, Block.getBlockById(2));
			world.setBlock(x+0, y+0, z+4, Block.getBlockById(2));
			world.setBlock(x+1, y+0, z+4, Block.getBlockById(5));
			world.setBlockMetadataWithNotify(x+1, y+0, z+4, 1, 1);
			world.setBlock(x+2, y+0, z+4, Block.getBlockById(17));
			world.setBlock(x+3, y+0, z+4, Block.getBlockById(17));
			world.setBlock(x+4, y+0, z+4, Block.getBlockById(17));
			world.setBlock(x+5, y+0, z+4, Block.getBlockById(17));
			world.setBlock(x+6, y+0, z+4, Block.getBlockById(17));
			world.setBlock(x+7, y+0, z+4, Block.getBlockById(17));
			world.setBlock(x+8, y+0, z+4, Block.getBlockById(17));
			world.setBlock(x+9, y+0, z+4, Block.getBlockById(5));
			world.setBlockMetadataWithNotify(x+9, y+0, z+4, 1, 1);
			world.setBlock(x+10, y+0, z+4, Block.getBlockById(2));
			world.setBlock(x+0, y+0, z+5, Block.getBlockById(2));
			world.setBlock(x+1, y+0, z+5, Block.getBlockById(5));
			world.setBlockMetadataWithNotify(x+1, y+0, z+5, 1, 1);
			world.setBlock(x+2, y+0, z+5, Block.getBlockById(17));
			world.setBlock(x+3, y+0, z+5, Block.getBlockById(17));
			world.setBlock(x+4, y+0, z+5, Block.getBlockById(17));
			world.setBlock(x+5, y+0, z+5, Block.getBlockById(17));
			world.setBlock(x+6, y+0, z+5, Block.getBlockById(17));
			world.setBlock(x+7, y+0, z+5, Block.getBlockById(17));
			world.setBlock(x+8, y+0, z+5, Block.getBlockById(17));
			world.setBlock(x+9, y+0, z+5, Block.getBlockById(5));
			world.setBlockMetadataWithNotify(x+9, y+0, z+5, 1, 1);
			world.setBlock(x+10, y+0, z+5, Block.getBlockById(2));
			world.setBlock(x+0, y+0, z+6, Block.getBlockById(2));
			world.setBlock(x+1, y+0, z+6, Block.getBlockById(5));
			world.setBlockMetadataWithNotify(x+1, y+0, z+6, 1, 1);
			world.setBlock(x+2, y+0, z+6, Block.getBlockById(17));
			world.setBlock(x+3, y+0, z+6, Block.getBlockById(17));
			world.setBlock(x+4, y+0, z+6, Block.getBlockById(17));
			world.setBlock(x+5, y+0, z+6, Block.getBlockById(17));
			world.setBlock(x+6, y+0, z+6, Block.getBlockById(17));
			world.setBlock(x+7, y+0, z+6, Block.getBlockById(17));
			world.setBlock(x+8, y+0, z+6, Block.getBlockById(17));
			world.setBlock(x+9, y+0, z+6, Block.getBlockById(5));
			world.setBlockMetadataWithNotify(x+9, y+0, z+6, 1, 1);
			world.setBlock(x+10, y+0, z+6, Block.getBlockById(2));
			world.setBlock(x+0, y+0, z+7, Block.getBlockById(2));
			world.setBlock(x+1, y+0, z+7, Block.getBlockById(2));
			world.setBlock(x+2, y+0, z+7, Block.getBlockById(5));
			world.setBlockMetadataWithNotify(x+2, y+0, z+7, 1, 1);
			world.setBlock(x+3, y+0, z+7, Block.getBlockById(17));
			world.setBlock(x+4, y+0, z+7, Block.getBlockById(17));
			world.setBlock(x+5, y+0, z+7, Block.getBlockById(17));
			world.setBlock(x+6, y+0, z+7, Block.getBlockById(17));
			world.setBlock(x+7, y+0, z+7, Block.getBlockById(17));
			world.setBlock(x+8, y+0, z+7, Block.getBlockById(5));
			world.setBlockMetadataWithNotify(x+8, y+0, z+7, 1, 1);
			world.setBlock(x+9, y+0, z+7, Block.getBlockById(2));
			world.setBlock(x+10, y+0, z+7, Block.getBlockById(2));
			world.setBlock(x+0, y+0, z+8, Block.getBlockById(2));
			world.setBlock(x+1, y+0, z+8, Block.getBlockById(2));
			world.setBlock(x+2, y+0, z+8, Block.getBlockById(2));
			world.setBlock(x+3, y+0, z+8, Block.getBlockById(5));
			world.setBlockMetadataWithNotify(x+3, y+0, z+8, 1, 1);
			world.setBlock(x+4, y+0, z+8, Block.getBlockById(17));
			world.setBlock(x+5, y+0, z+8, Block.getBlockById(17));
			world.setBlock(x+6, y+0, z+8, Block.getBlockById(17));
			world.setBlock(x+7, y+0, z+8, Block.getBlockById(5));
			world.setBlockMetadataWithNotify(x+7, y+0, z+8, 1, 1);
			world.setBlock(x+8, y+0, z+8, Block.getBlockById(2));
			world.setBlock(x+9, y+0, z+8, Block.getBlockById(2));
			world.setBlock(x+10, y+0, z+8, Block.getBlockById(3));
			world.setBlock(x+0, y+0, z+9, Block.getBlockById(2));
			world.setBlock(x+1, y+0, z+9, Block.getBlockById(2));
			world.setBlock(x+2, y+0, z+9, Block.getBlockById(2));
			world.setBlock(x+3, y+0, z+9, Block.getBlockById(3));
			world.setBlock(x+4, y+0, z+9, Block.getBlockById(5));
			world.setBlockMetadataWithNotify(x+4, y+0, z+9, 1, 1);
			world.setBlock(x+5, y+0, z+9, Block.getBlockById(5));
			world.setBlockMetadataWithNotify(x+5, y+0, z+9, 1, 1);
			world.setBlock(x+6, y+0, z+9, Block.getBlockById(5));
			world.setBlockMetadataWithNotify(x+6, y+0, z+9, 1, 1);
			world.setBlock(x+7, y+0, z+9, Block.getBlockById(2));
			world.setBlock(x+8, y+0, z+9, Block.getBlockById(2));
			world.setBlock(x+9, y+0, z+9, Block.getBlockById(3));
			world.setBlock(x+10, y+0, z+9, Block.getBlockById(3));
			world.setBlock(x+0, y+0, z+10, Block.getBlockById(2));
			world.setBlock(x+1, y+0, z+10, Block.getBlockById(2));
			world.setBlock(x+2, y+0, z+10, Block.getBlockById(3));
			world.setBlock(x+3, y+0, z+10, Block.getBlockById(3));
			world.setBlock(x+4, y+0, z+10, Block.getBlockById(3));
			world.setBlock(x+5, y+0, z+10, Block.getBlockById(3));
			world.setBlock(x+6, y+0, z+10, Block.getBlockById(3));
			world.setBlock(x+7, y+0, z+10, Block.getBlockById(3));
			world.setBlock(x+8, y+0, z+10, Block.getBlockById(3));
			world.setBlock(x+9, y+0, z+10, Block.getBlockById(3));
			world.setBlock(x+10, y+0, z+10, Block.getBlockById(3));
			world.setBlock(x+3, y+1, z+0, Block.getBlockById(2));
			world.setBlock(x+4, y+1, z+0, Block.getBlockById(2));
			world.setBlock(x+6, y+1, z+0, Block.getBlockById(31));
			world.setBlockMetadataWithNotify(x+6, y+1, z+0, 1, 1);
			world.setBlock(x+4, y+1, z+1, Block.getBlockById(5));
			world.setBlockMetadataWithNotify(x+4, y+1, z+1, 1, 1);
			world.setBlock(x+5, y+1, z+1, Block.getBlockById(5));
			world.setBlockMetadataWithNotify(x+5, y+1, z+1, 1, 1);
			world.setBlock(x+6, y+1, z+1, Block.getBlockById(5));
			world.setBlockMetadataWithNotify(x+6, y+1, z+1, 1, 1);
			world.setBlock(x+3, y+1, z+2, Block.getBlockById(5));
			world.setBlockMetadataWithNotify(x+3, y+1, z+2, 1, 1);
			world.setBlock(x+7, y+1, z+2, Block.getBlockById(5));
			world.setBlockMetadataWithNotify(x+7, y+1, z+2, 1, 1);
			world.setBlock(x+2, y+1, z+3, Block.getBlockById(5));
			world.setBlockMetadataWithNotify(x+2, y+1, z+3, 1, 1);
			world.setBlock(x+8, y+1, z+3, Block.getBlockById(5));
			world.setBlockMetadataWithNotify(x+8, y+1, z+3, 1, 1);
			world.setBlock(x+1, y+1, z+4, Block.getBlockById(5));
			world.setBlockMetadataWithNotify(x+1, y+1, z+4, 1, 1);
			world.setBlock(x+5, y+1, z+4, Block.getBlockById(53));
			world.setBlockMetadataWithNotify(x+5, y+1, z+4, 2, 2);
			world.setBlock(x+6, y+1, z+4, Block.getBlockById(89));
			world.setBlock(x+9, y+1, z+4, Block.getBlockById(5));
			world.setBlockMetadataWithNotify(x+9, y+1, z+4, 1, 1);
			world.setBlock(x+5, y+1, z+5, Block.getBlockById(5));
			world.setBlockMetadataWithNotify(x+5, y+1, z+5, 1, 1);
			world.setBlock(x+6, y+1, z+5, Block.getBlockById(53));
			world.setBlockMetadataWithNotify(x+6, y+1, z+5, 1, 1);
			world.setBlock(x+9, y+1, z+5, Block.getBlockById(5));
			world.setBlockMetadataWithNotify(x+9, y+1, z+5, 1, 1);
			world.setBlock(x+1, y+1, z+6, Block.getBlockById(5));
			world.setBlockMetadataWithNotify(x+1, y+1, z+6, 1, 1);
			world.setBlock(x+5, y+1, z+6, Block.getBlockById(53));
			world.setBlockMetadataWithNotify(x+5, y+1, z+6, 3, 3);
			world.setBlock(x+6, y+1, z+6, Block.getBlockById(89));
			world.setBlock(x+9, y+1, z+6, Block.getBlockById(5));
			world.setBlockMetadataWithNotify(x+9, y+1, z+6, 1, 1);
			world.setBlock(x+2, y+1, z+7, Block.getBlockById(5));
			world.setBlockMetadataWithNotify(x+2, y+1, z+7, 1, 1);
			world.setBlock(x+8, y+1, z+7, Block.getBlockById(5));
			world.setBlockMetadataWithNotify(x+8, y+1, z+7, 1, 1);
			world.setBlock(x+3, y+1, z+8, Block.getBlockById(5));
			world.setBlockMetadataWithNotify(x+3, y+1, z+8, 1, 1);
			world.setBlock(x+4, y+1, z+8, Block.getBlockById(23));
			world.setBlockMetadataWithNotify(x+4, y+1, z+8, 2, 2);
			world.setBlock(x+7, y+1, z+8, Block.getBlockById(5));
			world.setBlockMetadataWithNotify(x+7, y+1, z+8, 1, 1);
			world.setBlock(x+10, y+1, z+8, Block.getBlockById(2));
			world.setBlock(x+3, y+1, z+9, Block.getBlockById(2));
			world.setBlock(x+4, y+1, z+9, Block.getBlockById(5));
			world.setBlockMetadataWithNotify(x+4, y+1, z+9, 1, 1);
			world.setBlock(x+5, y+1, z+9, Block.getBlockById(5));
			world.setBlockMetadataWithNotify(x+5, y+1, z+9, 1, 1);
			world.setBlock(x+6, y+1, z+9, Block.getBlockById(5));
			world.setBlockMetadataWithNotify(x+6, y+1, z+9, 1, 1);
			world.setBlock(x+7, y+1, z+9, Block.getBlockById(31));
			world.setBlockMetadataWithNotify(x+7, y+1, z+9, 1, 1);
			world.setBlock(x+9, y+1, z+9, Block.getBlockById(2));
			world.setBlock(x+10, y+1, z+9, Block.getBlockById(2));
			world.setBlock(x+2, y+1, z+10, Block.getBlockById(2));
			world.setBlock(x+3, y+1, z+10, Block.getBlockById(2));
			world.setBlock(x+4, y+1, z+10, Block.getBlockById(2));
			world.setBlock(x+5, y+1, z+10, Block.getBlockById(2));
			world.setBlock(x+6, y+1, z+10, Block.getBlockById(2));
			world.setBlock(x+7, y+1, z+10, Block.getBlockById(2));
			world.setBlock(x+8, y+1, z+10, Block.getBlockById(2));
			world.setBlock(x+9, y+1, z+10, Block.getBlockById(2));
			world.setBlock(x+10, y+1, z+10, Block.getBlockById(2));
			world.setBlock(x+3, y+2, z+0, Block.getBlockById(31));
			world.setBlockMetadataWithNotify(x+3, y+2, z+0, 1, 1);
			world.setBlock(x+4, y+2, z+1, Block.getBlockById(5));
			world.setBlock(x+5, y+2, z+1, Block.getBlockById(5));
			world.setBlock(x+6, y+2, z+1, Block.getBlockById(5));
			world.setBlock(x+3, y+2, z+2, Block.getBlockById(5));
			world.setBlock(x+7, y+2, z+2, Block.getBlockById(5));
			world.setBlock(x+2, y+2, z+3, Block.getBlockById(5));
			world.setBlock(x+8, y+2, z+3, Block.getBlockById(5));
			world.setBlock(x+1, y+2, z+4, Block.getBlockById(5));
			world.setBlockMetadataWithNotify(x+1, y+2, z+4, 1, 1);
			world.setBlock(x+5, y+2, z+4, Block.getBlockById(85));
			world.setBlock(x+9, y+2, z+4, Block.getBlockById(5));
			world.setBlock(x+5, y+2, z+5, Block.getBlockById(85));
			world.setBlock(x+6, y+2, z+5, Block.getBlockById(85));
			world.setBlock(x+9, y+2, z+5, Block.getBlockById(5));
			world.setBlock(x+1, y+2, z+6, Block.getBlockById(5));
			world.setBlockMetadataWithNotify(x+1, y+2, z+6, 1, 1);
			world.setBlock(x+5, y+2, z+6, Block.getBlockById(85));
			world.setBlock(x+9, y+2, z+6, Block.getBlockById(5));
			world.setBlock(x+2, y+2, z+7, Block.getBlockById(5));
			world.setBlock(x+8, y+2, z+7, Block.getBlockById(5));
			world.setBlock(x+3, y+2, z+8, Block.getBlockById(5));
			world.setBlock(x+7, y+2, z+8, Block.getBlockById(5));
			world.setBlockMetadataWithNotify(x+7, y+2, z+8, 2, 2);
			world.setBlock(x+4, y+2, z+9, Block.getBlockById(5));
			world.setBlock(x+5, y+2, z+9, Block.getBlockById(5));
			world.setBlock(x+6, y+2, z+9, Block.getBlockById(5));
			world.setBlock(x+4, y+3, z+1, Block.getBlockById(5));
			world.setBlockMetadataWithNotify(x+4, y+3, z+1, 1, 1);
			world.setBlock(x+5, y+3, z+1, Block.getBlockById(5));
			world.setBlockMetadataWithNotify(x+5, y+3, z+1, 1, 1);
			world.setBlock(x+6, y+3, z+1, Block.getBlockById(5));
			world.setBlockMetadataWithNotify(x+6, y+3, z+1, 1, 1);
			world.setBlock(x+3, y+3, z+2, Block.getBlockById(5));
			world.setBlockMetadataWithNotify(x+3, y+3, z+2, 1, 1);
			world.setBlock(x+7, y+3, z+2, Block.getBlockById(5));
			world.setBlockMetadataWithNotify(x+7, y+3, z+2, 1, 1);
			world.setBlock(x+2, y+3, z+3, Block.getBlockById(5));
			world.setBlockMetadataWithNotify(x+2, y+3, z+3, 1, 1);
			world.setBlock(x+8, y+3, z+3, Block.getBlockById(5));
			world.setBlockMetadataWithNotify(x+8, y+3, z+3, 1, 1);
			world.setBlock(x+1, y+3, z+4, Block.getBlockById(5));
			world.setBlockMetadataWithNotify(x+1, y+3, z+4, 1, 1);
			world.setBlock(x+5, y+3, z+4, Block.getBlockById(85));
			world.setBlock(x+6, y+3, z+4, Block.getBlockById(85));
			world.setBlock(x+9, y+3, z+4, Block.getBlockById(5));
			world.setBlockMetadataWithNotify(x+9, y+3, z+4, 1, 1);
			world.setBlock(x+1, y+3, z+5, Block.getBlockById(5));
			world.setBlockMetadataWithNotify(x+1, y+3, z+5, 1, 1);
			world.setBlock(x+4, y+3, z+5, Block.getBlockById(85));
			world.setBlock(x+5, y+3, z+5, Block.getBlockById(85));
			world.setBlock(x+6, y+3, z+5, Block.getBlockById(85));
			world.setBlock(x+9, y+3, z+5, Block.getBlockById(5));
			world.setBlockMetadataWithNotify(x+9, y+3, z+5, 1, 1);
			world.setBlock(x+1, y+3, z+6, Block.getBlockById(5));
			world.setBlockMetadataWithNotify(x+1, y+3, z+6, 1, 1);
			world.setBlock(x+5, y+3, z+6, Block.getBlockById(85));
			world.setBlock(x+6, y+3, z+6, Block.getBlockById(85));
			world.setBlock(x+9, y+3, z+6, Block.getBlockById(5));
			world.setBlockMetadataWithNotify(x+9, y+3, z+6, 1, 1);
			world.setBlock(x+2, y+3, z+7, Block.getBlockById(5));
			world.setBlockMetadataWithNotify(x+2, y+3, z+7, 1, 1);
			world.setBlock(x+8, y+3, z+7, Block.getBlockById(5));
			world.setBlockMetadataWithNotify(x+8, y+3, z+7, 1, 1);
			world.setBlock(x+3, y+3, z+8, Block.getBlockById(5));
			world.setBlockMetadataWithNotify(x+3, y+3, z+8, 1, 1);
			world.setBlock(x+7, y+3, z+8, Block.getBlockById(5));
			world.setBlockMetadataWithNotify(x+7, y+3, z+8, 1, 1);
			world.setBlock(x+4, y+3, z+9, Block.getBlockById(5));
			world.setBlockMetadataWithNotify(x+4, y+3, z+9, 1, 1);
			world.setBlock(x+5, y+3, z+9, Block.getBlockById(5));
			world.setBlockMetadataWithNotify(x+5, y+3, z+9, 1, 1);
			world.setBlock(x+6, y+3, z+9, Block.getBlockById(5));
			world.setBlockMetadataWithNotify(x+6, y+3, z+9, 1, 1);
			world.setBlock(x+4, y+4, z+0, Block.getBlockById(50));
			world.setBlockMetadataWithNotify(x+4, y+4, z+0, 4, 4);
			world.setBlock(x+6, y+4, z+0, Block.getBlockById(50));
			world.setBlockMetadataWithNotify(x+6, y+4, z+0, 4, 4);
			world.setBlock(x+4, y+4, z+1, Block.getBlockById(5));
			world.setBlockMetadataWithNotify(x+4, y+4, z+1, 1, 1);
			world.setBlock(x+5, y+4, z+1, Block.getBlockById(5));
			world.setBlockMetadataWithNotify(x+5, y+4, z+1, 1, 1);
			world.setBlock(x+6, y+4, z+1, Block.getBlockById(5));
			world.setBlockMetadataWithNotify(x+6, y+4, z+1, 1, 1);
			world.setBlock(x+3, y+4, z+2, Block.getBlockById(5));
			world.setBlockMetadataWithNotify(x+3, y+4, z+2, 1, 1);
			world.setBlock(x+7, y+4, z+2, Block.getBlockById(5));
			world.setBlockMetadataWithNotify(x+7, y+4, z+2, 1, 1);
			world.setBlock(x+2, y+4, z+3, Block.getBlockById(5));
			world.setBlockMetadataWithNotify(x+2, y+4, z+3, 1, 1);
			world.setBlock(x+8, y+4, z+3, Block.getBlockById(5));
			world.setBlockMetadataWithNotify(x+8, y+4, z+3, 1, 1);
			world.setBlock(x+0, y+4, z+4, Block.getBlockById(50));
			world.setBlockMetadataWithNotify(x+0, y+4, z+4, 2, 2);
			world.setBlock(x+1, y+4, z+4, Block.getBlockById(5));
			world.setBlockMetadataWithNotify(x+1, y+4, z+4, 1, 1);
			world.setBlock(x+9, y+4, z+4, Block.getBlockById(5));
			world.setBlockMetadataWithNotify(x+9, y+4, z+4, 1, 1);
			world.setBlock(x+10, y+4, z+4, Block.getBlockById(50));
			world.setBlockMetadataWithNotify(x+10, y+4, z+4, 1, 1);
			world.setBlock(x+1, y+4, z+5, Block.getBlockById(5));
			world.setBlock(x+4, y+4, z+5, Block.getBlockById(85));
			world.setBlock(x+5, y+4, z+5, Block.getBlockById(85));
			world.setBlock(x+9, y+4, z+5, Block.getBlockById(5));
			world.setBlockMetadataWithNotify(x+9, y+4, z+5, 1, 1);
			world.setBlock(x+0, y+4, z+6, Block.getBlockById(50));
			world.setBlockMetadataWithNotify(x+0, y+4, z+6, 2, 2);
			world.setBlock(x+1, y+4, z+6, Block.getBlockById(5));
			world.setBlockMetadataWithNotify(x+1, y+4, z+6, 1, 1);
			world.setBlock(x+9, y+4, z+6, Block.getBlockById(5));
			world.setBlockMetadataWithNotify(x+9, y+4, z+6, 1, 1);
			world.setBlock(x+10, y+4, z+6, Block.getBlockById(50));
			world.setBlockMetadataWithNotify(x+10, y+4, z+6, 1, 1);
			world.setBlock(x+2, y+4, z+7, Block.getBlockById(5));
			world.setBlockMetadataWithNotify(x+2, y+4, z+7, 1, 1);
			world.setBlock(x+8, y+4, z+7, Block.getBlockById(5));
			world.setBlockMetadataWithNotify(x+8, y+4, z+7, 1, 1);
			world.setBlock(x+3, y+4, z+8, Block.getBlockById(5));
			world.setBlockMetadataWithNotify(x+3, y+4, z+8, 1, 1);
			world.setBlock(x+7, y+4, z+8, Block.getBlockById(5));
			world.setBlockMetadataWithNotify(x+7, y+4, z+8, 1, 1);
			world.setBlock(x+4, y+4, z+9, Block.getBlockById(5));
			world.setBlockMetadataWithNotify(x+4, y+4, z+9, 1, 1);
			world.setBlock(x+5, y+4, z+9, Block.getBlockById(5));
			world.setBlockMetadataWithNotify(x+5, y+4, z+9, 1, 1);
			world.setBlock(x+6, y+4, z+9, Block.getBlockById(5));
			world.setBlockMetadataWithNotify(x+6, y+4, z+9, 1, 1);
			world.setBlock(x+4, y+4, z+10, Block.getBlockById(50));
			world.setBlockMetadataWithNotify(x+4, y+4, z+10, 3, 3);
			world.setBlock(x+6, y+4, z+10, Block.getBlockById(50));
			world.setBlockMetadataWithNotify(x+6, y+4, z+10, 3, 3);
			world.setBlock(x+4, y+5, z+1, Block.getBlockById(5));
			world.setBlock(x+5, y+5, z+1, Block.getBlockById(5));
			world.setBlock(x+6, y+5, z+1, Block.getBlockById(5));
			world.setBlock(x+3, y+5, z+2, Block.getBlockById(5));
			world.setBlock(x+7, y+5, z+2, Block.getBlockById(5));
			world.setBlock(x+2, y+5, z+3, Block.getBlockById(5));
			world.setBlock(x+8, y+5, z+3, Block.getBlockById(5));
			world.setBlock(x+1, y+5, z+4, Block.getBlockById(5));
			world.setBlock(x+5, y+5, z+4, Block.getBlockById(85));
			world.setBlock(x+9, y+5, z+4, Block.getBlockById(5));
			world.setBlock(x+1, y+5, z+5, Block.getBlockById(5));
			world.setBlock(x+4, y+5, z+5, Block.getBlockById(85));
			world.setBlock(x+5, y+5, z+5, Block.getBlockById(85));
			world.setBlock(x+6, y+5, z+5, Block.getBlockById(85));
			world.setBlock(x+9, y+5, z+5, Block.getBlockById(5));
			world.setBlock(x+1, y+5, z+6, Block.getBlockById(5));
			world.setBlock(x+5, y+5, z+6, Block.getBlockById(85));
			world.setBlock(x+9, y+5, z+6, Block.getBlockById(5));
			world.setBlock(x+2, y+5, z+7, Block.getBlockById(5));
			world.setBlock(x+8, y+5, z+7, Block.getBlockById(5));
			world.setBlock(x+3, y+5, z+8, Block.getBlockById(5));
			world.setBlock(x+7, y+5, z+8, Block.getBlockById(5));
			world.setBlock(x+4, y+5, z+9, Block.getBlockById(5));
			world.setBlock(x+5, y+5, z+9, Block.getBlockById(5));
			world.setBlock(x+6, y+5, z+9, Block.getBlockById(5));
			world.setBlock(x+4, y+6, z+1, Block.getBlockById(5));
			world.setBlockMetadataWithNotify(x+4, y+6, z+1, 1, 1);
			world.setBlock(x+5, y+6, z+1, Block.getBlockById(5));
			world.setBlockMetadataWithNotify(x+5, y+6, z+1, 1, 1);
			world.setBlock(x+6, y+6, z+1, Block.getBlockById(5));
			world.setBlockMetadataWithNotify(x+6, y+6, z+1, 1, 1);
			world.setBlock(x+3, y+6, z+2, Block.getBlockById(5));
			world.setBlockMetadataWithNotify(x+3, y+6, z+2, 1, 1);
			world.setBlock(x+4, y+6, z+2, Block.getBlockById(5));
			world.setBlockMetadataWithNotify(x+4, y+6, z+2, 1, 1);
			world.setBlock(x+5, y+6, z+2, Block.getBlockById(5));
			world.setBlockMetadataWithNotify(x+5, y+6, z+2, 1, 1);
			world.setBlock(x+6, y+6, z+2, Block.getBlockById(5));
			world.setBlockMetadataWithNotify(x+6, y+6, z+2, 1, 1);
			world.setBlock(x+7, y+6, z+2, Block.getBlockById(5));
			world.setBlockMetadataWithNotify(x+7, y+6, z+2, 1, 1);
			world.setBlock(x+2, y+6, z+3, Block.getBlockById(5));
			world.setBlockMetadataWithNotify(x+2, y+6, z+3, 1, 1);
			world.setBlock(x+8, y+6, z+3, Block.getBlockById(5));
			world.setBlockMetadataWithNotify(x+8, y+6, z+3, 1, 1);
			world.setBlock(x+1, y+6, z+4, Block.getBlockById(5));
			world.setBlockMetadataWithNotify(x+1, y+6, z+4, 1, 1);
			world.setBlock(x+2, y+6, z+4, Block.getBlockById(5));
			world.setBlockMetadataWithNotify(x+2, y+6, z+4, 1, 1);
			world.setBlock(x+5, y+6, z+4, Block.getBlockById(85));
			world.setBlock(x+8, y+6, z+4, Block.getBlockById(5));
			world.setBlockMetadataWithNotify(x+8, y+6, z+4, 1, 1);
			world.setBlock(x+9, y+6, z+4, Block.getBlockById(5));
			world.setBlockMetadataWithNotify(x+9, y+6, z+4, 1, 1);
			world.setBlock(x+1, y+6, z+5, Block.getBlockById(5));
			world.setBlock(x+2, y+6, z+5, Block.getBlockById(5));
			world.setBlockMetadataWithNotify(x+2, y+6, z+5, 1, 1);
			world.setBlock(x+5, y+6, z+5, Block.getBlockById(85));
			world.setBlock(x+8, y+6, z+5, Block.getBlockById(5));
			world.setBlockMetadataWithNotify(x+8, y+6, z+5, 1, 1);
			world.setBlock(x+9, y+6, z+5, Block.getBlockById(5));
			world.setBlockMetadataWithNotify(x+9, y+6, z+5, 1, 1);
			world.setBlock(x+1, y+6, z+6, Block.getBlockById(5));
			world.setBlockMetadataWithNotify(x+1, y+6, z+6, 1, 1);
			world.setBlock(x+2, y+6, z+6, Block.getBlockById(5));
			world.setBlockMetadataWithNotify(x+2, y+6, z+6, 1, 1);
			world.setBlock(x+8, y+6, z+6, Block.getBlockById(5));
			world.setBlockMetadataWithNotify(x+8, y+6, z+6, 1, 1);
			world.setBlock(x+9, y+6, z+6, Block.getBlockById(5));
			world.setBlockMetadataWithNotify(x+9, y+6, z+6, 1, 1);
			world.setBlock(x+2, y+6, z+7, Block.getBlockById(5));
			world.setBlockMetadataWithNotify(x+2, y+6, z+7, 1, 1);
			world.setBlock(x+8, y+6, z+7, Block.getBlockById(5));
			world.setBlockMetadataWithNotify(x+8, y+6, z+7, 1, 1);
			world.setBlock(x+3, y+6, z+8, Block.getBlockById(5));
			world.setBlockMetadataWithNotify(x+3, y+6, z+8, 1, 1);
			world.setBlock(x+4, y+6, z+8, Block.getBlockById(5));
			world.setBlockMetadataWithNotify(x+4, y+6, z+8, 1, 1);
			world.setBlock(x+5, y+6, z+8, Block.getBlockById(5));
			world.setBlockMetadataWithNotify(x+5, y+6, z+8, 1, 1);
			world.setBlock(x+6, y+6, z+8, Block.getBlockById(5));
			world.setBlockMetadataWithNotify(x+6, y+6, z+8, 1, 1);
			world.setBlock(x+7, y+6, z+8, Block.getBlockById(5));
			world.setBlockMetadataWithNotify(x+7, y+6, z+8, 1, 1);
			world.setBlock(x+4, y+6, z+9, Block.getBlockById(5));
			world.setBlockMetadataWithNotify(x+4, y+6, z+9, 1, 1);
			world.setBlock(x+5, y+6, z+9, Block.getBlockById(5));
			world.setBlockMetadataWithNotify(x+5, y+6, z+9, 1, 1);
			world.setBlock(x+6, y+6, z+9, Block.getBlockById(5));
			world.setBlockMetadataWithNotify(x+6, y+6, z+9, 1, 1);
			world.setBlock(x+0, y+7, z+0, Block.getBlockById(35));
			world.setBlock(x+0, y+7, z+1, Block.getBlockById(5));
			world.setBlock(x+4, y+7, z+1, Block.getBlockById(134));
			world.setBlockMetadataWithNotify(x+4, y+7, z+1, 2, 2);
			world.setBlock(x+5, y+7, z+1, Block.getBlockById(134));
			world.setBlockMetadataWithNotify(x+5, y+7, z+1, 2, 2);
			world.setBlock(x+6, y+7, z+1, Block.getBlockById(134));
			world.setBlockMetadataWithNotify(x+6, y+7, z+1, 2, 2);
			world.setBlock(x+0, y+7, z+2, Block.getBlockById(5));
			world.setBlock(x+3, y+7, z+2, Block.getBlockById(134));
			world.setBlockMetadataWithNotify(x+3, y+7, z+2, 2, 2);
			world.setBlock(x+4, y+7, z+2, Block.getBlockById(5));
			world.setBlockMetadataWithNotify(x+4, y+7, z+2, 1, 1);
			world.setBlock(x+5, y+7, z+2, Block.getBlockById(5));
			world.setBlockMetadataWithNotify(x+5, y+7, z+2, 1, 1);
			world.setBlock(x+6, y+7, z+2, Block.getBlockById(5));
			world.setBlockMetadataWithNotify(x+6, y+7, z+2, 1, 1);
			world.setBlock(x+7, y+7, z+2, Block.getBlockById(134));
			world.setBlockMetadataWithNotify(x+7, y+7, z+2, 2, 2);
			world.setBlock(x+2, y+7, z+3, Block.getBlockById(134));
			world.setBlock(x+3, y+7, z+3, Block.getBlockById(5));
			world.setBlockMetadataWithNotify(x+3, y+7, z+3, 1, 1);
			world.setBlock(x+7, y+7, z+3, Block.getBlockById(5));
			world.setBlockMetadataWithNotify(x+7, y+7, z+3, 1, 1);
			world.setBlock(x+8, y+7, z+3, Block.getBlockById(134));
			world.setBlockMetadataWithNotify(x+8, y+7, z+3, 1, 1);
			world.setBlock(x+1, y+7, z+4, Block.getBlockById(134));
			world.setBlock(x+2, y+7, z+4, Block.getBlockById(5));
			world.setBlockMetadataWithNotify(x+2, y+7, z+4, 1, 1);
			world.setBlock(x+5, y+7, z+4, Block.getBlockById(85));
			world.setBlock(x+8, y+7, z+4, Block.getBlockById(5));
			world.setBlockMetadataWithNotify(x+8, y+7, z+4, 1, 1);
			world.setBlock(x+9, y+7, z+4, Block.getBlockById(134));
			world.setBlockMetadataWithNotify(x+9, y+7, z+4, 1, 1);
			world.setBlock(x+1, y+7, z+5, Block.getBlockById(134));
			world.setBlock(x+2, y+7, z+5, Block.getBlockById(5));
			world.setBlockMetadataWithNotify(x+2, y+7, z+5, 1, 1);
			world.setBlock(x+4, y+7, z+5, Block.getBlockById(85));
			world.setBlock(x+5, y+7, z+5, Block.getBlockById(85));
			world.setBlock(x+6, y+7, z+5, Block.getBlockById(85));
			world.setBlock(x+8, y+7, z+5, Block.getBlockById(5));
			world.setBlockMetadataWithNotify(x+8, y+7, z+5, 1, 1);
			world.setBlock(x+9, y+7, z+5, Block.getBlockById(134));
			world.setBlockMetadataWithNotify(x+9, y+7, z+5, 1, 1);
			world.setBlock(x+1, y+7, z+6, Block.getBlockById(134));
			world.setBlock(x+2, y+7, z+6, Block.getBlockById(5));
			world.setBlockMetadataWithNotify(x+2, y+7, z+6, 1, 1);
			world.setBlock(x+5, y+7, z+6, Block.getBlockById(85));
			world.setBlock(x+8, y+7, z+6, Block.getBlockById(5));
			world.setBlockMetadataWithNotify(x+8, y+7, z+6, 1, 1);
			world.setBlock(x+9, y+7, z+6, Block.getBlockById(134));
			world.setBlockMetadataWithNotify(x+9, y+7, z+6, 1, 1);
			world.setBlock(x+2, y+7, z+7, Block.getBlockById(134));
			world.setBlock(x+3, y+7, z+7, Block.getBlockById(5));
			world.setBlockMetadataWithNotify(x+3, y+7, z+7, 1, 1);
			world.setBlock(x+7, y+7, z+7, Block.getBlockById(5));
			world.setBlockMetadataWithNotify(x+7, y+7, z+7, 1, 1);
			world.setBlock(x+8, y+7, z+7, Block.getBlockById(134));
			world.setBlockMetadataWithNotify(x+8, y+7, z+7, 1, 1);
			world.setBlock(x+3, y+7, z+8, Block.getBlockById(134));
			world.setBlockMetadataWithNotify(x+3, y+7, z+8, 3, 3);
			world.setBlock(x+4, y+7, z+8, Block.getBlockById(5));
			world.setBlockMetadataWithNotify(x+4, y+7, z+8, 1, 1);
			world.setBlock(x+5, y+7, z+8, Block.getBlockById(5));
			world.setBlockMetadataWithNotify(x+5, y+7, z+8, 1, 1);
			world.setBlock(x+6, y+7, z+8, Block.getBlockById(5));
			world.setBlockMetadataWithNotify(x+6, y+7, z+8, 1, 1);
			world.setBlock(x+7, y+7, z+8, Block.getBlockById(134));
			world.setBlockMetadataWithNotify(x+7, y+7, z+8, 3, 3);
			world.setBlock(x+4, y+7, z+9, Block.getBlockById(134));
			world.setBlockMetadataWithNotify(x+4, y+7, z+9, 3, 3);
			world.setBlock(x+5, y+7, z+9, Block.getBlockById(134));
			world.setBlockMetadataWithNotify(x+5, y+7, z+9, 3, 3);
			world.setBlock(x+6, y+7, z+9, Block.getBlockById(134));
			world.setBlockMetadataWithNotify(x+6, y+7, z+9, 3, 3);
			world.setBlock(x+0, y+7, z+10, Block.getBlockById(35));
			world.setBlock(x+0, y+8, z+1, Block.getBlockById(35));
			world.setBlock(x+0, y+8, z+2, Block.getBlockById(5));
			world.setBlock(x+4, y+8, z+2, Block.getBlockById(5));
			world.setBlockMetadataWithNotify(x+4, y+8, z+2, 1, 1);
			world.setBlock(x+5, y+8, z+2, Block.getBlockById(5));
			world.setBlock(x+6, y+8, z+2, Block.getBlockById(5));
			world.setBlockMetadataWithNotify(x+6, y+8, z+2, 1, 1);
			world.setBlock(x+0, y+8, z+3, Block.getBlockById(5));
			world.setBlock(x+3, y+8, z+3, Block.getBlockById(5));
			world.setBlockMetadataWithNotify(x+3, y+8, z+3, 1, 1);
			world.setBlock(x+7, y+8, z+3, Block.getBlockById(5));
			world.setBlockMetadataWithNotify(x+7, y+8, z+3, 1, 1);
			world.setBlock(x+2, y+8, z+4, Block.getBlockById(5));
			world.setBlockMetadataWithNotify(x+2, y+8, z+4, 1, 1);
			world.setBlock(x+8, y+8, z+4, Block.getBlockById(5));
			world.setBlockMetadataWithNotify(x+8, y+8, z+4, 1, 1);
			world.setBlock(x+2, y+8, z+5, Block.getBlockById(5));
			world.setBlock(x+5, y+8, z+5, Block.getBlockById(85));
			world.setBlock(x+6, y+8, z+5, Block.getBlockById(85));
			world.setBlock(x+8, y+8, z+5, Block.getBlockById(5));
			world.setBlock(x+2, y+8, z+6, Block.getBlockById(5));
			world.setBlockMetadataWithNotify(x+2, y+8, z+6, 1, 1);
			world.setBlock(x+8, y+8, z+6, Block.getBlockById(5));
			world.setBlockMetadataWithNotify(x+8, y+8, z+6, 1, 1);
			world.setBlock(x+3, y+8, z+7, Block.getBlockById(5));
			world.setBlockMetadataWithNotify(x+3, y+8, z+7, 1, 1);
			world.setBlock(x+7, y+8, z+7, Block.getBlockById(5));
			world.setBlockMetadataWithNotify(x+7, y+8, z+7, 1, 1);
			world.setBlock(x+4, y+8, z+8, Block.getBlockById(5));
			world.setBlockMetadataWithNotify(x+4, y+8, z+8, 1, 1);
			world.setBlock(x+5, y+8, z+8, Block.getBlockById(5));
			world.setBlock(x+6, y+8, z+8, Block.getBlockById(5));
			world.setBlockMetadataWithNotify(x+6, y+8, z+8, 1, 1);
			world.setBlock(x+0, y+8, z+9, Block.getBlockById(35));
			world.setBlock(x+0, y+8, z+10, Block.getBlockById(5));
			world.setBlock(x+0, y+9, z+2, Block.getBlockById(35));
			world.setBlock(x+4, y+9, z+2, Block.getBlockById(5));
			world.setBlockMetadataWithNotify(x+4, y+9, z+2, 1, 1);
			world.setBlock(x+5, y+9, z+2, Block.getBlockById(5));
			world.setBlock(x+6, y+9, z+2, Block.getBlockById(5));
			world.setBlockMetadataWithNotify(x+6, y+9, z+2, 1, 1);
			world.setBlock(x+0, y+9, z+3, Block.getBlockById(5));
			world.setBlock(x+3, y+9, z+3, Block.getBlockById(5));
			world.setBlockMetadataWithNotify(x+3, y+9, z+3, 1, 1);
			world.setBlock(x+7, y+9, z+3, Block.getBlockById(5));
			world.setBlockMetadataWithNotify(x+7, y+9, z+3, 1, 1);
			world.setBlock(x+0, y+9, z+4, Block.getBlockById(5));
			world.setBlock(x+2, y+9, z+4, Block.getBlockById(5));
			world.setBlockMetadataWithNotify(x+2, y+9, z+4, 1, 1);
			world.setBlock(x+5, y+9, z+4, Block.getBlockById(85));
			world.setBlock(x+8, y+9, z+4, Block.getBlockById(5));
			world.setBlockMetadataWithNotify(x+8, y+9, z+4, 1, 1);
			world.setBlock(x+2, y+9, z+5, Block.getBlockById(5));
			world.setBlock(x+4, y+9, z+5, Block.getBlockById(85));
			world.setBlock(x+5, y+9, z+5, Block.getBlockById(85));
			world.setBlock(x+6, y+9, z+5, Block.getBlockById(85));
			world.setBlock(x+8, y+9, z+5, Block.getBlockById(5));
			world.setBlock(x+2, y+9, z+6, Block.getBlockById(5));
			world.setBlockMetadataWithNotify(x+2, y+9, z+6, 1, 1);
			world.setBlock(x+5, y+9, z+6, Block.getBlockById(85));
			world.setBlock(x+8, y+9, z+6, Block.getBlockById(5));
			world.setBlockMetadataWithNotify(x+8, y+9, z+6, 1, 1);
			world.setBlock(x+3, y+9, z+7, Block.getBlockById(5));
			world.setBlockMetadataWithNotify(x+3, y+9, z+7, 1, 1);
			world.setBlock(x+7, y+9, z+7, Block.getBlockById(5));
			world.setBlockMetadataWithNotify(x+7, y+9, z+7, 1, 1);
			world.setBlock(x+0, y+9, z+8, Block.getBlockById(35));
			world.setBlock(x+4, y+9, z+8, Block.getBlockById(5));
			world.setBlockMetadataWithNotify(x+4, y+9, z+8, 1, 1);
			world.setBlock(x+5, y+9, z+8, Block.getBlockById(5));
			world.setBlock(x+6, y+9, z+8, Block.getBlockById(5));
			world.setBlockMetadataWithNotify(x+6, y+9, z+8, 1, 1);
			world.setBlock(x+0, y+9, z+9, Block.getBlockById(5));
			world.setBlock(x+0, y+9, z+10, Block.getBlockById(5));
			world.setBlock(x+5, y+10, z+1, Block.getBlockById(50));
			world.setBlockMetadataWithNotify(x+5, y+10, z+1, 4, 4);
			world.setBlock(x+4, y+10, z+2, Block.getBlockById(5));
			world.setBlockMetadataWithNotify(x+4, y+10, z+2, 1, 1);
			world.setBlock(x+5, y+10, z+2, Block.getBlockById(5));
			world.setBlock(x+6, y+10, z+2, Block.getBlockById(5));
			world.setBlockMetadataWithNotify(x+6, y+10, z+2, 1, 1);
			world.setBlock(x+0, y+10, z+3, Block.getBlockById(35));
			world.setBlock(x+3, y+10, z+3, Block.getBlockById(5));
			world.setBlockMetadataWithNotify(x+3, y+10, z+3, 1, 1);
			world.setBlock(x+7, y+10, z+3, Block.getBlockById(5));
			world.setBlockMetadataWithNotify(x+7, y+10, z+3, 1, 1);
			world.setBlock(x+0, y+10, z+4, Block.getBlockById(5));
			world.setBlock(x+2, y+10, z+4, Block.getBlockById(5));
			world.setBlockMetadataWithNotify(x+2, y+10, z+4, 1, 1);
			world.setBlock(x+8, y+10, z+4, Block.getBlockById(5));
			world.setBlockMetadataWithNotify(x+8, y+10, z+4, 1, 1);
			world.setBlock(x+0, y+10, z+5, Block.getBlockById(5));
			world.setBlock(x+1, y+10, z+5, Block.getBlockById(50));
			world.setBlockMetadataWithNotify(x+1, y+10, z+5, 2, 2);
			world.setBlock(x+2, y+10, z+5, Block.getBlockById(5));
			world.setBlock(x+5, y+10, z+5, Block.getBlockById(85));
			world.setBlock(x+8, y+10, z+5, Block.getBlockById(5));
			world.setBlock(x+9, y+10, z+5, Block.getBlockById(50));
			world.setBlockMetadataWithNotify(x+9, y+10, z+5, 1, 1);
			world.setBlock(x+2, y+10, z+6, Block.getBlockById(5));
			world.setBlockMetadataWithNotify(x+2, y+10, z+6, 1, 1);
			world.setBlock(x+5, y+10, z+6, Block.getBlockById(85));
			world.setBlock(x+8, y+10, z+6, Block.getBlockById(5));
			world.setBlockMetadataWithNotify(x+8, y+10, z+6, 1, 1);
			world.setBlock(x+0, y+10, z+7, Block.getBlockById(35));
			world.setBlock(x+3, y+10, z+7, Block.getBlockById(5));
			world.setBlockMetadataWithNotify(x+3, y+10, z+7, 1, 1);
			world.setBlock(x+7, y+10, z+7, Block.getBlockById(5));
			world.setBlockMetadataWithNotify(x+7, y+10, z+7, 1, 1);
			world.setBlock(x+0, y+10, z+8, Block.getBlockById(5));
			world.setBlock(x+4, y+10, z+8, Block.getBlockById(5));
			world.setBlockMetadataWithNotify(x+4, y+10, z+8, 1, 1);
			world.setBlock(x+5, y+10, z+8, Block.getBlockById(5));
			world.setBlock(x+6, y+10, z+8, Block.getBlockById(5));
			world.setBlockMetadataWithNotify(x+6, y+10, z+8, 1, 1);
			world.setBlock(x+0, y+10, z+9, Block.getBlockById(5));
			world.setBlock(x+5, y+10, z+9, Block.getBlockById(50));
			world.setBlockMetadataWithNotify(x+5, y+10, z+9, 3, 3);
			world.setBlock(x+4, y+11, z+1, Block.getBlockById(134));
			world.setBlockMetadataWithNotify(x+4, y+11, z+1, 2, 2);
			world.setBlock(x+5, y+11, z+1, Block.getBlockById(134));
			world.setBlockMetadataWithNotify(x+5, y+11, z+1, 2, 2);
			world.setBlock(x+6, y+11, z+1, Block.getBlockById(134));
			world.setBlockMetadataWithNotify(x+6, y+11, z+1, 2, 2);
			world.setBlock(x+3, y+11, z+2, Block.getBlockById(134));
			world.setBlockMetadataWithNotify(x+3, y+11, z+2, 2, 2);
			world.setBlock(x+4, y+11, z+2, Block.getBlockById(5));
			world.setBlockMetadataWithNotify(x+4, y+11, z+2, 1, 1);
			world.setBlock(x+5, y+11, z+2, Block.getBlockById(5));
			world.setBlockMetadataWithNotify(x+5, y+11, z+2, 1, 1);
			world.setBlock(x+6, y+11, z+2, Block.getBlockById(5));
			world.setBlockMetadataWithNotify(x+6, y+11, z+2, 1, 1);
			world.setBlock(x+7, y+11, z+2, Block.getBlockById(134));
			world.setBlockMetadataWithNotify(x+7, y+11, z+2, 2, 2);
			world.setBlock(x+2, y+11, z+3, Block.getBlockById(134));
			world.setBlock(x+3, y+11, z+3, Block.getBlockById(5));
			world.setBlockMetadataWithNotify(x+3, y+11, z+3, 1, 1);
			world.setBlock(x+7, y+11, z+3, Block.getBlockById(5));
			world.setBlockMetadataWithNotify(x+7, y+11, z+3, 1, 1);
			world.setBlock(x+8, y+11, z+3, Block.getBlockById(134));
			world.setBlockMetadataWithNotify(x+8, y+11, z+3, 1, 1);
			world.setBlock(x+0, y+11, z+4, Block.getBlockById(35));
			world.setBlock(x+2, y+11, z+4, Block.getBlockById(5));
			world.setBlockMetadataWithNotify(x+2, y+11, z+4, 1, 1);
			world.setBlock(x+5, y+11, z+4, Block.getBlockById(85));
			world.setBlock(x+8, y+11, z+4, Block.getBlockById(5));
			world.setBlockMetadataWithNotify(x+8, y+11, z+4, 1, 1);
			world.setBlock(x+9, y+11, z+4, Block.getBlockById(134));
			world.setBlockMetadataWithNotify(x+9, y+11, z+4, 1, 1);
			world.setBlock(x+0, y+11, z+5, Block.getBlockById(5));
			world.setBlock(x+2, y+11, z+5, Block.getBlockById(5));
			world.setBlock(x+3, y+11, z+5, Block.getBlockById(85));
			world.setBlock(x+4, y+11, z+5, Block.getBlockById(85));
			world.setBlock(x+5, y+11, z+5, Block.getBlockById(85));
			world.setBlock(x+6, y+11, z+5, Block.getBlockById(85));
			world.setBlock(x+8, y+11, z+5, Block.getBlockById(5));
			world.setBlockMetadataWithNotify(x+8, y+11, z+5, 1, 1);
			world.setBlock(x+9, y+11, z+5, Block.getBlockById(134));
			world.setBlockMetadataWithNotify(x+9, y+11, z+5, 1, 1);
			world.setBlock(x+0, y+11, z+6, Block.getBlockById(35));
			world.setBlock(x+2, y+11, z+6, Block.getBlockById(5));
			world.setBlockMetadataWithNotify(x+2, y+11, z+6, 1, 1);
			world.setBlock(x+5, y+11, z+6, Block.getBlockById(85));
			world.setBlock(x+8, y+11, z+6, Block.getBlockById(5));
			world.setBlockMetadataWithNotify(x+8, y+11, z+6, 1, 1);
			world.setBlock(x+9, y+11, z+6, Block.getBlockById(134));
			world.setBlockMetadataWithNotify(x+9, y+11, z+6, 1, 1);
			world.setBlock(x+0, y+11, z+7, Block.getBlockById(5));
			world.setBlock(x+2, y+11, z+7, Block.getBlockById(134));
			world.setBlock(x+3, y+11, z+7, Block.getBlockById(5));
			world.setBlockMetadataWithNotify(x+3, y+11, z+7, 1, 1);
			world.setBlock(x+7, y+11, z+7, Block.getBlockById(5));
			world.setBlockMetadataWithNotify(x+7, y+11, z+7, 1, 1);
			world.setBlock(x+8, y+11, z+7, Block.getBlockById(134));
			world.setBlockMetadataWithNotify(x+8, y+11, z+7, 1, 1);
			world.setBlock(x+0, y+11, z+8, Block.getBlockById(5));
			world.setBlock(x+3, y+11, z+8, Block.getBlockById(134));
			world.setBlockMetadataWithNotify(x+3, y+11, z+8, 3, 3);
			world.setBlock(x+4, y+11, z+8, Block.getBlockById(5));
			world.setBlockMetadataWithNotify(x+4, y+11, z+8, 1, 1);
			world.setBlock(x+5, y+11, z+8, Block.getBlockById(5));
			world.setBlockMetadataWithNotify(x+5, y+11, z+8, 1, 1);
			world.setBlock(x+6, y+11, z+8, Block.getBlockById(5));
			world.setBlockMetadataWithNotify(x+6, y+11, z+8, 1, 1);
			world.setBlock(x+7, y+11, z+8, Block.getBlockById(134));
			world.setBlockMetadataWithNotify(x+7, y+11, z+8, 3, 3);
			world.setBlock(x+4, y+11, z+9, Block.getBlockById(134));
			world.setBlockMetadataWithNotify(x+4, y+11, z+9, 3, 3);
			world.setBlock(x+5, y+11, z+9, Block.getBlockById(134));
			world.setBlockMetadataWithNotify(x+5, y+11, z+9, 3, 3);
			world.setBlock(x+6, y+11, z+9, Block.getBlockById(134));
			world.setBlockMetadataWithNotify(x+6, y+11, z+9, 3, 3);
			world.setBlock(x+4, y+12, z+2, Block.getBlockById(134));
			world.setBlockMetadataWithNotify(x+4, y+12, z+2, 2, 2);
			world.setBlock(x+5, y+12, z+2, Block.getBlockById(134));
			world.setBlockMetadataWithNotify(x+5, y+12, z+2, 2, 2);
			world.setBlock(x+6, y+12, z+2, Block.getBlockById(134));
			world.setBlockMetadataWithNotify(x+6, y+12, z+2, 2, 2);
			world.setBlock(x+0, y+12, z+3, Block.getBlockById(5));
			world.setBlock(x+3, y+12, z+3, Block.getBlockById(125));
			world.setBlockMetadataWithNotify(x+3, y+12, z+3, 1, 1);
			world.setBlock(x+4, y+12, z+3, Block.getBlockById(5));
			world.setBlockMetadataWithNotify(x+4, y+12, z+3, 1, 1);
			world.setBlock(x+5, y+12, z+3, Block.getBlockById(5));
			world.setBlockMetadataWithNotify(x+5, y+12, z+3, 1, 1);
			world.setBlock(x+6, y+12, z+3, Block.getBlockById(5));
			world.setBlockMetadataWithNotify(x+6, y+12, z+3, 1, 1);
			world.setBlock(x+7, y+12, z+3, Block.getBlockById(125));
			world.setBlockMetadataWithNotify(x+7, y+12, z+3, 1, 1);
			world.setBlock(x+0, y+12, z+4, Block.getBlockById(5));
			world.setBlock(x+2, y+12, z+4, Block.getBlockById(134));
			world.setBlock(x+3, y+12, z+4, Block.getBlockById(5));
			world.setBlockMetadataWithNotify(x+3, y+12, z+4, 1, 1);
			world.setBlock(x+7, y+12, z+4, Block.getBlockById(5));
			world.setBlockMetadataWithNotify(x+7, y+12, z+4, 1, 1);
			world.setBlock(x+8, y+12, z+4, Block.getBlockById(134));
			world.setBlockMetadataWithNotify(x+8, y+12, z+4, 1, 1);
			world.setBlock(x+0, y+12, z+5, Block.getBlockById(17));
			world.setBlockMetadataWithNotify(x+0, y+12, z+5, 4, 4);
			world.setBlock(x+1, y+12, z+5, Block.getBlockById(85));
			world.setBlock(x+2, y+12, z+5, Block.getBlockById(5));
			world.setBlock(x+3, y+12, z+5, Block.getBlockById(5));
			world.setBlockMetadataWithNotify(x+3, y+12, z+5, 1, 1);
			world.setBlock(x+5, y+12, z+5, Block.getBlockById(89));
			world.setBlock(x+7, y+12, z+5, Block.getBlockById(5));
			world.setBlockMetadataWithNotify(x+7, y+12, z+5, 1, 1);
			world.setBlock(x+8, y+12, z+5, Block.getBlockById(134));
			world.setBlockMetadataWithNotify(x+8, y+12, z+5, 1, 1);
			world.setBlock(x+0, y+12, z+6, Block.getBlockById(5));
			world.setBlock(x+2, y+12, z+6, Block.getBlockById(134));
			world.setBlock(x+3, y+12, z+6, Block.getBlockById(5));
			world.setBlockMetadataWithNotify(x+3, y+12, z+6, 1, 1);
			world.setBlock(x+7, y+12, z+6, Block.getBlockById(5));
			world.setBlockMetadataWithNotify(x+7, y+12, z+6, 1, 1);
			world.setBlock(x+8, y+12, z+6, Block.getBlockById(134));
			world.setBlockMetadataWithNotify(x+8, y+12, z+6, 1, 1);
			world.setBlock(x+0, y+12, z+7, Block.getBlockById(5));
			world.setBlock(x+3, y+12, z+7, Block.getBlockById(125));
			world.setBlockMetadataWithNotify(x+3, y+12, z+7, 1, 1);
			world.setBlock(x+4, y+12, z+7, Block.getBlockById(5));
			world.setBlockMetadataWithNotify(x+4, y+12, z+7, 1, 1);
			world.setBlock(x+5, y+12, z+7, Block.getBlockById(5));
			world.setBlockMetadataWithNotify(x+5, y+12, z+7, 1, 1);
			world.setBlock(x+6, y+12, z+7, Block.getBlockById(5));
			world.setBlockMetadataWithNotify(x+6, y+12, z+7, 1, 1);
			world.setBlock(x+7, y+12, z+7, Block.getBlockById(125));
			world.setBlockMetadataWithNotify(x+7, y+12, z+7, 1, 1);
			world.setBlock(x+4, y+12, z+8, Block.getBlockById(134));
			world.setBlockMetadataWithNotify(x+4, y+12, z+8, 3, 3);
			world.setBlock(x+5, y+12, z+8, Block.getBlockById(134));
			world.setBlockMetadataWithNotify(x+5, y+12, z+8, 3, 3);
			world.setBlock(x+6, y+12, z+8, Block.getBlockById(134));
			world.setBlockMetadataWithNotify(x+6, y+12, z+8, 3, 3);
			world.setBlock(x+0, y+13, z+2, Block.getBlockById(5));
			world.setBlock(x+0, y+13, z+3, Block.getBlockById(5));
			world.setBlock(x+4, y+13, z+3, Block.getBlockById(134));
			world.setBlockMetadataWithNotify(x+4, y+13, z+3, 2, 2);
			world.setBlock(x+5, y+13, z+3, Block.getBlockById(134));
			world.setBlockMetadataWithNotify(x+5, y+13, z+3, 2, 2);
			world.setBlock(x+6, y+13, z+3, Block.getBlockById(134));
			world.setBlockMetadataWithNotify(x+6, y+13, z+3, 2, 2);
			world.setBlock(x+0, y+13, z+4, Block.getBlockById(35));
			world.setBlock(x+3, y+13, z+4, Block.getBlockById(134));
			world.setBlock(x+7, y+13, z+4, Block.getBlockById(134));
			world.setBlockMetadataWithNotify(x+7, y+13, z+4, 1, 1);
			world.setBlock(x+0, y+13, z+5, Block.getBlockById(5));
			world.setBlock(x+3, y+13, z+5, Block.getBlockById(134));
			world.setBlock(x+5, y+13, z+5, Block.getBlockById(89));
			world.setBlock(x+7, y+13, z+5, Block.getBlockById(134));
			world.setBlockMetadataWithNotify(x+7, y+13, z+5, 1, 1);
			world.setBlock(x+0, y+13, z+6, Block.getBlockById(35));
			world.setBlock(x+3, y+13, z+6, Block.getBlockById(134));
			world.setBlock(x+7, y+13, z+6, Block.getBlockById(134));
			world.setBlockMetadataWithNotify(x+7, y+13, z+6, 1, 1);
			world.setBlock(x+4, y+13, z+7, Block.getBlockById(134));
			world.setBlockMetadataWithNotify(x+4, y+13, z+7, 3, 3);
			world.setBlock(x+5, y+13, z+7, Block.getBlockById(134));
			world.setBlockMetadataWithNotify(x+5, y+13, z+7, 3, 3);
			world.setBlock(x+6, y+13, z+7, Block.getBlockById(134));
			world.setBlockMetadataWithNotify(x+6, y+13, z+7, 3, 3);
			world.setBlock(x+0, y+14, z+1, Block.getBlockById(5));
			world.setBlock(x+0, y+14, z+2, Block.getBlockById(5));
			world.setBlock(x+0, y+14, z+3, Block.getBlockById(35));
			world.setBlock(x+4, y+14, z+4, Block.getBlockById(126));
			world.setBlockMetadataWithNotify(x+4, y+14, z+4, 1, 1);
			world.setBlock(x+5, y+14, z+4, Block.getBlockById(134));
			world.setBlockMetadataWithNotify(x+5, y+14, z+4, 2, 2);
			world.setBlock(x+6, y+14, z+4, Block.getBlockById(126));
			world.setBlockMetadataWithNotify(x+6, y+14, z+4, 1, 1);
			world.setBlock(x+0, y+14, z+5, Block.getBlockById(5));
			world.setBlock(x+4, y+14, z+5, Block.getBlockById(134));
			world.setBlock(x+5, y+14, z+5, Block.getBlockById(5));
			world.setBlockMetadataWithNotify(x+5, y+14, z+5, 1, 1);
			world.setBlock(x+6, y+14, z+5, Block.getBlockById(134));
			world.setBlockMetadataWithNotify(x+6, y+14, z+5, 1, 1);
			world.setBlock(x+0, y+14, z+6, Block.getBlockById(5));
			world.setBlock(x+4, y+14, z+6, Block.getBlockById(126));
			world.setBlockMetadataWithNotify(x+4, y+14, z+6, 1, 1);
			world.setBlock(x+5, y+14, z+6, Block.getBlockById(134));
			world.setBlockMetadataWithNotify(x+5, y+14, z+6, 3, 3);
			world.setBlock(x+6, y+14, z+6, Block.getBlockById(126));
			world.setBlockMetadataWithNotify(x+6, y+14, z+6, 1, 1);
			world.setBlock(x+0, y+14, z+7, Block.getBlockById(35));
			world.setBlock(x+0, y+15, z+0, Block.getBlockById(5));
			world.setBlock(x+0, y+15, z+1, Block.getBlockById(5));
			world.setBlock(x+0, y+15, z+2, Block.getBlockById(35));
			world.setBlock(x+5, y+15, z+5, Block.getBlockById(5));
			world.setBlockMetadataWithNotify(x+5, y+15, z+5, 1, 1);
			world.setBlock(x+0, y+15, z+6, Block.getBlockById(5));
			world.setBlock(x+0, y+15, z+7, Block.getBlockById(5));
			world.setBlock(x+0, y+15, z+8, Block.getBlockById(35));
			world.setBlock(x+0, y+16, z+0, Block.getBlockById(5));
			world.setBlock(x+0, y+16, z+1, Block.getBlockById(35));
			world.setBlock(x+0, y+16, z+7, Block.getBlockById(5));
			world.setBlock(x+0, y+16, z+8, Block.getBlockById(5));
			world.setBlock(x+0, y+16, z+9, Block.getBlockById(35));
			world.setBlock(x+0, y+17, z+0, Block.getBlockById(35));
			world.setBlock(x+0, y+17, z+8, Block.getBlockById(5));
			world.setBlock(x+0, y+17, z+9, Block.getBlockById(5));
			world.setBlock(x+0, y+17, z+10, Block.getBlockById(35));
		}

}
